Workbook

Sheet EBIDTA
B3: Name of the Company : - KPW I (2026-27)
B5: Particulars | C5: AUGUST.26 | D5: % | E5: JULY.26 | F5: % | G5: JUNE.26 | H5: % | I5: MAY.26 | J5: % | K5: APRIL.26 | L5: % | M5: YTD AUGUST.26 | N5: % | O5: YTD JULY.26 | P5: % | Q5: YTD JUNE.26 | R5: % | S5: YTD MAY.26 | T5: % | U5: YTD APRIL.26 | V5: % | X5: Particulars | Y5: AUGUST.26 | Z5: JULY.26 | AA5: JUNE.26 | AB5: MAY.26 | AC5: APRIL.26 | AF5: APRIL.26 | AG5: MAY.26 | AH5: JUNE.26 | AI5: JULY.26 | AJ5: AUG..26
B6: Revenue from operations | X6: Inventory at the beginning of the year:
B7: Sale of finished goods | C7: =M7-O7 -> 2.5754881e+08 | D7: =C7/$C$30 -> 0.86984527 | E7: =O7-Q7 -> 2.3382328e+08 | F7: =E7/$E$30 -> 0.93667298 | G7: =Q7-S7 -> 1.7991097e+08 | H7: =(G7/$G$30) -> 0.89920522 | I7: =S7-U7 -> 1.9791503e+08 | J7: =(I7/$I$30) -> 0.97072984 | K7: =U7 -> 1.7902816e+08 | L7: =(K7/$K$30) -> 0.97738124 | M7: =-SUMIF('AUGUST - TB'!H:H,EBIDTA!B7,'AUGUST - TB'!G:G) -> 1.0482262e+09 | N7: =M7/$M$30 -> 0.92530076 | O7: =-SUMIF('JULY-TB'!H:H,EBIDTA!B7,'JULY-TB'!G:G) -> 7.9067744e+08 | P7: =O7/$O$30 -> 0.94492349 | Q7: =-SUMIF('JUNE - TB -'!H:H,EBIDTA!B7,'JUNE - TB -'!G:G) -> 5.5685415e+08 | R7: =(Q7/$Q$30) -> 0.94843137 | S7: =-SUMIF('MAY- TB - '!H:H,EBIDTA!B7,'MAY- TB - '!E:E) -> 3.7694318e+08 | T7: =(S7/$S$30) -> 0.97387758 | U7: =-SUMIF('APRIL - TB -'!H:H,EBIDTA!B7,'APRIL - TB -'!G:G) -> 1.7902816e+08 | V7: =(U7/$U$30) -> 0.97738124 | X7: Opening Stock of Raw material | Y7: =Z7 -> 78409106 | Z7: =AA7 -> 78409106 | AA7: =AB7 -> 78409106 | AB7: =AC7 -> 78409106 | AC7: ='Stock Sheet - KPW'!O5 -> 78409106
B8: Sale of traded goods | C8: =M8-O8 -> 3350474.1 | D8: =C8/$C$30 -> 0.01131589 | E8: =O8-Q8 -> 919114.45 | F8: =E8/$E$30 -> 0.0036818817 | G8: =Q8-S8 -> 443540 | H8: =(G8/$G$30) -> 0.002216838 | I8: =S8-U8 -> 691772.73 | J8: =(I8/$I$30) -> 0.0033929937 | K8: =U8 -> 4108107.4 | L8: =(K8/$K$30) -> 0.022427685 | M8: =-SUMIF('AUGUST - TB'!H:H,EBIDTA!B8,'AUGUST - TB'!G:G) -> 9513008.6 | N8: =M8/$M$30 -> 0.0083974181 | O8: =-SUMIF('JULY-TB'!H:H,EBIDTA!B8,'JULY-TB'!G:G) -> 6162534.5 | P8: =O8/$O$30 -> 0.0073647272 | Q8: =-SUMIF('JUNE - TB -'!H:H,EBIDTA!B8,'JUNE - TB -'!G:G) -> 5243420.1 | R8: =(Q8/$Q$30) -> 0.0089305683 | S8: =-SUMIF('MAY- TB - '!H:H,EBIDTA!B8,'MAY- TB - '!E:E) -> 4799880.1 | T8: =(S8/$S$30) -> 0.012401062 | U8: =-SUMIF('APRIL - TB -'!H:H,EBIDTA!B8,'APRIL - TB -'!G:G) -> 4108107.4 | V8: =(U8/$U$30) -> 0.022427685 | X8: Opening Stock of Packing material | AC8: 0
B9: Total Revenue from operations | C9: =SUM(C7:C8) -> 2.6089929e+08 | D9: =C9/$C$30 -> 0.88116116 | E9: =SUM(E7:E8) -> 2.347424e+08 | F9: =E9/$E$30 -> 0.94035486 | G9: =SUM(G7:G8) -> 1.8035451e+08 | H9: =(G9/$G$30) -> 0.90142206 | I9: =SUM(I7:I8) -> 1.986068e+08 | J9: =(I9/$I$30) -> 0.97412284 | K9: =SUM(K7:K8) -> 1.8313626e+08 | L9: =(K9/$K$30) -> 0.99980892 | M9: =SUM(M7:M8) -> 1.0577393e+09 | N9: =M9/$M$30 -> 0.93369818 | O9: =SUM(O7:O8) -> 7.9683997e+08 | P9: =O9/$O$30 -> 0.95228821 | Q9: =SUM(Q7:Q8) -> 5.6209757e+08 | R9: =(Q9/$Q$30) -> 0.95736194 | S9: =SUM(S7:S8) -> 381743062 | T9: =(S9/$S$30) -> 0.98627864 | U9: =SUM(U7:U8) -> 1.8313626e+08 | V9: =(U9/$U$30) -> 0.99980892
X10: Add: Purchase of raw materials | Y10: =SUMIF('AUGUST - TB'!H:H,EBIDTA!X10,'AUGUST - TB'!G:G) -> 6.8290635e+08 | Z10: =SUMIF('JULY-TB'!H:H,EBIDTA!X10,'JULY-TB'!G:G) -> 4.8088707e+08 | AA10: =SUMIF('JUNE - TB -'!H1:H1325,EBIDTA!X10,'JUNE - TB -'!G1:G1325) -> 2.8824663e+08 | AB10: =SUMIF('MAY- TB - '!H1:H1317,EBIDTA!X10,'MAY- TB - '!G1:G1317) -> 1.769685e+08 | AC10: =SUMIF('APRIL - TB -'!H2:H1238,EBIDTA!X10,'APRIL - TB -'!G2:G1231) -> 1.2064284e+08 | AF10: =AC10/10^7 -> 12.064284 | AG10: =(AB10-AF10)/10^7 -> 17.696849 | AH10: =(AA10-AB10)/10^7 -> 11.127812 | AI10: =(Z10-AA10)/10^7 -> 19.264044 | AJ10: =(Y10-Z10)/10^7 -> 20.201928
B11: Income from Jobwork charges | C11: =M11-O11 -> 34912345 | E11: =O11-Q11 -> 13688319 | G11: =Q11-S11 -> 17493444 | I11: =S11-U11 -> 5117576 | K11: =U11 -> 0 | M11: =-SUMIF('AUGUST - TB'!H:H,EBIDTA!B11,'AUGUST - TB'!G:G) -> 71211684 | O11: =-SUMIF('JULY-TB'!H:H,EBIDTA!B11,'JULY-TB'!G:G) -> 36299339 | Q11: =-SUMIF('JUNE - TB -'!H:H,EBIDTA!B11,'JUNE - TB -'!G:G) -> 22611020 | S11: =-SUMIF('MAY- TB - '!H:H,EBIDTA!B11,'MAY- TB - '!E:E) -> 5117576 | U11: =-SUMIF('APRIL - TB -'!H:H,EBIDTA!B11,'APRIL - TB -'!G:G) -> 0 | X11: Add: Purchase of packing materials | Y11: =SUMIF('AUGUST - TB'!H:H,EBIDTA!X11,'AUGUST - TB'!G:G) -> 7638900.9 | Z11: =SUMIF('JULY-TB'!H:H,EBIDTA!X11,'JULY-TB'!G:G) -> 6188686.3 | AA11: =SUMIF('JUNE - TB -'!H2:H1326,EBIDTA!X11,'JUNE - TB -'!G2:G1326) -> 3902200.5 | AB11: =SUMIF('MAY- TB - '!H2:H1318,EBIDTA!X11,'MAY- TB - '!G2:G1318) -> 2830055.7 | AC11: =SUMIF('APRIL - TB -'!H3:H1239,EBIDTA!X11,'APRIL - TB -'!G3:G1232) -> 1127244.8 | AF11: =AC11/10^7 -> 0.11272448 | AG11: =(AB11-AF11)/10^7 -> 0.28300556 | AH11: =(AA11-AB11)/10^7 -> 0.10721448 | AI11: =(Z11-AA11)/10^7 -> 0.22864858 | AJ11: =(Y11-Z11)/10^7 -> 0.14502146
B12: Total Sales of services | C12: =SUM(C10:C11) -> 34912345 | D12: =C12/$C$30 -> 0.11791294 | E12: =SUM(E10:E11) -> 13688319 | F12: =E12/$E$30 -> 0.054834054 | G12: =SUM(G10:G11) -> 17493444 | H12: =(G12/$G$30) -> 0.087433223 | I12: =SUM(I10:I11) -> 5117576 | J12: =(I12/$I$30) -> 0.025100589 | K12: =SUM(K10:K11) -> 0 | L12: =(K12/$K$30) -> 0 | M12: =SUM(M10:M11) -> 71211684 | N12: =M12/$M$30 -> 0.06286069 | O12: =SUM(O10:O11) -> 36299339 | P12: =O12/$O$30 -> 0.043380646 | Q12: =SUM(Q10:Q11) -> 22611020 | S12: =SUM(S10:S11) -> 5117576 | T12: =(S12/$S$30) -> 0.013221867 | U12: =SUM(U10:U11) -> 0 | V12: =(U12/$U$30) -> 0 | X12: Add: Purchase expenses | Y12: =SUMIF('AUGUST - TB'!H:H,EBIDTA!X12,'AUGUST - TB'!G:G) -> 6533679.1 | Z12: =SUMIF('JULY-TB'!H:H,EBIDTA!X12,'JULY-TB'!G:G) -> 5898962.8 | AA12: =SUMIF('JUNE - TB -'!H3:H1329,EBIDTA!X12,'JUNE - TB -'!G3:G1329) -> 6340260.4 | AB12: =SUMIF('MAY- TB - '!H3:H1319,EBIDTA!X12,'MAY- TB - '!G3:G1319) -> 5936506 | AC12: =SUMIF('APRIL - TB -'!H4:H1240,EBIDTA!X12,'APRIL - TB -'!G4:G1233) -> 3603365.7 | AF12: =AC12/10^7 -> 0.36033657 | AG12: =(AB12-AF12)/10^7 -> 0.59365057 | AH12: =(AA12-AB12)/10^7 -> 0.040375438 | AI12: =(Z12-AA12)/10^7 -> -0.044129762 | AJ12: =(Y12-Z12)/10^7 -> 0.063471632
B13: Other operating revenue | G13: =Q13-S13 -> 0 | I13: =S13-U13 -> 0 | Q13: =-SUMIF('JUNE - TB -'!H:H,EBIDTA!B13,'JUNE - TB -'!G:G) -> 0 | U13: =-SUMIF('APRIL - TB -'!H:H,EBIDTA!B13,'APRIL - TB -'!G:G) -> 0 | X13: Closing Stock of Raw material | Y13: ='Stock Sheet - KPW'!T5 -> 1.1168642e+08 | Z13: ='Stock Sheet - KPW'!S5 -> 84892889 | AA13: ='Stock Sheet - KPW'!R5 -> 63882998 | AB13: ='Stock Sheet - KPW'!Q5 -> 78548384 | AC13: ='Stock Sheet - KPW'!P5 -> 1.1669902e+08 | AF13: =AC13/10^7 -> 11.669902 | AG13: =(AB13-AF13)/10^7 -> 7.8548373 | AH13: =(AA13-AB13)/10^7 -> -1.4665386 | AI13: =(Z13-AA13)/10^7 -> 2.1009891 | AJ13: =(Y13-Z13)/10^7 -> 2.6793533
B14: Export incentives | C14: =M14-O14 -> 0 | G14: =Q14-S14 -> 0 | I14: =S14-U14 -> 0 | K14: =U14 -> 0 | M14: =-SUMIF('AUGUST - TB'!H:H,EBIDTA!B14,'AUGUST - TB'!G:G) -> 0 | O14: =-SUMIF('JULY-TB'!H:H,EBIDTA!B14,'JULY-TB'!G:G) -> 0 | Q14: =-SUMIF('JUNE - TB -'!H:H,EBIDTA!B14,'JUNE - TB -'!G:G) -> 0 | S14: =-SUMIF('MAY- TB - '!H:H,EBIDTA!B14,'MAY- TB - '!E:E) -> 0 | U14: =-SUMIF('APRIL - TB -'!H:H,EBIDTA!B14,'APRIL - TB -'!G:G) -> 0 | X14: Closing Stock of Packing material | AB14: 0 | AC14: 0
B15: Commission income | C15: =M15-O15 -> 0 | G15: =Q15-S15 -> 0 | I15: =S15-U15 -> 0 | K15: =U15 -> 0 | M15: =-SUMIF('AUGUST - TB'!H:H,EBIDTA!B15,'AUGUST - TB'!G:G) -> 0 | O15: =-SUMIF('JULY-TB'!H:H,EBIDTA!B15,'JULY-TB'!G:G) -> 0 | Q15: =-SUMIF('JUNE - TB -'!H:H,EBIDTA!B15,'JUNE - TB -'!G:G) -> 0 | S15: =-SUMIF('MAY- TB - '!H:H,EBIDTA!B15,'MAY- TB - '!E:E) -> 0 | U15: =-SUMIF('APRIL - TB -'!H:H,EBIDTA!B15,'APRIL - TB -'!G:G) -> 0 | X15: Total Cost of material consumed | Y15: =Y7+Y8+Y10+Y11+Y12-Y13 -> 6.6380162e+08 | Z15: =Z7+Z8+Z10+Z11+Z12-Z13 -> 4.8649093e+08 | AA15: =AA7+AA8+AA10+AA11+AA12-AA13 -> 3.130152e+08 | AB15: =AB7+AB8+AB10+AB11+AB12-AB13 -> 1.8559579e+08 | AC15: =AC7+AC8+AC10+AC11+AC12-AC13 -> 87083536 | AF15: =AC15/10^7 -> 8.7083536 | AG15: =(AB15-AF15)/10^7 -> 18.559578 | AH15: =(AA15-AB15)/10^7 -> 12.741941 | AI15: =(Z15-AA15)/10^7 -> 17.347574 | AJ15: =(Y15-Z15)/10^7 -> 17.731068
B16: Sales - Waste & Scrape | C16: =M16-O16 -> 274145 | E16: =O16-Q16 -> 814311.7 | G16: =Q16-S16 -> 1988550 | I16: =S16-U16 -> 358330 | K16: =U16 -> 35000 | M16: =-SUMIF('AUGUST - TB'!H:H,EBIDTA!B16,'AUGUST - TB'!G:G) -> 3470336.7 | O16: =-SUMIF('JULY-TB'!H:H,EBIDTA!B16,'JULY-TB'!G:G) -> 3196191.7 | Q16: =-SUMIF('JUNE - TB -'!H:H,EBIDTA!B16,'JUNE - TB -'!G:G) -> 2381880 | S16: =-SUMIF('MAY- TB - '!H:H,EBIDTA!B16,'MAY- TB - '!E:E) -> 393330 | U16: =-SUMIF('APRIL - TB -'!H:H,EBIDTA!B16,'APRIL - TB -'!G:G) -> 35000
B17: Total Other operating revenue | C17: =SUM(C14:C16) -> 274145 | D17: =C17/$C$30 -> 0.00092589723 | E17: =SUM(E14:E16) -> 814311.7 | F17: =E17/$E$30 -> 0.0032620523 | G17: =SUM(G14:G16) -> 1988550 | H17: =(G17/$G$30) -> 0.0099388854 | I17: =SUM(I14:I16) -> 358330 | J17: =(I17/$I$30) -> 0.0017575301 | K17: =SUM(K14:K16) -> 35000 | L17: =(K17/$K$30) -> 0.00019107801 | M17: =SUM(M14:M16) -> 3470336.7 | N17: =M17/$M$30 -> 0.0030633703 | O17: =SUM(O14:O16) -> 3196191.7 | P17: =O17/$O$30 -> 0.0038197076 | Q17: =SUM(Q14:Q16) -> 2381880 | R17: =(Q17/$Q$30) -> 0.0040568068 | S17: =SUM(S14:S16) -> 393330 | T17: =(S17/$S$30) -> 0.0010162149 | U17: =SUM(U14:U16) -> 35000 | V17: =(U17/$U$30) -> 0.00019107801 | X17: Changes in inventory of finished goods and work-in-progress
B18: Other income | X18: Inventory at the beginning of the year:
B19: Interest income: | C19: =M19-O19 -> 0 | E19: =O19-Q19 -> 0 | G19: =Q19-S19 -> 0 | I19: =S19-U19 -> 0 | M19: =-SUMIF('AUGUST - TB'!H:H,EBIDTA!B19,'AUGUST - TB'!G:G) -> 0 | O19: =-SUMIF('JULY-TB'!H:H,EBIDTA!B19,'JULY-TB'!G:G) -> 0 | Q19: =-SUMIF('JUNE - TB -'!H:H,EBIDTA!B19,'JUNE - TB -'!G:G) -> 0 | S19: =-SUMIF('MAY- TB - '!H:H,EBIDTA!B19,'MAY- TB - '!E:E) -> 0 | U19: =-SUMIF('APRIL - TB -'!H:H,EBIDTA!B19,'APRIL - TB -'!G:G) -> 0 | X19: Opening Work-in-progress | Y19: 0 | Z19: 0 | AA19: 0 | AB19: 0 | AC19: 0
B20: - on fixed deposits with Banks | C20: =M20-O20 -> 0 | E20: =O20-Q20 -> 0 | G20: =Q20-S20 -> 0 | I20: =S20-U20 -> 0 | K20: =U20 -> 0 | M20: =-SUMIF('AUGUST - TB'!H:H,EBIDTA!B20,'AUGUST - TB'!G:G) -> 0 | O20: =-SUMIF('JULY-TB'!H:H,EBIDTA!B20,'JULY-TB'!G:G) -> 0 | Q20: =-SUMIF('JUNE - TB -'!H:H,EBIDTA!B20,'JUNE - TB -'!G:G) -> 0 | S20: =-SUMIF('MAY- TB - '!H:H,EBIDTA!B20,'MAY- TB - '!E:E) -> 0 | U20: =-SUMIF('APRIL - TB -'!H:H,EBIDTA!B20,'APRIL - TB -'!G:G) -> 0 | X20: Opening Stock of Finished goods | Y20: =Z20 -> 2.0644672e+08 | Z20: =AA20 -> 2.0644672e+08 | AA20: =AB20 -> 2.0644672e+08 | AB20: =AC20 -> 2.0644672e+08 | AC20: ='Stock Sheet - KPW'!O10 -> 2.0644672e+08 | AF20: =AC20/10^7 -> 20.644672 | AG20: 20.644672 | AH20: 20.644672 | AI20: 20.644672 | AJ20: 20.644672
B21: Wind mill income | C21: =M21-O21 -> 0 | E21: =O21-Q21 -> 0 | G21: =Q21-S21 -> 0 | I21: =S21-U21 -> 0 | K21: =U21 -> 0 | M21: =-SUMIF('AUGUST - TB'!H:H,EBIDTA!B21,'AUGUST - TB'!G:G) -> 0 | O21: =-SUMIF('JULY-TB'!H:H,EBIDTA!B21,'JULY-TB'!G:G) -> 0 | Q21: =-SUMIF('JUNE - TB -'!H:H,EBIDTA!B21,'JUNE - TB -'!G:G) -> 0 | S21: =-SUMIF('MAY- TB - '!H:H,EBIDTA!B21,'MAY- TB - '!E:E) -> 0 | U21: =-SUMIF('APRIL - TB -'!H:H,EBIDTA!B21,'APRIL - TB -'!G:G) -> 0
B22: Rent Income | C22: =M22-O22 -> 0 | E22: =O22-Q22 -> 0 | G22: =Q22-S22 -> 0 | I22: =S22-U22 -> -200000 | K22: =U22 -> 0 | M22: =-SUMIF('AUGUST - TB'!H:H,EBIDTA!B22,'AUGUST - TB'!G:G) -> -200000 | O22: =-SUMIF('JULY-TB'!H:H,EBIDTA!B22,'JULY-TB'!G:G) -> -200000 | Q22: =-SUMIF('JUNE - TB -'!H:H,EBIDTA!B22,'JUNE - TB -'!G:G) -> -200000 | S22: =-SUMIF('MAY- TB - '!H:H,EBIDTA!B22,'MAY- TB - '!E:E) -> -200000 | U22: =-SUMIF('APRIL - TB -'!H:H,EBIDTA!B22,'APRIL - TB -'!G:G) -> 0 | X22: Less:Inventory at the end of the year:
B23: Advance License Utilization | C23: =M23-O23 -> 0 | E23: =O23-Q23 -> 0 | G23: =Q23-S23 -> 0 | I23: =S23-U23 -> 0 | K23: =U23 -> 0 | M23: =-SUMIF('AUGUST - TB'!H:H,EBIDTA!B23,'AUGUST - TB'!G:G) -> 0 | O23: =-SUMIF('JULY-TB'!H:H,EBIDTA!B23,'JULY-TB'!G:G) -> 0 | Q23: =-SUMIF('JUNE - TB -'!H:H,EBIDTA!B23,'JUNE - TB -'!G:G) -> 0 | S23: =-SUMIF('MAY- TB - '!H:H,EBIDTA!B23,'MAY- TB - '!E:E) -> 0 | U23: =-SUMIF('APRIL - TB -'!H:H,EBIDTA!B23,'APRIL - TB -'!G:G) -> 0 | X23: Closing Stock of Finished goods | Y23: ='Stock Sheet - KPW'!T10 -> 1.7394276e+08 | Z23: ='Stock Sheet - KPW'!S10 -> 1.7503296e+08 | AA23: ='Stock Sheet - KPW'!R10 -> 1.8609886e+08 | AB23: ='Stock Sheet - KPW'!Q10 -> 1.7228635e+08 | AC23: ='Stock Sheet - KPW'!P10 -> 1.7144735e+08 | AF23: =(AC20-AC23)/10^7 -> 3.4999374 | AG23: =(AB23-AC23)/10^7 -> 0.083900428 | AH23: =(AA23-AB23)/10^7 -> 1.3812508 | AI23: =(Z23-AA23)/10^7 -> -1.1065904 | AJ23: =(Y23-Z23)/10^7 -> -0.10901962
B24: Profit on sale of fixed assets | C24: =M24-O24 -> 0 | E24: =O24-Q24 -> 386687 | G24: =Q24-S24 -> -313071.41 | I24: =S24-U24 -> 0 | K24: =U24 -> 0 | M24: =-SUMIF('AUGUST - TB'!H:H,EBIDTA!B24,'AUGUST - TB'!G:G) -> 73615.59 | O24: =-SUMIF('JULY-TB'!H:H,EBIDTA!B24,'JULY-TB'!G:G) -> 73615.59 | Q24: =-SUMIF('JUNE - TB -'!H:H,EBIDTA!B24,'JUNE - TB -'!G:G) -> -313071.41 | S24: =-SUMIF('MAY- TB - '!H:H,EBIDTA!B24,'MAY- TB - '!E:E) -> 0 | U24: =-SUMIF('APRIL - TB -'!H:H,EBIDTA!B24,'APRIL - TB -'!G:G) -> 0 | X24: Closing Stock of Finished goods
B25: Profit on sale of investments | C25: =M25-O25 -> 0 | E25: =O25-Q25 -> 0 | G25: =Q25-S25 -> 0 | I25: =S25-U25 -> 0 | K25: =U25 -> 0 | M25: =-SUMIF('AUGUST - TB'!H:H,EBIDTA!B25,'AUGUST - TB'!G:G) -> 0 | O25: =-SUMIF('JULY-TB'!H:H,EBIDTA!B25,'JULY-TB'!G:G) -> 0 | Q25: =-SUMIF('JUNE - TB -'!H:H,EBIDTA!B25,'JUNE - TB -'!G:G) -> 0 | S25: =-SUMIF('MAY- TB - '!H:H,EBIDTA!B25,'MAY- TB - '!E:E) -> 0 | U25: =-SUMIF('APRIL - TB -'!H:H,EBIDTA!B25,'APRIL - TB -'!G:G) -> 0 | X25: Net change in inventory | Y25: =(Y19+Y20)-(Y23+Y24) -> 32503962 | Z25: =(Z19+Z20)-(Z23+Z24) -> 31413765 | AA25: =(AA19+AA20)-(AA23+AA24) -> 20347861 | AB25: =(AB19+AB20)-(AB23+AB24) -> 34160369 | AC25: =(AC19+AC20)-(AC23+AC24) -> 34999374 | AF25: =AC25/10^7 -> 3.4999374 | AG25: =(AB25-AF25)/10^7 -> 3.4160366 | AH25: =(AA25-AB25)/10^7 -> -1.3812508 | AI25: =(Z25-AA25)/10^7 -> 1.1065904 | AJ25: =(Y25-Z25)/10^7 -> 0.10901962
B26: Sundry balance written off | C26: =M26-O26 -> 0 | E26: =O26-Q26 -> 0 | G26: =Q26-S26 -> 554332.08 | I26: =S26-U26 -> 0 | K26: =U26 -> 0 | M26: =-SUMIF('AUGUST - TB'!H:H,EBIDTA!B26,'AUGUST - TB'!G:G) -> 554332.08 | O26: =-SUMIF('JULY-TB'!H:H,EBIDTA!B26,'JULY-TB'!G:G) -> 554332.08 | Q26: =-SUMIF('JUNE - TB -'!H:H,EBIDTA!B26,'JUNE - TB -'!G:G) -> 554332.08 | S26: =-SUMIF('MAY- TB - '!H:H,EBIDTA!B26,'MAY- TB - '!E:E) -> 0 | U26: =-SUMIF('APRIL - TB -'!H:H,EBIDTA!B26,'APRIL - TB -'!G:G) -> 0
B27: Miscellaneous income | C27: =M27-O27 -> 0 | E27: =O27-Q27 -> 0 | G27: =Q27-S27 -> 0 | I27: =S27-U27 -> 0 | K27: =U27 -> 0 | M27: =-SUMIF('AUGUST - TB'!H:H,EBIDTA!B27,'AUGUST - TB'!G:G) -> 0 | O27: =-SUMIF('JULY-TB'!H:H,EBIDTA!B27,'JULY-TB'!G:G) -> 0 | Q27: =-SUMIF('JUNE - TB -'!H:H,EBIDTA!B27,'JUNE - TB -'!G:G) -> 0 | S27: =-SUMIF('MAY- TB - '!H:H,EBIDTA!B27,'MAY- TB - '!E:E) -> 0 | U27: =-SUMIF('APRIL - TB -'!H:H,EBIDTA!B27,'APRIL - TB -'!G:G) -> 0 | X27: Stores, Spares & Consumables
B28: Total Other income | C28: =SUM(C19:C27) -> 0 | D28: =C28/$C$30 -> 0 | E28: =SUM(E19:E27) -> 386687 | F28: =E28/$E$30 -> 0.0015490299 | G28: =SUM(G19:G27) -> 241260.67 | H28: =(G28/$G$30) -> 0.0012058345 | I28: =SUM(I19:I27) -> -200000 | J28: =(I28/$I$30) -> -0.00098095618 | K28: =SUM(K19:K27) -> 0 | L28: =(K28/$K$30) -> 0 | M28: =SUM(M19:M27) -> 427947.67 | N28: =M28/$M$30 -> 0.00037776225 | O28: =SUM(O19:O27) -> 427947.67 | P28: =O28/$O$30 -> 0.00051143208 | Q28: =SUM(Q19:Q27) -> 41260.67 | R28: =(Q28/$Q$30) -> 7.0274978e-05 | S28: =SUM(S19:S27) -> -200000 | T28: =(S28/$S$30) -> -0.00051672381 | U28: =SUM(U19:U27) -> 0 | V28: =(U28/$U$30) -> 0 | X28: Inventory at the beginning of the year:
B30: Total Turnover | C30: =C9+C12+C17+C28 -> 2.9608578e+08 | D30: =C30/$C$30 -> 1 | E30: =E9+E12+E17+E28 -> 2.4963171e+08 | F30: =E30/$E$30 -> 1 | G30: =G9+G12+G17+G28 -> 2.0007777e+08 | H30: =(G30/$G$30) -> 1 | I30: =I9+I12+I17+I28 -> 2.038827e+08 | J30: =(I30/$I$30) -> 1 | K30: =K9+K12+K17+K28 -> 1.8317126e+08 | L30: =(K30/$K$30) -> 1 | M30: =M9+M12+M17+M28 -> 1132849226 | N30: =M30/$M$30 -> 1 | O30: =O9+O12+O17+O28 -> 836763450 | P30: =(O30/$O$30) -> 1 | Q30: =Q9+Q12+Q17+Q28 -> 5.8713174e+08 | R30: =(Q30/$Q$30) -> 1 | S30: =S9+S12+S17+S28 -> 3.8705397e+08 | T30: =(S30/$S$30) -> 1 | U30: =U9+U12+U17+U28 -> 1.8317126e+08 | V30: =(U30/$U$30) -> 1 | X30: Opening Stock of Consumables | Y30: =Z30 -> 12898280 | Z30: =AA30 -> 12898280 | AA30: =AB30 -> 12898280 | AB30: =AC30 -> 12898280 | AC30: ='Stock Sheet - KPW'!O16 -> 12898280 | AF30: =(AC27-AC30)/10^7 -> -1.289828 | AG30: =(AB30-AC30)/10^7 -> 0 | AH30: =(AA30-AB30)/10^7 -> 0 | AI30: =(Z30-AA30)/10^7 -> 0
B31: Cost of Goods
B32: Cost of materials consumed | C32: =M32-O32 -> 1.7731068e+08 | D32: =C32/$C$30 -> 0.59884904 | E32: =O32-Q32 -> 1.7347574e+08 | F32: =E32/$E$30 -> 0.69492668 | G32: =Q32-S32 -> 1.2741941e+08 | H32: =(G32/$G$30) -> 0.63684941 | I32: =S32-U32 -> 98512251 | J32: =(I32/$I$30) -> 0.48318101 | K32: =U32 -> 87083536 | L32: =(K32/$K$30) -> 0.47542139 | M32: =Y15 -> 6.6380162e+08 | N32: =M32/$M$30 -> 0.5859576 | O32: =Z15 -> 4.8649093e+08 | P32: =O32/$O$30 -> 0.58139601 | Q32: =AA15 -> 3.130152e+08 | R32: =(Q32/$Q$30) -> 0.53312601 | S32: =AB15 -> 1.8559579e+08 | T32: =(S32/$S$30) -> 0.47950881 | U32: =AC15 -> 87083536 | V32: =(U32/$U$30) -> 0.47542139 | X32: Add: Purchase of Stores, Spares & Consumables | Y32: =SUMIF('AUGUST - TB'!H:H,EBIDTA!X32,'AUGUST - TB'!G:G) -> 18737647 | Z32: =SUMIF('JULY-TB'!H:H,EBIDTA!X32,'JULY-TB'!G:G) -> 14206510 | AA32: =SUMIF('JUNE - TB -'!H23:H1349,EBIDTA!X32,'JUNE - TB -'!G23:G1349) -> 10776091 | AB32: =SUMIF('MAY- TB - '!H23:H1339,EBIDTA!X32,'MAY- TB - '!G23:G1339) -> 7002670.9 | AC32: =SUMIF('APRIL - TB -'!H2:H1232,EBIDTA!X32,'APRIL - TB -'!G2:G1231) -> 3866573.4 | AF32: =(AC29-AC32)/10^7 -> -0.38665734 | AG32: =(AB32-AC32)/10^7 -> 0.31360974 | AH32: =(AA32-AB32)/10^7 -> 0.37734203 | AI32: =(Z32-AA32)/10^7 -> 0.34304185 | AJ32: 20.644672
B33: Purchase of stock-in-trade | C33: =M33-O33 -> 0 | D33: =C33/$C$30 -> 0 | E33: =O33-Q33 -> 0 | F33: =E33/$E$30 -> 0 | G33: =Q33-S33 -> 0 | H33: =(G33/$G$30) -> 0 | I33: =S33-U33 -> 0 | J33: =(I33/$I$30) -> 0 | K33: =U33 -> 0 | L33: =(K33/$K$30) -> 0 | M33: 0 | N33: =M33/$M$30 -> 0 | O33: 0 | P33: =O33/$O$30 -> 0 | Q33: 0 | R33: =(Q33/$Q$30) -> 0 | S33: 0 | T33: =(S33/$S$30) -> 0 | U33: 0 | V33: =(U33/$U$30) -> 0
B34: Changes in inventory of finished goods and work-in-progress | C34: =M34-O34 -> 1090196.2 | D34: =C34/$C$30 -> 0.0036820283 | E34: =O34-Q34 -> 11065904 | F34: =E34/$E$30 -> 0.044328919 | G34: =Q34-S34 -> -13812508 | H34: =(G34/$G$30) -> -0.069035697 | I34: =S34-U34 -> -839004.28 | J34: =(I34/$I$30) -> -0.0041151322 | K34: =U34 -> 34999374 | L34: =(K34/$K$30) -> 0.19107459 | M34: =Y25 -> 32503962 | N34: =M34/$M$30 -> 0.028692222 | O34: =Z25 -> 31413765 | P34: =O34/$O$30 -> 0.03754199 | Q34: =AA25 -> 20347861 | R34: =(Q34/$Q$30) -> 0.034656381 | S34: =AB25 -> 34160369 | T34: =(S34/$S$30) -> 0.08825738 | U34: =AC25 -> 34999374 | V34: =(U34/$U$30) -> 0.19107459 | X34: Less:
B35: Stores, Spares & Consumables | C35: =M35-O35 -> 3771955.4 | D35: =C35/$C$30 -> 0.012739401 | E35: =O35-Q35 -> 4435366.6 | F35: =E35/$E$30 -> 0.017767641 | G35: =Q35-S35 -> 5023463.8 | H35: =(G35/$G$30) -> 0.025107556 | I35: =S35-U35 -> 1896959.8 | J35: =(I35/$I$30) -> 0.0093041721 | K35: =U35 -> 829101.07 | L35: =(K35/$K$30) -> 0.0045263709 | M35: =Y36 -> 15956847 | N35: =M35/$M$30 -> 0.014085587 | O35: =Z36 -> 12184891 | P35: =O35/$O$30 -> 0.014561931 | Q35: =AA36 -> 7749524.6 | R35: =(Q35/$Q$30) -> 0.013198954 | S35: =AB36 -> 2726060.8 | T35: =(S35/$S$30) -> 0.0070431027 | U35: =AC36 -> 829101.07 | V35: =(U35/$U$30) -> 0.0045263709 | X35: Closing Stock of Consumables | Y35: ='Stock Sheet - KPW'!T16 -> 15679080 | Z35: ='Stock Sheet - KPW'!S16 -> 14919898 | AA35: ='Stock Sheet - KPW'!R16 -> 15924847 | AB35: =+'Stock Sheet - KPW'!Q16 -> 17174890 | AC35: ='Stock Sheet - KPW'!P16 -> 15935752 | AF35: =AC35/10^7 -> 1.5935752 | AG35: =(AB35-AC35)/10^7 -> 0.12391377 | AH35: =(AA35-AB35)/10^7 -> -0.12500434 | AI35: =(Z35-AA35)/10^7 -> -0.10049481 | AJ35: 20.644672
B36: Total Cost of goods | C36: =C32+C34+C35+C33 -> 1.8217283e+08 | D36: =C36/$C$30 -> 0.61527047 | E36: =E32+E34+E35+E33 -> 1.8897701e+08 | F36: =E36/$E$30 -> 0.75702324 | G36: =G32+G34+G35+G33 -> 1.1863036e+08 | H36: =(G36/$G$30) -> 0.59292127 | I36: =I32+I34+I35+I33 -> 99570207 | J36: =(I36/$I$30) -> 0.48837005 | K36: =K32+K34+K35+K33 -> 1.2291201e+08 | L36: =(K36/$K$30) -> 0.67102235 | M36: =M32+M34+M35+M33 -> 7.1226242e+08 | N36: =M36/$M$30 -> 0.62873541 | O36: =O32+O34+O35+O33 -> 5.3008959e+08 | P36: =O36/$O$30 -> 0.63349993 | Q36: =Q32+Q34+Q35+Q33 -> 3.4111258e+08 | R36: =(Q36/$Q$30) -> 0.58098134 | S36: =S32+S34+S35+S33 -> 2.2248222e+08 | T36: =(S36/$S$30) -> 0.57480929 | U36: =U32+U34+U35+U33 -> 1.2291201e+08 | V36: =(U36/$U$30) -> 0.67102235 | X36: Cost of Consumables | Y36: =Y30+Y32-Y35 -> 15956847 | Z36: =Z30+Z32-Z35 -> 12184891 | AA36: =AA30+AA32-AA35 -> 7749524.6 | AB36: =AB30+AB32-AB35 -> 2726060.8 | AC36: =AC30+AC32-AC35 -> 829101.07 | AF36: =AC36/10^7 -> 0.082910107 | AG36: =(AB36-AF36)/10^7 -> 0.27260608 | AH36: =(AA36-AB36)/10^7 -> 0.50234638 | AI36: =(Z36-AA36)/10^7 -> 0.44353666 | AJ36: =(Y36-Z36)/10^7 -> 0.37719554
B37: Employee benefit expenses
B38: Salaries, wages and bonus | C38: =M38-O38 -> 20556497 | E38: =O38-Q38 -> 15351917 | G38: =Q38-S38 -> 17889551 | I38: =S38-U38 -> 14699525 | K38: =U38 -> 15495083 | M38: =SUMIF('AUGUST - TB'!H:H,EBIDTA!B38,'AUGUST - TB'!G:G) -> 83992573 | O38: =SUMIF('JULY-TB'!H:H,EBIDTA!B38,'JULY-TB'!G:G) -> 63436076 | Q38: =SUMIF('JUNE - TB -'!H:H,EBIDTA!B38,'JUNE - TB -'!G:G) -> 48084159 | S38: =SUMIF('MAY- TB - '!H:H,EBIDTA!B38,'MAY- TB - '!G:G) -> 30194608 | U38: =SUMIF('APRIL - TB -'!H:H,EBIDTA!B38,'APRIL - TB -'!G:G) -> 15495083
B39: Contribution to provident and other funds | C39: =M39-O39 -> 793099 | E39: =O39-Q39 -> 715987 | G39: =Q39-S39 -> 645056 | I39: =S39-U39 -> 518741 | K39: =U39 -> 564270 | M39: =SUMIF('AUGUST - TB'!H:H,EBIDTA!B39,'AUGUST - TB'!G:G) -> 3237153 | O39: =SUMIF('JULY-TB'!H:H,EBIDTA!B39,'JULY-TB'!G:G) -> 2444054 | Q39: =SUMIF('JUNE - TB -'!H:H,EBIDTA!B39,'JUNE - TB -'!G:G) -> 1728067 | S39: =SUMIF('MAY- TB - '!H:H,EBIDTA!B39,'MAY- TB - '!G:G) -> 1083011 | U39: =SUMIF('APRIL - TB -'!H:H,EBIDTA!B39,'APRIL - TB -'!G:G) -> 564270
B40: Gratuity Expenses | C40: =M40-O40 -> 0 | E40: =O40-Q40 -> 0 | G40: =Q40-S40 -> 0 | I40: =S40-U40 -> 0 | K40: =U40 -> 0 | M40: =SUMIF('AUGUST - TB'!H:H,EBIDTA!B40,'AUGUST - TB'!G:G) -> 0 | O40: =SUMIF('JULY-TB'!H:H,EBIDTA!B40,'JULY-TB'!G:G) -> 0 | Q40: =SUMIF('JUNE - TB -'!H:H,EBIDTA!B40,'JUNE - TB -'!G:G) -> 0 | S40: =SUMIF('MAY- TB - '!H:H,EBIDTA!B40,'MAY- TB - '!G:G) -> 0 | U40: =SUMIF('APRIL - TB -'!H:H,EBIDTA!B40,'APRIL - TB -'!G:G) -> 0
B41: Staff welfare expenses | C41: =M41-O41 -> 621764.74 | E41: =O41-Q41 -> 233643 | G41: =Q41-S41 -> 759802 | I41: =S41-U41 -> 255704.24 | K41: =U41 -> 9522 | M41: =SUMIF('AUGUST - TB'!H:H,EBIDTA!B41,'AUGUST - TB'!G:G) -> 1880436 | O41: =SUMIF('JULY-TB'!H:H,EBIDTA!B41,'JULY-TB'!G:G) -> 1258671.2 | Q41: =SUMIF('JUNE - TB -'!H:H,EBIDTA!B41,'JUNE - TB -'!G:G) -> 1025028.2 | S41: =SUMIF('MAY- TB - '!H:H,EBIDTA!B41,'MAY- TB - '!G:G) -> 265226.24 | U41: =SUMIF('APRIL - TB -'!H:H,EBIDTA!B41,'APRIL - TB -'!G:G) -> 9522
B42: Labour charges | C42: =M42-O42 -> 8448378 | E42: =O42-Q42 -> 7287531.9 | G42: =Q42-S42 -> 5896886.8 | I42: =S42-U42 -> 5108656.4 | K42: =U42 -> 4542834 | M42: =SUMIF('AUGUST - TB'!H:H,EBIDTA!B42,'AUGUST - TB'!G:G) -> 31284287 | O42: =SUMIF('JULY-TB'!H:H,EBIDTA!B42,'JULY-TB'!G:G) -> 22835909 | Q42: =SUMIF('JUNE - TB -'!H:H,EBIDTA!B42,'JUNE - TB -'!G:G) -> 15548377 | S42: =SUMIF('MAY- TB - '!H:H,EBIDTA!B42,'MAY- TB - '!G:G) -> 9651490.4 | U42: =SUMIF('APRIL - TB -'!H:H,EBIDTA!B42,'APRIL - TB -'!G:G) -> 4542834
B43: Total Employee benefit expenses | C43: =SUM(C38:C42) -> 30419739 | D43: =C43/$C$30 -> 0.10273962 | E43: =SUM(E38:E42) -> 23589079 | F43: =E43/$E$30 -> 0.094495521 | G43: =SUM(G38:G42) -> 25191296 | H43: =(G43/$G$30) -> 0.12590752 | I43: =SUM(I38:I42) -> 20582626 | J43: =(I43/$I$30) -> 0.10095327 | K43: =SUM(K38:K42) -> 20611709 | L43: =(K43/$K$30) -> 0.11252698 | M43: =SUM(M38:M42) -> 1.2039445e+08 | N43: =M43/$M$30 -> 0.10627579 | O43: =SUM(O38:O42) -> 89974710 | P43: =O43/$O$30 -> 0.10752706 | Q43: =SUM(Q38:Q42) -> 66385631 | R43: =(Q43/$Q$30) -> 0.11306769 | S43: =SUM(S38:S42) -> 41194335 | T43: =(S43/$S$30) -> 0.10643047 | U43: =SUM(U38:U42) -> 20611709 | V43: =(U43/$U$30) -> 0.11252698
B44: Manufacturing Expenses
...

Sheet Stock Sheet - KPW
C1: Stock sheet from Apr-24 to Mar-24
B3: Raw Material | O3: 26-27
B4: op.Stock | C4: 45383 | D4: MAY | E4: 45444 | F4: july.24 | G4: 45505 | H4: 45536 | I4: 45566 | J4: 45597 | K4: 45627 | L4: 45658 | M4: 45689 | N4: 45717 | O4: Op,stock 01.04.26 | P4: 46113 | Q4: MAY.26 | R4: 46174 | S4: July. 26 | T4: 46235 | U4: 46266 | V4: 46296 | W4: 46327 | X4: 46357 | Y4: 46388 | Z4: 46419 | AA4: 46447
C5: 40885502 | D5: 44690515 | E5: 59879823 | F5: 58718633 | G5: 60867855 | H5: 58655299 | I5: 49973632 | J5: 52326500 | K5: 51493051 | L5: 44011790 | M5: 61248778 | N5: 59069210 | O5: 78409106 | P5: 1.1669902e+08 | Q5: 78548384 | R5: 63882998 | S5: 84892889 | T5: 1.1168642e+08
B8: Finish Material
B9: op.Stock | C9: 45383 | D9: MAY | E9: 45444 | F9: july.24 | G9: 45505 | H9: 45536 | I9: 45566 | J9: 45597 | K9: 45627 | L9: 45658 | M9: 45689 | N9: 45717 | O9: Op,stock 01.04.26 | P9: 46113 | Q9: MAY.26 | R9: 46174 | S9: July. 26 | T9: 46235 | U9: 46266 | V9: 46296 | W9: 46327 | X9: 46357 | Y9: 46388 | Z9: 46419 | AA9: 46447
C10: 76985434 | D10: 73682752 | E10: 84421689 | F10: 87270138 | G10: 98165150 | H10: 1.1481412e+08 | I10: 109540747 | J10: 92932583 | K10: 1.0876437e+08 | L10: 1.1692796e+08 | M10: 1.203563e+08 | N10: 1.2409052e+08 | O10: 2.0644672e+08 | P10: 1.7144735e+08 | Q10: 1.7228635e+08 | R10: 1.8609886e+08 | S10: 1.7503296e+08 | T10: 1.7394276e+08
B13: Stores Spares
B14: op.Stock | C14: 45383 | D14: MAY | E14: 45444 | F14: july.24 | G14: 45505 | H14: 45536 | I14: 45566 | J14: 45597 | K14: 45627 | L14: 45658 | M14: 45689 | N14: 45717 | O14: Op,stock 01.04.26 | P14: 46113 | Q14: MAY.26 | R14: 46174 | S14: July. 26 | T14: 46235 | U14: 46266 | V14: 46296 | W14: 46327 | X14: 46357 | Y14: 46388 | Z14: 46419 | AA14: 46447
C16: 11212574 | D16: 11398463 | E16: 11966098 | F16: 11807893 | G16: 12281943 | H16: 11290716 | I16: 11937270 | J16: 11725252 | K16: 11462964 | L16: 10929459 | M16: 11096995 | N16: 10973564 | O16: 12898280 | P16: 15935752 | Q16: 17174890 | R16: 15924847 | S16: 14919898 | T16: 15679080

Sheet APRIL - TB -
A1: DOWNLOAD AS ON 11-08-26
A2: Perticular | B2: Opening | C2: Debit | D2: Credit | E2: Closing | F2: Provision | G2: Total | H2: Head
A3: Packing Forwading & Cartage Expense | B3: 0 | C3: 100 | D3: 0 | E3: 100 | G3: =E3+F3 -> 100 | H3: Add: Purchase expenses
A4: Freight Inward Expense (RCM) | B4: 0 | C4: 177110 | D4: 0 | E4: 177110 | G4: =E4+F4 -> 177110 | H4: Add: Purchase expenses
A5: Freight Inward Expense (With GST) | B5: 0 | C5: 62503.7 | D5: 0 | E5: 62503.7 | G5: =E5+F5 -> 62503.7 | H5: Add: Purchase expenses
A6: Purchase Withinstate- Packing Material | B6: 0 | C6: 1127244.8 | D6: 0 | E6: 1127244.8 | G6: =E6+F6 -> 1127244.8 | H6: Add: Purchase of packing materials
A7: Purchase Raw Material - Direct Import | B7: 0 | C7: 27922270 | D7: 0 | E7: 27922270 | G7: =E7+F7 -> 27922270 | H7: Add: Purchase of raw materials
A8: Purchase Interstate - Raw Material | B8: 0 | C8: 2231224.4 | D8: 0 | E8: 2231224.4 | G8: =E8+F8 -> 2231224.4 | H8: Add: Purchase of raw materials
A9: Purchase Withinstate - Raw Material | B9: 0 | C9: 73330942 | D9: 0 | E9: 73330942 | G9: =E9+F9 -> 73330942 | H9: Add: Purchase of raw materials
A10: Purchase Raw Material - High Seas | B10: 0 | C10: 17158400 | D10: 0 | E10: 17158400 | G10: =E10+F10 -> 17158400 | H10: Add: Purchase of raw materials
A11: Purchase Interstate- Stores, Spares & Consumable | B11: 0 | C11: 1436233.5 | D11: 0 | E11: 1436233.5 | G11: =E11+F11 -> 1436233.5 | H11: Add: Purchase of Stores, Spares & Consumables
A12: Purchase Return - Stores, Spares & Consumable | B12: 0 | C12: 54130 | D12: 0 | E12: 54130 | G12: =E12+F12 -> 54130 | H12: Add: Purchase of Stores, Spares & Consumables
A13: Purchase Withinstate- Stores, Spares & Consumable | B13: 0 | C13: 2376209.9 | D13: 0 | E13: 2376209.9 | G13: =E13+F13 -> 2376209.9 | H13: Add: Purchase of Stores, Spares & Consumables
A14: Bank Charges - Export Collection | B14: 0 | C14: 350726.34 | D14: 1669.95 | E14: 349056.39 | G14: =E14+F14 -> 349056.39 | H14: Bank Charges & Commission
... A23: Factoring Charges | B23: 0 | C23: 208120.64 | D23: 0 | E23: 208120.64 | G23: =E23+F23 -> 208120.64 | H23: Bank Charges & Commission
A24: P.F. Admin. Charge | B24: 0 | C24: 26644 | D24: 26644 | E24: 0 | F24: 21728 | G24: =E24+F24 -> 21728 | H24: Contribution to provident and other funds
A25: P.F. Contribution - Employer | B25: 0 | C25: 665196 | D25: 665196 | E25: 0 | F25: 542542 | G25: =E25+F25 -> 542542 | H25: Contribution to provident and other funds
A26: Conveyance Expenses | B26: 0 | C26: 5017 | D26: 0 | E26: 5017 | G26: =E26+F26 -> 5017 | H26: Conveyance, vehicle running and traveling expenses
A27: Petrol & Diesel Expense - Other Vehicles | B27: 0 | C27: 58296 | D27: 0 | E27: 58296 | G27: =E27+F27 -> 58296 | H27: Conveyance, vehicle running and traveling expenses
A28: Exchange Rate Difference - Debtors | B28: 0 | C28: 25161872 | D28: 3916167.8 | E28: 21245704 | F28: -25161872 | G28: =E28+F28 -> -3916167.8 | H28: Exchange Rate Difference
A29: Loading & Unloading Expense | B29: 0 | C29: 23680 | D29: 0 | E29: 23680 | F29: 100000 | G29: =E29+F29 -> 123680 | H29: Freight Outward and C & F Charges
A30: C & F Charges - Export | B30: 0 | C30: 972314.89 | D30: 0 | E30: 972314.89 | F30: 500000 | G30: =E30+F30 -> 1472314.9 | H30: Freight Outward and C & F Charges
A31: Discount -Early Payment - Sales | B31: 0 | C31: 16073.88 | D31: 0 | E31: 16073.88 | G31: =E31+F31 -> 16073.88 | H31: Freight Outward and C & F Charges
A32: Freight Outward Expense - Export | B32: 0 | C32: 298850 | D32: =12556110.47 -> 12556110 | E32: =C32-D32 -> -12257260 | F32: -10733989 | G32: =E32-F32 -> -1523271.5 | H32: Freight Outward and C & F Charges
A33: Freight Outward Expense (RCM) | B33: 0 | C33: 529500 | D33: 0 | E33: 529500 | G33: =E33+F33 -> 529500 | H33: Freight Outward and C & F Charges
A34: Freight Outward Expense (With GST) | B34: 0 | C34: 2102133.6 | D34: 1200 | E34: 2100933.6 | F34: 500000 | G34: =E34+F34 -> 2600933.6 | H34: Freight Outward and C & F Charges
A35: Insurance Expense - Ecgc - Pc | B35: 0 | C35: 379906.61 | D35: 0 | E35: 379906.61 | G35: =E35+F35 -> 379906.61 | H35: Freight Outward and C & F Charges
A36: Insurance Expenses - Other | B36: 0 | C36: 342799 | D36: 0 | E36: 342799 | F36: =2200800/12 -> 183400 | G36: =E36+F36 -> 526199 | H36: Insurance
A37: Accrued Interest -FDR | B37: 35987 | C37: 0 | D37: 0 | E37: 35987 | G37: =E37+F37 -> 35987 | H37: Interest Expense - Other
A38: Interest Expense - EPC | B38: 0 | C38: 2289146.4 | D38: 14014.17 | E38: 2275132.2 | G38: =E38+F38 -> 2275132.2 | H38: Interest Expense - Other
A39: Interest Expense - Factoring | B39: 0 | C39: 562528.38 | D39: 171590.28 | E39: 390938.1 | G39: =E39+F39 -> 390938.1 | H39: Interest Expense - Other
A40: Interest Expense - PCFC | B40: 0 | C40: 1081387.6 | D40: 0 | E40: 1081387.6 | G40: =E40+F40 -> 1081387.6 | H40: Interest Expense - Other
A41: Interest Expense - Other | B41: 0 | C41: 137378.57 | D41: 56823 | E41: 80555.57 | G41: =E41+F41 -> 80555.57 | H41: Interest Expense - Other
A42: Interest to MSME Vendors Payable | B42: -56823 | C42: 56823 | D42: 0 | E42: 0 | G42: =E42+F42 -> 0 | H42: Interest Expense - Other
A43: Interest Expense - Term Loan | B43: 0 | C43: 2113806 | D43: 0 | E43: 2113806 | G43: =E43+F43 -> 2113806 | H43: Interest on Term Loan
A44: Interest Expense - Working Capital | B44: 0 | C44: 1096147 | D44: 0 | E44: 1096147 | G44: =E44+F44 -> 1096147 | H44: Interest on Working Capital & Term Loan
A45: Job Charges | B45: 0 | C45: 11030011 | D45: 55384.56 | E45: 10974626 | G45: =E45+F45 -> 10974626 | H45: Jobwork charges
A46: Labour Charges | B46: 0 | C46: 129973 | D46: 129973 | E46: 0 | F46: =4436290+106544 -> 4542834 | G46: =E46+F46 -> 4542834 | H46: Labour charges
A47: Duty Clearing Account | B47: 0 | C47: 5144478 | D47: 5144478 | E47: 0 | G47: =E47+F47 -> 0 | H47: Not Applicable
A48: Income Tax Ay 2014-15 | B48: 1607000 | C48: 0 | D48: 0 | E48: 1607000 | G48: =E48+F48 -> 1607000 | H48: Not Applicable
...

Sheet MAY- TB - 
A1: Perticular | B1: Opening | C1: Debit | D1: Credit | E1: Closing | F1: Provision | G1: Total | H1: Head | I1: April | J1: Net May | K1: sales - stock mov.
A2: Duty Clearing Account | B2: 0 | C2: 5144478 | D2: 5144478 | E2: 0 | G2: =E2+F2 -> 0 | H2: Not Applicable
A3: Income Tax Ay 2014-15 | B3: 1607000 | C3: 0 | D3: 0 | E3: 1607000 | G3: =E3+F3 -> 1607000 | H3: Not Applicable
A4: Income Tax Ay 2016-17 | B4: 2200000 | C4: 0 | D4: 0 | E4: 2200000 | G4: =E4+F4 -> 2200000 | H4: Not Applicable
A5: Income Tax Refund Receivable | B5: 108787 | C5: 0 | D5: 0 | E5: 108787 | G5: =E5+F5 -> 108787 | H5: Not Applicable
A6: TCS On Purchase 20-21 | B6: 0 | C6: 0 | D6: 0 | E6: 0 | G6: =E6+F6 -> 0 | H6: Not Applicable
A7: TCS On Purchase 21-22 | B7: 0 | C7: 0 | D7: 0 | E7: 0 | G7: =E7+F7 -> 0 | H7: Not Applicable
A8: TCS On Purchase 22-23 | B8: -18585.94 | C8: 0 | D8: 0 | E8: -18585.94 | G8: =E8+F8 -> -18585.94 | H8: Not Applicable
A9: TCS On Purchase 23-24 | B9: 1151 | C9: 0 | D9: 0 | E9: 1151 | G9: =E9+F9 -> 1151 | H9: Not Applicable
A10: Tcs On Purchase 24-25 | B10: 30286.3 | C10: 0 | D10: 0 | E10: 30286.3 | G10: =E10+F10 -> 30286.3 | H10: Not Applicable
A11: Tcs On Purchase 25-26 | B11: 1335.22 | C11: 0 | D11: 0 | E11: 1335.22 | G11: =E11+F11 -> 1335.22 | H11: Not Applicable
A12: TDS Receivable 2021-22 | B12: 0 | C12: 0 | D12: 0 | E12: 0 | G12: =E12+F12 -> 0 | H12: Not Applicable
A13: TDS Receivable 2022-23 | B13: -418818 | C13: 0 | D13: 0 | E13: -418818 | G13: =E13+F13 -> -418818 | H13: Not Applicable
... A383: Round Off - Purchases | B383: 0 | C383: 51.62 | D383: 52.4 | E383: -0.78 | G383: =E383+F383 -> -0.78 | H383: Not Applicable
A384: C & F Charges - Import | B384: 0 | C384: 6302314.7 | D384: 0 | E384: 6302314.7 | F384: 115969 | G384: =E384+F384 -> 6418283.7 | H384: Add: Purchase expenses
A385: Freight Inward Expense (RCM) | B385: 0 | C385: 396540 | D385: 35000 | E385: 361540 | G385: =E385+F385 -> 361540 | H385: Add: Purchase expenses
A386: Freight Inward Expense (With GST) | B386: 0 | C386: 107838.05 | D386: 200 | E386: 107638.05 | G386: =E386+F386 -> 107638.05 | H386: Add: Purchase expenses
A387: Advance Licence Fee Expense | B387: 0 | C387: 9500 | D387: 0 | E387: 9500 | G387: =E387+F387 -> 9500 | H387: Not Applicable
A388: Factory Expense | B388: 0 | C388: 251879 | D388: 0 | E388: 251879 | G388: =E388+F388 -> 251879 | H388: Other Administrative Expenses
A389: Labour Charges | B389: 0 | C389: 4566263.4 | D389: 129973 | E389: 4436290.4 | F389: =5215200 -> 5215200 | G389: =E389+F389 -> 9651490.4 | H389: Labour charges
A390: Power Expense | B390: 0 | C390: 4870824 | D390: 0 | E390: 4870824 | F390: 4424704 | G390: =E390+F390 -> 9295528 | H390: Power and fuel
A391: Rent Expense - Colony | B391: 0 | C391: 1265900 | D391: 0 | E391: 1265900 | G391: =E391+F391 -> 1265900 | H391: Other Administrative Expenses
A392: Rent Expenses - Machineries | B392: 0 | C392: 600000 | D392: 0 | E392: 600000 | G392: =E392+F392 -> 600000 | H392: Other Administrative Expenses
A393: Exchange Rate Difference - Creditor | B393: 0 | C393: 313632 | D393: 30486.47 | E393: 283145.53 | G393: =E393+F393 -> 283145.53 | H393: Exchange Rate Difference
A394: Job Charges | B394: 0 | C394: 38009628 | D394: 55384.56 | E394: 37954244 | G394: =E394+F394 -> 37954244 | H394: Jobwork charges
A395: Loading & Unloading Expense | B395: 0 | C395: 143950 | D395: 0 | E395: 143950 | G395: =E395+F395 -> 143950 | H395: Freight Outward and C & F Charges
A396: Water Charges | B396: 0 | C396: 254890 | D396: 96272 | E396: 158618 | G396: =E396+F396 -> 158618 | H396: Other Administrative Expenses
A397: Repairs & Maintenance Exp - Plant & Machinery | B397: 0 | C397: 1375818.1 | D397: 0 | E397: 1375818.1 | F397: 200000 | G397: =E397+F397 -> 1575818.1 | H397: Other Manufacturing Expenses
A398: Purchase Raw Material - Direct Import | B398: 0 | C398: 27922270 | D398: 0 | E398: 27922270 | G398: =E398+F398 -> 27922270 | H398: Add: Purchase of raw materials
A399: Purchase Withinstate- Packing Material | B399: 0 | C399: 2830055.7 | D399: 0 | E399: 2830055.7 | G399: =E399+F399 -> 2830055.7 | H399: Add: Purchase of packing materials
A400: Purchase In Transit | B400: 0 | C400: 0 | D400: 36870023 | E400: -36870023 | G400: =E400+F400 -> -36870023 | H400: Not Applicable
A401: Purchase Interstate - Raw Material | B401: 0 | C401: 3134409.4 | D401: 0 | E401: 3134409.4 | G401: =E401+F401 -> 3134409.4 | H401: Add: Purchase of raw materials
A402: Purchase Withinstate - Raw Material | B402: 0 | C402: 1.2875342e+08 | D402: 0 | E402: 1.2875342e+08 | G402: =E402+F402 -> 1.2875342e+08 | H402: Add: Purchase of raw materials
A403: Purchase - Urd - Stores, Spares & Consumable | B403: 0 | C403: 7813 | D403: 0 | E403: 7813 | G403: =E403+F403 -> 7813 | H403: Add: Purchase of Stores, Spares & Consumables
A404: Purchase Interstate- Stores, Spares & Consumable | B404: 0 | C404: 2418895.5 | D404: 0 | E404: 2418895.5 | G404: =E404+F404 -> 2418895.5 | H404: Add: Purchase of Stores, Spares & Consumables
A405: Purchase Return - Stores, Spares & Consumable | B405: 0 | C405: 54130 | D405: 1700 | E405: 52430 | G405: =E405+F405 -> 52430 | H405: Add: Purchase of Stores, Spares & Consumables
A406: Purchase Withinstate- Stores, Spares & Consumable | B406: 0 | C406: 4523532.4 | D406: 0 | E406: 4523532.4 | G406: =E406+F406 -> 4523532.4 | H406: Add: Purchase of Stores, Spares & Consumables
A407: Purchase Raw Material - High Seas | B407: 0 | C407: 17158400 | D407: 0 | E407: 17158400 | G407: =E407+F407 -> 17158400 | H407: Add: Purchase of raw materials
A408: Conveyance Expenses | B408: 0 | C408: 61288 | D408: 0 | E408: 61288 | G408: =E408+F408 -> 61288 | H408: Conveyance, vehicle running and traveling expenses
A409: Corporate social responsibility | B409: 0 | C409: 24880 | D409: 0 | E409: 24880 | G409: =E409+F409 -> 24880 | H409: Other Administrative Expenses
...

Sheet JUNE - TB -
A1: Perticular | B1: Opening | C1: Debit | D1: Credit | E1: Closing | F1: Provision | G1: Total | H1: Head
A2: TDS Receivable 2022-23 | B2: -418818 | C2: 0 | D2: 0 | E2: -418818 | G2: =E2+F2 -> -418818 | H2: Not Applicable
A3: TDS Receivable 2023-24 | B3: 66480 | C3: 0 | D3: 0 | E3: 66480 | G3: =E3+F3 -> 66480 | H3: Not Applicable
A4: Tds Receivable 2024-25 | B4: 1767704.8 | C4: 0 | D4: 0 | E4: 1767704.8 | G4: =E4+F4 -> 1767704.8 | H4: Not Applicable
A5: Tds Receivable 2025-26 | B5: 1324336.4 | C5: 1788.8 | D5: 0 | E5: 1326125.2 | G5: =E5+F5 -> 1326125.2 | H5: Not Applicable
A6: Tds Receivable 2026-27 | B6: 0 | C6: 695424.7 | D6: 0 | E6: 695424.7 | G6: =E6+F6 -> 695424.7 | H6: Not Applicable
A7: Bank FDR BOB 73280300000558 | B7: 2176060 | C7: 0 | D7: 0 | E7: 2176060 | G7: =E7+F7 -> 2176060 | H7: Not Applicable
A8: Bank Fdr Bob 73280300001203 | B8: 2589775 | C8: 0 | D8: 0 | E8: 2589775 | G8: =E8+F8 -> 2589775 | H8: Not Applicable
A9: Bank FDR BOB 73280300001224 | B9: 6100000 | C9: 0 | D9: 6177119 | E9: -77119 | G9: =E9+F9 -> -77119 | H9: Not Applicable
A10: Bank Fdr Bob 73280300001261 | B10: 60017754 | C10: 0 | D10: 60142043 | E10: -124289 | G10: =E10+F10 -> -124289 | H10: Not Applicable
A11: Bank FDR The Karnataka Bank Ltd - 0021152400022801 | B11: 2300953 | C11: 33543 | D11: 0 | E11: 2334496 | G11: =E11+F11 -> 2334496 | H11: Not Applicable
A12: Bank Fdr The Karnataka Bank Ltd - 021152600003001 | B12: 50000000 | C12: 0 | D12: 532910 | E12: 49467090 | G12: =E12+F12 -> 49467090 | H12: Not Applicable
A13: Bank Fdr The Karnataka Bank Ltd - 021152600005001 | B13: 13000000 | C13: 0 | D13: 153952 | E13: 12846048 | G13: =E13+F13 -> 12846048 | H13: Not Applicable
... A116: Avira Naturals Pvt Ltd- Sales | B116: 0 | C116: 0 | D116: 0 | E116: 0 | G116: =E116+F116 -> 0 | H116: Not Applicable
A117: Accrued Interest -FDR | B117: 35987 | C117: 0 | D117: 0 | E117: 35987 | G117: =E117+F117 -> 35987 | H117: Interest Expense - Other | I117: =#REF! -> #REF! | J117: =G117-I117 -> #REF!
A118: Bhagwati Polyweave Private Limited | B118: -2088.7 | C118: 0 | D118: 0 | E118: -2088.7 | G118: =E118+F118 -> -2088.7 | H118: Not Applicable
A119: Bhagwati Products | B119: 0 | C119: 0 | D119: 0 | E119: 0 | G119: =E119+F119 -> 0 | H119: Not Applicable
A120: PI Industries Limited - 24AABCP2183M2ZA | B120: 675 | C120: 0 | D120: 0 | E120: 675 | G120: =E120+F120 -> 675 | H120: Not Applicable
A121: PI Industries Limited - 24AABCP2183M3Z9 | B121: 4692.88 | C121: 0 | D121: 0 | E121: 4692.88 | G121: =E121+F121 -> 4692.88 | H121: Not Applicable
A122: PI Polyblendz Private Limited | B122: 1789930 | C122: 0 | D122: 1300965 | E122: 488965 | G122: =E122+F122 -> 488965 | H122: Not Applicable
A123: Plastene India ltd - HO-Sales | B123: 0 | C123: 0 | D123: 0 | E123: 0 | G123: =E123+F123 -> 0 | H123: Not Applicable
A124: Plastene India ltd - Unit 1-Sales | B124: -2.677367e+08 | C124: 3.9899803e+08 | D124: 3.8207263e+08 | E124: -2.508113e+08 | G124: =E124+F124 -> -2.508113e+08 | H124: Not Applicable
A125: Plastene India ltd - Unit 2-Sales | B125: 1.1687861e+09 | C125: 95743361 | D125: 7700 | E125: 1.2645218e+09 | G125: =E125+F125 -> 1.2645218e+09 | H125: Not Applicable
A126: Plastene India ltd - Unit 6-Sales | B126: 4.3894615e+08 | C126: 0 | D126: 0 | E126: 4.3894615e+08 | G126: =E126+F126 -> 4.3894615e+08 | H126: Not Applicable
A127: Plastene Polyfilms Ltd-Sales | B127: 14316309 | C127: 49175816 | D127: 9000000 | E127: 54492125 | G127: =E127+F127 -> 54492125 | H127: Not Applicable
A128: Polytech International Pvt. Ltd | B128: 0 | C128: 0 | D128: 0 | E128: 0 | G128: =E128+F128 -> 0 | H128: Not Applicable
A129: Raajratna Metal Industries Limited | B129: 0 | C129: 138296 | D129: 138296 | E129: 0 | G129: =E129+F129 -> 0 | H129: Not Applicable
... A345: Round Off - Purchases | B345: 0 | C345: 86.97 | D345: 81.7 | E345: 5.27 | G345: =E345+F345 -> 5.27 | H345: Not Applicable
A346: C & F Charges - Import | B346: 0 | C346: 6428818.5 | D346: 0 | E346: 6428818.5 | F346: 216988 | G346: =E346+F346 -> 6645806.5 | H346: Add: Purchase expenses
A347: Freight Inward Expense (RCM) | B347: 0 | C347: 531840 | D347: 35000 | E347: 496840 | G347: =E347+F347 -> 496840 | H347: Add: Purchase expenses
A348: Freight Inward Expense (With GST) | B348: 0 | C348: 145339.39 | D348: 200 | E348: 145139.39 | G348: =E348+F348 -> 145139.39 | H348: Add: Purchase expenses
A349: Advance Licence Fee Expense | B349: 0 | C349: 26500 | D349: 0 | E349: 26500 | G349: =E349+F349 -> 26500 | H349: Not Applicable
A350: Factory Expense | B350: 0 | C350: 341749 | D350: 0 | E350: 341749 | G350: =E350+F350 -> 341749 | H350: Other Administrative Expenses | I350: =VLOOKUP(A350,'[1]JUNE - TB -'!$A:$G,7,0) -> 341749 | J350: =G350-I350 -> 0
A351: Labour Charges | B351: 0 | C351: 15692281 | D351: 143904 | E351: 15548377 | G351: =E351+F351 -> 15548377 | H351: Labour charges
A352: Power Expense | B352: 0 | C352: 12340121 | D352: 0 | E352: 12340121 | F352: 1322071 | G352: =E352+F352 -> 13662192 | H352: Power and fuel
A353: Rent Expense - Colony | B353: 0 | C353: 3887100 | D353: 0 | E353: 3887100 | G353: =E353+F353 -> 3887100 | H353: Other Administrative Expenses | J353: =G353-I353 -> 3887100
A354: Rent Expenses - Machineries | B354: 0 | C354: 1450000 | D354: 0 | E354: 1450000 | G354: =E354+F354 -> 1450000 | H354: Other Administrative Expenses | J354: =G354-I354 -> 1450000
A355: Exchange Rate Difference - Creditor | B355: 0 | C355: 313632 | D355: 30486.47 | E355: 283145.53 | G355: =E355+F355 -> 283145.53 | H355: Exchange Rate Difference
A356: Job Charges | B356: 0 | C356: 52727873 | D356: 55384.56 | E356: 52672488 | G356: =E356+F356 -> 52672488 | H356: Jobwork charges
A357: Loading & Unloading Expense | B357: 0 | C357: 181710 | D357: 0 | E357: 181710 | G357: =E357+F357 -> 181710 | H357: Freight Outward and C & F Charges
...

Sheet JULY-TB
A1: Perticular | B1: Opening | C1: Debit | D1: Credit | E1: Closing | F1: Provision | G1: Total | H1: Head | I1: 1
A2: Duty Clearing Account | B2: 0 | C2: 12782932 | D2: 12782932 | E2: 0 | G2: =E2+F2 -> 0 | H2: Not Applicable
A3: Income Tax Ay 2014-15 | B3: 1607000 | C3: 0 | D3: 0 | E3: 1607000 | G3: =E3+F3 -> 1607000 | H3: Not Applicable
A4: Income Tax Ay 2016-17 | B4: 2200000 | C4: 0 | D4: 0 | E4: 2200000 | G4: =E4+F4 -> 2200000 | H4: Not Applicable
A5: Income Tax Refund Receivable | B5: 108787 | C5: 0 | D5: 0 | E5: 108787 | G5: =E5+F5 -> 108787 | H5: Not Applicable
A6: TCS On Purchase 20-21 | B6: 0 | C6: 0 | D6: 0 | E6: 0 | G6: =E6+F6 -> 0 | H6: Not Applicable
A7: TCS On Purchase 21-22 | B7: 0 | C7: 0 | D7: 0 | E7: 0 | G7: =E7+F7 -> 0 | H7: Not Applicable
A8: TCS On Purchase 22-23 | B8: -18585.94 | C8: 0 | D8: 0 | E8: -18585.94 | G8: =E8+F8 -> -18585.94 | H8: Not Applicable
A9: TCS On Purchase 23-24 | B9: 1151 | C9: 0 | D9: 0 | E9: 1151 | G9: =E9+F9 -> 1151 | H9: Not Applicable
A10: Tcs On Purchase 24-25 | B10: 30286.3 | C10: 0 | D10: 0 | E10: 30286.3 | G10: =E10+F10 -> 30286.3 | H10: Not Applicable
A11: Tcs On Purchase 25-26 | B11: 1335.22 | C11: 0 | D11: 0 | E11: 1335.22 | G11: =E11+F11 -> 1335.22 | H11: Not Applicable
A12: TDS Receivable 2021-22 | B12: 0 | C12: 0 | D12: 0 | E12: 0 | G12: =E12+F12 -> 0 | H12: Not Applicable
A13: TDS Receivable 2022-23 | B13: -418818 | C13: 0 | D13: 0 | E13: -418818 | G13: =E13+F13 -> -418818 | H13: Not Applicable
... A393: Advance Licence Fee Expense | B393: 0 | C393: 26500 | D393: 0 | E393: 26500 | G393: =E393+F393 -> 26500 | H393: Add: Purchase expenses
A394: Equipment Certification Charges | B394: 0 | C394: 122760 | D394: 0 | E394: 122760 | F394: 31748 | G394: =E394+F394 -> 154508 | H394: Other Administrative Expenses
A395: Factory Expense | B395: 0 | C395: 371344 | D395: 0 | E395: 371344 | F395: 6200 | G395: =E395+F395 -> 377544 | H395: Other Administrative Expenses
A396: Labour Charges | B396: 0 | C396: 21496544 | D396: 5975817 | E396: 15520727 | F396: 7315182 | G396: =E396+F396 -> 22835909 | H396: Labour charges
A397: Power Expense | B397: 0 | C397: 16180289 | D397: 3474593 | E397: 12705696 | F397: 4130997 | G397: =E397+F397 -> 16836693 | H397: Power and fuel
A398: Rent Expense - Colony | B398: 0 | C398: 5200400 | D398: 1313300 | E398: 3887100 | F398: 1313300 | G398: =E398+F398 -> 5200400 | H398: Other Administrative Expenses
A399: Rent Expenses - Machineries | B399: 0 | C399: 1450000 | D399: 1400000 | E399: 50000 | G399: =E399+F399 -> 50000 | H399: Other Administrative Expenses
A400: Exchange Rate Difference - Creditor | B400: 0 | C400: 313632 | D400: 30486.47 | E400: 283145.53 | G400: =E400+F400 -> 283145.53 | H400: Exchange Rate Difference
A401: Job Charges | B401: 0 | C401: 54735092 | D401: 55384.56 | E401: 54679708 | F401: 228490 | G401: =E401+F401 -> 54908198 | H401: Jobwork charges
A402: Loading & Unloading Expense | B402: 0 | C402: 192700 | D402: 0 | E402: 192700 | G402: =E402+F402 -> 192700 | H402: Freight Outward and C & F Charges
A403: Testing Charges | B403: 0 | C403: 0 | D403: 33844 | E403: -33844 | G403: =E403+F403 -> -33844 | H403: Other Administrative Expenses
A404: Water Charges | B404: 0 | C404: 837191 | D404: 289214 | E404: 547977 | F404: 184784 | G404: =E404+F404 -> 732761 | H404: Other Administrative Expenses
A405: Repairs & Maintenance Exp - Plant & Machinery | B405: 0 | C405: 1847132.2 | D405: 0 | E405: 1847132.2 | G405: =E405+F405 -> 1847132.2 | H405: Other Manufacturing Expenses
A406: Purchase Raw Material - Direct Import | B406: 0 | C406: 27922270 | D406: 0 | E406: 27922270 | G406: =E406+F406 -> 27922270 | H406: Add: Purchase of raw materials
A407: Purchase Withinstate- Packing Material | B407: 0 | C407: 6190436.3 | D407: 1750 | E407: 6188686.3 | G407: =E407+F407 -> 6188686.3 | H407: Add: Purchase of packing materials
A408: Purchase In Transit | B408: 0 | C408: 0 | D408: 36870023 | E408: -36870023 | G408: =E408+F408 -> -36870023 | H408: Not Applicable
A409: Purchase Interstate - Raw Material | B409: 0 | C409: 8179409.4 | D409: 0 | E409: 8179409.4 | G409: =E409+F409 -> 8179409.4 | H409: Add: Purchase of raw materials
A410: Purchase Withinstate - Raw Material | B410: 0 | C410: 3.8083725e+08 | D410: 0 | E410: 3.8083725e+08 | G410: =E410+F410 -> 3.8083725e+08 | H410: Add: Purchase of raw materials
A411: Purchase - Urd - Stores, Spares & Consumable | B411: 0 | C411: 18056 | D411: 0 | E411: 18056 | G411: =E411+F411 -> 18056 | H411: Add: Purchase of Stores, Spares & Consumables
A412: Purchase Interstate- Stores, Spares & Consumable | B412: 0 | C412: 5043460.2 | D412: 0 | E412: 5043460.2 | G412: =E412+F412 -> 5043460.2 | H412: Add: Purchase of Stores, Spares & Consumables
A413: Purchase Return - Stores, Spares & Consumable | B413: 0 | C413: 54130 | D413: 84770 | E413: -30640 | G413: =E413+F413 -> -30640 | H413: Add: Purchase of Stores, Spares & Consumables
A414: Purchase Withinstate- Stores, Spares & Consumable | B414: 0 | C414: 9175683.5 | D414: 50 | E414: 9175633.5 | G414: =E414+F414 -> 9175633.5 | H414: Add: Purchase of Stores, Spares & Consumables
A415: Purchase Raw Material - High Seas | B415: 0 | C415: 63948135 | D415: 0 | E415: 63948135 | G415: =E415+F415 -> 63948135 | H415: Add: Purchase of raw materials
A416: Business Promotion Expense | B416: 0 | C416: 58000 | D416: 0 | E416: 58000 | G416: =E416+F416 -> 58000 | H416: Other Administrative Expenses
... A422: Garden Mainteance Exp | B422: 0 | C422: 5450 | D422: 0 | E422: 5450 | G422: =E422+F422 -> 5450 | H422: Other Administrative Expenses
A423: House Keeping Expense | B423: 0 | C423: 1978802.4 | D423: 467310 | E423: 1511492.4 | F423: 467310 | G423: =E423+F423 -> 1978802.4 | H423: Other Manufacturing Expenses
A424: Membership & Subscription Fees | B424: 0 | C424: 4550 | D424: 0 | E424: 4550 | G424: =E424+F424 -> 4550 | H424: Other Administrative Expenses
...

Sheet AUGUST - TB
A1: KPW I , Aug-26, T.B AS ON 11-09-26
A2: Perticular | B2: Opening | C2: Debit | D2: Credit | E2: Closing | F2: Provision | G2: Total | H2: Head | I2: 1 | J2: JULY TOTAL | K2: NET AUGSUT | L2: 1 | M2: 1
A3: Duty Clearing Account | B3: 0 | C3: 12782932 | D3: 12782932 | E3: 0 | G3: =E3+F3 -> 0 | H3: Not Applicable | J3: =VLOOKUP(A3,'JULY-TB'!A:G,7,0) -> 0
A4: Income Tax Ay 2014-15 | B4: 1607000 | C4: 0 | D4: 0 | E4: 1607000 | G4: =E4+F4 -> 1607000 | H4: Not Applicable | J4: =VLOOKUP(A4,'JULY-TB'!A:G,7,0) -> 1607000
A5: Income Tax Ay 2016-17 | B5: 2200000 | C5: 0 | D5: 0 | E5: 2200000 | G5: =E5+F5 -> 2200000 | H5: Not Applicable | J5: =VLOOKUP(A5,'JULY-TB'!A:G,7,0) -> 2200000
A6: Income Tax Refund Receivable | B6: 108787 | C6: 0 | D6: 0 | E6: 108787 | G6: =E6+F6 -> 108787 | H6: Not Applicable | J6: =VLOOKUP(A6,'JULY-TB'!A:G,7,0) -> 108787
A7: TCS On Purchase 20-21 | B7: 0 | C7: 0 | D7: 0 | E7: 0 | G7: =E7+F7 -> 0 | H7: Not Applicable | J7: =VLOOKUP(A7,'JULY-TB'!A:G,7,0) -> 0
A8: TCS On Purchase 21-22 | B8: 0 | C8: 0 | D8: 0 | E8: 0 | G8: =E8+F8 -> 0 | H8: Not Applicable | J8: =VLOOKUP(A8,'JULY-TB'!A:G,7,0) -> 0
A9: TCS On Purchase 22-23 | B9: -18585.94 | C9: 0 | D9: 0 | E9: -18585.94 | G9: =E9+F9 -> -18585.94 | H9: Not Applicable | J9: =VLOOKUP(A9,'JULY-TB'!A:G,7,0) -> -18585.94
A10: TCS On Purchase 23-24 | B10: 1151 | C10: 0 | D10: 0 | E10: 1151 | G10: =E10+F10 -> 1151 | H10: Not Applicable | J10: =VLOOKUP(A10,'JULY-TB'!A:G,7,0) -> 1151
A11: Tcs On Purchase 24-25 | B11: 30286.3 | C11: 0 | D11: 0 | E11: 30286.3 | G11: =E11+F11 -> 30286.3 | H11: Not Applicable | J11: =VLOOKUP(A11,'JULY-TB'!A:G,7,0) -> 30286.3
A12: Tcs On Purchase 25-26 | B12: 1335.22 | C12: 0 | D12: 0 | E12: 1335.22 | G12: =E12+F12 -> 1335.22 | H12: Not Applicable | J12: =VLOOKUP(A12,'JULY-TB'!A:G,7,0) -> 1335.22
A13: TDS Receivable 2021-22 | B13: 0 | C13: 0 | D13: 0 | E13: 0 | G13: =E13+F13 -> 0 | H13: Not Applicable | J13: =VLOOKUP(A13,'JULY-TB'!A:G,7,0) -> 0
A14: TDS Receivable 2022-23 | B14: -418818 | C14: 0 | D14: 0 | E14: -418818 | G14: =E14+F14 -> -418818 | H14: Not Applicable | J14: =VLOOKUP(A14,'JULY-TB'!A:G,7,0) -> -418818
... A401: Equipment Certification Charges | B401: 0 | C401: 201810 | D401: 0 | E401: 201810 | G401: =E401+F401 -> 201810 | H401: Other Administrative Expenses | J401: =VLOOKUP(A401,'JULY-TB'!A:G,7,0) -> 154508
A402: Factory Expense | B402: 0 | C402: 377544 | D402: 0 | E402: 377544 | F402: 5000 | G402: =E402+F402 -> 382544 | H402: Other Administrative Expenses | J402: =VLOOKUP(A402,'JULY-TB'!A:G,7,0) -> 377544
A403: Labour Charges | B403: 0 | C403: 29202215 | D403: 6030192 | E403: 23172023 | F403: 8112264 | G403: =E403+F403 -> 31284287 | H403: Labour charges | J403: =VLOOKUP(A403,'JULY-TB'!A:G,7,0) -> 22835909
A404: Power Expense | B404: 0 | C404: 21350160 | D404: 3474593 | E404: 17875567 | F404: =4215121+105000 -> 4320121 | G404: =E404+F404 -> 22195688 | H404: Power and fuel | J404: =VLOOKUP(A404,'JULY-TB'!A:G,7,0) -> 16836693
A405: Rent Expense - Colony | B405: 0 | C405: 6521700 | D405: 1313300 | E405: 5208400 | F405: 1321300 | G405: =E405+F405 -> 6529700 | H405: Other Administrative Expenses | J405: =VLOOKUP(A405,'JULY-TB'!A:G,7,0) -> 5200400
A406: Rent Expenses - Machineries | B406: 0 | C406: 1700000 | D406: 1400000 | E406: 300000 | G406: =E406+F406 -> 300000 | H406: Other Administrative Expenses | J406: =VLOOKUP(A406,'JULY-TB'!A:G,7,0) -> 50000
A407: Exchange Rate Difference - Creditor | B407: 0 | C407: 313632 | D407: 30486.47 | E407: 283145.53 | G407: =E407+F407 -> 283145.53 | H407: Exchange Rate Difference | J407: =VLOOKUP(A407,'JULY-TB'!A:G,7,0) -> 283145.53
A408: Job Charges | B408: 0 | C408: 55698265 | D408: 55384.56 | E408: 55642881 | F408: 207763 | G408: =E408+F408 -> 55850644 | H408: Jobwork charges | J408: =VLOOKUP(A408,'JULY-TB'!A:G,7,0) -> 54908198 | K408: =G408-J408 -> 942445.98
A409: Loading & Unloading Expense | B409: 0 | C409: 193430 | D409: 0 | E409: 193430 | G409: =E409+F409 -> 193430 | H409: Freight Outward and C & F Charges | J409: =VLOOKUP(A409,'JULY-TB'!A:G,7,0) -> 192700
A410: Testing Charges | B410: 0 | C410: 0 | D410: 33844 | E410: -33844 | G410: =E410+F410 -> -33844 | H410: Other Administrative Expenses | J410: =VLOOKUP(A410,'JULY-TB'!A:G,7,0) -> -33844
A411: Water Charges | B411: 0 | C411: 1021975 | D411: 289214 | E411: 732761 | F411: =87425+6680 -> 94105 | G411: =E411+F411 -> 826866 | H411: Other Administrative Expenses | J411: =VLOOKUP(A411,'JULY-TB'!A:G,7,0) -> 732761
A412: Repairs & Maintenance Exp - Plant & Machinery | B412: 0 | C412: 2776206.8 | D412: 0 | E412: 2776206.8 | F412: 164138 | G412: =E412+F412 -> 2940344.8 | H412: Other Manufacturing Expenses | J412: =VLOOKUP(A412,'JULY-TB'!A:G,7,0) -> 1847132.2
A413: Purchase Raw Material - Direct Import | B413: 0 | C413: 27922270 | D413: 0 | E413: 27922270 | G413: =E413+F413 -> 27922270 | H413: Add: Purchase of raw materials | J413: =VLOOKUP(A413,'JULY-TB'!A:G,7,0) -> 27922270
A414: Purchase Withinstate- Packing Material | B414: 0 | C414: 7640650.9 | D414: 1750 | E414: 7638900.9 | G414: =E414+F414 -> 7638900.9 | H414: Add: Purchase of packing materials | J414: =VLOOKUP(A414,'JULY-TB'!A:G,7,0) -> 6188686.3
A415: Purchase In Transit | B415: 0 | C415: 0 | D415: 36870023 | E415: -36870023 | G415: =E415+F415 -> -36870023 | H415: Add: Purchase of raw materials | J415: =VLOOKUP(A415,'JULY-TB'!A:G,7,0) -> -36870023
A416: Purchase Interstate - Raw Material | B416: 0 | C416: 8999989.4 | D416: 0 | E416: 8999989.4 | G416: =E416+F416 -> 8999989.4 | H416: Add: Purchase of raw materials | J416: =VLOOKUP(A416,'JULY-TB'!A:G,7,0) -> 8179409.4
A417: Purchase Return - Within State - Raw Material | B417: 0 | C417: 515217.19 | D417: 0 | E417: 515217.19 | G417: =E417+F417 -> 515217.19 | H417: Add: Purchase of raw materials | J417: =VLOOKUP(A417,'JULY-TB'!A:G,7,0) -> #N/A
A418: Purchase Withinstate - Raw Material | B418: 0 | C418: 5.6935576e+08 | D418: 0 | E418: 5.6935576e+08 | G418: =E418+F418 -> 5.6935576e+08 | H418: Add: Purchase of raw materials | J418: =VLOOKUP(A418,'JULY-TB'!A:G,7,0) -> 3.8083725e+08
A419: Purchase - Import - Stores, Spares & Consumable | B419: 0 | C419: 95444.93 | D419: 0 | E419: 95444.93 | G419: =E419+F419 -> 95444.93 | H419: Add: Purchase of Stores, Spares & Consumables | J419: =VLOOKUP(A419,'JULY-TB'!A:G,7,0) -> #N/A
A420: Purchase - Urd - Stores, Spares & Consumable | B420: 0 | C420: 23485 | D420: 0 | E420: 23485 | G420: =E420+F420 -> 23485 | H420: Add: Purchase of Stores, Spares & Consumables | J420: =VLOOKUP(A420,'JULY-TB'!A:G,7,0) -> 18056
A421: Purchase Interstate- Stores, Spares & Consumable | B421: 0 | C421: 6571202.7 | D421: 2000 | E421: 6569202.7 | G421: =E421+F421 -> 6569202.7 | H421: Add: Purchase of Stores, Spares & Consumables | J421: =VLOOKUP(A421,'JULY-TB'!A:G,7,0) -> 5043460.2
A422: Purchase Return - Stores, Spares & Consumable | B422: 0 | C422: 54130 | D422: 84770 | E422: -30640 | G422: =E422+F422 -> -30640 | H422: Add: Purchase of Stores, Spares & Consumables | J422: =VLOOKUP(A422,'JULY-TB'!A:G,7,0) -> -30640
A423: Purchase Withinstate- Stores, Spares & Consumable | B423: 0 | C423: 12080204 | D423: 50 | E423: 12080154 | G423: =E423+F423 -> 12080154 | H423: Add: Purchase of Stores, Spares & Consumables | J423: =VLOOKUP(A423,'JULY-TB'!A:G,7,0) -> 9175633.5
A424: Purchase Raw Material - High Seas | B424: 0 | C424: 1.1298313e+08 | D424: 0 | E424: 1.1298313e+08 | G424: =E424+F424 -> 1.1298313e+08 | H424: Add: Purchase of raw materials | J424: =VLOOKUP(A424,'JULY-TB'!A:G,7,0) -> 63948135
... A430: Garden Mainteance Exp | B430: 0 | C430: 5450 | D430: 0 | E430: 5450 | G430: =E430+F430 -> 5450 | H430: Other Administrative Expenses | J430: =VLOOKUP(A430,'JULY-TB'!A:G,7,0) -> 5450
A431: House Keeping Expense | B431: 0 | C431: 2021637.5 | D431: 467310 | E431: 1554327.5 | F431: 554014 | G431: =E431+F431 -> 2108341.5 | H431: Other Manufacturing Expenses | J431: =VLOOKUP(A431,'JULY-TB'!A:G,7,0) -> 1978802.4
...
