Workbook
Name Domestic: 'Cust Master'!$D$346:$D$383
Name Export: Table13[Export]

Sheet Quote Exports
JE2: G
B4: Column1 | C4: Column2 | D4: Column3 | E4: Column1791040 | F4: Column1791041 | G4: Column1791026 | H4: Column1791027 | I4: Column1791028 | J4: Column1791029 | K4: Column1791030 | L4: Column1791031 | M4: Column1791032 | N4: Column1791033 | O4: Column1791018 | P4: Column1791019 | Q4: Column1791020 | R4: Column1791021 | S4: Column1791022 | T4: Column1791023 | U4: Column1791024 | V4: Column1791025 | W4: Column1791010 | X4: Column1791011 | Y4: Column1791012 | Z4: Column1791013 | AA4: Column1791014 | AB4: Column1791015 | AC4: Column1791016 | AD4: Column1791017 | AE4: Column179102 | AF4: Column179103 | AG4: Column179104 | AH4: Column179105 | AI4: Column179106 | AJ4: Column179107 | AK4: Column179108 | AL4: Column179109 | AM4: Column1799 | AN4: Column1798 | AO4: Column1797 | AP4: Column1796 | AQ4: Column1795 | AR4: Column1794 | AS4: Column1793 | AT4: Column1792 | AU4: Column15522221122 | AV4: Column156 | AW4: Column1492 | AX4: End
B5: 0 | C5: To Fill | D5: Date | E5: 46161 | F5: 46161 | G5: 46161 | H5: 46161 | I5: 46161 | J5: 46161 | K5: 46161 | L5: 46161 | M5: 46161 | N5: 46161 | O5: 46161 | P5: 46161 | Q5: 46161 | R5: 46163 | S5: 46163 | T5: 46163 | U5: 46164 | V5: 46167
C6: To Fill | D6: Sector | E6: Export | F6: Export | G6: Export | H6: Export | I6: Export | J6: Export | K6: Export | L6: Export | M6: Export | N6: Export | O6: Export | P6: Export | Q6: Export | R6: Export | S6: Export | T6: Export | U6: Export | V6: Export
B7: 1 | C7: To Fill | D7: Customer | E7: ISP Korea | F7: ISP Korea | G7: Desabag | H7: Desabag | I7: Desabag | J7: Desabag | K7: Desabag | L7: Desabag | M7: Desabag | N7: Desabag | O7: Desabag | P7: Desabag | Q7: Desabag | R7: Safesack Scand | S7: Safesack Scand | T7: Condepols | U7: ATEA Turkey | V7: Procon
C8: To Fill | D8: Our Ref | E8: 100X155 | F8: 100X160 | G8: 140X220 | H8: 140X220 | I8: 140X220 | J8: 140X220 | K8: 70X110 | L8: 40X60 | M8: 100X150 | N8: 60X100 | O8: 70X110 | P8: 90X130 | Q8: 60X100 | R8: 46X75 | S8: 72X110 | T8: SB4070N60-122 (1) | U8: 176.5x115 | V8: PP Bag
B9: 2 | C9: To Fill | D9: Customer Ref | E9: 100X155 | F9: 100X160 | G9: 3.3002 | H9: 3.3004 | I9: 3.3006 | J9: 3.3011 | K9: 3.9001 | L9: 3.9003 | M9: 3.9004 | N9: 3.9005 | O9: 3.9008 | P9: 3.9014 | Q9: 3.9015 | S9: ART58961 | T9: 30+10X70 | U9: 176.5x115 | V9: 234589
B10: 3 | C10: To Fill | D10: Type of Fabric/Bag | E10: Tubular Bag | F10: Tubular Bag | G10: Tubular Bag | H10: Tubular Bag | I10: Tubular Bag | J10: Tubular Bag | K10: Tubular Bag | L10: Tubular Bag | M10: Tubular Bag | N10: Tubular Bag | O10: Tubular Bag | P10: Tubular Bag | Q10: Tubular Bag | R10: Tubular Bag | S10: Tubular Bag | T10: Tubular Bag | U10: Tubular Fabric | V10: Tubular Bag
B11: 4 | C11: Spec | D11: Fabric Colour | E11: Coloured | F11: Coloured | G11: MW | H11: MW | I11: MW | J11: MW | K11: MW | L11: MW | M11: MW | N11: MW | O11: MW | P11: Coloured | Q11: MW | R11: Coloured | S11: MW | T11: Transparent | U11: MW | V11: MW
B12: 5 | C12: Spec | D12: Face Width Cm | E12: 100 | F12: 100 | G12: 140 | H12: 140 | I12: 140 | J12: 140 | K12: 70 | L12: 40 | M12: 100 | N12: 60 | O12: 70 | P12: 90 | Q12: 60 | R12: 46 | S12: 72 | T12: 30 | U12: 176.5 | V12: 50
B13: 6 | C13: Spec | D13: Gusset Cm (Both Side) Cm | E13: 0 | F13: 0 | G13: 0 | H13: 0 | I13: 0 | J13: 0 | K13: 0 | L13: 0 | M13: 0 | N13: 0 | O13: 0 | P13: 0 | Q13: 0 | R13: 0 | S13: 0 | T13: 10 | V13: 0
B14: 7 | C14: Spec | D14: Length Cm | E14: 155 | F14: 160 | G14: 220 | H14: 220 | I14: 220 | J14: 220 | K14: 110 | L14: 60 | M14: 150 | N14: 100 | O14: 110 | P14: 130 | Q14: 100 | R14: 75 | S14: 110 | T14: 70 | U14: 115 | V14: 80
B15: 8 | C15: Spec | D15: Top | E15: Hemmed | F15: Hemmed | G15: Hemmed | H15: Hemmed | I15: Hemmed | J15: Hemmed | K15: Hemmed | L15: Hemmed | M15: Hemmed | N15: Hemmed | O15: Hemmed | P15: Hemmed | Q15: Hemmed | R15: Hemmed | S15: Hemmed | T15: Heat Cut | U15: No Fold | V15: Hemmed
B16: 103 | D16: Cut Length Cm | E16: {=IF(E15="","",_xlfn.IFS(E15="Heat Cut",E14+5,E15="Hemmed",E14+8,E15="Ez Open",E14,E15="No Fold",E14+0))} -> 163 | F16: {=IF(F15="","",_xlfn.IFS(F15="Heat Cut",F14+5,F15="Hemmed",F14+8,F15="Ez Open",F14,F15="No Fold",F14+0))} -> 168 | G16: {=IF(G15="","",_xlfn.IFS(G15="Heat Cut",G14+5,G15="Hemmed",G14+8,G15="Ez Open",G14,G15="No Fold",G14+0))} -> 228 | H16: {=IF(H15="","",_xlfn.IFS(H15="Heat Cut",H14+5,H15="Hemmed",H14+8,H15="Ez Open",H14,H15="No Fold",H14+0))} -> 228 | I16: {=IF(I15="","",_xlfn.IFS(I15="Heat Cut",I14+5,I15="Hemmed",I14+8,I15="Ez Open",I14,I15="No Fold",I14+0))} -> 228 | J16: {=IF(J15="","",_xlfn.IFS(J15="Heat Cut",J14+5,J15="Hemmed",J14+8,J15="Ez Open",J14,J15="No Fold",J14+0))} -> 228 | K16: {=IF(K15="","",_xlfn.IFS(K15="Heat Cut",K14+5,K15="Hemmed",K14+8,K15="Ez Open",K14,K15="No Fold",K14+0))} -> 118 | L16: {=IF(L15="","",_xlfn.IFS(L15="Heat Cut",L14+5,L15="Hemmed",L14+8,L15="Ez Open",L14,L15="No Fold",L14+0))} -> 68 | ... V16: {=IF(V15="","",_xlfn.IFS(V15="Heat Cut",V14+5,V15="Hemmed",V14+8,V15="Ez Open",V14,V15="No Fold",V14+0))} -> 88
B17: 9 | C17: Spec | D17: Total Weight Gram | E17: 273 | F17: 377.74 | G17: 673.27 | H17: 609.43 | I17: 539.43 | J17: 409.93 | K17: 114.56 | L17: 46.61 | M17: 274.58 | N17: 88.71 | O17: 148.55 | P17: 219.25 | Q17: 80.71 | R17: 63.73 | S17: 160 | T17: 49.59 | U17: =U19 -> 1096.065 | V17: =V19 -> 59.659016
D18: Fabric GSM TBM | E18: 58 | F18: 58 | G18: 70 | H18: 60 | I18: 60 | J18: 60 | K18: 60 | L18: 60 | M18: 60 | N18: 60 | O18: 60 | P18: 60 | Q18: 60 | R18: 70 | S18: 62.5 | T18: 60 | U18: 270 | V18: 65
D19: Calculated Weight | E19: {=_xlfn.IFS(E18="",0,E10="Back Seam Bag",(E12+E13+2.5)*2*E16*E18/10000+SUM(E31:E43),E10="Tubular Bag",(E12+E13)*2*E16*E18/10000+SUM(E31:E43),E10="Tubular Fabric",(E12+E13)*2*E16*E18/10000+SUM(E31:E43),E10="Flat Fabric",(E12+E13)*2*E16*E18/10000+SUM(E31:E43))} -> 272.65851 | F19: {=_xlfn.IFS(F18="",0,F10="Back Seam Bag",(F12+F13+2.5)*2*F16*F18/10000+SUM(F31:F43),F10="Tubular Bag",(F12+F13)*2*F16*F18/10000+SUM(F31:F43),F10="Tubular Fabric",(F12+F13)*2*F16*F18/10000+SUM(F31:F43),F10="Flat Fabric",(F12+F13)*2*F16*F18/10000+SUM(F31:F43))} -> 377.74123 | G19: {=_xlfn.IFS(G18="",0,G10="Back Seam Bag",(G12+G13+2.5)*2*G16*G18/10000+SUM(G31:G43),G10="Tubular Bag",(G12+G13)*2*G16*G18/10000+SUM(G31:G43),G10="Tubular Fabric",(G12+G13)*2*G16*G18/10000+SUM(G31:G43),G10="Flat Fabric",(G12+G13)*2*G16*G18/10000+SUM(G31:G43))} -> 673.26925 | H19: {=_xlfn.IFS(H18="",0,H10="Back Seam Bag",(H12+H13+2.5)*2*H16*H18/10000+SUM(H31:H43),H10="Tubular Bag",(H12+H13)*2*H16*H18/10000+SUM(H31:H43),H10="Tubular Fabric",(H12+H13)*2*H16*H18/10000+SUM(H31:H43),H10="Flat Fabric",(H12+H13)*2*H16*H18/10000+SUM(H31:H43))} -> 609.42925 | I19: {=_xlfn.IFS(I18="",0,I10="Back Seam Bag",(I12+I13+2.5)*2*I16*I18/10000+SUM(I31:I43),I10="Tubular Bag",(I12+I13)*2*I16*I18/10000+SUM(I31:I43),I10="Tubular Fabric",(I12+I13)*2*I16*I18/10000+SUM(I31:I43),I10="Flat Fabric",(I12+I13)*2*I16*I18/10000+SUM(I31:I43))} -> 539.42925 | J19: {=_xlfn.IFS(J18="",0,J10="Back Seam Bag",(J12+J13+2.5)*2*J16*J18/10000+SUM(J31:J43),J10="Tubular Bag",(J12+J13)*2*J16*J18/10000+SUM(J31:J43),J10="Tubular Fabric",(J12+J13)*2*J16*J18/10000+SUM(J31:J43),J10="Flat Fabric",(J12+J13)*2*J16*J18/10000+SUM(J31:J43))} -> 409.92525 | K19: {=_xlfn.IFS(K18="",0,K10="Back Seam Bag",(K12+K13+2.5)*2*K16*K18/10000+SUM(K31:K43),K10="Tubular Bag",(K12+K13)*2*K16*K18/10000+SUM(K31:K43),K10="Tubular Fabric",(K12+K13)*2*K16*K18/10000+SUM(K31:K43),K10="Flat Fabric",(K12+K13)*2*K16*K18/10000+SUM(K31:K43))} -> 114.56262 | L19: {=_xlfn.IFS(L18="",0,L10="Back Seam Bag",(L12+L13+2.5)*2*L16*L18/10000+SUM(L31:L43),L10="Tubular Bag",(L12+L13)*2*L16*L18/10000+SUM(L31:L43),L10="Tubular Fabric",(L12+L13)*2*L16*L18/10000+SUM(L31:L43),L10="Flat Fabric",(L12+L13)*2*L16*L18/10000+SUM(L31:L43))} -> 46.607213 | ... V19: {=_xlfn.IFS(V18="",0,V10="Back Seam Bag",(V12+V13+2.5)*2*V16*V18/10000+SUM(V31:V43),V10="Tubular Bag",(V12+V13)*2*V16*V18/10000+SUM(V31:V43),V10="Tubular Fabric",(V12+V13)*2*V16*V18/10000+SUM(V31:V43),V10="Flat Fabric",(V12+V13)*2*V16*V18/10000+SUM(V31:V43))} -> 59.659016
B20: =B16+1 -> 104 | D20: Gross Width Cm | E20: =IF(E10="","",IF(E10="Back Seam Bag",E12+E13+2.5,E12+E13)) -> 100 | F20: =IF(F10="","",IF(F10="Back Seam Bag",F12+F13+2.5,F12+F13)) -> 100 | G20: =IF(G10="","",IF(G10="Back Seam Bag",G12+G13+2.5,G12+G13)) -> 140 | H20: =IF(H10="","",IF(H10="Back Seam Bag",H12+H13+2.5,H12+H13)) -> 140 | I20: =IF(I10="","",IF(I10="Back Seam Bag",I12+I13+2.5,I12+I13)) -> 140 | J20: =IF(J10="","",IF(J10="Back Seam Bag",J12+J13+2.5,J12+J13)) -> 140 | K20: =IF(K10="","",IF(K10="Back Seam Bag",K12+K13+2.5,K12+K13)) -> 70 | L20: =IF(L10="","",IF(L10="Back Seam Bag",L12+L13+2.5,L12+L13)) -> 40 | ... V20: =IF(V10="","",IF(V10="Back Seam Bag",V12+V13+2.5,V12+V13)) -> 50
B21: 10 | C21: Spec | D21: Liner Micron | E21: 20 | F21: 50 | G21: 0 | S21: 30 | T21: 0
B22: 11 | C22: Spec | D22: Glossy BOPP Micron
B23: 12 | C23: Spec | D23: Matt BOPP Micron
B24: 13 | C24: Spec | D24: Metalised BOPP Micron
D25: White Paper GSM
D26: Brown Paper GSM
B27: 14 | C27: Spec | D27: Adhesive GSM (Solvant Less)
B28: 15 | C28: Spec | D28: Ink GSM | E28: 0 | F28: 0 | G28: 0 | H28: 0 | I28: 0 | J28: 0 | K28: 0 | L28: 0 | M28: 0 | N28: 0 | O28: 0 | P28: 0 | Q28: 0 | R28: 0 | S28: 0 | T28: 0 | U28: 0 | V28: 0
B29: 105 | D29: Back Seam Coating Gr/Meter | E29: =IF(E$5="","",IF(E10="Back Seam Bag",2,0)) -> 0 | F29: =IF(F$5="","",IF(F10="Back Seam Bag",2,0)) -> 0 | G29: =IF(G$5="","",IF(G10="Back Seam Bag",2,0)) -> 0 | H29: =IF(H$5="","",IF(H10="Back Seam Bag",2,0)) -> 0 | I29: =IF(I$5="","",IF(I10="Back Seam Bag",2,0)) -> 0 | J29: =IF(J$5="","",IF(J10="Back Seam Bag",2,0)) -> 0 | K29: =IF(K$5="","",IF(K10="Back Seam Bag",2,0)) -> 0 | L29: =IF(L$5="","",IF(L10="Back Seam Bag",2,0)) -> 0 | ... V29: =IF(V$5="","",IF(V10="Back Seam Bag",2,0)) -> 0
B30: 16 | C30: Spec | D30: Coating GSM | E30: 0 | F30: 0 | G30: 20 | H30: 20 | I30: 20 | J30: 0 | K30: 0 | L30: 0 | M30: 20 | N30: 0 | O30: 20 | P30: 20 | Q30: 0 | R30: 0 | T30: 20
B31: 17 | C31: Spec | D31: Handle | E31: 15.6 | F31: 15.6 | G31: 90 | H31: 90 | I31: 20 | J31: 20 | K31: 12 | L31: 12 | M31: 15.6 | N31: 8 | O31: 12 | P31: 15 | Q31: 0 | R31: 8 | S31: 0 | T31: 0
B32: 106 | D32: Easy Open | E32: =IF(E5="","",IF(E15="Ez Open",7/100*(E12+10),0)) -> 0 | F32: =IF(F5="","",IF(F15="Ez Open",7/100*(F12+10),0)) -> 0 | G32: =IF(G5="","",IF(G15="Ez Open",7/100*(G12+10),0)) -> 0 | H32: =IF(H5="","",IF(H15="Ez Open",7/100*(H12+10),0)) -> 0 | I32: =IF(I5="","",IF(I15="Ez Open",7/100*(I12+10),0)) -> 0 | J32: =IF(J5="","",IF(J15="Ez Open",7/100*(J12+10),0)) -> 0 | K32: =IF(K5="","",IF(K15="Ez Open",7/100*(K12+10),0)) -> 0 | L32: =IF(L5="","",IF(L15="Ez Open",7/100*(L12+10),0)) -> 0 | ... V32: =IF(V5="","",IF(V15="Ez Open",7/100*(V12+10),0)) -> 0
B33: =B32+1 -> 107 | D33: Liner Wt | E33: =IFERROR((E$12+E$13+2)*2*(E$16+5)/10000*E21*0.92,"") -> 63.06048 | F33: =IFERROR((F$12+F$13+2)*2*(F$16+5)/10000*F21*0.92,"") -> 162.3432 | G33: =IFERROR((G$12+G$13+2)*2*(G$16+5)/10000*G21*0.92,"") -> 0 | H33: =IFERROR((H$12+H$13+2)*2*(H$16+5)/10000*H21*0.92,"") -> 0 | I33: =IFERROR((I$12+I$13+2)*2*(I$16+5)/10000*I21*0.92,"") -> 0 | J33: =IFERROR((J$12+J$13+2)*2*(J$16+5)/10000*J21*0.92,"") -> 0 | K33: =IFERROR((K$12+K$13+2)*2*(K$16+5)/10000*K21*0.92,"") -> 0 | L33: =IFERROR((L$12+L$13+2)*2*(L$16+5)/10000*L21*0.92,"") -> 0 | ... V33: =IFERROR((V$12+V$13+2)*2*(V$16+5)/10000*V21*0.92,"") -> 0
B34: =B33+1 -> 108 | D34: Glossy BOPP Wt | E34: =IFERROR((E$12+E$13+1.5)*2*E$16/10000*E22*0.92,"") -> 0 | F34: =IFERROR((F$12+F$13+1.5)*2*F$16/10000*F22*0.92,"") -> 0 | G34: =IFERROR((G$12+G$13+1.5)*2*G$16/10000*G22*0.92,"") -> 0 | H34: =IFERROR((H$12+H$13+1.5)*2*H$16/10000*H22*0.92,"") -> 0 | I34: =IFERROR((I$12+I$13+1.5)*2*I$16/10000*I22*0.92,"") -> 0 | J34: =IFERROR((J$12+J$13+1.5)*2*J$16/10000*J22*0.92,"") -> 0 | K34: =IFERROR((K$12+K$13+1.5)*2*K$16/10000*K22*0.92,"") -> 0 | L34: =IFERROR((L$12+L$13+1.5)*2*L$16/10000*L22*0.92,"") -> 0 | ... V34: =IFERROR((V$12+V$13+1.5)*2*V$16/10000*V22*0.92,"") -> 0
B35: =B34+1 -> 109 | D35: Matt BOPP Wt | E35: =IFERROR((E$12+E$13+1.5)*2*E$16/10000*E23*0.92,"") -> 0 | F35: =IFERROR((F$12+F$13+1.5)*2*F$16/10000*F23*0.92,"") -> 0 | G35: =IFERROR((G$12+G$13+1.5)*2*G$16/10000*G23*0.92,"") -> 0 | H35: =IFERROR((H$12+H$13+1.5)*2*H$16/10000*H23*0.92,"") -> 0 | I35: =IFERROR((I$12+I$13+1.5)*2*I$16/10000*I23*0.92,"") -> 0 | J35: =IFERROR((J$12+J$13+1.5)*2*J$16/10000*J23*0.92,"") -> 0 | K35: =IFERROR((K$12+K$13+1.5)*2*K$16/10000*K23*0.92,"") -> 0 | L35: =IFERROR((L$12+L$13+1.5)*2*L$16/10000*L23*0.92,"") -> 0 | ... V35: =IFERROR((V$12+V$13+1.5)*2*V$16/10000*V23*0.92,"") -> 0
B36: =B35+1 -> 110 | D36: Metalised BOPP Wt | E36: =IFERROR((E$12+E$13+1.5)*2*E$16/10000*E24*0.92,"") -> 0 | F36: =IFERROR((F$12+F$13+1.5)*2*F$16/10000*F24*0.92,"") -> 0 | G36: =IFERROR((G$12+G$13+1.5)*2*G$16/10000*G24*0.92,"") -> 0 | H36: =IFERROR((H$12+H$13+1.5)*2*H$16/10000*H24*0.92,"") -> 0 | I36: =IFERROR((I$12+I$13+1.5)*2*I$16/10000*I24*0.92,"") -> 0 | J36: =IFERROR((J$12+J$13+1.5)*2*J$16/10000*J24*0.92,"") -> 0 | K36: =IFERROR((K$12+K$13+1.5)*2*K$16/10000*K24*0.92,"") -> 0 | L36: =IFERROR((L$12+L$13+1.5)*2*L$16/10000*L24*0.92,"") -> 0 | ... V36: =IFERROR((V$12+V$13+1.5)*2*V$16/10000*V24*0.92,"") -> 0
D37: White Paper Wt | E37: =IFERROR((E$12+E$13+1.5)*2*E$16/10000*E25,"") -> 0 | F37: =IFERROR((F$12+F$13+1.5)*2*F$16/10000*F25,"") -> 0 | G37: =IFERROR((G$12+G$13+1.5)*2*G$16/10000*G25,"") -> 0 | H37: =IFERROR((H$12+H$13+1.5)*2*H$16/10000*H25,"") -> 0 | I37: =IFERROR((I$12+I$13+1.5)*2*I$16/10000*I25,"") -> 0 | J37: =IFERROR((J$12+J$13+1.5)*2*J$16/10000*J25,"") -> 0 | K37: =IFERROR((K$12+K$13+1.5)*2*K$16/10000*K25,"") -> 0 | L37: =IFERROR((L$12+L$13+1.5)*2*L$16/10000*L25,"") -> 0 | ... V37: =IFERROR((V$12+V$13+1.5)*2*V$16/10000*V25,"") -> 0
D38: Brown Paper Wt | E38: =IFERROR((E$12+E$13+1.5)*2*E$16/10000*E26,"") -> 0 | F38: =IFERROR((F$12+F$13+1.5)*2*F$16/10000*F26,"") -> 0 | G38: =IFERROR((G$12+G$13+1.5)*2*G$16/10000*G26,"") -> 0 | H38: =IFERROR((H$12+H$13+1.5)*2*H$16/10000*H26,"") -> 0 | I38: =IFERROR((I$12+I$13+1.5)*2*I$16/10000*I26,"") -> 0 | J38: =IFERROR((J$12+J$13+1.5)*2*J$16/10000*J26,"") -> 0 | K38: =IFERROR((K$12+K$13+1.5)*2*K$16/10000*K26,"") -> 0 | L38: =IFERROR((L$12+L$13+1.5)*2*L$16/10000*L26,"") -> 0 | ... V38: =IFERROR((V$12+V$13+1.5)*2*V$16/10000*V26,"") -> 0
B39: =B36+1 -> 111 | D39: Adhesive Wt | E39: =IFERROR((E$12+E$13+1.5)*2*E$16/10000*E27*0.92,"") -> 0 | F39: =IFERROR((F$12+F$13+1.5)*2*F$16/10000*F27*0.92,"") -> 0 | G39: =IFERROR((G$12+G$13+1.5)*2*G$16/10000*G27*0.92,"") -> 0 | H39: =IFERROR((H$12+H$13+1.5)*2*H$16/10000*H27*0.92,"") -> 0 | I39: =IFERROR((I$12+I$13+1.5)*2*I$16/10000*I27*0.92,"") -> 0 | J39: =IFERROR((J$12+J$13+1.5)*2*J$16/10000*J27*0.92,"") -> 0 | K39: =IFERROR((K$12+K$13+1.5)*2*K$16/10000*K27*0.92,"") -> 0 | L39: =IFERROR((L$12+L$13+1.5)*2*L$16/10000*L27*0.92,"") -> 0 | ... V39: =IFERROR((V$12+V$13+1.5)*2*V$16/10000*V27*0.92,"") -> 0
B40: =B39+1 -> 112 | D40: Ink Wt | E40: =IFERROR((E$12+E$13+1.5)*2*E$16/10000*E28,"") -> 0 | F40: =IFERROR((F$12+F$13+1.5)*2*F$16/10000*F28,"") -> 0 | G40: =IFERROR((G$12+G$13+1.5)*2*G$16/10000*G28,"") -> 0 | H40: =IFERROR((H$12+H$13+1.5)*2*H$16/10000*H28,"") -> 0 | I40: =IFERROR((I$12+I$13+1.5)*2*I$16/10000*I28,"") -> 0 | J40: =IFERROR((J$12+J$13+1.5)*2*J$16/10000*J28,"") -> 0 | K40: =IFERROR((K$12+K$13+1.5)*2*K$16/10000*K28,"") -> 0 | L40: =IFERROR((L$12+L$13+1.5)*2*L$16/10000*L28,"") -> 0 | ... V40: =IFERROR((V$12+V$13+1.5)*2*V$16/10000*V28,"") -> 0
B41: =B40+1 -> 113 | D41: Back Seam Coating Weight | E41: =IFERROR(E29*E16/100,"") -> 0 | F41: =IFERROR(F29*F16/100,"") -> 0 | G41: =IFERROR(G29*G16/100,"") -> 0 | H41: =IFERROR(H29*H16/100,"") -> 0 | I41: =IFERROR(I29*I16/100,"") -> 0 | J41: =IFERROR(J29*J16/100,"") -> 0 | K41: =IFERROR(K29*K16/100,"") -> 0 | L41: =IFERROR(L29*L16/100,"") -> 0 | ... V41: =IFERROR(V29*V16/100,"") -> 0
B42: =B41+1 -> 114 | D42: Coating Wt | E42: =IFERROR((E$12+E$13+2)*2*E$16/10000*E30,"") -> 0 | F42: =IFERROR((F$12+F$13+2)*2*F$16/10000*F30,"") -> 0 | G42: =IFERROR((G$12+G$13+2)*2*G$16/10000*G30,"") -> 129.504 | H42: =IFERROR((H$12+H$13+2)*2*H$16/10000*H30,"") -> 129.504 | I42: =IFERROR((I$12+I$13+2)*2*I$16/10000*I30,"") -> 129.504 | J42: =IFERROR((J$12+J$13+2)*2*J$16/10000*J30,"") -> 0 | K42: =IFERROR((K$12+K$13+2)*2*K$16/10000*K30,"") -> 0 | L42: =IFERROR((L$12+L$13+2)*2*L$16/10000*L30,"") -> 0 | ... V42: =IFERROR((V$12+V$13+2)*2*V$16/10000*V30,"") -> 0
...

Sheet Filter CstWs DtWs
D1: Customer Name | E1: Desabag
D2: Date | E2: 46161
D3: Our Ref
C5: Print | D5: Date | E5: {=IFERROR(_xlfn.IFS(AND(E3="",E2="",E1=""),"Fill Customer Name",AND(E3="",E2=""),_xlfn._xlws.FILTER('Quote Exports'!D5:AX216,('Quote Exports'!D7:AX7=E1)),E3="",_xlfn._xlws.FILTER('Quote Exports'!D5:AX216,('Quote Exports'!D7:AX7=E1)*('Quote Exports'!D5:AX5=E2)),E3<>"",_xlfn._xlws.FILTER('Quote Exports'!D5:AX216,('Quote Exports'!D7:AX7=E1)*('Quote Exports'!D5:AX5=E2)*('Quote Exports'!D8:AX8=E3))),"Not Found")} -> 46161 | F5: 46161 | G5: 46161 | H5: 46161 | I5: 46161 | J5: 46161 | K5: 46161 | L5: 46161 | M5: 46161 | N5: 46161 | O5: 46161 | JF5: End
A6: =IF('Quote Exports'!C6="","",'Quote Exports'!C6) -> To Fill | D6: Sector | E6: Export | F6: Export | G6: Export | H6: Export | I6: Export | J6: Export | K6: Export | L6: Export | M6: Export | N6: Export | O6: Export | JF6: End
A7: =IF('Quote Exports'!C7="","",'Quote Exports'!C7) -> To Fill | D7: Customer | E7: Desabag | F7: Desabag | G7: Desabag | H7: Desabag | I7: Desabag | J7: Desabag | K7: Desabag | L7: Desabag | M7: Desabag | N7: Desabag | O7: Desabag | JF7: End
A8: =IF('Quote Exports'!C8="","",'Quote Exports'!C8) -> To Fill | D8: Our Ref | E8: 140X220 | F8: 140X220 | G8: 140X220 | H8: 140X220 | I8: 70X110 | J8: 40X60 | K8: 100X150 | L8: 60X100 | M8: 70X110 | N8: 90X130 | O8: 60X100 | JF8: End
A9: =IF('Quote Exports'!C9="","",'Quote Exports'!C9) -> To Fill | D9: Customer Ref | E9: 3.3002 | F9: 3.3004 | G9: 3.3006 | H9: 3.3011 | I9: 3.9001 | J9: 3.9003 | K9: 3.9004 | L9: 3.9005 | M9: 3.9008 | N9: 3.9014 | O9: 3.9015 | JF9: End
A10: =IF('Quote Exports'!C10="","",'Quote Exports'!C10) -> To Fill | D10: Type of Fabric/Bag | E10: Tubular Bag | F10: Tubular Bag | G10: Tubular Bag | H10: Tubular Bag | I10: Tubular Bag | J10: Tubular Bag | K10: Tubular Bag | L10: Tubular Bag | M10: Tubular Bag | N10: Tubular Bag | O10: Tubular Bag | JF10: End
A11: =IF('Quote Exports'!C11="","",'Quote Exports'!C11) -> Spec | D11: Fabric Colour | E11: MW | F11: MW | G11: MW | H11: MW | I11: MW | J11: MW | K11: MW | L11: MW | M11: MW | N11: Coloured | O11: MW | JF11: End
A12: =IF('Quote Exports'!C12="","",'Quote Exports'!C12) -> Spec | D12: Face Width Cm | E12: 140 | F12: 140 | G12: 140 | H12: 140 | I12: 70 | J12: 40 | K12: 100 | L12: 60 | M12: 70 | N12: 90 | O12: 60 | JF12: End
A13: =IF('Quote Exports'!C13="","",'Quote Exports'!C13) -> Spec | D13: Gusset Cm (Both Side) Cm | E13: 0 | F13: 0 | G13: 0 | H13: 0 | I13: 0 | J13: 0 | K13: 0 | L13: 0 | M13: 0 | N13: 0 | O13: 0 | JF13: End
A14: =IF('Quote Exports'!C14="","",'Quote Exports'!C14) -> Spec | D14: Length Cm | E14: 220 | F14: 220 | G14: 220 | H14: 220 | I14: 110 | J14: 60 | K14: 150 | L14: 100 | M14: 110 | N14: 130 | O14: 100 | JF14: End
A15: =IF('Quote Exports'!C15="","",'Quote Exports'!C15) -> Spec | D15: Top | E15: Hemmed | F15: Hemmed | G15: Hemmed | H15: Hemmed | I15: Hemmed | J15: Hemmed | K15: Hemmed | L15: Hemmed | M15: Hemmed | N15: Hemmed | O15: Hemmed | JF15: End
A16: =IF('Quote Exports'!C16="","",'Quote Exports'!C16) | D16: Cut Length Cm | E16: 228 | F16: 228 | G16: 228 | H16: 228 | I16: 118 | J16: 68 | K16: 158 | L16: 108 | M16: 118 | N16: 138 | O16: 108 | JF16: End
A17: =IF('Quote Exports'!C17="","",'Quote Exports'!C17) -> Spec | D17: Total Weight Gram | E17: 673.27 | F17: 609.43 | G17: 539.43 | H17: 409.93 | I17: 114.56 | J17: 46.61 | K17: 274.58 | L17: 88.71 | M17: 148.55 | N17: 219.25 | O17: 80.71 | JF17: End
D18: Fabric GSM TBM | E18: 70 | F18: 60 | G18: 60 | H18: 60 | I18: 60 | J18: 60 | K18: 60 | L18: 60 | M18: 60 | N18: 60 | O18: 60 | JF18: End
D19: Calculated Weight | E19: 673.26925 | F19: 609.42925 | G19: 539.42925 | H19: 409.92525 | I19: 114.56262 | J19: 46.607213 | K19: 274.58203 | L19: 88.71082 | M19: 148.54662 | N19: 219.25023 | O19: 80.71082 | JF19: End
A20: =IF('Quote Exports'!C20="","",'Quote Exports'!C20) | D20: Gross Width Cm | E20: 140 | F20: 140 | G20: 140 | H20: 140 | I20: 70 | J20: 40 | K20: 100 | L20: 60 | M20: 70 | N20: 90 | O20: 60 | JF20: End
A21: =IF('Quote Exports'!C21="","",'Quote Exports'!C21) -> Spec | D21: Liner Micron | E21: 0 | F21: 0 | G21: 0 | H21: 0 | I21: 0 | J21: 0 | K21: 0 | L21: 0 | M21: 0 | N21: 0 | O21: 0 | JF21: End
A22: =IF('Quote Exports'!C22="","",'Quote Exports'!C22) -> Spec | D22: Glossy BOPP Micron | E22: 0 | F22: 0 | G22: 0 | H22: 0 | I22: 0 | J22: 0 | K22: 0 | L22: 0 | M22: 0 | N22: 0 | O22: 0 | JF22: End
A23: =IF('Quote Exports'!C23="","",'Quote Exports'!C23) -> Spec | D23: Matt BOPP Micron | E23: 0 | F23: 0 | G23: 0 | H23: 0 | I23: 0 | J23: 0 | K23: 0 | L23: 0 | M23: 0 | N23: 0 | O23: 0 | JF23: End
A24: =IF('Quote Exports'!C24="","",'Quote Exports'!C24) -> Spec | D24: Metalised BOPP Micron | E24: 0 | F24: 0 | G24: 0 | H24: 0 | I24: 0 | J24: 0 | K24: 0 | L24: 0 | M24: 0 | N24: 0 | O24: 0 | JF24: End
A25: =IF('Quote Exports'!C27="","",'Quote Exports'!C27) -> Spec | D25: White Paper GSM | E25: 0 | F25: 0 | G25: 0 | H25: 0 | I25: 0 | J25: 0 | K25: 0 | L25: 0 | M25: 0 | N25: 0 | O25: 0 | JF25: End
A26: =IF('Quote Exports'!C28="","",'Quote Exports'!C28) -> Spec | D26: Brown Paper GSM | E26: 0 | F26: 0 | G26: 0 | H26: 0 | I26: 0 | J26: 0 | K26: 0 | L26: 0 | M26: 0 | N26: 0 | O26: 0 | JF26: End
A27: =IF('Quote Exports'!C29="","",'Quote Exports'!C29) | D27: Adhesive GSM (Solvant Less) | E27: 0 | F27: 0 | G27: 0 | H27: 0 | I27: 0 | J27: 0 | K27: 0 | L27: 0 | M27: 0 | N27: 0 | O27: 0 | JF27: End
A28: =IF('Quote Exports'!C30="","",'Quote Exports'!C30) -> Spec | D28: Ink GSM | E28: 0 | F28: 0 | G28: 0 | H28: 0 | I28: 0 | J28: 0 | K28: 0 | L28: 0 | M28: 0 | N28: 0 | O28: 0 | JF28: End
A29: =IF('Quote Exports'!C31="","",'Quote Exports'!C31) -> Spec | D29: Back Seam Coating Gr/Meter | E29: 0 | F29: 0 | G29: 0 | H29: 0 | I29: 0 | J29: 0 | K29: 0 | L29: 0 | M29: 0 | N29: 0 | O29: 0 | JF29: End
A30: =IF('Quote Exports'!C32="","",'Quote Exports'!C32) | D30: Coating GSM | E30: 20 | F30: 20 | G30: 20 | H30: 0 | I30: 0 | J30: 0 | K30: 20 | L30: 0 | M30: 20 | N30: 20 | O30: 0 | JF30: End
A31: =IF('Quote Exports'!C33="","",'Quote Exports'!C33) | D31: Handle | E31: 90 | F31: 90 | G31: 20 | H31: 20 | I31: 12 | J31: 12 | K31: 15.6 | L31: 8 | M31: 12 | N31: 15 | O31: 0 | JF31: End
A32: =IF('Quote Exports'!C34="","",'Quote Exports'!C34) | D32: Easy Open | E32: 0 | F32: 0 | G32: 0 | H32: 0 | I32: 0 | J32: 0 | K32: 0 | L32: 0 | M32: 0 | N32: 0 | O32: 0 | JF32: End
A33: =IF('Quote Exports'!C35="","",'Quote Exports'!C35) | D33: Liner Wt | E33: 0 | F33: 0 | G33: 0 | H33: 0 | I33: 0 | J33: 0 | K33: 0 | L33: 0 | M33: 0 | N33: 0 | O33: 0 | JF33: End
A34: =IF('Quote Exports'!C36="","",'Quote Exports'!C36) | D34: Glossy BOPP Wt | E34: 0 | F34: 0 | G34: 0 | H34: 0 | I34: 0 | J34: 0 | K34: 0 | L34: 0 | M34: 0 | N34: 0 | O34: 0 | JF34: End
A35: =IF('Quote Exports'!C39="","",'Quote Exports'!C39) | D35: Matt BOPP Wt | E35: 0 | F35: 0 | G35: 0 | H35: 0 | I35: 0 | J35: 0 | K35: 0 | L35: 0 | M35: 0 | N35: 0 | O35: 0 | JF35: End
A36: =IF('Quote Exports'!C40="","",'Quote Exports'!C40) | D36: Metalised BOPP Wt | E36: 0 | F36: 0 | G36: 0 | H36: 0 | I36: 0 | J36: 0 | K36: 0 | L36: 0 | M36: 0 | N36: 0 | O36: 0 | JF36: End
A37: =IF('Quote Exports'!C41="","",'Quote Exports'!C41) | D37: White Paper Wt | E37: 0 | F37: 0 | G37: 0 | H37: 0 | I37: 0 | J37: 0 | K37: 0 | L37: 0 | M37: 0 | N37: 0 | O37: 0 | JF37: End
A38: =IF('Quote Exports'!C42="","",'Quote Exports'!C42) | D38: Brown Paper Wt | E38: 0 | F38: 0 | G38: 0 | H38: 0 | I38: 0 | J38: 0 | K38: 0 | L38: 0 | M38: 0 | N38: 0 | O38: 0 | JF38: End
A39: =IF('Quote Exports'!C43="","",'Quote Exports'!C43) | D39: Adhesive Wt | E39: 0 | F39: 0 | G39: 0 | H39: 0 | I39: 0 | J39: 0 | K39: 0 | L39: 0 | M39: 0 | N39: 0 | O39: 0 | JF39: End
A40: =IF('Quote Exports'!C44="","",'Quote Exports'!C44) | D40: Ink Wt | E40: 0 | F40: 0 | G40: 0 | H40: 0 | I40: 0 | J40: 0 | K40: 0 | L40: 0 | M40: 0 | N40: 0 | O40: 0 | JF40: End
A41: =IF('Quote Exports'!C45="","",'Quote Exports'!C45) | B41: 1 | D41: Back Seam Coating Weight | E41: 0 | F41: 0 | G41: 0 | H41: 0 | I41: 0 | J41: 0 | K41: 0 | L41: 0 | M41: 0 | N41: 0 | O41: 0 | JF41: End
...

Sheet Z Ad Star Bag
B4: Date | C4: 45536 | D4: 45536 | E4: 45585 | F4: 45594 | G4: 45647 | H4: 45647 | I4: 45647 | J4: 45656 | K4: 45656 | L4: 45656 | M4: 45656 | N4: 45667 | O4: 45667 | P4: 45667 | Q4: 45678 | R4: 45698 | S4: 45699 | T4: 45699 | U4: 45667 | V4: 45667 | W4: 45712 | X4: 45735 | Y4: 45736 | Z4: 45736 | AA4: 45736 | AB4: 45736 | AC4: 45775 | AD4: 45775 | AE4: 45775 | AF4: 45783 | AG4: 45790 | AH4: 45819 | AI4: 45819 | AJ4: 45853 | AK4: 45853 | AL4: 45853 | AM4: 45856 | AN4: 45868 | AO4: 45875 | AP4: 45922 | AQ4: 45929 | AR4: 45951 | AS4: 45951 | AT4: 45952 | AU4: 45958 | AV4: 45964 | AW4: 45964 | AX4: 45964 | AY4: 45964 | AZ4: 45967 | BA4: 45967 | BB4: 46001 | BC4: 46029 | BD4: 46029 | BE4: 46029 | BF4: 46029 | BG4: 46038 | BH4: 46038 | BI4: 46043 | BJ4: 46043 | BK4: 46045 | BL4: 46045 | BM4: 45647 | BN4: 46045 | BO4: 46045 | BP4: 46045 | BQ4: 46051 | BR4: 46051 | BS4: 46052 | BT4: 46052 | BU4: 46052 | BV4: 46054 | BW4: 46054 | BX4: 46056 | BY4: 46061 | BZ4: 46070 | CA4: 46071 | CB4: 46071 | CC4: 46078 | CD4: 46078 | CE4: 46079 | CF4: 46080 | CG4: 46087 | CH4: 46088 | CI4: 46088 | CJ4: 46088 | CK4: 46090 | CL4: 46090 | CM4: 46091 | CN4: 46092 | CO4: 46092 | CP4: 46092 | CQ4: 46093 | CR4: 46099 | CS4: 46099 | CT4: 46099 | CU4: 46099 | CV4: 46099 | CW4: 46099 | CX4: 46101 | CY4: 46108 | CZ4: 46108 | DA4: 46118 | DB4: 46120 | DC4: 46135 | DD4: 46135 | DE4: 46135 | DF4: 46136 | DG4: 46136 | DH4: 46136 | DI4: 46136 | DJ4: 46136 | DK4: 46139 | DL4: 46139 | DM4: 46139 | DN4: 46139 | DO4: 46140 | DP4: 46141 | DQ4: 46160 | DR4: 46161 | DS4: 46162 | DT4: 46164 | DU4: 46165
B5: Sector | C5: Export | D5: Export | E5: Export | F5: Export | G5: Export | H5: Export | I5: Export | J5: Export | K5: Export | L5: Export | M5: Export | N5: Export | O5: Export | P5: Export | Q5: Export | R5: Export | S5: Export | T5: Export | U5: Export | V5: Export | W5: Domestic | X5: Export | Y5: Export | Z5: Export | AA5: Export | AB5: Export | AC5: Export | AD5: Export | AE5: Export | AF5: Export | AG5: Export | AH5: Domestic | AI5: Export | AJ5: Export | AK5: Export | AL5: Export | AM5: Domestic | AN5: Domestic | AO5: Domestic | AP5: Export | AQ5: Export | AR5: Export | AS5: Export | AT5: Export | AU5: Export | AV5: Export | AW5: Domestic | AX5: Domestic | AY5: Domestic | AZ5: Export | BA5: Export | BB5: Export | BC5: Domestic | BD5: Export | BE5: Export | BF5: Export | BG5: Export | BH5: Export | BI5: Export | BJ5: Export | BK5: Domestic | BL5: Domestic | BM5: Domestic | BN5: Domestic | BO5: Domestic | BP5: Export | BQ5: Export | BR5: Export | BS5: Domestic | BT5: Export | BU5: Export | BV5: Export | BW5: Export | BX5: Export | BY5: Domestic | BZ5: Export | CA5: Export | CB5: Export | CC5: Export | CD5: Export | CE5: Export | CF5: Export | CG5: Export | CH5: Export | CI5: Export | CJ5: Export | CK5: Export | CL5: Export | CM5: Domestic | CN5: Export | CO5: Export | CP5: Export | CQ5: Export | CR5: Export | CS5: Export | CT5: Export | CU5: Export | CV5: Export | CW5: Export | CX5: Domestic | CY5: Domestic | CZ5: Export | DA5: Domestic | DB5: Domestic | DC5: Export | DD5: Export | DE5: Export | DF5: Export | DG5: Export | DH5: Export | DI5: Export | DJ5: Domestic | DK5: Export | DL5: Export | DM5: Export | DN5: Export | DO5: Export | DP5: Export | DQ5: Domestic | DR5: Export | DS5: Domestic | DT5: Domestic | DU5: Domestic
B6: Customer | C6: Fibco | D6: Fibco | E6: Terceirence | F6: Fibco | G6: Ravitalment | H6: Ravitalment | I6: Ravitalment | J6: Ravitalment | K6: Ravitalment | L6: Ravitalment | M6: Ravitalment | N6: FIBCO | O6: Nuvi | P6: Nuvi | Q6: Jordan Minerals | R6: Uma Dutta | S6: Akash Wadhwa | T6: Akash Wadhwa | U6: FIBCO | V6: Gravis Global | W6: Nirmal | X6: Condepols | Y6: Tisser | Z6: Uma Dutta | AA6: Uma Dutta | AB6: Uma Dutta | AC6: Ravitalment | AD6: Ravitalment | AE6: Ravitalment | AF6: HL-TopMix | AG6: HL-TopMix | AH6: Sunil SHarma | AI6: Sunil SHarma | AJ6: JGL | AK6: JGL | AL6: JGL | AM6: Kyoson | AN6: Swastik | AO6: Amrfeo | AP6: Kenz Jordan | AQ6: Nirmal | AR6: Ameriglobe | AS6: Caspian Ind | AT6: Ameriglobe | AU6: Material Motion | AV6: SafeSack | AW6: Swastik | AX6: Swastik | AY6: Swastik | AZ6: Chinguitty Cement | BA6: Chinguitty Cement | BB6: Agroszemek | BC6: Swastik | BD6: FIBCO | BE6: FIBCO | BF6: FIBCO | BG6: Sadlier | BH6: Sadlier | BI6: Sadlier | BJ6: Sadlier | BK6: Exleeir | BL6: Exleeir | BM6: Exleeir | BN6: Swastik | BO6: Swastik | BP6: SafeSack | BQ6: Fibco | BR6: Fibco | BS6: Amrfeo | BT6: Bluepack | BU6: Bluepack | BV6: Fibco | BW6: Fibco | BX6: Ameriglobe | BY6: Kypson | BZ6: Bluepack | CA6: Agroszemek | CB6: Agroszemek | CC6: NNZ | CD6: NNZ | CE6: Minini | CF6: FPS Italy | CG6: Terceirence | CH6: Mam Platre | CI6: KM Obaly | CJ6: FPS Italy | CK6: Agroszemek | CL6: Agroszemek | CM6: Amrfeo | CN6: Ravitalment | CO6: Ravitalment | CP6: Ravitalment | CQ6: KM Obaly | CR6: Minini | CS6: Chinguitty Cement | CT6: Chinguitty Cement | CU6: KM Obaly | CV6: Agroszemek | CW6: Agroszemek | CX6: Kypson | CY6: Kypson | CZ6: FPS Italy | DA6: Zaak | DB6: Kypson | DC6: Ambiflex | DD6: Ambiflex | DE6: Ambiflex | DF6: Sunil Sharma | DG6: Sunil Sharma | DH6: Sunil Sharma | DI6: Sunil Sharma | DJ6: Swastik | DK6: Chinguitty Cement | DL6: Chinguitty Cement | DM6: Norus | DN6: Chinguitty Cement | DO6: Mam Platre | DP6: Sadliers | DQ6: Amrfeo | DR6: Minini | DS6: Aman | DT6: Zaak | DU6: Bharat Carbonates
B7: Our Ref | G7: PS2020 | H7: PS2040 | I7: PS2030 | J7: PS2030 | K7: PS2030 | L7: PS2030 | M7: PS2030 | N7: Phosphea | O7: Double Colour | P7: Single Colour | U7: Phosphea | V7: Phosphea | AC7: PS-2020 | AD7: PS-2030 | AE7: PS-2040 | BD7: RAK | BE7: RAK | BF7: RAK | BQ7: 2543 | BR7: 2126 | BV7: 2543 | BW7: 2126 | CN7: PS-2020 | CO7: PS-2030 | CP7: PS-2040
B8: Customer Ref
B9: Bag Width | C9: 45 | D9: 45 | E9: 40 | F9: 36 | G9: 37.5 | H9: 37.5 | I9: 38 | J9: 50 | K9: 50 | L9: 45 | M9: 47 | N9: 50 | O9: 51 | P9: 51 | Q9: 50 | R9: 40.5 | S9: 38 | T9: 38 | U9: 50 | V9: =15*2.54 -> 38.1 | W9: 57 | X9: 50 | Y9: 40 | Z9: 40 | AA9: 50 | AB9: 35 | AC9: 37.5 | AD9: 38 | AE9: 37.5 | AF9: 51 | AG9: 54 | AH9: 55 | AI9: 55 | AJ9: 47 | AK9: 48 | AL9: 50 | AM9: =17*2.54 -> 43.18 | AN9: 45 | AO9: =18*2.54 -> 45.72 | AP9: 45 | AQ9: 48 | AR9: =22*2.54 -> 55.88 | AS9: 54 | AT9: =22*2.54 -> 55.88 | AU9: =23.5*2.54 -> 59.69 | AV9: 49 | AW9: 43 | AX9: 50 | AY9: 43 | AZ9: 51 | BA9: 48 | BB9: 50 | BC9: 43 | BD9: 51 | BE9: 48.5 | BF9: 41 | BG9: 46 | BH9: 52 | BI9: 46 | BJ9: 52 | BK9: 50 | BL9: 50 | BM9: 37.5 | BN9: 43 | BO9: 45 | BP9: 47 | BQ9: 51 | BR9: 48 | BS9: 45 | BT9: 54 | BU9: 50 | BV9: 51 | BW9: 48 | BX9: =22*2.54 -> 55.88 | BY9: 50 | BZ9: 50 | CA9: 50 | CB9: 55 | CC9: 51 | CD9: 51 | CE9: 50 | CF9: 48 | CG9: 40 | CH9: 50 | CI9: 45 | CJ9: 48 | CK9: 50 | CL9: 55 | CM9: 45 | CN9: 37.5 | CO9: 38 | CP9: 37.5 | CQ9: 45 | CR9: 50 | CS9: 51 | CT9: 48 | CU9: 45 | CV9: 50 | CW9: 55 | CX9: 58.5 | CY9: 50 | CZ9: 48 | DA9: 50 | DB9: 50 | DC9: 45 | DD9: 45 | DE9: 40 | DF9: 58 | DG9: 50 | DH9: 50 | DI9: 49 | DJ9: 43 | DK9: 51 | DL9: 48 | DM9: 44.5 | DN9: 51 | DO9: 50 | DP9: 48 | DQ9: 45 | DR9: 59 | DS9: 55 | DT9: 35 | DU9: 50
B10: Length | C10: 71 | D10: 61 | E10: 52 | F10: 57 | G10: 48 | H10: 48 | I10: 50 | J10: 52 | K10: 56 | L10: 51 | M10: 57 | N10: 65 | O10: 76 | P10: 76 | Q10: 58 | R10: 67 | S10: 48 | T10: 48 | U10: 62 | V10: =19*2.54 -> 48.26 | W10: 67 | X10: 78 | Y10: 47 | Z10: 60 | AA10: 85 | AB10: 55 | AC10: 48 | AD10: 50 | AE10: 48 | AF10: 72 | AG10: 74 | AH10: =23.5*2.54 -> 59.69 | AI10: =23.5*2.54 -> 59.69 | AJ10: 55 | AK10: 55 | AL10: 55 | AM10: =20.5*2.54 -> 52.07 | AN10: 54 | AO10: =19*2.54 -> 48.26 | AP10: 67 | AQ10: 56 | AR10: =23.5*2.54 -> 59.69 | AS10: 92 | AT10: =23.5*2.54 -> 59.69 | AU10: =40.3*2.54 -> 102.362 | AV10: 85 | AW10: 48 | AX10: 54 | AY10: 48 | AZ10: 59 | BA10: 52 | BB10: 90 | BC10: 48 | BD10: 59.5 | BE10: 59.5 | BF10: 46 | BG10: 72 | BH10: 88 | BI10: 72 | BJ10: 88 | BK10: 62 | BL10: 62 | BM10: 48 | BN10: 48 | BO10: 56 | BP10: 85 | BQ10: 59 | BR10: 59 | BS10: 49 | BT10: 59 | BU10: 85 | BV10: 59 | BW10: 59 | BX10: =23.5*2.54 -> 59.69 | BY10: 63 | BZ10: 76 | CA10: 80 | CB10: 100.5 | CC10: 72 | CD10: 72 | CE10: 85 | CF10: 56 | CG10: 52 | CH10: 69 | CI10: 75 | CJ10: 56 | CK10: 80 | CL10: 100.5 | CM10: 49 | CN10: 48 | CO10: 50 | CP10: 48 | CQ10: 75 | CR10: 85 | CS10: 59 | CT10: 52 | CU10: 75 | CV10: 80 | CW10: 100.5 | CX10: 68.7 | CY10: 63 | CZ10: 56 | DA10: 52 | DB10: 65 | DC10: 70 | DD10: 70 | DE10: 68 | DF10: 63 | DG10: 63 | DH10: 59 | DI10: 55 | DJ10: 48 | DK10: 59 | DL10: 52 | DM10: 74.5 | DN10: 59 | DO10: 69 | DP10: 68.5 | DQ10: 49 | DR10: 70 | DS10: 80 | DT10: 46 | DU10: 52
B11: Patch | C11: 15 | D11: 11 | E11: 12 | F11: 10 | G11: 11 | H11: 11 | I11: 11 | J11: 14 | K11: 14 | L11: 10 | M11: 10 | N11: 10 | O11: 12 | P11: 12 | Q11: 10 | R11: 10 | S11: 10 | T11: 10 | U11: 11 | V11: =4*2.54 -> 10.16 | W11: 15 | X11: 16 | Y11: 12 | Z11: 9 | AA11: 10 | AB11: 8 | AC11: 11 | AD11: 11 | AE11: 11 | AF11: 16 | AG11: 18 | AH11: 14 | AI11: 14 | AJ11: 11 | AK11: 11 | AL11: 11 | AM11: =4.5*2.54 -> 11.43 | AN11: 13 | AO11: =4*2.54 -> 10.16 | AP11: 15 | AQ11: 11 | AR11: =6*2.54 -> 15.24 | AS11: 14 | AT11: =6*2.54 -> 15.24 | AU11: =5.5*2.54 -> 13.97 | AV11: 13 | AW11: 13 | AX11: 11 | AY11: 13 | AZ11: 12 | BA11: 11 | BB11: 14 | BC11: 13 | BD11: 12 | BE11: 9.5 | BF11: 9 | BG11: 10 | BH11: 10 | BI11: 10 | BJ11: 10 | BK11: 11 | BL11: 11 | BM11: 11 | BN11: 13 | BO11: 10 | BP11: 13 | BQ11: 12.5 | BR11: 10 | BS11: 10 | BT11: 16 | BU11: 13 | BV11: 12.5 | BW11: 10 | BX11: =6*2.54 -> 15.24 | BY11: 11 | BZ11: 14 | CA11: 18 | CB11: 17 | CC11: 16 | CD11: 16 | CE11: 13 | CF11: 15 | CG11: 12 | CH11: 10 | CI11: 13 | CJ11: 15 | CK11: 18 | CL11: 17 | CM11: 10 | CN11: 11 | CO11: 11 | CP11: 11 | CQ11: 13 | CR11: 13 | CS11: 12 | CT11: 11 | CU11: 13 | CV11: 18 | CW11: 17 | CX11: 15.3 | CY11: 11 | CZ11: 15 | DA11: 11 | DB11: 11 | DC11: 13 | DD11: 13 | DE11: 13 | DF11: 16 | DG11: 16 | DH11: 16 | DI11: 16 | DJ11: 13 | DK11: 12 | DL11: 11 | DM11: 12 | DN11: 12 | DO11: 10 | DP11: 12.5 | DQ11: 10 | DR11: 16 | DS11: 13 | DT11: 9 | DU11: 11
B12: Valve Length (Depth) | C12: 18 | D12: 13 | E12: 15 | F12: 13 | G12: 13 | H12: 13 | I12: 13 | J12: 18 | K12: 18 | L12: 14 | M12: 14 | N12: 14 | O12: 16 | P12: 16 | Q12: 14 | R12: 14 | S12: 14 | T12: 14 | U12: 15 | V12: 15 | W12: 22 | X12: 20 | Y12: 16 | Z12: 13 | AA12: 15 | AB12: 13 | AC12: 13 | AD12: 13 | AE12: 13 | AF12: 20 | AG12: 22 | AH12: 17 | AI12: 17 | AJ12: 16 | AK12: 16 | AL12: 16 | AM12: 16 | AN12: 15 | AO12: 16 | AP12: 20 | AQ12: 20 | AR12: 22 | AS12: 20 | AT12: 22 | AU12: 0 | AV12: 0 | AW12: 16 | AX12: 16 | AY12: 16 | AZ12: 16 | BA12: 15 | BB12: 0 | BC12: 16 | BD12: 15 | BE12: 12 | BF12: 12 | BG12: 13 | BH12: 13 | BI12: 13 | BJ12: 13 | BK12: 15 | BL12: 15 | BM12: 13 | BN12: 16 | BO12: 13 | BP12: 0 | BQ12: 15 | BR12: 15 | BS12: 15 | BT12: 20 | BU12: 16 | BV12: 15 | BW12: 15 | BX12: 22 | BY12: 14 | BZ12: 16 | CA12: 0 | CB12: 0 | CC12: 0 | CD12: 0 | CE12: 0 | CF12: 16 | CG12: 15 | CH12: 14 | CI12: 15 | CJ12: 16 | CK12: 0 | CL12: 0 | CM12: 15 | CN12: 13 | CO12: 13 | CP12: 13 | CQ12: 15 | CR12: 0 | CS12: 16 | CT12: 15 | CU12: 15 | CV12: 0 | CW12: 0 | CX12: 18 | CY12: 15 | CZ12: 16 | DA12: 15 | DB12: 15 | DC12: 16 | DD12: 16 | DE12: 16 | DF12: 18 | DG12: 18 | DH12: 18 | DI12: 18 | DJ12: 16 | DK12: 16 | DL12: 15 | DM12: 16 | DN12: 16 | DO12: 14 | DP12: 14 | DQ12: 15 | DR12: 0 | DS12: 0 | DT12: 13 | DU12: 15
B13: Extended Valve | C13: 0 | D13: 0 | E13: 0 | F13: 0 | G13: 1.5 | H13: 1.5 | I13: 1.5 | J13: 0 | K13: 0 | L13: 0 | M13: 0 | N13: 0 | O13: 0 | P13: 0 | Q13: 0 | R13: 0 | S13: 0 | T13: 0 | U13: 0 | V13: 0 | W13: 1.5 | X13: 0 | Y13: 0 | Z13: 0 | AA13: 0 | AB13: 0 | AC13: 1.5 | AD13: 1.5 | AE13: 1.5 | AF13: 0 | AG13: 0 | AH13: 0 | AI13: 0 | AJ13: 0 | AK13: 0 | AL13: 0 | AM13: 0 | AN13: 0 | AO13: 0 | AP13: 0 | AQ13: 0 | AR13: 0 | AS13: 0 | AT13: 0 | AU13: 0 | AV13: 0 | AW13: 0 | AX13: 0 | AY13: 0 | AZ13: 0 | BA13: 0 | BB13: 0 | BC13: 0 | BD13: 0 | BE13: 0 | BF13: 0 | BG13: 0 | BH13: 0 | BI13: 0 | BJ13: 0 | BK13: 0 | BL13: 0 | BM13: 1.5 | BN13: 0 | BO13: 0 | BP13: 0 | BQ13: 0 | BR13: 0 | BS13: 0 | BT13: 0 | BU13: 0 | BV13: 0 | BW13: 0 | BX13: 0 | BY13: 0 | BZ13: 2 | CA13: 0 | CB13: 0 | CC13: 0 | CD13: 0 | CE13: 0 | CF13: 0 | CG13: 0 | CH13: 0 | CI13: 0 | CJ13: 0 | CK13: 0 | CL13: 0 | CM13: 0 | CN13: 1.5 | CO13: 1.5 | CP13: 1.5 | CQ13: 0 | CR13: 0 | CS13: 0 | CT13: 0 | CU13: 0 | CV13: 0 | CW13: 0 | CX13: 1.5 | CY13: 0 | CZ13: 0 | DA13: 0 | DB13: 0 | DC13: 0 | DD13: 0 | DE13: 0 | DF13: 0 | DG13: 0 | DH13: 0 | DI13: 0 | DJ13: 0 | DK13: 0 | DL13: 0 | DM13: 0 | DN13: 0 | DO13: 0 | DP13: 0 | DQ13: 0 | DR13: 0 | DS13: 0 | DT13: 0 | DU13: 0
B14: Fabric GSM | C14: 65 | D14: 65 | E14: 65 | F14: 65 | G14: 66 | H14: 66 | I14: 67.1 | J14: 53 | K14: 45 | L14: 47 | M14: 52 | N14: 60 | O14: 65 | P14: 65 | Q14: 55 | R14: 55 | S14: 65 | T14: 63 | U14: 55 | V14: 65 | W14: 57 | X14: 65 | Y14: 66 | Z14: 59.1 | AA14: 57 | AB14: 57 | AC14: 66 | AD14: 67.1 | AE14: 66 | AF14: 65 | AG14: 60 | AH14: 64 | AI14: 64 | AJ14: 65 | AK14: 65 | AL14: 65 | AM14: 60 | AN14: 66 | AO14: 68 | AP14: 100 | AQ14: 50 | AR14: 65 | AS14: 53 | AT14: 65 | AU14: 68 | AV14: 67 | AW14: 60 | AX14: 60 | AY14: 66 | AZ14: 58 | BA14: 58 | BB14: 65 | BC14: 64 | BD14: 65.04 | BE14: 66.1 | BF14: 68.9 | BG14: 65 | BH14: 68.9 | BI14: 65 | BJ14: 68.9 | BK14: 65 | BL14: 61 | BM14: 66 | BN14: 64 | BO14: 62 | BP14: 70 | BQ14: 65 | BR14: 65.7 | BS14: 70 | BT14: 65 | BU14: 65 | BV14: 64.53 | BW14: 65.66 | BX14: 65 | BY14: 65.6 | BZ14: 65 | CA14: 65 | CB14: 65 | CC14: 65 | CD14: 65 | CE14: 65 | CF14: 65 | CG14: 66 | CH14: 61 | CI14: 65 | CJ14: 65 | CK14: 65 | CL14: 65 | CM14: 70 | CN14: 70.3 | CO14: 71.5 | CP14: 70.3 | CQ14: 65 | CR14: 65 | CS14: 58 | CT14: 58 | CU14: 65 | CV14: 65 | CW14: 65 | CX14: 60 | CY14: 63.9 | CZ14: 65 | DA14: 59.62 | DB14: 63.41 | DC14: 61 | DD14: 61 | DE14: 61 | DF14: 52 | DG14: 52 | DH14: 52 | DI14: 52 | DJ14: 64 | DK14: 58 | DL14: 58 | DM14: 68 | DN14: 57.4 | DO14: 61 | DP14: 75 | DQ14: 70 | DR14: 60 | DS14: 65 | DT14: 65 | DU14: 63
B15: Coating GSM | C15: 22 | D15: 22 | E15: 22 | F15: 22 | G15: 22 | H15: 22 | I15: 22 | J15: 22 | K15: 22 | L15: 22 | M15: 22 | N15: 22 | O15: 23 | P15: 23 | Q15: 22 | R15: 22 | S15: 25 | T15: 22 | U15: 22 | V15: 22 | W15: 22 | X15: 23 | Y15: 23 | Z15: 23 | AA15: 22 | AB15: 22 | AC15: 22 | AD15: 22 | AE15: 22 | AF15: 22 | AG15: 22 | AH15: 23 | AI15: 23 | AJ15: 22 | AK15: 22 | AL15: 22 | AM15: 22 | AN15: 22 | AO15: 22 | AP15: 22 | AQ15: 22 | AR15: 22 | AS15: 22 | AT15: 22 | AU15: 22 | AV15: 22 | AW15: 22 | AX15: 22 | AY15: 22 | AZ15: 22 | BA15: 22 | BB15: 22 | BC15: 22 | BD15: 22 | BE15: 22 | BF15: 22 | BG15: 22 | BH15: 22 | BI15: 22 | BJ15: 22 | BK15: 22 | BL15: 22 | BM15: 22 | BN15: 22 | BO15: 22 | BP15: 22 | BQ15: 22 | BR15: 22 | BS15: 23 | BT15: 22 | BU15: 22 | BV15: 22 | BW15: 22 | BX15: 22 | BY15: 22 | BZ15: 22 | CA15: 23 | CB15: 22 | CC15: 23 | CD15: 23 | CE15: 25 | CF15: 25 | CG15: 23 | CH15: 22 | CI15: 23 | CJ15: 25 | CK15: 23 | CL15: 22 | CM15: 23 | CN15: 22 | CO15: 22 | CP15: 22 | CQ15: 23 | CR15: 25 | CS15: 22 | CT15: 22 | CU15: 23 | CV15: 23 | CW15: 22 | CX15: 22 | CY15: 22 | CZ15: 25 | DA15: 23 | DB15: 22 | DC15: 24.85 | DD15: 24.85 | DE15: 24.85 | DF15: 23 | DG15: 23 | DH15: 23 | DI15: 23.5 | DJ15: 22 | DK15: 22 | DL15: 22 | DM15: 24 | DN15: 22 | DO15: 22 | DP15: 22.9 | DQ15: 23 | DR15: 25 | DS15: 23 | DT15: 23 | DU15: 23
B16: BOPP GSM | C16: 15 | D16: 15 | E16: 0 | F16: 0 | G16: 0 | H16: 0 | I16: 0 | J16: 0 | K16: 0 | L16: 0 | M16: 0 | N16: 18 | O16: 0 | P16: 0 | Q16: 0 | R16: 0 | S16: 0 | T16: 0 | U16: 0 | V16: 0 | W16: 0 | X16: 0 | Y16: 0 | Z16: 0 | AA16: 0 | AB16: 0 | AC16: 0 | AD16: 0 | AE16: 0 | AF16: 18 | AT16: 20 | AU16: 20 | AV16: 0 | BD16: 0 | BE16: 0 | BF16: 0 | BG16: 0 | BH16: 0 | BI16: 18 | BJ16: 18 | BL16: 18 | BM16: 0 | BP16: 0 | BQ16: 0 | BR16: 0 | BT16: 0 | BU16: 0 | BV16: 0 | BW16: 0 | CC16: 18 | CF16: 18 | CG16: 0 | CH16: 0 | CI16: 20 | CJ16: 18 | CN16: 0 | CO16: 0 | CP16: 0 | CQ16: 20 | CU16: 20 | CX16: 15 | CZ16: 18 | DA16: 0 | DD16: 20.15 | DE16: 20.15 | DM16: 20 | DO16: 0 | DP16: 19 | DS16: 18 | DT16: 0 | DU16: 0
B17: Open Mouth | C17: Yes | D17: No | E17: Yes | F17: Yes | G17: No | H17: No | I17: No | J17: No | K17: No | L17: No | M17: No | N17: No | O17: Yes | P17: Yes | Q17: No | R17: Yes | S17: No | T17: No | U17: No | V17: No | W17: No | X17: Yes | Y17: Yes | Z17: Yes | AA17: Yes | AB17: Yes | AC17: No | AD17: No | AE17: No | AF17: Yes | AG17: Yes | AH17: No | AI17: No | AJ17: No | AK17: No | AL17: No | AM17: Yes | AN17: No | AO17: No | AP17: Yes | AQ17: No | AR17: No | AS17: No | AT17: No | AU17: Yes | AV17: Yes | AW17: No | AX17: No | AY17: No | AZ17: No | BA17: No | BB17: Yes | BC17: No | BD17: No | BE17: No | BF17: No | BG17: No | BH17: No | BI17: No | BJ17: No | BK17: No | BL17: No | BM17: No | BN17: No | BO17: No | BP17: Yes | BQ17: No | BR17: No | BS17: No | BT17: No | BU17: Yes | BV17: No | BW17: No | BX17: No | BY17: No | BZ17: No | CA17: Yes | CB17: Yes | CC17: Yes | CD17: Yes | CE17: Yes | CF17: No | CG17: Yes | CH17: No | CI17: No | CJ17: No | CK17: Yes | CL17: Yes | CM17: No | CN17: No | CO17: No | CP17: No | CQ17: No | CR17: Yes | CS17: No | CT17: No | CU17: No | CV17: Yes | CW17: Yes | CX17: No | CY17: No | CZ17: No | DA17: No | DB17: No | DC17: Yes | DD17: Yes | DE17: Yes | DF17: No | DG17: No | DH17: No | DI17: No | DJ17: No | DK17: No | DL17: No | DM17: Yes | DN17: No | DO17: No | DP17: Yes | DQ17: No | DR17: No | DS17: Yes | DT17: No | DU17: No
B18: UV (Y/N) | C18: No | D18: No | E18: No | F18: Yes | G18: Yes | H18: Yes | I18: Yes | J18: Yes | K18: Yes | L18: Yes | M18: Yes | N18: Yes | O18: No | P18: No | Q18: No | R18: Yes | S18: No | T18: No | U18: No | V18: No | W18: No | X18: Yes | Y18: Yes | Z18: No | AA18: No | AB18: No | AC18: Yes | AD18: Yes | AE18: Yes | AF18: No | AG18: No | AH18: No | AI18: No | AJ18: No | AK18: No | AL18: No | AM18: No | AN18: No | AO18: No | AP18: Yes | AQ18: Yes | AR18: No | AS18: No | AT18: No | AU18: Yes | AV18: Yes | AW18: No | AX18: No | AY18: No | AZ18: Yes | BA18: Yes | BB18: No | BC18: No | BD18: No | BE18: No | BF18: No | BG18: No | BH18: No | BI18: No | BJ18: No | BK18: No | BL18: No | BM18: No | BN18: No | BO18: No | BP18: Yes | BQ18: Yes | BR18: Yes | BS18: No | BT18: No | BU18: No | BV18: Yes | BW18: Yes | BX18: No | BY18: No | BZ18: Yes | CA18: No | CB18: No | CC18: Yes | CD18: Yes | CE18: Yes | CF18: Yes | CG18: No | CH18: No | CI18: No | CJ18: Yes | CK18: No | CL18: No | CM18: No | CN18: Yes | CO18: Yes | CP18: Yes | CQ18: No | CR18: Yes | CS18: Yes | CT18: Yes | CU18: No | CV18: No | CW18: No | CX18: No | CY18: No | CZ18: Yes | DA18: No | DB18: No | DC18: No | DD18: No | DE18: No | DF18: No | DG18: No | DH18: No | DI18: No | DJ18: No | DK18: Yes | DL18: Yes | DM18: No | DN18: Yes | DO18: No | DP18: No | DQ18: No | DR18: Yes | DS18: Yes | DT18: No | DU18: Yes
B19: Printing | C19: 2/2 | D19: 2/2 | E19: 2/2 | F19: 2/2 | G19: 2/2 | H19: 2/2 | I19: 2/2 | J19: 2/2 | K19: 2/2 | L19: 2/2 | M19: 2/2 | O19: 2/2 | P19: 2/2 | Q19: 2/2 | V19: 1/1 | W19: 1/1 | AC19: 2/2 | AD19: 2/2 | AE19: 2/2 | BM19: 2/2 | CG19: 2/2 | CN19: 2/2 | CO19: 2/2 | CP19: 2/2
