Workbook

Sheet Summary
A1: STOCK AS ON 01/09/2026 | AP1: 45261
D2: Opening Stock | G2: Inventory movement fo the month of JUNE-2026 | W2: Closing Stock -As per Movement Sheet | Z2: Closing Stock - As per Actual (Physical) ERP | AC2: Difference | AP2: Opening As per ERP | AS2: Difference In Opening | AV2: Closing As per ERP | AY2: Difference In Closing
A3: Group | B3: Sub group | C3: Details of Items / Products | D3: Factory Owned | E3: Factory JW (Others) | F3: At JW (Own) | G3: Branch Tfr Recd | H3: Purchase | I3: Recd from JW (Own) | J3: Recd For JW (Others) | K3: Sales | L3: Br Transfer Sent | M3: Sent for JW (Own) | N3: Return JW(Others) | O3: Total Production Own+JW | P3: Total Consumption Own+JW | Q3: Production at JW | R3: Consumption At JW | S3: Pord of JW | T3: Consumption of JW | U3: Net Production Own | V3: Net Consumption Own | W3: Factory Owned | X3: Factory JW (Others) | Y3: At JW (Own) | Z3: Factory Owned | AA3: Factory JW (Others) | AB3: At JW (Own) | AC3: Factory Owned | AD3: Factory JW (Others) | AE3: At JW (Own) | AF3: Remark for Difference, If any | AG3: Rate | AH3: Value | AI3: Job Value | AP3: Factory Owned | AQ3: Factory JW (Others) | AR3: At JW (Own) | AS3: Factory Owned | AT3: Factory JW (Others) | AU3: At JW (Own) | AV3: Factory Owned | AW3: Factory JW (Others) | AX3: At JW (Own) | AY3: Factory Owned | AZ3: Factory JW (Others) | BA3: At JW (Own)
A4: =VLOOKUP(C4,Master!A:D,4,0) -> #N/A | B4: =VLOOKUP(C4,Master!A:C,3,0) -> #N/A | C4: Masterbatch | D4: =SUMIF(Master!E:E,Summary!C4,Master!F:F)-E4 -> 0 | E4: 0 | F4: 0 | Q4: =+I4 -> 0 | U4: =O4-S4 -> 0 | V4: =P4-T4 -> 0 | W4: =SUMIF(Master!E:E,Summary!C4,Master!G:G) -> 0 | X4: =E4+J4-N4-T4+S4 -> 0 | Y4: =F4-I4+M4-R4+Q4 -> 0 | Z4: 0 | AA4: 0 | AB4: 0 | AC4: =W4-Z4 -> 0 | AD4: =X4-AA4 -> 0 | AE4: =Y4-AB4 -> 0
A5: =VLOOKUP(C5,Master!A:D,4,0) -> RM | B5: =VLOOKUP(C5,Master!A:C,3,0) -> Granuals | C5: PP Granuals | D5: =SUMIF(Master!E:E,Summary!C5,Master!F:F)-E5 -> 976828.63 | E5: 25685.5 | F5: 415208.1 | G5: 15000 | H5: 499500 | I5: 122250 | J5: 140000 | K5: 81375 | L5: 104225 | M5: 262120 | N5: 26130 | P5: =967468-0.37 -> 967467.63 | Q5: =+I5 -> 122250 | R5: 352161.7 | T5: 27370 | U5: =O5-S5 -> 0 | V5: =P5-T5 -> 940097.63 | W5: =D5+G5+H5+I5-K5-L5-M5-V5+U5 -> 225761 | X5: =E5+J5-N5-T5+S5 -> 112185.5 | Y5: =F5-I5+M5-R5+Q5 -> 325166.4 | Z5: 225761 | AA5: 112185.5 | AB5: 325166.4 | AC5: =W5-Z5 -> 0 | AD5: =X5-AA5 -> 0 | AE5: =Y5-AB5 -> 0 | AG5: 122.43 | AH5: =W5*AG5 -> 27639919 | AI5: =Y5*AG5 -> 39810122 | AS5: =+D5-AP5 -> 976828.63 | AT5: =+E5-AQ5 -> 25685.5 | AU5: =+F5-AR5 -> 415208.1 | AY5: =+W5-AV5 -> 225761 | AZ5: =+X5-AW5 -> 112185.5 | BA5: =+Y5-AX5 -> 325166.4 | BE5: 1109750 | BF5: =+H5-BE5 -> -610250
A6: =VLOOKUP(C6,Master!A:D,4,0) -> RM | B6: =VLOOKUP(C6,Master!A:C,3,0) -> Granuals | C6: HDPE Granuals | D6: =SUMIF(Master!E:E,Summary!C6,Master!F:F)-E6 -> 2574.95 | E6: 0 | F6: 0 | G6: 5000 | H6: 22000 | K6: 22000 | P6: =1375-0.05 -> 1374.95 | Q6: =+I6 -> 0 | U6: =O6-S6 -> 0 | V6: =P6-T6 -> 1374.95 | W6: =D6+G6+H6+I6-K6-L6-M6-V6+U6 -> 6200 | X6: =E6+J6-N6-T6+S6 -> 0 | Y6: =F6-I6+M6-R6+Q6 -> 0 | Z6: 6200 | AA6: 0 | AB6: 0 | AC6: =W6-Z6 -> 0 | AD6: =X6-AA6 -> 0 | AE6: =Y6-AB6 -> 0 | AG6: 141.07 | AH6: =W6*AG6 -> 874634 | AI6: =Y6*AG6 -> 0 | AS6: =+D6-AP6 -> 2574.95 | AT6: =+E6-AQ6 -> 0 | AU6: =+F6-AR6 -> 0 | AY6: =+W6-AV6 -> 6200 | AZ6: =+X6-AW6 -> 0 | BA6: =+Y6-AX6 -> 0 | BF6: =+H6-BE6 -> 22000
A7: =VLOOKUP(C7,Master!A:D,4,0) -> RM | B7: =VLOOKUP(C7,Master!A:C,3,0) -> Granuals | C7: LDPE Granuals | D7: =SUMIF(Master!E:E,Summary!C7,Master!F:F)-E7 -> 110405.92 | E7: 45.6 | F7: 101302.03 | G7: 10000 | H7: 50700 | K7: 2750 | M7: 5000 | P7: =91672-0.075 -> 91671.925 | Q7: =+I7 -> 0 | R7: 24801.3 | U7: =O7-S7 -> 0 | V7: =P7-T7 -> 91671.925 | W7: =D7+G7+H7+I7-K7-L7-M7-V7+U7 -> 71684 | X7: =E7+J7-N7-T7+S7 -> 45.6 | Y7: =F7-I7+M7-R7+Q7 -> 81500.73 | Z7: 71684 | AA7: 45.6 | AB7: 81500.73 | AC7: =W7-Z7 -> 0 | AD7: =X7-AA7 -> 0 | AE7: =Y7-AB7 -> 0 | AG7: 152.59 | AH7: =W7*AG7 -> 10938262 | AI7: =Y7*AG7 -> 12436196 | AS7: =+D7-AP7 -> 110405.92 | AT7: =+E7-AQ7 -> 45.6 | AU7: =+F7-AR7 -> 101302.03 | AY7: =+W7-AV7 -> 71684 | AZ7: =+X7-AW7 -> 45.6 | BA7: =+Y7-AX7 -> 81500.73 | BE7: 100000 | BF7: =+H7-BE7 -> -49300
A8: =VLOOKUP(C8,Master!A:D,4,0) -> RM | B8: =VLOOKUP(C8,Master!A:C,3,0) -> Granuals | C8: LLDPE Granuals | D8: =SUMIF(Master!E:E,Summary!C8,Master!F:F)-E8 -> 209617.79 | E8: 9.094947e-12 | F8: 43288 | H8: 140000 | M8: 64000 | P8: =195997-1.205 -> 195995.8 | Q8: =+I8 -> 0 | R8: 7726 | U8: =O8-S8 -> 0 | V8: =P8-T8 -> 195995.8 | W8: =D8+G8+H8+I8-K8-L8-M8-V8+U8 -> 89622 | X8: =E8+J8-N8-T8+S8 -> 9.094947e-12 | Y8: =F8-I8+M8-R8+Q8 -> 99562 | Z8: 89622 | AA8: 9.094947e-12 | AB8: 99562 | AC8: =W8-Z8 -> 0 | AD8: =X8-AA8 -> 0 | AE8: =Y8-AB8 -> 0 | AG8: 121.5 | AH8: =W8*AG8 -> 10889073 | AI8: =Y8*AG8 -> 12096783 | AS8: =+D8-AP8 -> 209617.79 | AT8: =+E8-AQ8 -> 9.094947e-12 | AU8: =+F8-AR8 -> 43288 | AY8: =+W8-AV8 -> 89622 | AZ8: =+X8-AW8 -> 9.094947e-12 | BA8: =+Y8-AX8 -> 99562 | BE8: =125000+24750 -> 149750 | BF8: =+H8-BE8 -> -9750
A9: =VLOOKUP(C9,Master!A:D,4,0) -> RM | B9: =VLOOKUP(C9,Master!A:C,3,0) -> Granuals | C9: UV MB | D9: =SUMIF(Master!E:E,Summary!C9,Master!F:F)-E9 -> 50014.22 | E9: 0 | F9: 63200.2 | G9: 18300 | H9: 16507 | K9: 5650 | M9: 8200 | P9: 42186.22 | Q9: =+I9 -> 0 | R9: 39718.1 | U9: =O9-S9 -> 0 | V9: =P9-T9 -> 42186.22 | W9: =D9+G9+H9+I9-K9-L9-M9-V9+U9 -> 28785 | X9: =E9+J9-N9-T9+S9 -> 0 | Y9: =F9-I9+M9-R9+Q9 -> 31682.1 | Z9: 28785 | AA9: 0 | AB9: 31682.1 | AC9: =W9-Z9 -> 0 | AD9: =X9-AA9 -> 0 | AE9: =Y9-AB9 -> 0 | AG9: 215.68 | AH9: =W9*AG9 -> 6208348.8 | AI9: =Y9*AG9 -> 6833195.3 | AS9: =+D9-AP9 -> 50014.22 | AT9: =+E9-AQ9 -> 0 | AU9: =+F9-AR9 -> 63200.2 | AY9: =+W9-AV9 -> 28785 | AZ9: =+X9-AW9 -> 0 | BA9: =+Y9-AX9 -> 31682.1 | BE9: =15320.6+30200 -> 45520.6 | BF9: =+H9-BE9 -> -29013.6
A10: =VLOOKUP(C10,Master!A:D,4,0) -> RM | B10: =VLOOKUP(C10,Master!A:C,3,0) -> Craft Paper | C10: Craft Paper | D10: =SUMIF(Master!E:E,Summary!C10,Master!F:F)-E10 -> 22897 | E10: 0 | F10: 54 | H10: 16614 | I10: 54 | P10: 22518 | Q10: =+I10 -> 54 | R10: 54 | U10: =O10-S10 -> 0 | V10: =P10-T10 -> 22518 | W10: =D10+G10+H10+I10-K10-L10-M10-V10+U10 -> 17047 | X10: =E10+J10-N10-T10+S10 -> 0 | Y10: =F10-I10+M10-R10+Q10 -> 0 | Z10: 17047 | AA10: 0 | AB10: 0 | AC10: =W10-Z10 -> 0 | AD10: =X10-AA10 -> 0 | AE10: =Y10-AB10 -> 0 | AG10: 71.87 | AH10: =W10*AG10 -> 1225167.9 | AI10: =Y10*AG10 -> 0 | AS10: =+D10-AP10 -> 22897 | AT10: =+E10-AQ10 -> 0 | AU10: =+F10-AR10 -> 54 | AY10: =+W10-AV10 -> 17047 | AZ10: =+X10-AW10 -> 0 | BA10: =+Y10-AX10 -> 0 | BE10: 9078 | BF10: =+H10-BE10 -> 7536
A11: =VLOOKUP(C11,Master!A:D,4,0) -> RM | B11: =VLOOKUP(C11,Master!A:C,3,0) -> Films All | C11: Polyester Film | D11: =SUMIF(Master!E:E,Summary!C11,Master!F:F)-E11 -> 0 | E11: 0 | F11: 0 | Q11: =+I11 -> 0 | U11: =O11-S11 -> 0 | V11: =P11-T11 -> 0 | W11: =D11+G11+H11+I11-K11-L11-M11-V11+U11 -> 0 | X11: =E11+J11-N11-T11+S11 -> 0 | Y11: =F11-I11+M11-R11+Q11 -> 0 | Z11: 0 | AA11: 0 | AB11: 0 | AC11: =W11-Z11 -> 0 | AD11: =X11-AA11 -> 0 | AE11: =Y11-AB11 -> 0 | AG11: 0 | AH11: =W11*AG11 -> 0 | AI11: =Y11*AG11 -> 0 | AS11: =+D11-AP11 -> 0 | AT11: =+E11-AQ11 -> 0 | AU11: =+F11-AR11 -> 0 | AY11: =+W11-AV11 -> 0 | AZ11: =+X11-AW11 -> 0 | BA11: =+Y11-AX11 -> 0 | BF11: =+H11-BE11 -> 0
A12: =VLOOKUP(C12,Master!A:D,4,0) -> RM | B12: =VLOOKUP(C12,Master!A:C,3,0) -> Granuals | C12: Filler | D12: =SUMIF(Master!E:E,Summary!C12,Master!F:F)-E12 -> 15892.407 | E12: 0 | F12: 0 | H12: 60000 | K12: 17500 | P12: 55345.407 | Q12: =+I12 -> 0 | U12: =O12-S12 -> 0 | V12: =P12-T12 -> 55345.407 | W12: =D12+G12+H12+I12-K12-L12-M12-V12+U12 -> 3047.0005 | X12: =E12+J12-N12-T12+S12 -> 0 | Y12: =F12-I12+M12-R12+Q12 -> 0 | Z12: 3047.0005 | AA12: 0 | AB12: 0 | AC12: =W12-Z12 -> 0 | AD12: =X12-AA12 -> 0 | AE12: =Y12-AB12 -> 0 | AG12: 39.5 | AH12: =W12*AG12 -> 120356.52 | AI12: =Y12*AG12 -> 0 | AS12: =+D12-AP12 -> 15892.407 | AT12: =+E12-AQ12 -> 0 | AU12: =+F12-AR12 -> 0 | AY12: =+W12-AV12 -> 3047.0005 | AZ12: =+X12-AW12 -> 0 | BA12: =+Y12-AX12 -> 0 | BE12: 60000 | BF12: =+H12-BE12 -> 0
A13: =VLOOKUP(C13,Master!A:D,4,0) -> RM | B13: =VLOOKUP(C13,Master!A:C,3,0) -> Films All | C13: PE Film | D13: =SUMIF(Master!E:E,Summary!C13,Master!F:F)-E13 -> 21659.52 | E13: 0 | F13: 509.4 | H13: =305.83+2278.45 -> 2584.28 | K13: 6388.9 | L13: 949.7 | O13: 303895.1 | P13: =310741-0.7 -> 310740.3 | Q13: =+I13 -> 0 | R13: 314 | U13: =O13-S13 -> 303895.1 | V13: =P13-T13 -> 310740.3 | W13: =D13+G13+H13+I13-K13-L13-M13-V13+U13 -> 10060 | X13: =E13+J13-N13-T13+S13 -> 0 | Y13: =F13-I13+M13-R13+Q13 -> 195.4 | Z13: 10060 | AA13: 0 | AB13: 195.4 | AC13: =W13-Z13 -> 0 | AD13: =X13-AA13 -> 0 | AE13: =Y13-AB13 -> 0 | AG13: =+AG8+22 -> 143.5 | AH13: =W13*AG13 -> 1443610 | AI13: =Y13*AG13 -> 28039.9 | AS13: =+D13-AP13 -> 21659.52 | AT13: =+E13-AQ13 -> 0 | AU13: =+F13-AR13 -> 509.4 | AY13: =+W13-AV13 -> 10060 | AZ13: =+X13-AW13 -> 0 | BA13: =+Y13-AX13 -> 195.4 | BE13: 95.9 | BF13: =+H13-BE13 -> 2488.38
A14: =VLOOKUP(C14,Master!A:D,4,0) -> #N/A | B14: EVA Granuals | C14: EVA Granuals | D14: =SUMIF(Master!E:E,Summary!C14,Master!F:F)-E14 -> 2231.375 | E14: 0 | F14: 0 | P14: 824.375 | Q14: =+I14 -> 0 | U14: =O14-S14 -> 0 | V14: =P14-T14 -> 824.375 | W14: =D14+G14+H14+I14-K14-L14-M14-V14+U14 -> 1407 | X14: =E14+J14-N14-T14+S14 -> 0 | Y14: =F14-I14+M14-R14+Q14 -> 0 | Z14: 1407 | AA14: 0 | AB14: 0 | AC14: =W14-Z14 -> 0 | AD14: =X14-AA14 -> 0 | AE14: =Y14-AB14 -> 0 | AG14: 146 | AH14: =W14*AG14 -> 205422 | AI14: =Y14*AG14 -> 0 | AP14: 462.9 | AQ14: 0 | AR14: 0 | AS14: =+D14-AP14 -> 1768.475 | AT14: =+E14-AQ14 -> 0 | AU14: =+F14-AR14 -> 0 | AY14: =+W14-AV14 -> 1407 | AZ14: =+X14-AW14 -> 0 | BA14: =+Y14-AX14 -> 0 | BE14: 500 | BF14: =+H14-BE14 -> -500
A15: =VLOOKUP(C15,Master!A:D,4,0) -> RM | B15: =VLOOKUP(C15,Master!A:C,3,0) -> Granuals | C15: mLLDPE Granuals | D15: =SUMIF(Master!E:E,Summary!C15,Master!F:F)-E15 -> 0 | E15: 0 | F15: 0 | Q15: =+I15 -> 0 | U15: =O15-S15 -> 0 | V15: =P15-T15 -> 0 | W15: =D15+G15+H15+I15-K15-L15-M15-V15+U15 -> 0 | X15: =E15+J15-N15-T15+S15 -> 0 | Y15: =F15-I15+M15-R15+Q15 -> 0 | Z15: 0 | AA15: 0 | AB15: 0 | AC15: =W15-Z15 -> 0 | AD15: =X15-AA15 -> 0 | AE15: =Y15-AB15 -> 0 | AG15: 0 | AH15: =W15*AG15 -> 0 | AI15: =Y15*AG15 -> 0 | AS15: =+D15-AP15 -> 0 | AT15: =+E15-AQ15 -> 0 | AU15: =+F15-AR15 -> 0 | AY15: =+W15-AV15 -> 0 | AZ15: =+X15-AW15 -> 0 | BA15: =+Y15-AX15 -> 0 | BF15: =+H15-BE15 -> 0
A16: =VLOOKUP(C16,Master!A:D,4,0) -> RM | B16: =VLOOKUP(C16,Master!A:C,3,0) -> Films All | C16: BOPP Film | D16: =SUMIF(Master!E:E,Summary!C16,Master!F:F)-E16 -> 5855 | E16: 0 | F16: 5972.5 | H16: 6120.86 | I16: 922 | K16: 269.6 | P16: 58.26 | Q16: =+I16 -> 922 | R16: 922 | U16: =O16-S16 -> 0 | V16: =P16-T16 -> 58.26 | W16: =D16+G16+H16+I16-K16-L16-M16-V16+U16 -> 12570 | X16: =E16+J16-N16-T16+S16 -> 0 | Y16: =F16-I16+M16-R16+Q16 -> 5050.5 | Z16: 12570 | AA16: 0 | AB16: 5050.5 | AC16: =W16-Z16 -> 0 | AD16: =X16-AA16 -> 0 | AE16: =Y16-AB16 -> 0 | AG16: 186.3 | AH16: =W16*AG16 -> 2341791 | AI16: =Y16*AG16 -> 940908.15 | AS16: =+D16-AP16 -> 5855 | AT16: =+E16-AQ16 -> 0 | AU16: =+F16-AR16 -> 5972.5 | AY16: =+W16-AV16 -> 12570 | AZ16: =+X16-AW16 -> 0 | BA16: =+Y16-AX16 -> 5050.5 | BE16: 4935.38 | BF16: =+H16-BE16 -> 1185.48
A17: =VLOOKUP(C17,Master!A:D,4,0) -> RM | B17: =VLOOKUP(C17,Master!A:C,3,0) -> Granuals | C17: Enable Granuals | D17: =SUMIF(Master!E:E,Summary!C17,Master!F:F)-E17 -> 0 | E17: 0 | F17: 0 | Q17: =+I17 -> 0 | U17: =O17-S17 -> 0 | V17: =P17-T17 -> 0 | W17: =D17+G17+H17+I17-K17-L17-M17-V17+U17 -> 0 | X17: =E17+J17-N17-T17+S17 -> 0 | Y17: =F17-I17+M17-R17+Q17 -> 0 | Z17: 0 | AA17: 0 | AB17: 0 | AC17: =W17-Z17 -> 0 | AD17: =X17-AA17 -> 0 | AE17: =Y17-AB17 -> 0 | AG17: 0 | AH17: =W17*AG17 -> 0 | AI17: =Y17*AG17 -> 0 | AS17: =+D17-AP17 -> 0 | AT17: =+E17-AQ17 -> 0 | AU17: =+F17-AR17 -> 0 | AY17: =+W17-AV17 -> 0 | AZ17: =+X17-AW17 -> 0 | BA17: =+Y17-AX17 -> 0 | BF17: =+H17-BE17 -> 0
A18: =VLOOKUP(C18,Master!A:D,4,0) -> SF | B18: =VLOOKUP(C18,Master!A:C,3,0) -> Yarn All | C18: PP Yarn | D18: =SUMIF(Master!E:E,Summary!C18,Master!F:F)-E18-D19 -> 19909.21 | E18: 0.002 | F18: 1977.81 | H18: =3570.8+1017 -> 4587.8 | K18: 64064.75 | L18: 24902.34 | M18: 2466.1 | O18: 221753 | P18: =139094-0.18 -> 139093.82 | Q18: =+I18 -> 0 | R18: 1843.3 | U18: =O18-S18 -> 221753 | V18: =P18-T18 -> 139093.82 | W18: =D18+G18+H18+I18-K18-L18-M18-V18+U18 -> 15723 | X18: =E18+J18-N18-T18+S18 -> 0.002 | Y18: =F18-I18+M18-R18+Q18 -> 2600.61 | Z18: 15723 | AA18: 0.002 | AB18: 2600.61 | AC18: =W18-Z18 -> 0 | AD18: =X18-AA18 -> 0 | AE18: =Y18-AB18 -> 0 | AG18: =154.09*0.97 -> 149.4673 | AH18: =W18*AG18 -> 2350074.4 | AI18: =Y18*AG18 -> 388706.16 | AS18: =+D18-AP18 -> 19909.21 | AT18: =+E18-AQ18 -> 0.002 | AU18: =+F18-AR18 -> 1977.81 | AY18: =+W18-AV18 -> 15723 | AZ18: =+X18-AW18 -> 0.002 | BA18: =+Y18-AX18 -> 2600.61 | BE18: 4747.2 | BF18: =+H18-BE18 -> -159.4
A19: =VLOOKUP(C19,Master!A:D,4,0) -> #N/A | B19: =VLOOKUP(C19,Master!A:C,3,0) -> #N/A | C19: PP Yarn WIP | D19: 7704 | E19: 0 | F19: 0 | O19: 26952.61 | P19: 25596.61 | U19: =O19-S19 -> 26952.61 | V19: =P19-T19 -> 25596.61 | W19: =D19+G19+H19+I19-K19-L19-M19-V19+U19 -> 9060 | X19: =E19+J19-N19-T19+S19 -> 0 | Y19: =F19-I19+M19-R19+Q19 -> 0 | Z19: 9060 | AA19: 0 | AB19: 0 | AC19: =W19-Z19 -> 0 | AD19: =X19-AA19 -> 0 | AE19: =Y19-AB19 -> 0 | AG19: =154.09*0.95 -> 146.3855 | AH19: =W19*AG19 -> 1326252.6 | AI19: =Y19*AG19 -> 0 | AS19: =+D19-AP19 -> 7704 | AT19: =+E19-AQ19 -> 0 | AU19: =+F19-AR19 -> 0 | AY19: =+W19-AV19 -> 9060 | AZ19: =+X19-AW19 -> 0 | BA19: =+Y19-AX19 -> 0 | BF19: =+H19-BE19 -> 0
A20: =VLOOKUP(C20,Master!A:D,4,0) -> SF | B20: =VLOOKUP(C20,Master!A:C,3,0) -> PP/PE Fabric | C20: PP UL Fabric | D20: =SUMIF(Master!E:E,Summary!C20,Master!F:F)-E20 -> 334069.9 | E20: 0 | F20: 0 | G20: 41900.8 | H20: 243007.6 | K20: 706382.8 | L20: 2717 | O20: =809523.7+979 -> 810502.7 | P20: 425047.2 | Q20: =+I20 -> 0 | U20: =O20-S20 -> 810502.7 | V20: =P20-T20 -> 425047.2 | W20: =D20+G20+H20+I20-K20-L20-M20-V20+U20 -> 295334 | X20: =E20+J20-N20-T20+S20 -> 0 | Y20: =F20-I20+M20-R20+Q20 -> 0 | Z20: 295334 | AA20: 0 | AB20: 0 | AC20: =W20-Z20 -> 0 | AD20: =X20-AA20 -> 0 | AE20: =Y20-AB20 -> 0 | AG20: =AG5+20 -> 142.43 | AH20: =W20*AG20 -> 42064422 | AI20: =Y20*AG20 -> 0 | AS20: =+D20-AP20 -> 334069.9 | AT20: =+E20-AQ20 -> 0 | AU20: =+F20-AR20 -> 0 | AY20: =+W20-AV20 -> 295334 | AZ20: =+X20-AW20 -> 0 | BA20: =+Y20-AX20 -> 0 | BE20: 163864.3 | BF20: =+H20-BE20 -> 79143.3
A21: =VLOOKUP(C21,Master!A:D,4,0) -> #N/A | B21: =VLOOKUP(C21,Master!A:C,3,0) -> #N/A | C21: PP Lam Fabric WIP | D21: 20523 | E21: 0 | F21: 0 | O21: 74095.5 | P21: 65193.5 | Q21: =+I21 -> 0 | U21: =O21-S21 -> 74095.5 | V21: =P21-T21 -> 65193.5 | W21: =D21+G21+H21+I21-K21-L21-M21-V21+U21 -> 29425 | X21: =E21+J21-N21-T21+S21 -> 0 | Y21: =F21-I21+M21-R21+Q21 -> 0 | Z21: 29425 | AA21: 0 | AB21: 0 | AC21: =W21-Z21 -> 0 | AD21: =X21-AA21 -> 0 | AE21: =Y21-AB21 -> 0 | AG21: =AG5+25 -> 147.43 | AH21: =W21*AG21 -> 4338127.8 | AI21: =Y21*AG21 -> 0 | AS21: =+D21-AP21 -> 20523 | AT21: =+E21-AQ21 -> 0 | AU21: =+F21-AR21 -> 0 | AY21: =+W21-AV21 -> 29425 | AZ21: =+X21-AW21 -> 0 | BA21: =+Y21-AX21 -> 0 | BF21: =+H21-BE21 -> 0
A22: =VLOOKUP(C22,Master!A:D,4,0) -> SF | B22: =VLOOKUP(C22,Master!A:C,3,0) -> PP/PE Fabric | C22: PP Lam Fabric | D22: =SUMIF(Master!E:E,Summary!C22,Master!F:F)-E22-D21 -> 138341.5 | E22: 0 | F22: 1.1644019e-12 | H22: 26544.4 | K22: 317263.5 | L22: 707 | N22: 27370 | O22: =338993+27370 -> 366363 | P22: =79059-0.6 -> 79058.4 | Q22: =+I22 -> 0 | S22: 27370 | U22: =O22-S22 -> 338993 | V22: =P22-T22 -> 79058.4 | W22: =D22+G22+H22+I22-K22-L22-M22-V22+U22 -> 106850 | X22: =E22+J22-N22-T22+S22 -> 0 | Y22: =F22-I22+M22-R22+Q22 -> 1.1644019e-12 | Z22: 106850 | AA22: 0 | AB22: 1.1644019e-12 | AC22: =W22-Z22 -> 0 | AD22: =X22-AA22 -> 0 | AE22: =Y22-AB22 -> 0 | AG22: =AG5+25 -> 147.43 | AH22: =W22*AG22 -> 15752896 | AI22: =Y22*AG22 -> 1.7166777e-10 | AS22: =+D22-AP22 -> 138341.5 | AT22: =+E22-AQ22 -> 0 | AU22: =+F22-AR22 -> 1.1644019e-12 | AY22: =+W22-AV22 -> 106850 | AZ22: =+X22-AW22 -> 0 | BA22: =+Y22-AX22 -> 1.1644019e-12 | BE22: 6346 | BF22: =+H22-BE22 -> 20198.4
A23: =VLOOKUP(C23,Master!A:D,4,0) -> SF | B23: =VLOOKUP(C23,Master!A:C,3,0) -> PP/PE Fabric | C23: HD UL Fabric | D23: =SUMIF(Master!E:E,Summary!C23,Master!F:F)-E23 -> 0 | E23: 0 | F23: 0 | Q23: =+I23 -> 0 | U23: =O23-S23 -> 0 | V23: =P23-T23 -> 0 | W23: =D23+G23+H23+I23-K23-L23-M23-V23+U23 -> 0 | X23: =E23+J23-N23-T23+S23 -> 0 | Y23: =F23-I23+M23-R23+Q23 -> 0 | Z23: 0 | AA23: 0 | AB23: 0 | AC23: =W23-Z23 -> 0 | AD23: =X23-AA23 -> 0 | AE23: =Y23-AB23 -> 0 | AG23: 0 | AH23: =W23*AG23 -> 0 | AI23: =Y23*AG23 -> 0 | AS23: =+D23-AP23 -> 0 | AT23: =+E23-AQ23 -> 0 | AU23: =+F23-AR23 -> 0 | AY23: =+W23-AV23 -> 0 | AZ23: =+X23-AW23 -> 0 | BA23: =+Y23-AX23 -> 0 | BF23: =+H23-BE23 -> 0
A24: =VLOOKUP(C24,Master!A:D,4,0) -> SF | B24: =VLOOKUP(C24,Master!A:C,3,0) -> PP/PE Fabric | C24: HD Lam Fabric | D24: =SUMIF(Master!E:E,Summary!C24,Master!F:F)-E24 -> 0 | E24: 0 | F24: 0 | Q24: =+I24 -> 0 | U24: =O24-S24 -> 0 | V24: =P24-T24 -> 0 | W24: =D24+G24+H24+I24-K24-L24-M24-V24+U24 -> 0 | X24: =E24+J24-N24-T24+S24 -> 0 | Y24: =F24-I24+M24-R24+Q24 -> 0 | Z24: 0 | AA24: 0 | AB24: 0 | AC24: =W24-Z24 -> 0 | AD24: =X24-AA24 -> 0 | AE24: =Y24-AB24 -> 0 | AG24: 0 | AH24: =W24*AG24 -> 0 | AI24: =Y24*AG24 -> 0 | AS24: =+D24-AP24 -> 0 | AT24: =+E24-AQ24 -> 0 | AU24: =+F24-AR24 -> 0 | AY24: =+W24-AV24 -> 0 | AZ24: =+X24-AW24 -> 0 | BA24: =+Y24-AX24 -> 0 | BF24: =+H24-BE24 -> 0
A25: =VLOOKUP(C25,Master!A:D,4,0) -> SF | B25: =VLOOKUP(C25,Master!A:C,3,0) -> Granuals | C25: RP Granuals | D25: =SUMIF(Master!E:E,Summary!C25,Master!F:F)-E25 -> 151808.63 | E25: 0 | F25: 0 | H25: 17500 | I25: 70050 | K25: 97425 | N25: 13375 | O25: =130875-17500 -> 113375 | P25: 111822.63 | Q25: =+I25 -> 70050 | S25: 13375 | U25: =O25-S25 -> 100000 | V25: =P25-T25 -> 111822.63 | W25: =D25+G25+H25+I25-K25-L25-M25-V25+U25 -> 130111 | X25: =E25+J25-N25-T25+S25 -> 0 | Y25: =F25-I25+M25-R25+Q25 -> 0 | Z25: 130111 | AA25: 0 | AB25: 0 | AC25: =W25-Z25 -> 0 | AD25: =X25-AA25 -> 0 | AE25: =Y25-AB25 -> 0 | AG25: 28 | AH25: =W25*AG25 -> 3643108 | AI25: =Y25*AG25 -> 0 | AS25: =+D25-AP25 -> 151808.63 | AT25: =+E25-AQ25 -> 0 | AU25: =+F25-AR25 -> 0 | AY25: =+W25-AV25 -> 130111 | AZ25: =+X25-AW25 -> 0 | BA25: =+Y25-AX25 -> 0 | BE25: 18025 | BF25: =+H25-BE25 -> -525
A26: =VLOOKUP(C26,Master!A:D,4,0) -> #N/A | B26: =VLOOKUP(C26,Master!A:C,3,0) -> #N/A | C26: Webbing WIP | D26: 4400 | E26: 0 | F26: 0 | O26: 43049.96 | P26: 43064.96 | Q26: =+I26 -> 0 | U26: =O26-S26 -> 43049.96 | V26: =P26-T26 -> 43064.96 | W26: =D26+G26+H26+I26-K26-L26-M26-V26+U26 -> 4385 | X26: =E26+J26-N26-T26+S26 -> 0 | Y26: =F26-I26+M26-R26+Q26 -> 0 | Z26: 4385 | AA26: 0 | AB26: 0 | AC26: =W26-Z26 -> 0 | AD26: =X26-AA26 -> 0 | AE26: =Y26-AB26 -> 0 | AG26: =AG5+20 -> 142.43 | AH26: =W26*AG26 -> 624555.55 | AI26: =Y26*AG26 -> 0 | AS26: =+D26-AP26 -> 4400 | AT26: =+E26-AQ26 -> 0 | AU26: =+F26-AR26 -> 0 | AY26: =+W26-AV26 -> 4385 | AZ26: =+X26-AW26 -> 0 | BA26: =+Y26-AX26 -> 0 | BF26: =+H26-BE26 -> 0
A27: =VLOOKUP(C27,Master!A:D,4,0) -> SF | B27: =VLOOKUP(C27,Master!A:C,3,0) -> Webbing | C27: PP Webbing | D27: =SUMIF(Master!E:E,Summary!C27,Master!F:F)-E27-D26 -> 44905 | E27: 0 | F27: 1771.8 | G27: 9048.3 | H27: 4088.4 | K27: 126237.39 | O27: =143390.8+147 -> 143537.8 | P27: 43239.11 | Q27: =+I27 -> 0 | R27: 839 | U27: =O27-S27 -> 143537.8 | V27: =P27-T27 -> 43239.11 | W27: =D27+G27+H27+I27-K27-L27-M27-V27+U27 -> 32103 | X27: =E27+J27-N27-T27+S27 -> 0 | Y27: =F27-I27+M27-R27+Q27 -> 932.8 | Z27: 32103 | AA27: 0 | AB27: 932.8 | AC27: =W27-Z27 -> 0 | AD27: =X27-AA27 -> 0 | AE27: =Y27-AB27 -> 0 | AG27: =AG5+20 -> 142.43 | AH27: =W27*AG27 -> 4572430.3 | AI27: =Y27*AG27 -> 132858.7 | AS27: =+D27-AP27 -> 44905 | AT27: =+E27-AQ27 -> 0 | AU27: =+F27-AR27 -> 1771.8 | AY27: =+W27-AV27 -> 32103 | AZ27: =+X27-AW27 -> 0 | BA27: =+Y27-AX27 -> 932.8 | BE27: 19207.6 | BF27: =+H27-BE27 -> -15119.2
A28: =VLOOKUP(C28,Master!A:D,4,0) -> SF | B28: =VLOOKUP(C28,Master!A:C,3,0) -> Liners | C28: LDPE/LLDPE Bags | D28: =SUMIF(Master!E:E,Summary!C28,Master!F:F)-E28 -> 24896.583 | E28: 0 | F28: 0 | H28: 4001 | I28: 294 | K28: 192675.06 | L28: 25335.7 | O28: 240580 | P28: =2216-0.177 -> 2215.823 | Q28: =+I28 -> 294 | U28: =O28-S28 -> 240580 | V28: =P28-T28 -> 2215.823 | W28: =D28+G28+H28+I28-K28-L28-M28-V28+U28 -> 49545 | X28: =E28+J28-N28-T28+S28 -> 0 | Y28: =F28-I28+M28-R28+Q28 -> 0 | Z28: 49545 | AA28: 0 | AB28: 0 | AC28: =W28-Z28 -> 0 | AD28: =X28-AA28 -> 0 | AE28: =Y28-AB28 -> 0 | AG28: =182.02*0.97 -> 176.5594 | AH28: =W28*AG28 -> 8747635.5 | AI28: =Y28*AG28 -> 0 | AS28: =+D28-AP28 -> 24896.583 | AT28: =+E28-AQ28 -> 0 | AU28: =+F28-AR28 -> 0 | AY28: =+W28-AV28 -> 49545 | AZ28: =+X28-AW28 -> 0 | BA28: =+Y28-AX28 -> 0 | BE28: 910 | BF28: =+H28-BE28 -> 3091
A29: =VLOOKUP(C29,Master!A:D,4,0) -> #N/A | B29: =VLOOKUP(C29,Master!A:C,3,0) -> #N/A | C29: Cheese Pipe | D29: =SUMIF(Master!E:E,Summary!C29,Master!F:F)-E29 -> 0 | E29: 0 | F29: 0 | Q29: =+I29 -> 0 | U29: =O29-S29 -> 0 | V29: =P29-T29 -> 0 | W29: =D29+G29+H29+I29-K29-L29-M29-V29+U29 -> 0 | X29: =E29+J29-N29-T29+S29 -> 0 | Y29: =F29-I29+M29-R29+Q29 -> 0 | Z29: 0 | AA29: 0 | AB29: 0 | AC29: =W29-Z29 -> 0 | AD29: =X29-AA29 -> 0 | AE29: =Y29-AB29 -> 0 | AG29: 0 | AH29: =W29*AG29 -> 0 | AI29: =Y29*AG29 -> 0 | AS29: =+D29-AP29 -> 0 | AT29: =+E29-AQ29 -> 0 | AU29: =+F29-AR29 -> 0 | AY29: =+W29-AV29 -> 0 | AZ29: =+X29-AW29 -> 0 | BA29: =+Y29-AX29 -> 0 | BF29: =+H29-BE29 -> 0
A30: =VLOOKUP(C30,Master!A:D,4,0) -> SF | B30: =VLOOKUP(C30,Master!A:C,3,0) -> Tape Stock | C30: PP Tapes | D30: =SUMIF(Master!E:E,Summary!C30,Master!F:F)-E30 -> 114532.67 | E30: 0 | F30: 0 | H30: 16760.2 | K30: 27214.2 | O30: 952236.03 | P30: =951813.9-0.202 -> 951813.7 | Q30: =+I30 -> 0 | U30: =O30-S30 -> 952236.03 | V30: =P30-T30 -> 951813.7 | W30: =D30+G30+H30+I30-K30-L30-M30-V30+U30 -> 104501 | X30: =E30+J30-N30-T30+S30 -> 0 | Y30: =F30-I30+M30-R30+Q30 -> 0 | Z30: 104501 | AA30: 0 | AB30: 0 | AC30: =W30-Z30 -> 0 | AD30: =X30-AA30 -> 0 | AE30: =Y30-AB30 -> 0 | AG30: =+AG5+10 -> 132.43 | AH30: =W30*AG30 -> 13839067 | AI30: =Y30*AG30 -> 0 | AS30: =+D30-AP30 -> 114532.67 | AT30: =+E30-AQ30 -> 0 | AU30: =+F30-AR30 -> 0 | AY30: =+W30-AV30 -> 104501 | AZ30: =+X30-AW30 -> 0 | BA30: =+Y30-AX30 -> 0 | BE30: 9563.8 | BF30: =+H30-BE30 -> 7196.4
A31: =VLOOKUP(C31,Master!A:D,4,0) -> SF | B31: =VLOOKUP(C31,Master!A:C,3,0) -> RP Agglo | C31: RP Agglo | D31: =SUMIF(Master!E:E,Summary!C31,Master!F:F)-E31 -> 0 | E31: 0 | F31: 0 | Q31: =+I31 -> 0 | U31: =O31-S31 -> 0 | V31: =P31-T31 -> 0 | W31: =D31+G31+H31+I31-K31-L31-M31-V31+U31 -> 0 | X31: =E31+J31-N31-T31+S31 -> 0 | Y31: =F31-I31+M31-R31+Q31 -> 0 | Z31: 0 | AA31: 0 | AB31: 0 | AC31: =W31-Z31 -> 0 | AD31: =X31-AA31 -> 0 | AE31: =Y31-AB31 -> 0 | AG31: 0 | AH31: =W31*AG31 -> 0 | AI31: =Y31*AG31 -> 0 | AS31: =+D31-AP31 -> 0 | AT31: =+E31-AQ31 -> 0 | AU31: =+F31-AR31 -> 0 | AY31: =+W31-AV31 -> 0 | AZ31: =+X31-AW31 -> 0 | BA31: =+Y31-AX31 -> 0 | BE31: 15000 | BF31: =+H31-BE31 -> -15000
A32: =VLOOKUP(C32,Master!A:D,4,0) -> SF | B32: =VLOOKUP(C32,Master!A:C,3,0) -> Wastage/Scrap | C32: Wastage/Scrap | D32: =SUMIF(Master!E:E,Summary!C32,Master!F:F)-E32 -> 80153.2 | E32: 0 | F32: 72940 | H32: 45832 | I32: 5659 | J32: 26715 | K32: 12534 | M32: 119570 | N32: 144 | O32: =182727+7628 -> 190355 | P32: 115341.2 | Q32: =+I32 -> 5659 | R32: 71275 | T32: 13375 | U32: =O32-S32 -> 190355 | V32: =P32-T32 -> 101966.2 | W32: =D32+G32+H32+I32-K32-L32-M32-V32+U32 -> 87929 | X32: =E32+J32-N32-T32+S32 -> 13196 | Y32: =F32-I32+M32-R32+Q32 -> 121235 | Z32: 87929 | AA32: 13196 | AB32: 121235 | AC32: =W32-Z32 -> 0 | AD32: =X32-AA32 -> 0 | AE32: =Y32-AB32 -> 0 | AG32: 15 | AH32: =W32*AG32 -> 1318935 | AI32: =Y32*AG32 -> 1818525 | AS32: =+D32-AP32 -> 80153.2 | AT32: =+E32-AQ32 -> 0 | AU32: =+F32-AR32 -> 72940 | AY32: =+W32-AV32 -> 87929 | AZ32: =+X32-AW32 -> 13196 | BA32: =+Y32-AX32 -> 121235 | BE32: 39700 | BF32: =+H32-BE32 -> 6132
A33: =VLOOKUP(C33,Master!A:D,4,0) -> #N/A | B33: =VLOOKUP(C33,Master!A:C,3,0) -> #N/A | C33: PP PAPER FABRIC | D33: =SUMIF(Master!E:E,Summary!C33,Master!F:F)-E33-D34 -> 2249 | E33: 0 | F33: 0 | O33: 47181 | P33: 49430 | Q33: =+I33 -> 0 | U33: =O33-S33 -> 47181 | V33: =P33-T33 -> 49430 | W33: =D33+G33+H33+I33-K33-L33-M33-V33+U33 -> 0 | X33: =E33+J33-N33-T33+S33 -> 0 | Y33: =F33-I33+M33-R33+Q33 -> 0 | Z33: 0 | AA33: 0 | AB33: 0 | AC33: =W33-Z33 -> 0 | AD33: =X33-AA33 -> 0 | AE33: =Y33-AB33 -> 0 | AG33: 115.46 | AH33: =W33*AG33 -> 0 | AI33: =Y33*AG33 -> 0 | AS33: =+D33-AP33 -> 2249 | AT33: =+E33-AQ33 -> 0 | AU33: =+F33-AR33 -> 0 | AY33: =+W33-AV33 -> 0 | AZ33: =+X33-AW33 -> 0 | BA33: =+Y33-AX33 -> 0 | BF33: =+H33-BE33 -> 0
A34: =VLOOKUP(C34,Master!A:D,4,0) -> #N/A | B34: =VLOOKUP(C34,Master!A:C,3,0) -> #N/A | C34: BOPP Fabric WIP | D34: 8486 | E34: 0 | F34: 0 | O34: 49430 | P34: 57916 | Q34: =+I34 -> 0 | U34: =O34-S34 -> 49430 | V34: =P34-T34 -> 57916 | W34: =D34+G34+H34+I34-K34-L34-M34-V34+U34 -> 0 | X34: =E34+J34-N34-T34+S34 -> 0 | Y34: =F34-I34+M34-R34+Q34 -> 0 | Z34: 0 | AA34: 0 | AB34: 0 | AC34: =W34-Z34 -> 0 | AD34: =X34-AA34 -> 0 | AE34: =Y34-AB34 -> 0 | AG34: =AG20 -> 142.43 | AH34: =W34*AG34 -> 0 | AI34: =Y34*AG34 -> 0 | AS34: =+D34-AP34 -> 8486 | AT34: =+E34-AQ34 -> 0 | AU34: =+F34-AR34 -> 0 | AY34: =+W34-AV34 -> 0 | AZ34: =+X34-AW34 -> 0 | BA34: =+Y34-AX34 -> 0 | BF34: =+H34-BE34 -> 0
A35: =VLOOKUP(C35,Master!A:D,4,0) -> FG | B35: =VLOOKUP(C35,Master!A:C,3,0) -> FIBC Bags | C35: FIBC Bags | D35: =SUMIF(Master!E:E,Summary!C35,Master!F:F)-E35-D41 -> 118386 | E35: 0 | F35: 4016.25 | G35: 16889 | H35: 327430.16 | I35: 300425.4 | K35: 737019.36 | O35: 158337 | P35: 2530.2 | Q35: =+I35 -> 300425.4 | U35: =O35-S35 -> 158337 | V35: =P35-T35 -> 2530.2 | W35: =D35+G35+H35+I35-K35-L35-M35-V35+U35 -> 181918 | X35: =E35+J35-N35-T35+S35 -> 0 | Y35: =F35-I35+M35-R35+Q35 -> 4016.25 | Z35: 181918 | AA35: 0 | AB35: 4016.25 | AC35: =W35-Z35 -> 0 | AD35: =X35-AA35 -> 0 | AE35: =Y35-AB35 -> 0 | AG35: =222.75*0.95 -> 211.6125 | AH35: =W35*AG35 -> 38496123 | AI35: =Y35*AG35 -> 849888.7 | AS35: =+D35-AP35 -> 118386 | AT35: =+E35-AQ35 -> 0 | AU35: =+F35-AR35 -> 4016.25 | AY35: =+W35-AV35 -> 181918 | AZ35: =+X35-AW35 -> 0 | BA35: =+Y35-AX35 -> 4016.25 | BE35: 413997.2 | BF35: =+H35-BE35 -> -86567.04
A36: =VLOOKUP(C36,Master!A:D,4,0) -> FG | B36: =VLOOKUP(C36,Master!A:C,3,0) -> Small Bags | C36: PP Lami Bags | D36: =SUMIF(Master!E:E,Summary!C36,Master!F:F)-E36 -> 3497 | E36: 0 | F36: 0 | G36: 1004 | K36: 12892.8 | O36: =17652.529+0.271 -> 17652.8 | Q36: =+I36 -> 0 | U36: =O36-S36 -> 17652.8 | V36: =P36-T36 -> 0 | W36: =D36+G36+H36+I36-K36-L36-M36-V36+U36 -> 9261 | X36: =E36+J36-N36-T36+S36 -> 0 | Y36: =F36-I36+M36-R36+Q36 -> 0 | Z36: 9261 | AA36: 0 | AB36: 0 | AC36: =W36-Z36 -> 0 | AD36: =X36-AA36 -> 0 | AE36: =Y36-AB36 -> 0 | AG36: =280.32*0.97 -> 271.9104 | AH36: =W36*AG36 -> 2518162.2 | AI36: =Y36*AG36 -> 0 | AS36: =+D36-AP36 -> 3497 | AT36: =+E36-AQ36 -> 0 | AU36: =+F36-AR36 -> 0 | AY36: =+W36-AV36 -> 9261 | AZ36: =+X36-AW36 -> 0 | BA36: =+Y36-AX36 -> 0 | BF36: =+H36-BE36 -> 0
A37: =VLOOKUP(C37,Master!A:D,4,0) -> #N/A | B37: Craft Paper | C37: Paper Poly Bags | D37: =SUMIF(Master!E:E,Summary!C37,Master!F:F)-E37 -> 16358.24 | E37: 0 | F37: 0 | K37: 50542.5 | O37: =49512+0.26 -> 49512.26 | Q37: =+I37 -> 0 | U37: =O37-S37 -> 49512.26 | V37: =P37-T37 -> 0 | W37: =D37+G37+H37+I37-K37-L37-M37-V37+U37 -> 15328 | X37: =E37+J37-N37-T37+S37 -> 0 | Y37: =F37-I37+M37-R37+Q37 -> 0 | Z37: 15328 | AA37: 0 | AB37: 0 | AC37: =W37-Z37 -> 0 | AD37: =X37-AA37 -> 0 | AE37: =Y37-AB37 -> 0 | AG37: =188.34*0.97 -> 182.6898 | AH37: =W37*AG37 -> 2800269.3 | AI37: =Y37*AG37 -> 0 | AS37: =+D37-AP37 -> 16358.24 | AT37: =+E37-AQ37 -> 0 | AU37: =+F37-AR37 -> 0 | AY37: =+W37-AV37 -> 15328 | AZ37: =+X37-AW37 -> 0 | BA37: =+Y37-AX37 -> 0 | BF37: =+H37-BE37 -> 0
A38: =VLOOKUP(C38,Master!A:D,4,0) -> FG | B38: =VLOOKUP(C38,Master!A:C,3,0) -> Trading Items | C38: Trading Items | D38: =SUMIF(Master!E:E,Summary!C38,Master!F:F)-E38 -> 0 | E38: 0 | F38: 0 | Q38: =+I38 -> 0 | U38: =O38-S38 -> 0 | V38: =P38-T38 -> 0 | W38: =D38+G38+H38+I38-K38-L38-M38-V38+U38 -> 0 | X38: =E38+J38-N38-T38+S38 -> 0 | Y38: =F38-I38+M38-R38+Q38 -> 0 | Z38: 0 | AA38: 0 | AB38: 0 | AC38: =W38-Z38 -> 0 | AD38: =X38-AA38 -> 0 | AE38: =Y38-AB38 -> 0 | AG38: 0 | AH38: =W38*AG38 -> 0 | AI38: =Y38*AG38 -> 0 | AS38: =+D38-AP38 -> 0 | AT38: =+E38-AQ38 -> 0 | AU38: =+F38-AR38 -> 0 | AY38: =+W38-AV38 -> 0 | AZ38: =+X38-AW38 -> 0 | BA38: =+Y38-AX38 -> 0 | BF38: =+H38-BE38 -> 0
A39: =VLOOKUP(C39,Master!A:D,4,0) -> FG | B39: =VLOOKUP(C39,Master!A:C,3,0) -> Small Bags | C39: PP Bags | D39: =SUMIF(Master!E:E,Summary!C39,Master!F:F)-E39 -> 0 | E39: 0 | F39: 0 | H39: 1745 | K39: 1745 | Q39: =+I39 -> 0 | U39: =O39-S39 -> 0 | V39: =P39-T39 -> 0 | W39: =D39+G39+H39+I39-K39-L39-M39-V39+U39 -> 0 | X39: =E39+J39-N39-T39+S39 -> 0 | Y39: =F39-I39+M39-R39+Q39 -> 0 | Z39: 0 | AA39: 0 | AB39: 0 | AC39: =W39-Z39 -> 0 | AD39: =X39-AA39 -> 0 | AE39: =Y39-AB39 -> 0 | AG39: 0 | AH39: =W39*AG39 -> 0 | AI39: =Y39*AG39 -> 0 | AS39: =+D39-AP39 -> 0 | AT39: =+E39-AQ39 -> 0 | AU39: =+F39-AR39 -> 0 | AY39: =+W39-AV39 -> 0 | AZ39: =+X39-AW39 -> 0 | BA39: =+Y39-AX39 -> 0 | BE39: 7762 | BF39: =+H39-BE39 -> -6017
A40: =VLOOKUP(C40,Master!A:D,4,0) -> FG | B40: =VLOOKUP(C40,Master!A:C,3,0) -> Small Bags WIP | C40: Small Bags WIP | D40: 0 | E40: 0 | F40: 0 | Q40: =+I40 -> 0 | U40: =O40-S40 -> 0 | V40: =P40-T40 -> 0 | W40: =D40+G40+H40+I40-K40-L40-M40-V40+U40 -> 0 | X40: =E40+J40-N40-T40+S40 -> 0 | Y40: =F40-I40+M40-R40+Q40 -> 0 | Z40: 0 | AA40: 0 | AB40: 0 | AC40: =W40-Z40 -> 0 | AD40: =X40-AA40 -> 0 | AE40: =Y40-AB40 -> 0 | AG40: 0 | AH40: =W40*AG40 -> 0 | AI40: =Y40*AG40 -> 0 | AS40: =+D40-AP40 -> 0 | AT40: =+E40-AQ40 -> 0 | AU40: =+F40-AR40 -> 0 | AY40: =+W40-AV40 -> 0 | AZ40: =+X40-AW40 -> 0 | BA40: =+Y40-AX40 -> 0 | BF40: =+H40-BE40 -> 0
...

Sheet Master
A1: =+Summary!A1 -> STOCK AS ON 01/09/2026 | F1: =SUBTOTAL(9,F3:F852) -> 2549982.9 | G1: =SUBTOTAL(9,G3:G852) -> 1687226.7
A2: SubGroupName | B2: Item Name | C2: GroupName | D2: MainGroupName | E2: SubGroupName | F2: Opening | G2: Closing
A3: Craft Paper | B3: Craft Paper | C3: Craft Paper | D3: RM | E3: Craft Paper | F3: 22897 | G3: 17047
A4: BOPP Film | B4: BOPP Film | C4: Films All | D4: RM | E4: BOPP Film | F4: 5855 | G4: 12570
A5: BOPP Film | B5: BOPP Film Printed | C5: Films All | D5: RM | E5: BOPP Film
A6: Enable Granuals | B6: Enable Exxon 2005MC | C6: Granuals | D6: RM | E6: Enable Granuals
A7: Enable Granuals | B7: Enable Exxon 2005ME | C7: Granuals | D7: RM | E7: Enable Granuals
A8: EVA Granules | B8: EVA Granules | C8: EVA Granuals | D8: RM | E8: EVA Granuals | F8: 2231.375 | G8: 1407.025
A9: FIBC Accessories | B9: Non Woven Fabric (Felt) 170Gsm.Pati Cut Length- 2" ( 5 Cm ) | C9: FIBC Accessories | D9: RM | E9: FIBC Accessories
A10: FIBC Accessories | B10: Spun Bound Non Woven Fabric 118 Cm 90 Gsm Uncoated | C10: FIBC Accessories | D10: RM | E10: FIBC Accessories
A11: FIBC Accessories | B11: Non Woven Fabric (Felt) 170Gsm.Pati Cut Length- 2" ( 5 Cm ) (Food Grade Quality) | C11: FIBC Accessories | D11: RM | E11: FIBC Accessories
A12: FIBC Accessories | B12: Non Woven Fabric (Felt) 200 Gsm.Pati Cut Length- 4" (10 Cm) | C12: FIBC Accessories | D12: RM | E12: FIBC Accessories
A13: FIBC Accessories | B13: Non Woven Fabric (Felt) | C13: FIBC Accessories | D13: RM | E13: FIBC Accessories
A14: FIBC Accessories | B14: Non Woven Fabric (Felt) 170Gsm.Pati Cut Length- 4" ( 10 Cm ) | C14: FIBC Accessories | D14: RM | E14: FIBC Accessories
A15: FIBC Bags | B15: FIBC Bags With UV With Liner | C15: FIBC Bags | D15: FG | E15: FIBC Bags
A16: FIBC Bags | B16: FIBC Bags With UV Without Liner | C16: FIBC Bags | D16: FG | E16: FIBC Bags | F16: 134441 | G16: 206062
A17: FIBC WIP | B17: FIBC WIP | C17: FIBC WIP | D17: FG | E17: FIBC WIP
A18: Filler | B18: Filler Everplus Natural TPT - Sodium Base | C18: Granuals | D18: RM | E18: Filler
A19: Filler | B19: Filler Terramag Calcium 20% | C19: Granuals | D19: RM | E19: Filler | F19: 15438.9
A20: Filler | B20: Filler Satyendra True AFMB003 | C20: Granuals | D20: RM | E20: Filler | F20: 48.5
A21: Filler | B21: Filler Soltex TPT | C21: Granuals | D21: RM | E21: Filler
A22: Filler | B22: Filler Goldmine LL GM 101 MB | C22: Granuals | D22: RM | E22: Filler
A23: Filler | B23: Filler Soltex PTUFF23 | C23: Granuals | D23: RM | E23: Filler | F23: 380.0075 | G23: 3022
A24: Filler | B24: Filler Shri Ambica TPT | C24: Granuals | D24: RM | E24: Filler
A25: Filler | B25: Filler Karnavati GOM Liner | C25: Granuals | D25: RM | E25: Filler
A26: Filler | B26: Filler Everplus TPT-75 E110 | C26: Granuals | D26: RM | E26: Filler | F26: 25 | G26: 25
A27: Filler | B27: Filler Soltex White02 | C27: Granuals | D27: RM | E27: Filler
A28: Filler | B28: FILLER JJ AF03PL | C28: Granuals | D28: RM | E28: Filler
A29: Filler | B29: Filler Alpha ASCOM 40 TM | C29: Granuals | D29: RM | E29: Filler
A30: Filler | B30: Filler 365 Goldfill PX5 | C30: Granuals | D30: RM | E30: Filler
A31: Filler | B31: Filler Everplus E103 Liner | C31: Granuals | D31: RM | E31: Filler
A32: Filler | B32: Filler Everplus Modifier E-105 | C32: Granuals | D32: RM | E32: Filler
A33: Filler | B33: Filler PK Modifier Sp71030538 | C33: Granuals | D33: RM | E33: Filler
A34: Filler | B34: Filler Everplus E102 PP | C34: Granuals | D34: RM | E34: Filler
A35: Filler | B35: Filler Omya film 715 DS | C35: Granuals | D35: RM | E35: Filler
A36: Filler | B36: Filler Everplus E101 LLDPE | C36: Granuals | D36: RM | E36: Filler
A37: Filler | B37: Filler Soltex PTUFF24 | C37: Granuals | D37: RM | E37: Filler
A38: Filler | B38: Filler Simandhar Sodium Sulphate Transparent | C38: Granuals | D38: RM | E38: Filler
... A66: HDPE Granuals | B66: HDPE Gail Y50A010U A | C66: Granuals | D66: RM | E66: HDPE Granuals
A67: HDPE Granuals | B67: HDPE OPAL P5002 | C67: Granuals | D67: RM | E67: HDPE Granuals | F67: 2200 | G67: 825
...
