Workbook

Sheet Master
A2: SubGroupName | B2: Item Name | C2: GroupName | D2: MainGroupName | E2: SubGroupName | F2: Opening | G2: Closing
A3: Beam Stock | B3: PP Tape on Beams | C3: Tape Stock | D3: SF | E3: Beam Stock | F3: 0 | G3: 0
A4: BOPP Film | B4: BOPP Film | C4: Films All | D4: RM | E4: BOPP Film | F4: 0 | G4: 0
A5: BOPP Film | B5: BOPP Film Printed | C5: Films All | D5: RM | E5: BOPP Film | F5: 0 | G5: 0
A6: Enable Granuals | B6: Enable Exxon 2005MC | C6: Granuals | D6: RM | E6: Enable Granuals | F6: 0 | G6: 0
A7: Enable Granuals | B7: Enable Exxon 2005ME | C7: Granuals | D7: RM | E7: Enable Granuals | F7: 0 | G7: 0
A8: EVA Granuals | B8: EVA Granuals | C8: Granuals | D8: RM | E8: EVA Granuals | F8: 0 | G8: 0
A9: FIBC Accessories | B9: Non Woven Fabric (Felt) 170Gsm.Pati Cut Length- 2" ( 5 Cm ) | C9: FIBC Accessories | D9: RM | E9: FIBC Accessories | F9: 0 | G9: 0
A10: FIBC Accessories | B10: Spun Bound Non Woven Fabric 118 Cm 90 Gsm Uncoated | C10: FIBC Accessories | D10: RM | E10: FIBC Accessories | F10: 0 | G10: 0
A11: FIBC Accessories | B11: Non Woven Fabric (Felt) 170Gsm.Pati Cut Length- 2" ( 5 Cm ) (Food Grade Quality) | C11: FIBC Accessories | D11: RM | E11: FIBC Accessories | F11: 0 | G11: 0
A12: FIBC Accessories | B12: Non Woven Fabric (Felt) 200 Gsm.Pati Cut Length- 4" (10 Cm) | C12: FIBC Accessories | D12: RM | E12: FIBC Accessories | F12: 0 | G12: 0
A13: FIBC Accessories | B13: Non Woven Fabric (Felt) | C13: FIBC Accessories | D13: RM | E13: FIBC Accessories | F13: 0 | G13: 0
A14: FIBC Accessories | B14: Non Woven Fabric (Felt) 170Gsm.Pati Cut Length- 4" ( 10 Cm ) | C14: FIBC Accessories | D14: RM | E14: FIBC Accessories | F14: 0 | G14: 0
... A928: Wastage/Scrap | B928: PP/HD Wastage/Scrap | C928: Wastage/Scrap | D928: SF | E928: Wastage/Scrap | F928: 0 | G928: 0

Sheet Summary
D2: Opening Stock | G2: Inventory movement fo the month of APRIL 2026 | W2: Closing Stock -As per Movement Sheet | Z2: Closing Stock - As per Actual (Physical) | AC2: Difference
A3: Group | B3: Sub group | C3: Details of Items / Products | D3: Factory Owned | E3: Factory JW (Others) | F3: At JW (Own) | G3: Branch Tfr Recd | H3: Purchase | I3: Recd from JW (Own) | J3: Recd For JW (Others) | K3: Sales | L3: Br Transfer Sent | M3: Sent for JW (Own) | N3: Return JW(Others) | O3: Total Production Own+JW | P3: Total Consumption Own+JW | Q3: Production at JW | R3: Consumption At JW | S3: Pord of JW | T3: Consumption of JW | U3: Net Production Own | V3: Net Consumption Own | W3: Factory Owned | X3: Factory JW (Others) | Y3: At JW (Own) | Z3: Factory Owned | AA3: Factory JW (Others) | AB3: At JW (Own) | AC3: Factory Owned | AD3: Factory JW (Others) | AE3: At JW (Own) | AF3: Remark for Difference, If any | AG3: Rate | AH3: Value Factory Own
A4: =VLOOKUP(C4,Master!A:D,4,0) -> RM | B4: =VLOOKUP(C4,Master!A:C,3,0) -> Granuals | C4: Masterbatch | D4: 1834.7 | E4: 350 | F4: 0 | J4: 700 | P4: 287.9 | T4: 50 | U4: =O4-S4 -> 0 | V4: =P4-T4 -> 237.9 | W4: =D4+G4+H4+I4-K4-L4-M4-V4+U4 -> 1596.8 | X4: =E4+J4-N4-T4+S4 -> 1000 | Y4: =F4-I4+M4-R4+Q4 -> 0 | Z4: 1596.8 | AA4: 1000 | AB4: 0 | AC4: =W4-Z4 -> 0 | AD4: =X4-AA4 -> 0 | AE4: =Y4-AB4 -> 0 | AG4: 201 | AH4: =+W4*AG4 -> 320956.8
A5: =VLOOKUP(C5,Master!A:D,4,0) -> RM | B5: =VLOOKUP(C5,Master!A:C,3,0) -> Granuals | C5: PP Granuals | D5: 23534.349 | E5: 579675.5 | F5: 0 | H5: 112000 | J5: 196000 | P5: 299193.15 | T5: 238057.96 | U5: =O5-S5 -> 0 | V5: =P5-T5 -> 61135.189 | W5: =D5+G5+H5+I5-K5-L5-M5-V5+U5 -> 74399.16 | X5: =E5+J5-N5-T5+S5 -> 537617.54 | Y5: =F5-I5+M5-R5+Q5 -> 0 | Z5: 74399.16 | AA5: 537617.54 | AB5: 0 | AC5: =W5-Z5 -> 0 | AD5: =X5-AA5 -> 0 | AE5: =Y5-AB5 -> 0 | AG5: 108 | AH5: =+W5*AG5 -> 8035109.3
A6: =VLOOKUP(C6,Master!A:D,4,0) -> RM | B6: =VLOOKUP(C6,Master!A:C,3,0) -> Granuals | C6: HDPE Granuals | D6: 0 | E6: 0 | F6: 0 | T6: 0 | U6: =O6-S6 -> 0 | V6: =P6-T6 -> 0 | W6: =D6+G6+H6+I6-K6-L6-M6-V6+U6 -> 0 | X6: =E6+J6-N6-T6+S6 -> 0 | Y6: =F6-I6+M6-R6+Q6 -> 0 | Z6: 0 | AA6: 0 | AB6: 0 | AC6: =W6-Z6 -> 0 | AD6: =X6-AA6 -> 0 | AE6: =Y6-AB6 -> 0 | AH6: =+W6*AG6 -> 0
A7: =VLOOKUP(C7,Master!A:D,4,0) -> RM | B7: =VLOOKUP(C7,Master!A:C,3,0) -> Granuals | C7: LDPE Granuals | D7: 0 | E7: 13000 | F7: 0 | T7: 0 | U7: =O7-S7 -> 0 | V7: =P7-T7 -> 0 | W7: =D7+G7+H7+I7-K7-L7-M7-V7+U7 -> 0 | X7: =E7+J7-N7-T7+S7 -> 13000 | Y7: =F7-I7+M7-R7+Q7 -> 0 | Z7: 0 | AA7: 13000 | AB7: 0 | AC7: =W7-Z7 -> 0 | AD7: =X7-AA7 -> 0 | AE7: =Y7-AB7 -> 0 | AH7: =+W7*AG7 -> 0
A8: =VLOOKUP(C8,Master!A:D,4,0) -> RM | B8: =VLOOKUP(C8,Master!A:C,3,0) -> Granuals | C8: LLDPE Granuals | D8: 0 | E8: 0 | F8: 0 | T8: 0 | U8: =O8-S8 -> 0 | V8: =P8-T8 -> 0 | W8: =D8+G8+H8+I8-K8-L8-M8-V8+U8 -> 0 | X8: =E8+J8-N8-T8+S8 -> 0 | Y8: =F8-I8+M8-R8+Q8 -> 0 | Z8: 0 | AA8: 0 | AB8: 0 | AC8: =W8-Z8 -> 0 | AD8: =X8-AA8 -> 0 | AE8: =Y8-AB8 -> 0 | AH8: =+W8*AG8 -> 0
A9: =VLOOKUP(C9,Master!A:D,4,0) -> RM | B9: =VLOOKUP(C9,Master!A:C,3,0) -> Granuals | C9: UV MB | D9: 0 | E9: 15000 | F9: 0 | J9: 6575 | T9: 0 | U9: =O9-S9 -> 0 | V9: =P9-T9 -> 0 | W9: =D9+G9+H9+I9-K9-L9-M9-V9+U9 -> 0 | X9: =E9+J9-N9-T9+S9 -> 21575 | Y9: =F9-I9+M9-R9+Q9 -> 0 | Z9: 0 | AA9: 21575 | AB9: 0 | AC9: =W9-Z9 -> 0 | AD9: =X9-AA9 -> 0 | AE9: =Y9-AB9 -> 0 | AH9: =+W9*AG9 -> 0
A10: =VLOOKUP(C10,Master!A:D,4,0) -> RM | B10: =VLOOKUP(C10,Master!A:C,3,0) -> FIBC Accessories | C10: FIBC Accessories | D10: 0 | E10: 0 | F10: 0 | T10: 0 | U10: =O10-S10 -> 0 | V10: =P10-T10 -> 0 | W10: =D10+G10+H10+I10-K10-L10-M10-V10+U10 -> 0 | X10: =E10+J10-N10-T10+S10 -> 0 | Y10: =F10-I10+M10-R10+Q10 -> 0 | Z10: 0 | AA10: 0 | AB10: 0 | AC10: =W10-Z10 -> 0 | AD10: =X10-AA10 -> 0 | AE10: =Y10-AB10 -> 0 | AH10: =+W10*AG10 -> 0
A11: =VLOOKUP(C11,Master!A:D,4,0) -> RM | B11: =VLOOKUP(C11,Master!A:C,3,0) -> Films All | C11: Polyester Film | D11: 0 | E11: 0 | F11: 0 | T11: 0 | U11: =O11-S11 -> 0 | V11: =P11-T11 -> 0 | W11: =D11+G11+H11+I11-K11-L11-M11-V11+U11 -> 0 | X11: =E11+J11-N11-T11+S11 -> 0 | Y11: =F11-I11+M11-R11+Q11 -> 0 | Z11: 0 | AA11: 0 | AB11: 0 | AC11: =W11-Z11 -> 0 | AD11: =X11-AA11 -> 0 | AE11: =Y11-AB11 -> 0 | AH11: =+W11*AG11 -> 0
A12: =VLOOKUP(C12,Master!A:D,4,0) -> RM | B12: =VLOOKUP(C12,Master!A:C,3,0) -> Granuals | C12: Filler | D12: 0 | E12: 0 | F12: 0 | J12: 6000 | T12: 0 | U12: =O12-S12 -> 0 | V12: =P12-T12 -> 0 | W12: =D12+G12+H12+I12-K12-L12-M12-V12+U12 -> 0 | X12: =E12+J12-N12-T12+S12 -> 6000 | Y12: =F12-I12+M12-R12+Q12 -> 0 | Z12: 0 | AA12: 6000 | AB12: 0 | AC12: =W12-Z12 -> 0 | AD12: =X12-AA12 -> 0 | AE12: =Y12-AB12 -> 0 | AH12: =+W12*AG12 -> 0
A13: =VLOOKUP(C13,Master!A:D,4,0) -> RM | B13: =VLOOKUP(C13,Master!A:C,3,0) -> Films All | C13: PE Film | D13: 0 | E13: 0 | F13: 0 | T13: 0 | U13: =O13-S13 -> 0 | V13: =P13-T13 -> 0 | W13: =D13+G13+H13+I13-K13-L13-M13-V13+U13 -> 0 | X13: =E13+J13-N13-T13+S13 -> 0 | Y13: =F13-I13+M13-R13+Q13 -> 0 | Z13: 0 | AA13: 0 | AB13: 0 | AC13: =W13-Z13 -> 0 | AD13: =X13-AA13 -> 0 | AE13: =Y13-AB13 -> 0 | AH13: =+W13*AG13 -> 0
A14: =VLOOKUP(C14,Master!A:D,4,0) -> RM | B14: =VLOOKUP(C14,Master!A:C,3,0) -> Granuals | C14: EVA Granuals | D14: 0 | E14: 0 | F14: 0 | T14: 0 | U14: =O14-S14 -> 0 | V14: =P14-T14 -> 0 | W14: =D14+G14+H14+I14-K14-L14-M14-V14+U14 -> 0 | X14: =E14+J14-N14-T14+S14 -> 0 | Y14: =F14-I14+M14-R14+Q14 -> 0 | Z14: 0 | AA14: 0 | AB14: 0 | AC14: =W14-Z14 -> 0 | AD14: =X14-AA14 -> 0 | AE14: =Y14-AB14 -> 0 | AH14: =+W14*AG14 -> 0
A15: =VLOOKUP(C15,Master!A:D,4,0) -> RM | B15: =VLOOKUP(C15,Master!A:C,3,0) -> Granuals | C15: mLLDPE Granuals | D15: 0 | E15: 0 | F15: 0 | T15: 0 | U15: =O15-S15 -> 0 | V15: =P15-T15 -> 0 | W15: =D15+G15+H15+I15-K15-L15-M15-V15+U15 -> 0 | X15: =E15+J15-N15-T15+S15 -> 0 | Y15: =F15-I15+M15-R15+Q15 -> 0 | Z15: 0 | AA15: 0 | AB15: 0 | AC15: =W15-Z15 -> 0 | AD15: =X15-AA15 -> 0 | AE15: =Y15-AB15 -> 0 | AH15: =+W15*AG15 -> 0
A16: =VLOOKUP(C16,Master!A:D,4,0) -> RM | B16: =VLOOKUP(C16,Master!A:C,3,0) -> Films All | C16: BOPP Film | D16: 0 | E16: 0 | F16: 0 | T16: 0 | U16: =O16-S16 -> 0 | V16: =P16-T16 -> 0 | W16: =D16+G16+H16+I16-K16-L16-M16-V16+U16 -> 0 | X16: =E16+J16-N16-T16+S16 -> 0 | Y16: =F16-I16+M16-R16+Q16 -> 0 | Z16: 0 | AA16: 0 | AB16: 0 | AC16: =W16-Z16 -> 0 | AD16: =X16-AA16 -> 0 | AE16: =Y16-AB16 -> 0 | AH16: =+W16*AG16 -> 0
A17: =VLOOKUP(C17,Master!A:D,4,0) -> RM | B17: =VLOOKUP(C17,Master!A:C,3,0) -> Granuals | C17: Enable Granuals | D17: 0 | E17: 0 | F17: 0 | T17: 0 | U17: =O17-S17 -> 0 | V17: =P17-T17 -> 0 | W17: =D17+G17+H17+I17-K17-L17-M17-V17+U17 -> 0 | X17: =E17+J17-N17-T17+S17 -> 0 | Y17: =F17-I17+M17-R17+Q17 -> 0 | Z17: 0 | AA17: 0 | AB17: 0 | AC17: =W17-Z17 -> 0 | AD17: =X17-AA17 -> 0 | AE17: =Y17-AB17 -> 0 | AH17: =+W17*AG17 -> 0
A18: =VLOOKUP(C18,Master!A:D,4,0) -> SF | B18: =VLOOKUP(C18,Master!A:C,3,0) -> Yarn All | C18: PP Yarn | D18: 0 | E18: 15276.14 | F18: 0 | H18: 3286.76 | J18: 13674.7 | O18: 1796.3 | P18: 16825.6 | T18: 11742.54 | U18: =O18-S18 -> 1796.3 | V18: =P18-T18 -> 5083.06 | W18: =D18+G18+H18+I18-K18-L18-M18-V18+U18 -> 0 | X18: =E18+J18-N18-T18+S18 -> 17208.3 | Z18: 0 | AA18: 17208.3 | AB18: 0 | AC18: =W18-Z18 -> 0 | AD18: =X18-AA18 -> 0 | AE18: =Y18-AB18 -> 0 | AH18: =+W18*AG18 -> 0
A19: =VLOOKUP(C19,Master!A:D,4,0) -> SF | B19: =VLOOKUP(C19,Master!A:C,3,0) -> PP/PE Fabric | C19: PP UL Fabric | D19: 0 | E19: 11815 | F19: 0 | H19: 767.8 | J19: 47218.9 | K19: 27139.1 | O19: 156688 | P19: 142132 | T19: 11815.3 | U19: =O19-S19 -> 156688 | V19: =P19-T19 -> 130316.7 | W19: =D19+G19+H19+I19-K19-L19-M19-V19+U19 -> 0 | X19: =E19+J19-N19-T19+S19 -> 47218.6 | Y19: =F19-I19+M19-R19+Q19 -> 0 | Z19: 0 | AA19: 47218.6 | AB19: 0 | AC19: =W19-Z19 -> 0 | AD19: =X19-AA19 -> 0 | AE19: =Y19-AB19 -> 0 | AH19: =+W19*AG19 -> 0
A20: =VLOOKUP(C20,Master!A:D,4,0) -> SF | B20: =VLOOKUP(C20,Master!A:C,3,0) -> Flexitank Accessories | C20: Flexitank Accessories | D20: 0 | E20: 0 | F20: 0 | T20: 0 | U20: =O20-S20 -> 0 | V20: =P20-T20 -> 0 | W20: =D20+G20+H20+I20-K20-L20-M20-V20+U20 -> 0 | X20: =E20+J20-N20-T20+S20 -> 0 | Y20: =F20-I20+M20-R20+Q20 -> 0 | Z20: 0 | AA20: 0 | AB20: 0 | AC20: =W20-Z20 -> 0 | AD20: =X20-AA20 -> 0 | AE20: =Y20-AB20 -> 0 | AH20: =+W20*AG20 -> 0
A21: =VLOOKUP(C21,Master!A:D,4,0) -> SF | B21: =VLOOKUP(C21,Master!A:C,3,0) -> PP/PE Fabric | C21: PP Lam Fabric | D21: 0 | E21: 9587 | F21: 0 | J21: 18916 | O21: 106320 | P21: 115906.7 | T21: 9586.7 | U21: =O21-S21 -> 106320 | V21: =P21-T21 -> 106320 | W21: =D21+G21+H21+I21-K21-L21-M21-V21+U21 -> 0 | X21: =E21+J21-N21-T21+S21 -> 18916.3 | Y21: =F21-I21+M21-R21+Q21 -> 0 | Z21: 0 | AA21: 18916.3 | AB21: 0 | AC21: =W21-Z21 -> 0 | AD21: =X21-AA21 -> 0 | AE21: =Y21-AB21 -> 0 | AH21: =+W21*AG21 -> 0
A22: =VLOOKUP(C22,Master!A:D,4,0) -> SF | B22: =VLOOKUP(C22,Master!A:C,3,0) -> PP/PE Fabric | C22: HD UL Fabric | D22: 0 | E22: 0 | F22: 0 | T22: 0 | U22: =O22-S22 -> 0 | V22: =P22-T22 -> 0 | W22: =D22+G22+H22+I22-K22-L22-M22-V22+U22 -> 0 | X22: =E22+J22-N22-T22+S22 -> 0 | Y22: =F22-I22+M22-R22+Q22 -> 0 | Z22: 0 | AA22: 0 | AB22: 0 | AC22: =W22-Z22 -> 0 | AD22: =X22-AA22 -> 0 | AE22: =Y22-AB22 -> 0 | AH22: =+W22*AG22 -> 0
A23: =VLOOKUP(C23,Master!A:D,4,0) -> SF | B23: =VLOOKUP(C23,Master!A:C,3,0) -> PP/PE Fabric | C23: HD Lam Fabric | D23: 0 | E23: 0 | F23: 0 | T23: 0 | U23: =O23-S23 -> 0 | V23: =P23-T23 -> 0 | W23: =D23+G23+H23+I23-K23-L23-M23-V23+U23 -> 0 | X23: =E23+J23-N23-T23+S23 -> 0 | Y23: =F23-I23+M23-R23+Q23 -> 0 | Z23: 0 | AA23: 0 | AB23: 0 | AC23: =W23-Z23 -> 0 | AD23: =X23-AA23 -> 0 | AE23: =Y23-AB23 -> 0 | AH23: =+W23*AG23 -> 0
A24: =VLOOKUP(C24,Master!A:D,4,0) -> SF | B24: =VLOOKUP(C24,Master!A:C,3,0) -> Granuals | C24: RP Granuals | D24: 46952.75 | E24: 0 | F24: 0 | J24: 3000 | K24: 76000 | O24: 64525 | P24: 35477.75 | T24: 0 | U24: =O24-S24 -> 64525 | V24: =P24-T24 -> 35477.75 | W24: =D24+G24+H24+I24-K24-L24-M24-V24+U24 -> 0 | X24: =E24+J24-N24-T24+S24 -> 3000 | Y24: =F24-I24+M24-R24+Q24 -> 0 | Z24: 0 | AA24: 3000 | AB24: 0 | AC24: =W24-Z24 -> 0 | AD24: =X24-AA24 -> 0 | AE24: =Y24-AB24 -> 0 | AH24: =+W24*AG24 -> 0
A25: =VLOOKUP(C25,Master!A:D,4,0) -> SF | B25: =VLOOKUP(C25,Master!A:C,3,0) -> Liners | C25: Liner for Flexitank | D25: 0 | E25: 0 | F25: 0 | T25: 0 | U25: =O25-S25 -> 0 | V25: =P25-T25 -> 0 | W25: =D25+G25+H25+I25-K25-L25-M25-V25+U25 -> 0 | X25: =E25+J25-N25-T25+S25 -> 0 | Y25: =F25-I25+M25-R25+Q25 -> 0 | Z25: 0 | AA25: 0 | AB25: 0 | AC25: =W25-Z25 -> 0 | AD25: =X25-AA25 -> 0 | AE25: =Y25-AB25 -> 0 | AH25: =+W25*AG25 -> 0
A26: =VLOOKUP(C26,Master!A:D,4,0) -> SF | B26: =VLOOKUP(C26,Master!A:C,3,0) -> Webbing | C26: PP Webbing | D26: 0 | E26: 1656.1 | F26: 0 | J26: 81 | K26: 5343.8 | O26: 57195.2 | P26: 51851.4 | T26: 0 | U26: =O26-S26 -> 57195.2 | V26: =P26-T26 -> 51851.4 | W26: =D26+G26+H26+I26-K26-L26-M26-V26+U26 -> 0 | X26: =E26+J26-N26-T26+S26 -> 1737.1 | Y26: =F26-I26+M26-R26+Q26 -> 0 | Z26: 0 | AA26: 1737.1 | AB26: 0 | AC26: =W26-Z26 -> 0 | AD26: =X26-AA26 -> 0 | AE26: =Y26-AB26 -> 0 | AH26: =+W26*AG26 -> 0
A27: =VLOOKUP(C27,Master!A:D,4,0) -> SF | B27: =VLOOKUP(C27,Master!A:C,3,0) -> Liners | C27: LDPE/LLDPE Bags | D27: 0 | E27: 8281.3 | F27: 0 | J27: 39624.8 | P27: 8281.3 | T27: 8281.3 | U27: =O27-S27 -> 0 | V27: =P27-T27 -> 0 | W27: =D27+G27+H27+I27-K27-L27-M27-V27+U27 -> 0 | X27: =E27+J27-N27-T27+S27 -> 39624.8 | Y27: =F27-I27+M27-R27+Q27 -> 0 | Z27: 0 | AA27: 39624.8 | AB27: 0 | AC27: =W27-Z27 -> 0 | AD27: =X27-AA27 -> 0 | AE27: =Y27-AB27 -> 0 | AH27: =+W27*AG27 -> 0
A28: =VLOOKUP(C28,Master!A:D,4,0) -> SF | B28: =VLOOKUP(C28,Master!A:C,3,0) -> Tape Stock | C28: Beam Stock | D28: 0 | E28: 0 | F28: 0 | T28: 0 | U28: =O28-S28 -> 0 | V28: =P28-T28 -> 0 | W28: =D28+G28+H28+I28-K28-L28-M28-V28+U28 -> 0 | X28: =E28+J28-N28-T28+S28 -> 0 | Y28: =F28-I28+M28-R28+Q28 -> 0 | Z28: 0 | AA28: 0 | AB28: 0 | AC28: =W28-Z28 -> 0 | AD28: =X28-AA28 -> 0 | AE28: =Y28-AB28 -> 0 | AH28: =+W28*AG28 -> 0
A29: =VLOOKUP(C29,Master!A:D,4,0) -> SF | B29: =VLOOKUP(C29,Master!A:C,3,0) -> Tape Stock | C29: PP Tapes | D29: 0 | E29: 3243.2 | F29: 0 | J29: 8730.6 | O29: 193076 | P29: 196319.2 | T29: 3243.2 | U29: =O29-S29 -> 193076 | V29: =P29-T29 -> 193076 | W29: =D29+G29+H29+I29-K29-L29-M29-V29+U29 -> 0 | X29: =E29+J29-N29-T29+S29 -> 8730.6 | Y29: =F29-I29+M29-R29+Q29 -> 0 | Z29: 0 | AA29: 8730.6 | AB29: 0 | AC29: =W29-Z29 -> 0 | AD29: =X29-AA29 -> 0 | AE29: =Y29-AB29 -> 0 | AH29: =+W29*AG29 -> 0
A30: =VLOOKUP(C30,Master!A:D,4,0) -> SF | B30: =VLOOKUP(C30,Master!A:C,3,0) -> RP Agglo | C30: RP Agglo | D30: 0 | E30: 0 | F30: 0 | T30: 0 | U30: =O30-S30 -> 0 | V30: =P30-T30 -> 0 | W30: =D30+G30+H30+I30-K30-L30-M30-V30+U30 -> 0 | X30: =E30+J30-N30-T30+S30 -> 0 | Y30: =F30-I30+M30-R30+Q30 -> 0 | Z30: 0 | AA30: 0 | AB30: 0 | AC30: =W30-Z30 -> 0 | AD30: =X30-AA30 -> 0 | AE30: =Y30-AB30 -> 0 | AH30: =+W30*AG30 -> 0
A31: =VLOOKUP(C31,Master!A:D,4,0) -> SF | B31: =VLOOKUP(C31,Master!A:C,3,0) -> Wastage/Scrap | C31: Wastage/Scrap | D31: 17957.96 | E31: 0 | F31: 0 | H31: 20774 | K31: 16000 | N31: 20774 | O31: 39203 | P31: 11334.5 | S31: 20774 | T31: 0 | U31: =O31-S31 -> 18429 | V31: =P31-T31 -> 11334.5 | W31: =D31+G31+H31+I31-K31-L31-M31-V31+U31 -> 29826.46 | X31: =E31+J31-N31-T31+S31 -> 0 | Y31: =F31-I31+M31-R31+Q31 -> 0 | Z31: 29826.46 | AA31: 0 | AB31: 0 | AC31: =W31-Z31 -> 0 | AD31: =X31-AA31 -> 0 | AE31: =Y31-AB31 -> 0 | AG31: 60 | AH31: =+W31*AG31 -> 1789587.6
A32: =VLOOKUP(C32,Master!A:D,4,0) -> FG | B32: =VLOOKUP(C32,Master!A:C,3,0) -> FIBC WIP | C32: FIBC WIP | D32: 40457 | E32: 0 | F32: 0 | O32: 296532 | P32: 301629 | T32: 0 | U32: =O32-S32 -> 296532 | V32: =P32-T32 -> 301629 | W32: =D32+G32+H32+I32-K32-L32-M32-V32+U32 -> 35359.999 | X32: =E32+J32-N32-T32+S32 -> 0 | Y32: =F32-I32+M32-R32+Q32 -> 0 | Z32: 35359.999 | AA32: 0 | AB32: 0 | AC32: =W32-Z32 -> 0 | AD32: =X32-AA32 -> 0 | AE32: =Y32-AB32 -> 0 | AG32: 135 | AH32: =+W32*AG32 -> 4773599.8
A33: =VLOOKUP(C33,Master!A:D,4,0) -> FG | B33: =VLOOKUP(C33,Master!A:C,3,0) -> Label Div | C33: Label Div | D33: 0 | E33: 0 | F33: 0 | T33: 0 | U33: =O33-S33 -> 0 | V33: =P33-T33 -> 0 | W33: =D33+G33+H33+I33-K33-L33-M33-V33+U33 -> 0 | X33: =E33+J33-N33-T33+S33 -> 0 | Y33: =F33-I33+M33-R33+Q33 -> 0 | Z33: 0 | AA33: 0 | AB33: 0 | AC33: =W33-Z33 -> 0 | AD33: =X33-AA33 -> 0 | AE33: =Y33-AB33 -> 0 | AH33: =+W33*AG33 -> 0
A34: =VLOOKUP(C34,Master!A:D,4,0) -> FG | B34: =VLOOKUP(C34,Master!A:C,3,0) -> FIBC Bags | C34: FIBC Bags | D34: 0 | E34: 0 | F34: 0 | K34: 1900 | N34: 262003 | O34: 263903 | S34: 262003 | T34: 0 | U34: =O34-S34 -> 1900 | V34: =P34-T34 -> 0 | W34: =D34+G34+H34+I34-K34-L34-M34-V34+U34 -> 0 | X34: =E34+J34-N34-T34+S34 -> 0 | Y34: =F34-I34+M34-R34+Q34 -> 0 | Z34: 0 | AA34: 0 | AB34: 0 | AC34: =W34-Z34 -> 0 | AD34: =X34-AA34 -> 0 | AE34: =Y34-AB34 -> 0 | AH34: =+W34*AG34 -> 0
A35: =VLOOKUP(C35,Master!A:D,4,0) -> FG | B35: =VLOOKUP(C35,Master!A:C,3,0) -> Small Bags | C35: HDPE Bags | D35: 0 | E35: 0 | F35: 0 | T35: 0 | U35: =O35-S35 -> 0 | V35: =P35-T35 -> 0 | W35: =D35+G35+H35+I35-K35-L35-M35-V35+U35 -> 0 | X35: =E35+J35-N35-T35+S35 -> 0 | Y35: =F35-I35+M35-R35+Q35 -> 0 | Z35: 0 | AA35: 0 | AB35: 0 | AC35: =W35-Z35 -> 0 | AD35: =X35-AA35 -> 0 | AE35: =Y35-AB35 -> 0 | AH35: =+W35*AG35 -> 0
A36: =VLOOKUP(C36,Master!A:D,4,0) -> FG | B36: =VLOOKUP(C36,Master!A:C,3,0) -> Tarps | C36: Tarpauline | D36: 0 | E36: 0 | F36: 0 | T36: 0 | U36: =O36-S36 -> 0 | V36: =P36-T36 -> 0 | W36: =D36+G36+H36+I36-K36-L36-M36-V36+U36 -> 0 | X36: =E36+J36-N36-T36+S36 -> 0 | Y36: =F36-I36+M36-R36+Q36 -> 0 | Z36: 0 | AA36: 0 | AB36: 0 | AC36: =W36-Z36 -> 0 | AD36: =X36-AA36 -> 0 | AE36: =Y36-AB36 -> 0 | AH36: =+W36*AG36 -> 0
A37: =VLOOKUP(C37,Master!A:D,4,0) -> FG | B37: =VLOOKUP(C37,Master!A:C,3,0) -> Trading Items | C37: Trading Items | D37: 0 | E37: 0 | F37: 0 | T37: 0 | U37: =O37-S37 -> 0 | V37: =P37-T37 -> 0 | W37: =D37+G37+H37+I37-K37-L37-M37-V37+U37 -> 0 | X37: =E37+J37-N37-T37+S37 -> 0 | Y37: =F37-I37+M37-R37+Q37 -> 0 | Z37: 0 | AA37: 0 | AB37: 0 | AC37: =W37-Z37 -> 0 | AD37: =X37-AA37 -> 0 | AE37: =Y37-AB37 -> 0 | AH37: =+W37*AG37 -> 0
A38: =VLOOKUP(C38,Master!A:D,4,0) -> FG | B38: =VLOOKUP(C38,Master!A:C,3,0) -> Small Bags | C38: PP Bags | D38: 0 | E38: 0 | F38: 0 | T38: 0 | U38: =O38-S38 -> 0 | V38: =P38-T38 -> 0 | W38: =D38+G38+H38+I38-K38-L38-M38-V38+U38 -> 0 | X38: =E38+J38-N38-T38+S38 -> 0 | Y38: =F38-I38+M38-R38+Q38 -> 0 | Z38: 0 | AA38: 0 | AB38: 0 | AC38: =W38-Z38 -> 0 | AD38: =X38-AA38 -> 0 | AE38: =Y38-AB38 -> 0 | AH38: =+W38*AG38 -> 0
A39: =VLOOKUP(C39,Master!A:D,4,0) -> FG | B39: =VLOOKUP(C39,Master!A:C,3,0) -> Small Bags WIP | C39: Small Bags WIP | D39: 0 | E39: 0 | F39: 0 | T39: 0 | U39: =O39-S39 -> 0 | V39: =P39-T39 -> 0 | W39: =D39+G39+H39+I39-K39-L39-M39-V39+U39 -> 0 | X39: =E39+J39-N39-T39+S39 -> 0 | Y39: =F39-I39+M39-R39+Q39 -> 0 | Z39: 0 | AA39: 0 | AB39: 0 | AC39: =W39-Z39 -> 0 | AD39: =X39-AA39 -> 0 | AE39: =Y39-AB39 -> 0 | AH39: =+W39*AG39 -> 0
A40: =VLOOKUP(C40,Master!A:D,4,0) -> FG | B40: =VLOOKUP(C40,Master!A:C,3,0) -> Flexitank | C40: Flexitank | D40: 0 | E40: 0 | F40: 0 | T40: 0 | U40: =O40-S40 -> 0 | V40: =P40-T40 -> 0 | W40: =D40+G40+H40+I40-K40-L40-M40-V40+U40 -> 0 | X40: =E40+J40-N40-T40+S40 -> 0 | Y40: =F40-I40+M40-R40+Q40 -> 0 | Z40: 0 | AA40: 0 | AB40: 0 | AC40: =W40-Z40 -> 0 | AD40: =X40-AA40 -> 0 | AE40: =Y40-AB40 -> 0 | AH40: =+W40*AG40 -> 0
A41: Total | D41: =SUM(D4:D40) -> 130736.76 | E41: =SUM(E4:E40) -> 657884.24 | F41: =SUM(F4:F40) -> 0 | G41: =SUM(G4:G40) -> 0 | H41: =SUM(H4:H40) -> 136828.56 | I41: =SUM(I4:I40) -> 0 | J41: =SUM(J4:J40) -> 340521 | K41: =SUM(K4:K40) -> 126382.9 | ... AF41: =SUM(AF4:AF40) -> 0 | AH41: =SUM(AH4:AH40) -> 14919254
...

Sheet Sheet1
B2: Physical | F2: JOB Stock | H2: AS PER REPORT
A3: Details of Items / Products | B3: OEL-1 | C3: KPW-3
A4: Masterbatch | B4: 5172 | D4: =+B4+C4 -> 5172 | F4: 6325 | G4: =+D4-F4 -> -1153 | H4: 0
A5: PP Granuals | B5: 76937 | D5: =+B5+C5 -> 76937 | F5: =162178.34+4500 -> 166678.34 | G5: =+D5-F5 -> -89741.34 | H5: 0
A6: Filler | B6: 4613 | D6: =+B6+C6 -> 4613 | F6: 10202 | G6: =+D6-F6 -> -5589 | H6: 0
A7: PP Yarn | B7: 43813.92 | D7: =+B7+C7 -> 43813.92 | F7: 18694.3 | G7: =+D7-F7 -> 25119.62 | H7: 15119.28
A8: PP UL Fabric | B8: 65408 | D8: =+B8+C8 -> 65408 | F8: 11978.4 | G8: =+D8-F8 -> 53429.6 | H8: 13429.6
A9: PP Lam Fabric | B9: 78964 | D9: =+B9+C9 -> 78964 | F9: 22509 | G9: =+D9-F9 -> 56455 | H9: 26455
A10: RP Granuals | B10: 56144 | D10: =+B10+C10 -> 56144 | G10: =+D10-F10 -> 56144 | H10: 56144
A11: PP Webbing | B11: 28984 | D11: =+B11+C11 -> 28984 | F11: 5791.74 | G11: =+D11-F11 -> 23192.26 | H11: 16709.3
A12: LDPE/LLDPE Bags | B12: 7178.6 | D12: =+B12+C12 -> 7178.6 | F12: 7178.56 | G12: =+D12-F12 -> 0.04 | H12: 0
A13: PP Tapes | B13: 35300 | D13: =+B13+C13 -> 35300 | F13: 5595.4 | G13: =+D13-F13 -> 29704.6 | H13: 19704.6
A14: Wastage/Scrap | B14: 27372 | D14: =+B14+C14 -> 27372 | G14: =+D14-F14 -> 27372 | H14: 27372
A15: FIBC WIP | B15: 63870.5 | D15: =+B15+C15 -> 63870.5 | G15: =+D15-F15 -> 63870.5 | H15: 63870.5
A16: FIBC Bags | B16: =247069.9-C16-B17 -> 208673.9 | C16: 35271 | D16: =+B16+C16 -> 243944.9 | G16: =+D16-F16 -> 243944.9 | H16: 186365.57
A17: PP Bags | B17: 3125 | D17: =+B17+C17 -> 3125 | G17: =+D17-F17 -> 3125 | H17: 3125
G18: =+D18-F18 -> 0
A19: Total | B19: =SUM(B4:B18) -> 705555.92 | C19: =SUM(C4:C18) -> 35271 | D19: =SUM(D4:D18) -> 740826.92 | F19: =SUM(F4:F18) -> 254952.74 | G19: =SUM(G4:G18) -> 485874.18 | H19: =SUM(H4:H18) -> 428294.85

Sheet Sales 
A1: Row Labels | B1: Sum of Quantity | C1: Sum of Amount
A2: Jambo Bag/Fibc Bag Mfr (Kg) | B2: 4752 | C2: 1241120 | D2: =C2/B2 -> 261.17845
A3: PP Webbing | B3: 1566.9 | C3: 159824 | D3: =C3/B3 -> 102.00013
A4: PP Woven Fabric | B4: 76072.4 | C4: 10649973 | D4: =C4/B4 -> 139.99786
A5: Reprocessed Granules | B5: 69750 | C5: 3627000 | D5: =C5/B5 -> 52
A6: Other Scrap | B6: 15864.2 | C6: 15025 | D6: =C6/B6 -> 0.94710102
A7: Grand Total | B7: 168005.5 | C7: 15692942
A24: Date | B24: Particular | C24: Voucher Type | D24: Voucher No | E24: Type | F24: Invoice No | G24: Invoice Date | H24: Main Grp | I24: Group Name | J24: Sub Grup | K24: sales Group Name | L24: Item Name | M24: Quantity | N24: Amount | O24: Item Desc | P24: Bill Amount | Q24: CGST Rate | R24: CGST Amt | S24: SGST Rate | T24: SGST Amt | U24: IGST Rate | V24: IGST Amt | W24: Freight GST | X24: Total GST | Y24: TCS | Z24: GST-IN | AA24: Unit | AB24: HSN Code | AC24: Currencty | AD24: Exc.Rate | AE24: Net Wt
A25: 46060 | B25: Plastene India ltd - Unit 1-Sales | C25: Deemed Export | D25: OEL1/DE/051/26-27 | E25: Sales - Interstate - Manufactured Goods | F25: OEL1/DE/051/26-27 | G25: 46060 | H25: SF | I25: PP/PE Fabric | J25: PP UL Fabric | K25: PP Woven Fabric | L25: PP UL Fabric With UV | M25: 2670 | N25: 373789 | O25: PP WOVEN FABRICS | P25: 373415.21 | Q25: 0 | R25: 0 | S25: 0 | T25: 0 | U25: 0 | V25: 0 | W25: 0 | X25: 0 | Y25: 0 | Z25: 24AAACO3087C1ZT | AA25: KGS | AB25: 39269080 | AC25: Rs. | AD25: 1 | AE25: 2670 | AF25: India
A26: 46088 | B26: Plastene India ltd - Unit 1-Sales | C26: Deemed Export | D26: OEL1/DE/052/26-27 | E26: Sales - Interstate - Manufactured Goods | F26: OEL1/DE/052/26-27 | G26: 46088 | H26: SF | I26: PP/PE Fabric | J26: PP UL Fabric | K26: PP Woven Fabric | L26: PP UL Fabric With UV | M26: 2543 | N26: 356009 | O26: PP WOVEN FABRICS | P26: 355652.99 | Q26: 0 | R26: 0 | S26: 0 | T26: 0 | U26: 0 | V26: 0 | W26: 0 | X26: 0 | Y26: 0 | Z26: 24AAACO3087C1ZT | AA26: KGS | AB26: 392690 | AC26: Rs. | AD26: 1 | AE26: 2543 | AF26: India
A27: 46180 | B27: Plastene India ltd - Unit 1-Sales | C27: Deemed Export | D27: OEL1/DE/053/26-27 | E27: Sales - Interstate - Manufactured Goods | F27: OEL1/DE/053/26-27 | G27: 46180 | H27: SF | I27: PP/PE Fabric | J27: PP UL Fabric | K27: PP Woven Fabric | L27: PP UL Fabric With UV | M27: 6681 | N27: 935311 | O27: PP WOVEN FABRICS | P27: 934375.69 | Q27: 0 | R27: 0 | S27: 0 | T27: 0 | U27: 0 | V27: 0 | W27: 0 | X27: 0 | Y27: 0 | Z27: 24AAACO3087C1ZT | AA27: KGS | AB27: 39269080 | AC27: Rs. | AD27: 1 | AE27: 6681 | AF27: India
A28: 46241 | B28: Plastene India ltd - Unit 1-Sales | C28: Domestic Sales | D28: OEL/DTA/019/26-27 | E28: Sales - Waste & Scrape | F28: OEL/DTA/019/26-27 | G28: 46241 | H28: Other Scrap | I28: Wastage/Scrap | J28: Misc | K28: Other Scrap | L28: MS/Other Scrap | M28: 3040 | N28: 1520 | O28: OTHER SCRAPS | P28: 1560 | Q28: 0 | R28: 0 | S28: 0 | T28: 0 | U28: 0 | V28: 0 | W28: 0 | X28: 0 | Y28: 39.82 | Z28: 24AAACO3087C1ZT | AA28: KGS | AB28: 68114010 | AC28: Rs. | AD28: 1 | AE28: 3040 | AF28: India
A29: 46241 | B29: Plastene India ltd - Unit 1-Sales | C29: Deemed Export | D29: OEL1/DE/054/26-27 | E29: Sales - Interstate - Manufactured Goods | F29: OEL1/DE/054/26-27 | G29: 46241 | H29: SF | I29: PP/PE Fabric | J29: PP UL Fabric | K29: PP Woven Fabric | L29: PP UL Fabric With UV | M29: 4172 | N29: 584062 | O29: PP WOVEN FABRICS | P29: 583477.94 | Q29: 0 | R29: 0 | S29: 0 | T29: 0 | U29: 0 | V29: 0 | W29: 0 | X29: 0 | Y29: 0 | Z29: 24AAACO3087C1ZT | AA29: KGS | AB29: 39269080 | AC29: Rs. | AD29: 1 | AE29: 4172 | AF29: India
A30: 46272 | B30: Plastene India ltd - Unit 1-Sales | C30: Domestic Sales | D30: OEL/DTA/020/26-27 | E30: Sales - Interstate - Manufactured Goods | F30: OEL/DTA/020/26-27 | G30: 46272 | H30: SF | I30: RP Granules | J30: RP Granules | K30: Reprocessed Granules | L30: RP Granules | M30: 15000 | N30: 780000 | O30: RP GRANULES | P30: 779220 | Q30: 0 | R30: 0 | S30: 0 | T30: 0 | U30: 0 | V30: 0 | W30: 0 | X30: 0 | Y30: 0 | Z30: 24AAACO3087C1ZT | AA30: KGS | AB30: 39021000 | AC30: Rs. | AD30: 1 | AE30: 15000 | AF30: India
A31: 46272 | B31: Plastene India ltd - Unit 1-Sales | C31: Deemed Export | D31: OEL1/DE/055/26-27 | E31: Sales - Interstate - Manufactured Goods | F31: OEL1/DE/055/26-27 | G31: 46272 | H31: SF | I31: PP/PE Fabric | J31: PP UL Fabric | K31: PP Woven Fabric | L31: PP UL Fabric With UV | M31: 646 | N31: 90437 | O31: PP WOVEN FABRICS | P31: 90346.56 | Q31: 0 | R31: 0 | S31: 0 | T31: 0 | U31: 0 | V31: 0 | W31: 0 | X31: 0 | Y31: 0 | Z31: 24AAACO3087C1ZT | AA31: KGS | AB31: 39269080 | AC31: Rs. | AD31: 1 | AE31: 646 | AF31: India
A32: 46302 | B32: Gokul Overseas | C32: Deemed Export | D32: OEL/IZS/26-27/007 | E32: Sales - Kasez - Mfg - U/B | F32: OEL/IZS/26-27/007 | G32: 46302 | H32: FG | I32: FIBC Bags | J32: FIBC Bags | K32: Jambo Bag/Fibc Bag Mfr (Kg) | L32: FIBC Bags With UV With Liner | M32: 226 | N32: 69200 | O32: PP WOVEN BIG BAGS | P32: 69200 | Q32: 0 | R32: 0 | S32: 0 | T32: 0 | U32: 0 | V32: 0 | W32: 0 | X32: 0 | Y32: 0 | Z32: 24AACFG9539L2Z0 | AA32: KGS | AB32: 63053200 | AC32: Rs. | AD32: 1 | AE32: 226 | AF32: India
A33: 46302 | B33: Plastene India ltd - Unit 1-Sales | C33: Domestic Sales | D33: OEL/DTA/021/26-27 | E33: Sales - Interstate - Manufactured Goods | F33: OEL/DTA/021/26-27 | G33: 46302 | H33: SF | I33: RP Granules | J33: RP Granules | K33: Reprocessed Granules | L33: RP Granules | M33: 22500 | N33: 1170000 | O33: RP GRANULES | P33: 1168830 | Q33: 0 | R33: 0 | S33: 0 | T33: 0 | U33: 0 | V33: 0 | W33: 0 | X33: 0 | Y33: 0 | Z33: 24AAACO3087C1ZT | AA33: KGS | AB33: 39029080 | AC33: Rs. | AD33: 1 | AE33: 22500 | AF33: India
A34: 46302 | B34: Plastene India ltd - Unit 1-Sales | C34: Domestic Sales | D34: OEL/DTA/022/26-27 | E34: Sales - Interstate - Manufactured Goods | F34: OEL/DTA/022/26-27 | G34: 46302 | H34: SF | I34: RP Granules | J34: RP Granules | K34: Reprocessed Granules | L34: RP Granules | M34: 2250 | N34: 117000 | O34: RP GRANULES | P34: 116883 | Q34: 0 | R34: 0 | S34: 0 | T34: 0 | U34: 0 | V34: 0 | W34: 0 | X34: 0 | Y34: 0 | Z34: 24AAACO3087C1ZT | AA34: KGS | AB34: 39011090 | AC34: Rs. | AD34: 1 | AE34: 2250 | AF34: India
A35: 46333 | B35: Plastene India ltd - Unit 1-Sales | C35: Deemed Export | D35: OEL1/DE/056/26-27 | E35: Sales - Interstate - Manufactured Goods | F35: OEL1/DE/056/26-27 | G35: 46333 | H35: SF | I35: PP/PE Fabric | J35: PP UL Fabric | K35: PP Woven Fabric | L35: PP UL Fabric With UV | M35: 4518 | N35: 632501 | O35: PP WOVEN FABRICS | P35: 631868.5 | Q35: 0 | R35: 0 | S35: 0 | T35: 0 | U35: 0 | V35: 0 | W35: 0 | X35: 0 | Y35: 0 | Z35: 24AAACO3087C1ZT | AA35: KGS | AB35: 39269080 | AC35: Rs. | AD35: 1 | AE35: 4518 | AF35: India
A36: 14-07-2026 | B36: Plastene India ltd - Unit 1-Sales | C36: Deemed Export | D36: OEL1/DE/057/26-27 | E36: Sales - Interstate - Manufactured Goods | F36: OEL1/DE/057/26-27 | G36: 14-07-2026 | H36: SF | I36: PP/PE Fabric | J36: PP UL Fabric | K36: PP Woven Fabric | L36: PP UL Fabric With UV | M36: 5080 | N36: 711178 | O36: PP WOVEN FABRICS | P36: 710466.82 | Q36: 0 | R36: 0 | S36: 0 | T36: 0 | U36: 0 | V36: 0 | W36: 0 | X36: 0 | Y36: 0 | Z36: 24AAACO3087C1ZT | AA36: KGS | AB36: 39269080 | AC36: Rs. | AD36: 1 | AE36: 5080 | AF36: India
A37: 16-07-2026 | B37: Plastene India ltd - Unit 1-Sales | C37: Deemed Export | D37: OEL1/DE/058/26-27 | E37: Sales - Interstate - Manufactured Goods | F37: OEL1/DE/058/26-27 | G37: 16-07-2026 | H37: SF | I37: PP/PE Fabric | J37: PP UL Fabric | K37: PP Woven Fabric | L37: PP UL Fabric With UV | M37: 2434 | N37: 340750 | O37: PP WOVEN FABRICS | P37: 340409.25 | Q37: 0 | R37: 0 | S37: 0 | T37: 0 | U37: 0 | V37: 0 | W37: 0 | X37: 0 | Y37: 0 | Z37: 24AAACO3087C1ZT | AA37: KGS | AB37: 39269080 | AC37: Rs. | AD37: 1 | AE37: 2434 | AF37: India
A38: 17-07-2026 | B38: Plastene India ltd - Unit 1-Sales | C38: Deemed Export | D38: OEL1/DE/059/26-27 | E38: Sales - Interstate - Manufactured Goods | F38: OEL1/DE/059/26-27 | G38: 17-07-2026 | H38: SF | I38: PP/PE Fabric | J38: PP UL Fabric | K38: PP Woven Fabric | L38: PP UL Fabric With UV | M38: 5328 | N38: 745897 | O38: PP WOVEN FABRICS | P38: 745151.1 | Q38: 0 | R38: 0 | S38: 0 | T38: 0 | U38: 0 | V38: 0 | W38: 0 | X38: 0 | Y38: 0 | Z38: 24AAACO3087C1ZT | AA38: KGS | AB38: 39269080 | AC38: Rs. | AD38: 1 | AE38: 5328 | AF38: India
A39: 17-07-2026 | B39: Plastene India ltd - Unit 1-Sales | C39: Deemed Export | D39: OEL1/DE/060/26-27 | E39: Sales - Interstate - Manufactured Goods | F39: OEL1/DE/060/26-27 | G39: 17-07-2026 | H39: SF | I39: Webbing | J39: PP Webbing | K39: PP Webbing | L39: Webbing | M39: 553.4 | N39: 56447 | O39: PP WEBBING | P39: 56390.55 | Q39: 0 | R39: 0 | S39: 0 | T39: 0 | U39: 0 | V39: 0 | W39: 0 | X39: 0 | Y39: 0 | Z39: 24AAACO3087C1ZT | AA39: KGS | AB39: 39269080 | AC39: Rs. | AD39: 1 | AE39: 553.4 | AF39: India
A40: 18-07-2026 | B40: Plastene India ltd - Unit 1-Sales | C40: Deemed Export | D40: OEL/DTA/023/26-27 | E40: Sales - Interstate - Manufactured Goods | F40: OEL/DTA/023/26-27 | G40: 18-07-2026 | H40: SF | I40: RP Granules | J40: RP Granules | K40: Reprocessed Granules | L40: RP Granules | M40: 30000 | N40: 1560000 | O40: RP GRNULES | P40: 1558440 | Q40: 0 | R40: 0 | S40: 0 | T40: 0 | U40: 0 | V40: 0 | W40: 0 | X40: 0 | Y40: 0 | Z40: 24AAACO3087C1ZT | AA40: KGS | AB40: 39021000 | AC40: Rs. | AD40: 1 | AE40: 30000 | AF40: India
A41: 20-07-2026 | B41: Plastene India ltd - Unit 1-Sales | C41: Domestic Sales | D41: OEL/DTA/024/26-27 | E41: Sales - Waste & Scrape | F41: OEL/DTA/024/26-27 | G41: 20-07-2026 | H41: Other Scrap | I41: Wastage/Scrap | J41: Misc | K41: Other Scrap | L41: MS/Other Scrap | M41: 14.2 | N41: 7100 | O41: OTHER SCRAPS | P41: 7286 | Q41: 0 | R41: 0 | S41: 0 | T41: 0 | U41: 0 | V41: 0 | W41: 0 | X41: 0 | Y41: 185.99 | Z41: 24AAACO3087C1ZT | AA41: KGS | AB41: 68114010 | AC41: Rs. | AD41: 1 | AE41: 14.2 | AF41: India
A42: 20-07-2026 | B42: Plastene India ltd - Unit 1-Sales | C42: Deemed Export | D42: OEL1/DE/061/26-27 | E42: Sales - Interstate - Manufactured Goods | F42: OEL1/DE/061/26-27 | G42: 20-07-2026 | H42: SF | I42: PP/PE Fabric | J42: PP UL Fabric | K42: PP Woven Fabric | L42: PP UL Fabric With UV | M42: 4542 | N42: 635860 | O42: PP WOVEN FABRICS | P42: 635224.14 | Q42: 0 | R42: 0 | S42: 0 | T42: 0 | U42: 0 | V42: 0 | W42: 0 | X42: 0 | Y42: 0 | Z42: 24AAACO3087C1ZT | AA42: KGS | AB42: 39269080 | AC42: Rs. | AD42: 1 | AE42: 4542 | AF42: India
A43: 20-07-2026 | B43: Plastene India ltd - Unit 1-Sales | C43: Deemed Export | D43: OEL1/DE/062/26-27 | E43: Sales - Interstate - Manufactured Goods | F43: OEL1/DE/062/26-27 | G43: 20-07-2026 | H43: SF | I43: Webbing | J43: PP Webbing | K43: PP Webbing | L43: Webbing | M43: 519.5 | N43: 52989 | O43: PP WEBBING | P43: 52936.01 | Q43: 0 | R43: 0 | S43: 0 | T43: 0 | U43: 0 | V43: 0 | W43: 0 | X43: 0 | Y43: 0 | Z43: 24AAACO3087C1ZT | AA43: KGS | AB43: 39269080 | AC43: Rs. | AD43: 1 | AE43: 519.5 | AF43: India
A44: 22-07-2026 | B44: Plastene India ltd - Unit 1-Sales | C44: Deemed Export | D44: OEL1/DE/063/26-27 | E44: Sales - Interstate - Manufactured Goods | F44: OEL1/DE/063/26-27 | G44: 22-07-2026 | H44: SF | I44: PP/PE Fabric | J44: PP UL Fabric | K44: PP Woven Fabric | L44: PP UL Fabric With UV | M44: 7157 | N44: 1001981 | O44: PP WOVEN FABRICS | P44: 1000979 | Q44: 0 | R44: 0 | S44: 0 | T44: 0 | U44: 0 | V44: 0 | W44: 0 | X44: 0 | Y44: 0 | Z44: 24AAACO3087C1ZT | AA44: KGS | AB44: 39269080 | AC44: Rs. | AD44: 1 | AE44: 7157 | AF44: India
A45: 22-07-2026 | B45: Plastene India ltd - Unit 1-Sales | C45: Deemed Export | D45: OEL1/DE/064/26-27 | E45: Sales - Interstate - Manufactured Goods | F45: OEL1/DE/064/26-27 | G45: 22-07-2026 | H45: SF | I45: Webbing | J45: PP Webbing | K45: PP Webbing | L45: Webbing | M45: 494 | N45: 50388 | O45: PP WEBBING | P45: 50337.61 | Q45: 0 | R45: 0 | S45: 0 | T45: 0 | U45: 0 | V45: 0 | W45: 0 | X45: 0 | Y45: 0 | Z45: 24AAACO3087C1ZT | AA45: KGS | AB45: 39269080 | AC45: Rs. | AD45: 1 | AE45: 494 | AF45: India
A46: 23-07-2026 | B46: Plastene India ltd - Unit 1-Sales | C46: Deemed Export | D46: OEL1/DE/065/26-27 | E46: Sales - Interstate - Manufactured Goods | F46: OEL1/DE/065/26-27 | G46: 23-07-2026 | H46: SF | I46: PP/PE Fabric | J46: PP UL Fabric | K46: PP Woven Fabric | L46: PP UL Fabric With UV | M46: 3223 | N46: 451220 | O46: PP WOVEN FABRICS | P46: 450768.78 | Q46: 0 | R46: 0 | S46: 0 | T46: 0 | U46: 0 | V46: 0 | W46: 0 | X46: 0 | Y46: 0 | Z46: 24AAACO3087C1ZT | AA46: KGS | AB46: 39269080 | AC46: Rs. | AD46: 1 | AE46: 3223 | AF46: India
A47: 24-07-2026 | B47: OCCL Limited | C47: Deemed Export | D47: OEL/IZS/26-27/008 | E47: Sales - Kasez - Mfg - U/B | F47: OEL/IZS/26-27/008 | G47: 24-07-2026 | H47: FG | I47: FIBC Bags | J47: FIBC Bags | K47: Jambo Bag/Fibc Bag Mfr (Kg) | L47: FIBC Bags With UV With Liner | M47: 4300 | N47: 1102720 | O47: FIBC JUMBO BAG | P47: 1102720 | Q47: 0 | R47: 0 | S47: 0 | T47: 0 | U47: 0 | V47: 0 | W47: 0 | X47: 0 | Y47: 0 | Z47: 24AADCO7609P2ZY | AA47: KGS | AB47: 63053200 | AC47: Rs. | AD47: 1 | AE47: 4300 | AF47: India
... A53: 31-07-2026 | B53: Plastene India ltd - Unit 1-Sales | C53: Deemed Export | D53: OEL1/DE/069/26-27 | E53: Sales - Interstate - Manufactured Goods | F53: OEL1/DE/069/26-27 | G53: 31-07-2026 | H53: SF | I53: PP/PE Fabric | J53: PP UL Fabric | K53: PP Woven Fabric | L53: PP UL Fabric With UV | M53: 9851.4 | N53: 1379197 | O53: PP WOVEN FABRICS | P53: 1377817.8 | Q53: 0 | R53: 0 | S53: 0 | T53: 0 | U53: 0 | V53: 0 | W53: 0 | X53: 0 | Y53: 0 | Z53: 24AAACO3087C1ZT | AA53: KGS | AB53: 39269080 | AC53: Rs. | AD53: 1 | AE53: 9851.4 | AF53: India

Sheet Purchase
A1: Row Labels | B1: Sum of Acceptedqty | C1: Sum of Basic Amount
A2: PP Granules | B2: 182900 | C2: 21226637 | D2: =C2/B2 -> 116.05597
A3: PP MF Yarn Twisted | B3: 12102.53 | C3: 1466330 | D3: =C3/B3 -> 121.15896
A4: PP/HD Wastage/Scrap | B4: 10643 | C4: 106430 | D4: =C4/B4 -> 10
A5: MB Karnavati Polyplast Blue | B5: 925 | C5: 175875 | D5: =C5/B5 -> 190.13514
A6: PP Woven Fabric | B6: 3006.7 | C6: 485155 | D6: =C6/B6 -> 161.35797
A7: LDPE/LLDPE Bags/Liner | B7: 136 | C7: 36856 | D7: =C7/B7 -> 271
A8: LDPE Granuals | B8: 1000 | C8: 145000 | D8: =C8/B8 -> 145
A9: Grand Total | B9: 210713.23 | C9: 23642283
B27: CompanyName | C27: Date | D27: srno | E27: Itemcode | F27: Itemname | G27: Indentsubcode | H27: PoNO | I27: OrderQty | J27: Challanqty | K27: Unit | L27: Recdqty | M27: PendingQty | N27: Acceptedqty | O27: Vehicalno | P27: Partyname | Q27: Suppliername | R27: ChallanNo | S27: Challan Date | T27: category | U27: subcategory | V27: MRno | W27: Rate | X27: Amount | Y27: BillNo | Z27: Bill Date | AA27: ItemRemarks | AB27: Remarks | AC27: Note | AD27: Transportname | AE27: Lrnodate | AF27: Discamt | AG27: Discamt1 | AH27: ExciseAmount | AI27: EducessAmount | AJ27: HiEducessamount | AK27: InwardVatType | AL27: Vatamount | AM27: Addvatamount | AN27: Frieght | AO27: Pkgfwd | AP27: Otherchg | AQ27: Spdutyname | AR27: Spdutyamt | AS27: Additionalduty | AT27: Billamount | AU27: Deptt | AV27: GroupName | AW27: SubGroupName | AX27: Deptt Po Indent | AY27: LoginName | AZ27: servicetax | BA27: Basic Amount | BB27: GateInwardNo | BC27: GateInwardDate | BD27: VendorGST | BE27: MRN User | BF27: POUserName | BG27: CGSTPer | BH27: CGSTAmount | BI27: SGSTPer | BJ27: SGSTAmount | BK27: IGSTPer | BL27: IGSTAmount | BM27: RBIllmount | BN27: EWayNo | BO27: EWayDt | BP27: netwt
B28: Oswal Extrusion Limited | C28: 46060 | D28: OEL/26-27/SII00487 | E28: WIP00022 | F28: PP MF Yarn Twisted | H28: OEL/RAW/26-27/17 | I28: 6000 | J28: 6000 | K28: Kgs | L28: 6000 | M28: 0 | N28: 6000 | O28: GJ12BZ8686 | P28: Plastene India ltd - Unit 2-Purchase | Q28: Plastene India ltd - Unit 2-Purchase | R28: PIL2/E/79 | S28: 46029 | T28: RAW MATERIAL | U28: INDIGENOUS | V28: RM 13 | W28: 120.1 | X28: 120.1 | Y28: PIL2/E/79 | Z28: 46029 | AD28: PARTY SELF | AE28: - | AF28: 0 | AG28: 0 | AH28: 0 | AI28: 0 | AJ28: 0 | AK28: VAT | AL28: 0 | AM28: 0 | AN28: 0 | AO28: 0 | AP28: 0 | AR28: 0 | AS28: 0 | AT28: 720600 | AU28: SF | AV28: Yarn All | AW28: PP Yarn | AX28: RM | AY28: erp | AZ28: 0 | BA28: 720600 | BB28: 524 | BC28: 46060 | BD28: 24AAACO3087C1ZT | BE28: bharatd | BF28: bharatd | BG28: 0 | BH28: 0 | BI28: 0 | BJ28: 0 | BK28: 0 | BL28: 0 | BM28: 720600 | BN28: 682138252973 | BO28: 46204 | BP28: 0
B29: Oswal Extrusion Limited | C29: 46241 | D29: OEL/26-27/SII00519 | E29: FIB10766 | F29: PP Woven Fabric | G29: OEL/26-27/STR00097/01 | H29: OEL/RAW/26-27/10 | I29: 2000 | J29: 2000.1 | K29: Kgs | L29: 2000.1 | M29: -0.1 | N29: 2000.1 | O29: RJ47GA4382 | P29: Dynamic Wooltex | Q29: Dynamic Wooltex | R29: 13526 | S29: 46029 | T29: RAW MATERIAL | U29: INDIGENOUS | V29: RM 14 | W29: 150 | X29: 160.99945 | Y29: 13526 | Z29: 46029 | AD29: PARTY SELF | AE29: - | AF29: 0 | AG29: 0 | AH29: 0 | AI29: 0 | AJ29: 0 | AK29: VAT | AL29: 0 | AM29: 0 | AN29: 22000 | AO29: 0 | AP29: 0 | AR29: 0 | AS29: 0 | AT29: 322015 | AU29: RM | AV29: FIBC Accessories | AW29: FIBC Accessories | AX29: Consumables | AY29: erp | AZ29: 0 | BA29: 322015 | BB29: 555 | BC29: 46210 | BD29: 08ABFPB2251A1ZI | BE29: bharatd | BF29: shyam | BG29: 0 | BH29: 0 | BI29: 0 | BJ29: 0 | BK29: 0 | BL29: 0 | BM29: 322015 | BN29: 721647716182 | BO29: 46204 | BP29: 2000.1
B30: Oswal Extrusion Limited | C30: 14-07-2026 | D30: OEL/26-27/SII00554 | E30: RAW05065 | F30: MB Karnavati Polyplast Blue | H30: OEL/RAW/26-27/18 | I30: 50 | J30: 50 | K30: Kgs | L30: 50 | M30: 0 | N30: 50 | O30: GJ12BY1595 | P30: Plastene India ltd - Unit 1-Purchase | Q30: Plastene India ltd - Unit 1-Purchase | R30: PIL1/E/367 | S30: 46363 | T30: RAW MATERIAL | U30: INDIGENOUS | V30: RM 17 | W30: 216 | X30: 216 | Y30: PIL1/E/367 | Z30: 46363 | AD30: - | AE30: - | AF30: 0 | AG30: 0 | AH30: 0 | AI30: 0 | AJ30: 0 | AK30: VAT | AL30: 0 | AM30: 0 | AN30: 0 | AO30: 0 | AP30: 0 | AR30: 0 | AS30: 0 | AT30: 660474 | AU30: RM | AV30: Granules | AW30: Masterbatch | AX30: RM | AY30: erp | AZ30: 0 | BA30: 10800 | BB30: 591 | BC30: 13-07-2026 | BD30: 24AAACO3087C1ZT | BE30: bharatd | BF30: bharatd | BG30: 0 | BH30: 0 | BI30: 0 | BJ30: 0 | BK30: 0 | BL30: 0 | BM30: 660474 | BN30: 642143935223 | BO30: 46215 | BP30: 50
B31: Oswal Extrusion Limited | C31: 14-07-2026 | D31: OEL/26-27/SII00554 | E31: RAW05067 | F31: MB Karnavati Polyplast Blue | H31: OEL/RAW/26-27/18 | I31: 50 | J31: 50 | K31: Kgs | L31: 50 | M31: 0 | N31: 50 | O31: GJ12BY1595 | P31: Plastene India ltd - Unit 1-Purchase | Q31: Plastene India ltd - Unit 1-Purchase | R31: PIL1/E/367 | S31: 46363 | T31: RAW MATERIAL | U31: INDIGENOUS | V31: RM 17 | W31: 236 | X31: 236 | Y31: PIL1/E/367 | Z31: 46363 | AD31: - | AE31: - | AF31: 0 | AG31: 0 | AH31: 0 | AI31: 0 | AJ31: 0 | AK31: VAT | AL31: 0 | AM31: 0 | AN31: 0 | AO31: 0 | AP31: 0 | AR31: 0 | AS31: 0 | AT31: 660474 | AU31: RM | AV31: Granules | AW31: Masterbatch | AX31: RM | AY31: erp | AZ31: 0 | BA31: 11800 | BB31: 591 | BC31: 13-07-2026 | BD31: 24AAACO3087C1ZT | BE31: bharatd | BF31: bharatd | BG31: 0 | BH31: 0 | BI31: 0 | BJ31: 0 | BK31: 0 | BL31: 0 | BM31: 0 | BN31: 642143935223 | BO31: 46215 | BP31: 50
B32: Oswal Extrusion Limited | C32: 14-07-2026 | D32: OEL/26-27/SII00554 | E32: RAW05075 | F32: MB Karnavati Polyplast Blue | H32: OEL/RAW/26-27/18 | I32: 200 | J32: 200 | K32: Kgs | L32: 200 | M32: 0 | N32: 200 | O32: GJ12BY1595 | P32: Plastene India ltd - Unit 1-Purchase | Q32: Plastene India ltd - Unit 1-Purchase | R32: PIL1/E/367 | S32: 46363 | T32: RAW MATERIAL | U32: INDIGENOUS | V32: RM 17 | W32: 264 | X32: 264 | Y32: PIL1/E/367 | Z32: 46363 | AD32: - | AE32: - | AF32: 0 | AG32: 0 | AH32: 0 | AI32: 0 | AJ32: 0 | AK32: VAT | AL32: 0 | AM32: 0 | AN32: 0 | AO32: 0 | AP32: 0 | AR32: 0 | AS32: 0 | AT32: 660474 | AU32: RM | AV32: Granules | AW32: Masterbatch | AX32: RM | AY32: erp | AZ32: 0 | BA32: 52800 | BB32: 591 | BC32: 13-07-2026 | BD32: 24AAACO3087C1ZT | BE32: bharatd | BF32: bharatd | BG32: 0 | BH32: 0 | BI32: 0 | BJ32: 0 | BK32: 0 | BL32: 0 | BM32: 0 | BN32: 642143935223 | BO32: 46215 | BP32: 200
B33: Oswal Extrusion Limited | C33: 14-07-2026 | D33: OEL/26-27/SII00554 | E33: RAW06258 | F33: PP Granules | H33: OEL/RAW/26-27/18 | I33: 4000 | J33: 4000 | K33: Kgs | L33: 4000 | M33: 0 | N33: 4000 | O33: GJ12BY1595 | P33: Plastene India ltd - Unit 1-Purchase | Q33: Plastene India ltd - Unit 1-Purchase | R33: PIL1/E/367 | S33: 46363 | T33: RAW MATERIAL | U33: INDIGENOUS | V33: RM 17 | W33: 136.331 | X33: 136.331 | Y33: PIL1/E/367 | Z33: 46363 | AD33: - | AE33: - | AF33: 0 | AG33: 0 | AH33: 0 | AI33: 0 | AJ33: 0 | AK33: VAT | AL33: 0 | AM33: 0 | AN33: 0 | AO33: 0 | AP33: 0 | AR33: 0 | AS33: 0 | AT33: 660474 | AU33: RM | AV33: Granules | AW33: PP Granules | AX33: RM | AY33: mani | AZ33: 0 | BA33: 545324 | BB33: 591 | BC33: 13-07-2026 | BD33: 24AAACO3087C1ZT | BE33: bharatd | BF33: bharatd | BG33: 0 | BH33: 0 | BI33: 0 | BJ33: 0 | BK33: 0 | BL33: 0 | BM33: 0 | BN33: 642143935223 | BO33: 46215 | BP33: 4000
B34: Oswal Extrusion Limited | C34: 14-07-2026 | D34: OEL/26-27/SII00554 | E34: RAW06279 | F34: MB Karnavati Polyplast Blue | H34: OEL/RAW/26-27/18 | I34: 250 | J34: 250 | K34: Kgs | L34: 250 | M34: 0 | N34: 250 | O34: GJ12BY1595 | P34: Plastene India ltd - Unit 1-Purchase | Q34: Plastene India ltd - Unit 1-Purchase | R34: PIL1/E/367 | S34: 46363 | T34: RAW MATERIAL | U34: INDIGENOUS | V34: RM 17 | W34: 159 | X34: 159 | Y34: PIL1/E/367 | Z34: 46363 | AD34: - | AE34: - | AF34: 0 | AG34: 0 | AH34: 0 | AI34: 0 | AJ34: 0 | AK34: VAT | AL34: 0 | AM34: 0 | AN34: 0 | AO34: 0 | AP34: 0 | AR34: 0 | AS34: 0 | AT34: 660474 | AU34: RM | AV34: Granules | AW34: Masterbatch | AX34: RM | AZ34: 0 | BA34: 39750 | BB34: 591 | BC34: 13-07-2026 | BD34: 24AAACO3087C1ZT | BE34: bharatd | BF34: bharatd | BG34: 0 | BH34: 0 | BI34: 0 | BJ34: 0 | BK34: 0 | BL34: 0 | BM34: 0 | BN34: 642143935223 | BO34: 46215 | BP34: 250
B35: Oswal Extrusion Limited | C35: 14-07-2026 | D35: OEL/26-27/SII00555 | E35: RAW06223 | F35: PP Granules | H35: OEL/RAW/26-27/18 | I35: 14000 | J35: 14000 | K35: Kgs | L35: 14000 | M35: 0 | N35: 14000 | O35: GJ12BY1595 | P35: Plastene India ltd - Unit 1-Purchase | Q35: Plastene India ltd - Unit 1-Purchase | R35: PIL1/E/372 | S35: 46363 | T35: RAW MATERIAL | U35: INDIGENOUS | V35: RM 18 | W35: 115 | X35: 115 | Y35: PIL1/E/372 | Z35: 46363 | AD35: - | AE35: - | AF35: 0 | AG35: 0 | AH35: 0 | AI35: 0 | AJ35: 0 | AK35: VAT | AL35: 0 | AM35: 0 | AN35: 0 | AO35: 0 | AP35: 0 | AR35: 0 | AS35: 0 | AT35: 1610000 | AU35: RM | AV35: Granules | AW35: PP Granules | AX35: RM | AY35: mani | AZ35: 0 | BA35: 1610000 | BB35: 597 | BC35: 13-07-2026 | BD35: 24AAACO3087C1ZT | BE35: bharatd | BF35: bharatd | BG35: 0 | BH35: 0 | BI35: 0 | BJ35: 0 | BK35: 0 | BL35: 0 | BM35: 1610000 | BN35: 602144460805 | BO35: 46215 | BP35: 14000
B36: Oswal Extrusion Limited | C36: 15-07-2026 | D36: OEL/26-27/SII00558 | E36: RAW06348 | F36: PP Granules | H36: OEL/RAW/26-27/19 | I36: 15500 | J36: 15500 | K36: Kgs | L36: 15500 | M36: 0 | N36: 15500 | O36: GJ14Z0334 | P36: Plastene India ltd - Unit 1-Purchase | Q36: Plastene India ltd - Unit 1-Purchase | R36: PIL1/E/375 | S36: 14-07-2026 | T36: RAW MATERIAL | U36: INDIGENOUS | V36: RM 19 | W36: 82.8 | X36: 82.8 | Y36: PIL1/E/375 | Z36: 14-07-2026 | AD36: - | AE36: - | AF36: 0 | AG36: 0 | AH36: 0 | AI36: 0 | AJ36: 0 | AK36: VAT | AL36: 0 | AM36: 0 | AN36: 0 | AO36: 0 | AP36: 0 | AR36: 0 | AS36: 0 | AT36: 1896200 | AU36: RM | AV36: Granules | AW36: PP Granules | AX36: RM | AZ36: 0 | BA36: 1283400 | BB36: 599 | BC36: 14-07-2026 | BD36: 24AAACO3087C1ZT | BE36: bharatd | BF36: bharatd | BG36: 0 | BH36: 0 | BI36: 0 | BJ36: 0 | BK36: 0 | BL36: 0 | BM36: 1896200 | BN36: 672144908278 | BO36: 46217 | BP36: 15500
B37: Oswal Extrusion Limited | C37: 15-07-2026 | D37: OEL/26-27/SII00558 | E37: RAW06011 | F37: PP Granules | H37: OEL/RAW/26-27/19 | I37: 8000 | J37: 8000 | K37: Kgs | L37: 8000 | M37: 0 | N37: 8000 | O37: GJ14Z0334 | P37: Plastene India ltd - Unit 1-Purchase | Q37: Plastene India ltd - Unit 1-Purchase | R37: PIL1/E/375 | S37: 14-07-2026 | T37: RAW MATERIAL | U37: INDIGENOUS | V37: RM 19 | W37: 76.6 | X37: 76.6 | Y37: PIL1/E/375 | Z37: 14-07-2026 | AD37: - | AE37: - | AF37: 0 | AG37: 0 | AH37: 0 | AI37: 0 | AJ37: 0 | AK37: VAT | AL37: 0 | AM37: 0 | AN37: 0 | AO37: 0 | AP37: 0 | AR37: 0 | AS37: 0 | AT37: 1896200 | AU37: RM | AV37: Granules | AW37: PP Granules | AX37: RM | AY37: anil | AZ37: 0 | BA37: 612800 | BB37: 599 | BC37: 14-07-2026 | BD37: 24AAACO3087C1ZT | BE37: bharatd | BF37: bharatd | BG37: 0 | BH37: 0 | BI37: 0 | BJ37: 0 | BK37: 0 | BL37: 0 | BM37: 0 | BN37: 672144908278 | BO37: 46217 | BP37: 8000
B38: Oswal Extrusion Limited | C38: 15-07-2026 | D38: OEL/26-27/SII00560 | E38: FIB21881 | F38: PP Woven Fabric | G38: OEL/26-27/RWM00002/01 | H38: OEL/RAW/26-27/15 | I38: 1000 | J38: 1006.6 | K38: Kgs | L38: 1006.6 | M38: -6.6 | N38: 1006.6 | O38: GJ12BT4481 | P38: Dynamic Wooltex | Q38: Dynamic Wooltex | R38: 13552 | S38: 46272 | T38: RAW MATERIAL | U38: INDIGENOUS | V38: RM 20 | W38: 150 | X38: 162.07034 | Y38: 13552 | Z38: 46272 | AD38: PARTY SELF | AE38: 88/25293 | AF38: 0 | AG38: 0 | AH38: 0 | AI38: 0 | AJ38: 0 | AK38: VAT | AL38: 0 | AM38: 0 | AN38: 12150 | AO38: 0 | AP38: 0 | AR38: 0 | AS38: 0 | AT38: 163140 | AU38: RM | AV38: FIBC Accessories | AW38: FIBC Accessories | AX38: RM | AY38: erp | AZ38: 0 | BA38: 163140 | BB38: 593 | BC38: 13-07-2026 | BD38: 08ABFPB2251A1ZI | BE38: bharatd | BF38: shyam | BG38: 0 | BH38: 0 | BI38: 0 | BJ38: 0 | BK38: 0 | BL38: 0 | BM38: 163140 | BN38: 701649864777 | BO38: 46212 | BP38: 1006.6
B39: Oswal Extrusion Limited | C39: 18-07-2026 | D39: OEL/26-27/SII00582 | E39: RAW06398 | F39: LDPE Granuals | H39: OEL/RAW/26-27/20 | I39: 1000 | J39: 1000 | K39: Kgs | L39: 1000 | M39: 0 | N39: 1000 | O39: GJ09Z0572 | P39: Plastene India ltd - Unit 1-Purchase | Q39: Plastene India ltd - Unit 1-Purchase | R39: PIL1/E/385 | S39: 17-07-2026 | T39: RAW MATERIAL | U39: INDIGENOUS | V39: RM 21 | W39: 145 | X39: 145 | Y39: PIL1/E/385 | Z39: 17-07-2026 | AD39: - | AE39: - | AF39: 0 | AG39: 0 | AH39: 0 | AI39: 0 | AJ39: 0 | AK39: VAT | AL39: 0 | AM39: 0 | AN39: 0 | AO39: 0 | AP39: 0 | AR39: 0 | AS39: 0 | AT39: 145000 | AU39: RM | AV39: Granules | AW39: LDPE Granules | AX39: RM | AZ39: 0 | BA39: 145000 | BB39: 622 | BC39: 17-07-2026 | BD39: 24AAACO3087C1ZT | BE39: bharatd | BF39: bharatd | BG39: 0 | BH39: 0 | BI39: 0 | BJ39: 0 | BK39: 0 | BL39: 0 | BM39: 145000 | BN39: 682146825150 | BO39: 46220 | BP39: 1000
B40: Oswal Extrusion Limited | C40: 18-07-2026 | D40: OEL/26-27/SII00583 | E40: RAW06251 | F40: PP Granules | H40: OEL/26-27/IMP/2 | I40: 135000 | J40: 135000 | K40: Kgs | L40: 135000 | M40: 0 | N40: 135000 | O40: GJ14Z6310/ GJ39TA0541/ GJ14Z0613/ GJ39TA3007/ GJ14Z0406 | P40: HCP Enterprise Ltd-Purchase | Q40: HCP Enterprise Ltd-Purchase | R40: HCP/26-27/25 | S40: 30-06-2026 | T40: RAW MATERIAL | U40: IMPORT/HIGH SEA SALES | V40: RMIMP 2 | W40: 121.55 | X40: 121.55 | Y40: HCP/26-27/25 | Z40: 30-06-2026 | AD40: SELF | AE40: - | AF40: 0 | AG40: 0 | AH40: 0 | AI40: 0 | AJ40: 0 | AK40: VAT | AL40: 0 | AM40: 0 | AN40: 0 | AO40: 0 | AP40: 0 | AR40: 0 | AS40: 0 | AT40: 16409250 | AU40: RM | AV40: Granules | AW40: PP Granules | AX40: RM | AZ40: 0 | BA40: 16409250 | BB40: 620 | BC40: 17-07-2026 | BD40: 24AAACC7815N1ZI | BE40: bharatd | BG40: 0 | BH40: 0 | BI40: 0 | BJ40: 0 | BK40: 0 | BL40: 0 | BM40: 16409250 | BN40: - | BO40: 46220.432 | BP40: 135000
B41: Oswal Extrusion Limited | C41: 18-07-2026 | D41: OEL/26-27/SII00585 | E41: WIP00017 | F41: PP MF Yarn Twisted | H41: OEL/RAW/26-27/21 | I41: 1077.01 | J41: 1077.01 | K41: Kgs | L41: 1077.01 | M41: 0 | N41: 1077.01 | O41: GJ12CT6064 | P41: Plastene India ltd - Unit 2-Purchase | Q41: Plastene India ltd - Unit 2-Purchase | R41: PIL2/E/97 | S41: 18-07-2026 | T41: RAW MATERIAL | U41: INDIGENOUS | V41: RM 22 | W41: 132 | X41: 131.99995 | Y41: PIL2/E/97 | Z41: 18-07-2026 | AD41: PARTY SELF | AE41: - | AF41: 0 | AG41: 0 | AH41: 0 | AI41: 0 | AJ41: 0 | AK41: VAT | AL41: 0 | AM41: 0 | AN41: 0 | AO41: 0 | AP41: 0 | AR41: 0 | AS41: 0 | AT41: 745730 | AU41: SF | AV41: Yarn All | AW41: Polyester Yarn | AX41: RM | AY41: erp | AZ41: 0 | BA41: 142165.27 | BB41: 629 | BC41: 18-07-2026 | BD41: 24AAACO3087C1ZT | BE41: bharatd | BF41: bharatd | BG41: 0 | BH41: 0 | BI41: 0 | BJ41: 0 | BK41: 0 | BL41: 0 | BM41: 745730 | BN41: 692147548655 | BO41: 46221 | BP41: 1077.01
B42: Oswal Extrusion Limited | C42: 18-07-2026 | D42: OEL/26-27/SII00585 | E42: WIP00022 | F42: PP MF Yarn Twisted | H42: OEL/RAW/26-27/21 | I42: 5025.52 | J42: 5025.52 | K42: Kgs | L42: 5025.52 | M42: 0 | N42: 5025.52 | O42: GJ12CT6064 | P42: Plastene India ltd - Unit 2-Purchase | Q42: Plastene India ltd - Unit 2-Purchase | R42: PIL2/E/97 | S42: 18-07-2026 | T42: RAW MATERIAL | U42: INDIGENOUS | V42: RM 22 | W42: 120.1 | X42: 120.09996 | Y42: PIL2/E/97 | Z42: 18-07-2026 | AD42: PARTY SELF | AE42: - | AF42: 0 | AG42: 0 | AH42: 0 | AI42: 0 | AJ42: 0 | AK42: VAT | AL42: 0 | AM42: 0 | AN42: 0 | AO42: 0 | AP42: 0 | AR42: 0 | AS42: 0 | AT42: 745730 | AU42: SF | AV42: Yarn All | AW42: PP Yarn | AX42: RM | AY42: erp | AZ42: 0 | BA42: 603564.73 | BB42: 629 | BC42: 18-07-2026 | BD42: 24AAACO3087C1ZT | BE42: bharatd | BF42: bharatd | BG42: 0 | BH42: 0 | BI42: 0 | BJ42: 0 | BK42: 0 | BL42: 0 | BM42: 0 | BN42: 692147548655 | BO42: 46221 | BP42: 5025.52
B43: Oswal Extrusion Limited | C43: 22-07-2026 | D43: OEL/26-27/SII00598 | E43: RAW06279 | F43: MB Karnavati Polyplast Blue | H43: OEL/RAW/26-27/23 | I43: 275 | J43: 275 | K43: Kgs | L43: 275 | M43: 0 | N43: 275 | O43: GJ12BY1595 | P43: Plastene India ltd - Unit 1-Purchase | Q43: Plastene India ltd - Unit 1-Purchase | R43: PIL1/E/399 | S43: 21-07-2026 | T43: RAW MATERIAL | U43: INDIGENOUS | V43: RM 23 | W43: 155 | X43: 155 | Y43: PIL1/E/399 | Z43: 21-07-2026 | AD43: - | AF43: 0 | AG43: 0 | AH43: 0 | AI43: 0 | AJ43: 0 | AK43: VAT | AL43: 0 | AM43: 0 | AN43: 0 | AO43: 0 | AP43: 0 | AR43: 0 | AS43: 0 | AT43: 635725 | AU43: RM | AV43: Granules | AW43: Masterbatch | AX43: RM | AZ43: 0 | BA43: 42625 | BB43: 651 | BC43: 21-07-2026 | BD43: 24AAACO3087C1ZT | BE43: bharatd | BF43: bharatd | BG43: 0 | BH43: 0 | BI43: 0 | BJ43: 0 | BK43: 0 | BL43: 0 | BM43: 635725 | BN43: - | BO43: 46224 | BP43: 275
B44: Oswal Extrusion Limited | C44: 22-07-2026 | D44: OEL/26-27/SII00598 | E44: RAW05527 | F44: MB Karnavati Polyplast Blue | H44: OEL/RAW/26-27/23 | I44: 100 | J44: 100 | K44: Kgs | L44: 100 | M44: 0 | N44: 100 | O44: GJ12BY1595 | P44: Plastene India ltd - Unit 1-Purchase | Q44: Plastene India ltd - Unit 1-Purchase | R44: PIL1/E/399 | S44: 21-07-2026 | T44: RAW MATERIAL | U44: INDIGENOUS | V44: RM 23 | W44: 181 | X44: 181 | Y44: PIL1/E/399 | Z44: 21-07-2026 | AD44: - | AF44: 0 | AG44: 0 | AH44: 0 | AI44: 0 | AJ44: 0 | AK44: VAT | AL44: 0 | AM44: 0 | AN44: 0 | AO44: 0 | AP44: 0 | AR44: 0 | AS44: 0 | AT44: 635725 | AU44: RM | AV44: Granules | AW44: Masterbatch | AX44: RM | AY44: erp | AZ44: 0 | BA44: 18100 | BB44: 651 | BC44: 21-07-2026 | BD44: 24AAACO3087C1ZT | BE44: bharatd | BF44: bharatd | BG44: 0 | BH44: 0 | BI44: 0 | BJ44: 0 | BK44: 0 | BL44: 0 | BM44: 0 | BN44: - | BO44: 46224 | BP44: 100
B45: Oswal Extrusion Limited | C45: 22-07-2026 | D45: OEL/26-27/SII00598 | E45: RAW05187 | F45: PP Granules | H45: OEL/RAW/26-27/23 | I45: 5000 | J45: 5000 | K45: Kgs | L45: 5000 | M45: 0 | N45: 5000 | O45: GJ12BY1595 | P45: Plastene India ltd - Unit 1-Purchase | Q45: Plastene India ltd - Unit 1-Purchase | R45: PIL1/E/399 | S45: 21-07-2026 | T45: RAW MATERIAL | U45: INDIGENOUS | V45: RM 23 | W45: 115 | X45: 115 | Y45: PIL1/E/399 | Z45: 21-07-2026 | AD45: - | AF45: 0 | AG45: 0 | AH45: 0 | AI45: 0 | AJ45: 0 | AK45: VAT | AL45: 0 | AM45: 0 | AN45: 0 | AO45: 0 | AP45: 0 | AR45: 0 | AS45: 0 | AT45: 635725 | AU45: RM | AV45: Granules | AW45: PP Granules | AX45: RM | AY45: erp | AZ45: 0 | BA45: 575000 | BB45: 651 | BC45: 21-07-2026 | BD45: 24AAACO3087C1ZT | BE45: bharatd | BF45: bharatd | BG45: 0 | BH45: 0 | BI45: 0 | BJ45: 0 | BK45: 0 | BL45: 0 | BM45: 0 | BN45: - | BO45: 46224 | BP45: 5000
B46: Oswal Extrusion Limited | C46: 23-07-2026 | D46: OEL/26-27/SII00603 | E46: RAW05187 | F46: PP Granules | H46: OEL/RAW/26-27/24 | I46: 400 | J46: 400 | K46: Kgs | L46: 400 | M46: 0 | N46: 400 | O46: GJ12BY0479 | P46: Plastene India ltd - Unit 1-Purchase | Q46: Plastene India ltd - Unit 1-Purchase | R46: PIL1/E/405 | S46: 22-07-2026 | T46: RAW MATERIAL | U46: INDIGENOUS | V46: RM 24 | W46: 136.331 | X46: 136.33 | Y46: PIL1/E/405 | Z46: 22-07-2026 | AD46: - | AF46: 0 | AG46: 0 | AH46: 0 | AI46: 0 | AJ46: 0 | AK46: VAT | AL46: 0 | AM46: 0 | AN46: 0 | AO46: 0 | AP46: 0 | AR46: 0 | AS46: 0 | AT46: 54532 | AU46: RM | AV46: Granules | AW46: PP Granules | AX46: RM | AY46: erp | AZ46: 0 | BA46: 54532 | BB46: - | BC46: 22-07-2026 | BD46: 24AAACO3087C1ZT | BE46: bharatd | BF46: bharatd | BG46: 0 | BH46: 0 | BI46: 0 | BJ46: 0 | BK46: 0 | BL46: 0 | BM46: 54532 | BN46: - | BO46: 46225 | BP46: 400
B47: Oswal Extrusion Limited | C47: 24-07-2026 | D47: OEL/26-27/SII00605 | E47: RAW05187 | F47: PP Granules | H47: OEL/RAW/26-27/25 | I47: 1000 | J47: 1000 | K47: Kgs | L47: 1000 | M47: 0 | N47: 1000 | O47: GJ27T3559 | P47: Plastene India ltd - Unit 1-Purchase | Q47: Plastene India ltd - Unit 1-Purchase | R47: PIL1/E/408 | S47: 23-07-2026 | T47: RAW MATERIAL | U47: INDIGENOUS | V47: RM 25 | W47: 136.331 | X47: 136.331 | Y47: PIL1/E/408 | Z47: 23-07-2026 | AD47: - | AF47: 0 | AG47: 0 | AH47: 0 | AI47: 0 | AJ47: 0 | AK47: VAT | AL47: 0 | AM47: 0 | AN47: 0 | AO47: 0 | AP47: 0 | AR47: 0 | AS47: 0 | AT47: 136331 | AU47: RM | AV47: Granules | AW47: PP Granules | AX47: RM | AY47: erp | AZ47: 0 | BA47: 136331 | BB47: 661 | BC47: 23-07-2026 | BD47: 24AAACO3087C1ZT | BE47: bharatd | BF47: bharatd | BG47: 0 | BH47: 0 | BI47: 0 | BJ47: 0 | BK47: 0 | BL47: 0 | BM47: 136331 | BN47: - | BO47: 46226 | BP47: 1000
B48: Oswal Extrusion Limited | C48: 26-07-2026 | D48: OEL/26-27/SII00619 | E48: WIP00031 | F48: PP/HD Wastage/Scrap | H48: OEL/RAW/26-27/26 | I48: 10643 | J48: 10643 | K48: Kgs | L48: 10643 | M48: 0 | N48: 10643 | O48: GJ02Z4078 | P48: K.P. Woven Pvt Ltd - Unit 3 -Purchase | Q48: K.P. Woven Pvt Ltd - Unit 3 -Purchase | R48: KPW3/IZS/26-27/04 | S48: 25-07-2026 | T48: RAW MATERIAL | U48: INDIGENOUS | V48: RM 26 | W48: 10 | X48: 10 | Y48: KPW3/IZS/26-27/04 | Z48: 25-07-2026 | AD48: - | AF48: 0 | AG48: 0 | AH48: 0 | AI48: 0 | AJ48: 0 | AK48: VAT | AL48: 0 | AM48: 0 | AN48: 0 | AO48: 0 | AP48: 0 | AR48: 0 | AS48: 0 | AT48: 106430 | AU48: SF | AV48: Wastage/Scrap | AW48: Wastage/Scrap | AX48: RM | AY48: erp | AZ48: 0 | BA48: 106430 | BB48: 671 | BC48: 25-07-2026 | BD48: 24AAECK6307M2ZE | BE48: bharatd | BF48: bharatd | BG48: 0 | BH48: 0 | BI48: 0 | BJ48: 0 | BK48: 0 | BL48: 0 | BM48: 106430 | BN48: - | BO48: 46228 | BP48: 0
B49: Oswal Extrusion Limited | C49: 31-07-2026 | D49: OEL/26-27/SII00663 | E49: SMF00147 | F49: LDPE/LLDPE Bags/Liner | H49: OEL/RAW/26-27/27 | I49: 136 | J49: 136 | K49: Kgs | L49: 136 | M49: 0 | N49: 136 | O49: GJ09Z0572 | P49: Plastene Polyfilms Ltd-Purchase | Q49: Plastene Polyfilms Ltd-Purchase | R49: PPL/E/60 | S49: 25-07-2026 | T49: RAW MATERIAL | U49: INDIGENOUS | V49: RM 28 | W49: 271 | X49: 271 | Y49: PPL/E/60 | Z49: 25-07-2026 | AD49: - | AF49: 0 | AG49: 0 | AH49: 0 | AI49: 0 | AJ49: 0 | AK49: VAT | AL49: 0 | AM49: 0 | AN49: 0 | AO49: 0 | AP49: 0 | AR49: 0 | AS49: 0 | AT49: 36856 | AU49: SF | AV49: Liners | AW49: LDPE/LLDPE Bags | AX49: RM | AY49: erp | AZ49: 0 | BA49: 36856 | BB49: 668 | BC49: 25-08-2026 | BD49: 24AAFCP2956A1ZR | BE49: bharatd | BF49: bharatd | BG49: 0 | BH49: 0 | BI49: 0 | BJ49: 0 | BK49: 0 | BL49: 0 | BM49: 36856 | BN49: - | BO49: 46228 | BP49: 0

Sheet JOB issued
A1: Row Labels | B1: Sum of Quantity | C1: Sum of Amount
A2: Jambo Bag/Fibc Bag Mfr (Kg) | B2: 417716.34 | C2: 43947990 | D2: =C2/B2 -> 105.21013
A3: Scrap | B3: 10643 | C3: 0 | D3: =C3/B3 -> 0
A4: Grand Total | B4: 428359.34 | C4: 43947990
A21: Date | B21: Particular | C21: Voucher Type | D21: Voucher No | E21: Type | F21: Invoice No | G21: Invoice Date | H21: Main Grp | I21: Group Name | J21: Sub Grup | K21: sales Group Name | L21: Item Name | M21: Quantity | N21: Amount | O21: Item Desc | P21: Bill Amount | Q21: CGST Rate | R21: CGST Amt | S21: SGST Rate | T21: SGST Amt | U21: IGST Rate | V21: IGST Amt | W21: Freight GST | X21: Total GST | Y21: TCS | Z21: GST-IN | AA21: Unit | AB21: HSN Code | AC21: Currencty | AD21: Exc.Rate | AE21: Net Wt
A22: 46241 | B22: K.P. Woven Pvt Ltd - Unit 3 -Sales | C22: Job Invoice | D22: OEL1/D/23 | E22: Job Work Income | F22: OEL1/D/23 | G22: 46241 | H22: FG | I22: FIBC Bags | J22: FIBC Bags | K22: Jambo Bag/Fibc Bag Mfr (Kg) | L22: FIBC Bags With UV With Liner | M22: 1230 | N22: 114943.5 | O22: MANUFACTURER OF PP WOVEN BIG BAGS/SACKS | P22: 7832868 | Q22: 0 | R22: 0 | S22: 0 | T22: 0 | U22: 0 | V22: 0 | W22: 0 | X22: 0 | Y22: 0 | Z22: 24AAECK6307M2ZE | AA22: KGS | AB22: 998852 | AC22: Rs. | AD22: 1 | AE22: 1230 | AF22: India
A23: 46241 | B23: K.P. Woven Pvt Ltd - Unit 3 -Sales | C23: Job Invoice | D23: OEL1/D/23 | E23: Job Work Income | F23: OEL1/D/23 | G23: 46241 | H23: FG | I23: FIBC Bags | J23: FIBC Bags | K23: Jambo Bag/Fibc Bag Mfr (Kg) | L23: FIBC Bags With UV With Liner | M23: 4214 | N23: 393798.3 | O23: MANUFACTURER OF PP WOVEN BIG BAGS/SACKS | P23: 0 | Q23: 0 | R23: 0 | S23: 0 | T23: 0 | U23: 0 | V23: 0 | W23: 0 | X23: 0 | Y23: 0 | Z23: 24AAECK6307M2ZE | AA23: KGS | AB23: 998852 | AC23: Rs. | AD23: 1 | AE23: 4214 | AF23: India
A24: 46241 | B24: K.P. Woven Pvt Ltd - Unit 3 -Sales | C24: Job Invoice | D24: OEL1/D/23 | E24: Job Work Income | F24: OEL1/D/23 | G24: 46241 | H24: FG | I24: FIBC Bags | J24: FIBC Bags | K24: Jambo Bag/Fibc Bag Mfr (Kg) | L24: FIBC Bags With UV With Liner | M24: 1220 | N24: 114009 | O24: MANUFACTURER OF PP WOVEN BIG BAGS/SACKS | P24: 0 | Q24: 0 | R24: 0 | S24: 0 | T24: 0 | U24: 0 | V24: 0 | W24: 0 | X24: 0 | Y24: 0 | Z24: 24AAECK6307M2ZE | AA24: KGS | AB24: 998852 | AC24: Rs. | AD24: 1 | AE24: 1220 | AF24: India
A25: 46241 | B25: K.P. Woven Pvt Ltd - Unit 3 -Sales | C25: Job Invoice | D25: OEL1/D/23 | E25: Job Work Income | F25: OEL1/D/23 | G25: 46241 | H25: FG | I25: FIBC Bags | J25: FIBC Bags | K25: Jambo Bag/Fibc Bag Mfr (Kg) | L25: FIBC Bags With UV With Liner | M25: 977.9 | N25: 91384.76 | O25: MANUFACTURER OF PP WOVEN BIG BAGS/SACKS | P25: 0 | Q25: 0 | R25: 0 | S25: 0 | T25: 0 | U25: 0 | V25: 0 | W25: 0 | X25: 0 | Y25: 0 | Z25: 24AAECK6307M2ZE | AA25: KGS | AB25: 998852 | AC25: Rs. | AD25: 1 | AE25: 977.9 | AF25: India
