Workbook

Sheet Summary
B2: EBIDTA - Summary
B3: Plant | C3: EBIDTA | E3: PBT | G3: EBIDTA | I3: PBT | K3: EBIDTA | M3: PBT | O3: EBIDTA | Q3: PBT | S3: EBIDTA | U3: PBT | W3: EBIDTA | Y3: PBT | AA3: EBIDTA | AC3: PBT | AE3: EBIDTA | AG3: PBT | AI3: EBIDTA | AK3: PBT | AM3: EBIDTA | AO3: PBT | AQ3: EBIDTA | AS3: PBT | AU3: EBIDTA | AW3: PBT
A4: 0 | C4: April'2026 | D4: YTD | E4: =C4 -> April'2026 | F4: YTD | G4: May'2025 | H4: YTD | I4: =G4 -> May'2025 | J4: YTD | K4: Jun'2025 | L4: YTD | M4: =K4 -> Jun'2025 | N4: YTD | O4: Jul'2025 | P4: YTD | Q4: =O4 -> Jul'2025 | R4: YTD | S4: Aug'2025 | T4: YTD | U4: =S4 -> Aug'2025 | V4: YTD | W4: Sep'2025 | X4: YTD | Y4: =W4 -> Sep'2025 | Z4: YTD | AA4: Oct'2025 | AB4: YTD | AC4: =AA4 -> Oct'2025 | AD4: YTD | AE4: Nov'2025 | AF4: YTD | AG4: =AE4 -> Nov'2025 | AH4: YTD | AI4: Dec'2025 | AJ4: YTD | AK4: =AI4 -> Dec'2025 | AL4: YTD | AM4: Jan'2026 | AN4: YTD | AO4: =AM4 -> Jan'2026 | AP4: YTD | AQ4: Feb'2026 | AR4: YTD | AS4: =AQ4 -> Feb'2026 | AT4: YTD | AU4: Mar'2026 | AV4: YTD | AW4: =AU4 -> Mar'2026 | AX4: YTD
B5: PIL I | C5: =+'Apr-26'!$C$82 -> 727.75151 | D5: =+'Apr-26'!$E$82 -> 727.75151 | E5: =+'Apr-26'!$C$89 -> 604.44113 | F5: =+'Apr-26'!$E$89 -> 604.44113 | G5: =+'May-26'!$C$82 -> 382.62154 | H5: =+'May-26'!$E$82 -> 1110.3731 | I5: =+'May-26'!$C$89 -> 144.29429 | J5: =+'May-26'!$E$89 -> 872.04581
B6: PIL II | C6: =+'Apr-26'!$G$82 -> 225.11669 | D6: =+'Apr-26'!$I$82 -> 225.11669 | E6: =+'Apr-26'!$G$89 -> 218.65362 | F6: =+'Apr-26'!$I$89 -> 218.65362 | G6: =+'May-26'!$G$82 -> 212.48089 | H6: =+'May-26'!$I$82 -> 437.59757 | I6: =+'May-26'!$G$89 -> 179.88929 | J6: =+'May-26'!$I$89 -> 405.00598
B7: PIL III | C7: =+'Apr-26'!$K$82 -> 37.266779 | D7: =+'Apr-26'!$M$82 -> 37.266779 | E7: =+'Apr-26'!$K$89 -> 15.992645 | F7: =+'Apr-26'!$M$89 -> 15.992645 | G7: =+'May-26'!$K$82 -> 19.081349 | H7: =+'May-26'!$M$82 -> 56.348128 | I7: =+'May-26'!$K$89 -> -31.006677 | J7: =+'May-26'!$M$89 -> 6.2601022
B8: HPBL4 | C8: =+'Apr-26'!$O$82 -> 135.03311 | D8: =+'Apr-26'!$Q$82 -> 135.03311 | E8: =+'Apr-26'!$O$89 -> 133.93357 | F8: =+'Apr-26'!$Q$89 -> 133.93357 | G8: =+'May-26'!$O$82 -> 303.63346 | H8: =+'May-26'!$Q$82 -> 438.66658 | I8: =+'May-26'!$O$89 -> 301.19332 | J8: =+'May-26'!$Q$89 -> 436.22644
B9: PIL HO | C9: =+'Apr-26'!$S$82 -> -10.92026 | D9: =+'Apr-26'!$U$82 -> -10.92026 | E9: =+'Apr-26'!$S$89 -> -18.961649 | F9: =+'Apr-26'!$U$89 -> -18.961649 | G9: =+'May-26'!$S$82 -> -18.114826 | H9: =+'May-26'!$U$82 -> -29.035086 | I9: =+'May-26'!$S$89 -> -15.065947 | J9: =+'May-26'!$U$89 -> -25.986207
B10: HCP | C10: =+'Apr-26'!$W$82 -> 34.936401 | D10: =+'Apr-26'!$Y$82 -> 34.936401 | E10: =+'Apr-26'!$W$89 -> 33.868702 | F10: =+'Apr-26'!$Y$89 -> 33.868702 | G10: =+'May-26'!$W$82 -> -64.340984 | H10: =+'May-26'!$Y$82 -> -29.404583 | I10: =+'May-26'!$W$89 -> -64.834428 | J10: =+'May-26'!$Y$89 -> -29.898027 | BF10: =59.57-59.25 -> 0.32
B11: OEL I | C11: =+'Apr-26'!$AG$82 -> 71.725646 | D11: =+'Apr-26'!$AI$82 -> 71.725646 | E11: =+'Apr-26'!$AG$89 -> 51.229445 | F11: =+'Apr-26'!$AI$89 -> 51.229445 | G11: =+'May-26'!$AG$82 -> 36.774061 | H11: =+'May-26'!$AI$82 -> 108.49971 | I11: =+'May-26'!$AG$89 -> -5.5149987 | J11: =+'May-26'!$AI$89 -> 66.210647
B12: PPL | C12: =+'Apr-26'!$AL$82 -> 164.56858 | D12: =+'Apr-26'!$AN$82 -> 164.56858 | E12: =+'Apr-26'!$AL$89 -> 140.97763 | F12: =+'Apr-26'!$AN$89 -> 140.97763 | G12: =+'May-26'!$AL$82 -> -113.8955 | H12: =+'May-26'!$AN$82 -> 50.67308 | I12: =+'May-26'!$AL$89 -> -177.49363 | J12: =+'May-26'!$AN$89 -> -12.925049
B13: KP I | C13: =+'Apr-26'!$AQ$82 -> 568.90214 | D13: =+'Apr-26'!$AS$82 -> 568.90214 | E13: =+'Apr-26'!$AQ$89 -> 505.99822 | F13: =+'Apr-26'!$AS$89 -> 505.99822 | G13: =+'May-26'!$AQ$82 -> 741.82315 | H13: =+'May-26'!$AS$82 -> 1310.7253 | I13: =+'May-26'!$AQ$89 -> 592.64676 | J13: =+'May-26'!$AS$89 -> 1161.5489
B14: KP III | C14: =+'Apr-26'!$AU$82 -> 126.07635 | D14: =+'Apr-26'!$AW$82 -> 126.07635 | E14: =+'Apr-26'!$AU$89 -> 119.87334 | F14: =+'Apr-26'!$AW$89 -> 119.87334 | G14: =+'May-26'!$AU$82 -> 303.92958 | H14: =+'May-26'!$AW$82 -> 430.00593 | I14: =+'May-26'!$AU$89 -> 292.28164 | J14: =+'May-26'!$AW$89 -> 418.35799
B15: HPBL I | C15: =+'Apr-26'!$BE$82 -> 24.908538 | D15: =+'Apr-26'!$BG$82 -> 24.908538 | E15: =+'Apr-26'!$BE$89 -> -11.892947 | F15: =+'Apr-26'!$BG$89 -> -11.892947 | G15: =+'May-26'!$BE$82 -> -115.29488 | H15: =+'May-26'!$BG$82 -> -90.386341 | I15: =+'May-26'!$BE$89 -> -152.09636 | J15: =+'May-26'!$BG$89 -> -127.18783
B16: HPBL II | C16: =+'Apr-26'!$BI$82 -> -6.1781505 | D16: =+'Apr-26'!$BK$82 -> -6.1781505 | E16: =+'Apr-26'!$BI$89 -> -6.1781505 | F16: =+'Apr-26'!$BK$89 -> -6.1781505 | G16: =+'May-26'!$BI$82 -> 10.591816 | H16: =+'May-26'!$BK$82 -> 4.413665 | I16: =+'May-26'!$BI$89 -> 10.591816 | J16: =+'May-26'!$BK$89 -> 4.413665
B17: HPBL III | C17: =+'Apr-26'!$BM$82 -> 0.07617 | D17: =+'Apr-26'!$BO$82 -> 0.07617 | E17: =+'Apr-26'!$BM$89 -> 0.07617 | F17: =+'Apr-26'!$BO$89 -> 0.07617 | G17: =+'May-26'!$BM$82 -> 0 | H17: =+'May-26'!$BO$82 -> 0.07617 | I17: =+'May-26'!$BM$89 -> 0 | J17: =+'May-26'!$BO$89 -> 0.07617
B18: OCPL | C18: =+'Apr-26'!$BW$82 -> 52.699454 | D18: =+'Apr-26'!$BY$82 -> 52.699454 | E18: =+'Apr-26'!$BW$89 -> 52.699454 | F18: =+'Apr-26'!$BY$89 -> 52.699454 | G18: =+'May-26'!$BW$82 -> 49.856209 | H18: =+'May-26'!$BY$82 -> 102.55566 | I18: =+'May-26'!$BW$89 -> 49.856209 | J18: =+'May-26'!$BY$89 -> 102.55566
B19: Total Group | C19: =SUM(C5:C18) -> 2151.963 | D19: =SUM(D5:D18) -> 2151.963 | E19: =SUM(E5:E18) -> 1840.7112 | F19: =SUM(F5:F18) -> 1840.7112 | G19: =SUM(G5:G18) -> 1749.1459 | H19: =SUM(H5:H18) -> 3901.1088 | I19: =SUM(I5:I18) -> 1124.7413 | J19: =SUM(J5:J18) -> 3276.7043 | ... AX19: =SUM(AX5:AX18) -> 0 | BC19: =+AQ19-#REF! -> #REF! | BD19: =+#REF!-Summary!AR19 -> #REF! | BG19: =+AM19-#REF! -> #REF! | BH19: =+#REF!-Summary!AN19 -> #REF!
B20: Cash PBT
B21: % | C21: ='[1]APR-2022'!CQ86 -> #REF! | D21: ='[2]APR-2022'!CT86 -> 0.14263615 | F21: ='[2]APR-2022'!CT91 -> 0.073411415 | G21: ='[2]May-2022'!CQ86 -> 0.090850873 | H21: ='[2]May-2022'!CT86 -> 0.090527574 | J21: ='[2]May-2022'!CT91 -> 0.0045169428 | K21: ='[2]May-2022'!CU86 -> 0 | L21: ='[2]May-2022'!CX86 -> 0 | N21: ='[2]May-2022'!CX91 -> 0 | O21: ='[2]May-2022'!CY86 -> 0 | P21: ='[2]May-2022'!DB86 -> 0 | R21: ='[2]May-2022'!DB91 -> 0 | S21: ='[2]May-2022'!DC86 -> 0 | T21: ='[2]May-2022'!DF86 -> 0 | V21: ='[2]May-2022'!DF91 -> 0 | W21: ='[2]May-2022'!DG86 -> 0 | X21: ='[2]May-2022'!DJ86 -> 0 | Z21: ='[2]May-2022'!DJ91 -> 0
C23: =+C19-'Apr-26'!CE82 -> 0 | D23: =+D19-'Apr-26'!CG82 -> 0 | E23: =+E19-'Apr-26'!CE88 -> 2.9558578e-12 | F23: =+F19-'Apr-26'!CG88 -> 2.9558578e-12 | G23: =+G19-'May-26'!CE82 -> 0 | H23: =+H19-'May-26'!CG82 -> 6.3664629e-12 | I23: =I19-'May-26'!CE89 -> 0 | J23: =J19-'May-26'!CG89 -> 6.3664629e-12

Sheet Sheet1
B2: PIL I | C2: PIL II | D2: PIL III | E2: PIL VI | F2: PIL HO | G2: HCP | H2: OEL | I2: PPL | J2: KPW | K2: KPW II | L2: HPBL I | M2: HPBL II | N2: HPBL III | O2: JBP | P2: Total
A3: Jan | B3: =#REF! -> #REF! | C3: =#REF! -> #REF! | D3: =#REF! -> #REF! | E3: =#REF! -> #REF! | F3: =#REF! -> #REF! | G3: =#REF! -> #REF! | H3: =#REF! -> #REF! | I3: =#REF! -> #REF! | ... O3: =#REF! -> #REF! | P3: =SUM(B3:O3) -> #REF!
A4: Feb | B4: =#REF! -> #REF! | C4: =#REF! -> #REF! | D4: =#REF! -> #REF! | E4: =#REF! -> #REF! | F4: =#REF! -> #REF! | G4: =#REF! -> #REF! | H4: =#REF! -> #REF! | I4: =#REF! -> #REF! | ... N4: =#REF! -> #REF! | O4: =#REF!+26.52 -> #REF! | P4: =SUM(B4:O4) -> #REF!
A5: Total | B5: =SUM(B3:B4) -> #REF! | C5: =SUM(C3:C4) -> #REF! | D5: =SUM(D3:D4) -> #REF! | E5: =SUM(E3:E4) -> #REF! | F5: =SUM(F3:F4) -> #REF! | G5: =SUM(G3:G4) -> #REF! | H5: =SUM(H3:H4) -> #REF! | I5: =SUM(I3:I4) -> #REF! | ... P5: =SUM(P3:P4) -> #REF!
A6: Avg | B6: =B5/2 -> #REF! | C6: =C5/2 -> #REF! | D6: =D5/2 -> #REF! | E6: =E5/2 -> #REF! | F6: =F5/2 -> #REF! | G6: =G5/2 -> #REF! | H6: =H5/2 -> #REF! | I6: =I5/2 -> #REF! | ... P6: =P5/2 -> #REF!

Sheet May-26
B1: GROUP EBIDTA & PBT FOR THE MONTH OF | D1: May-26 | AG1: 367529 | AL1: 441624 | AQ1: 597025 | CE1: =SUM(G1:BZ1) -> 1406178
B3: PARTICULARS | C3: QTY | D3: SALES/PUR QTY | E3: SALE/PUR RATE | G3: QTY | H3: SALE IN LACS | I3: SALE/PUR RATE | O3: QTY | P3: SALE IN LACS | Q3: SALE/PUR RATE | AG3: QTY | AH3: SALE IN LACS | AI3: SALE/PUR RATE | AL3: QTY | AM3: SALE IN LACS | AN3: SALE/PUR RATE | AQ3: QTY | AR3: SALE IN LACS | AS3: SALE/PUR RATE | AU3: QTY | AV3: SALE IN LACS | AW3: SALE/PUR RATE | BE3: QTY | BF3: SALE IN LACS | BG3: SALE/PUR RATE | BM3: QTY | BN3: SALE IN LACS | BO3: SALE/PUR RATE
B4: BUDGETED / PLANNED
B6: PRODUCTION
B7: FIBC | C7: 0 | G7: 0 | I7: 0 | O7: 0 | Q7: 0 | AG7: 0 | AL7: 0 | AN7: 0 | AQ7: 0 | AS7: 0 | AU7: 0 | BE7: 0 | BG7: 0 | BM7: 0 | BN7: 0 | BO7: 0 | CE7: =SUM(C7:CD7) -> 0 | CF7: 165.52
B8: Fabric (Liner Mtr) | BM8: 0 | CE8: =SUM(C8:CD8) -> 0
C9: =(C8*0.4)+C7 -> 0 | G9: =(G8*0.4)+G7 -> 0 | O9: =(O8*0.4)+O7 -> 0 | AG9: =(AG8*0.4)+AG7 -> 0 | AL9: =(AL8*0.4)+AL7 -> 0 | AQ9: =(AQ8*0.4)+AQ7 -> 0 | AU9: 0 | BE9: 0 | BM9: =(BM8*0.4)+BM7 -> 0 | CE9: =SUM(C9:CD9) -> 0
B10: DISPATCH | CE10: =SUM(C10:CD10) -> 0
B11: FIBC | CE11: =SUM(C11:CD11) -> 0
B12: Fabric | CE12: =SUM(C12:CD12) -> 0
CE13: =SUM(C13:CD13) -> 0
B14: PURCHASE | CE14: =SUM(C14:CD14) -> 0
B15: Fabric | CE15: =SUM(C15:CD15) -> 0
B16: PP Granules | CE16: =SUM(C16:CD16) -> 0
B17: Conversion Cost per KG | C17: =#REF!-#REF!+#REF! -> #REF! | G17: =#REF!-#REF!+#REF! -> #REF! | O17: =#REF!-#REF!+#REF! -> #REF! | AG17: =#REF!-#REF!+#REF! -> #REF! | AL17: =#REF!-#REF!+#REF! -> #REF! | AQ17: =#REF!-#REF!+#REF! -> #REF! | AU17: =#REF!-#REF!+#REF! -> #REF! | BM17: =#REF!-#REF!+#REF! -> #REF! | CE17: =+#REF!-#REF!+#REF! -> #REF!
B19: Particulars | C19: May-26 | D19: % To Sales | E19: YTD | F19: % To Sales | G19: =C19 -> May-26 | H19: % To Sales | I19: YTD | J19: % To Sales | K19: =C19 -> May-26 | L19: % To Sales | M19: YTD | N19: % To Sales | O19: =C19 -> May-26 | P19: % To Sales | Q19: YTD | R19: % To Sales | S19: =K19 -> May-26 | T19: % Tw Sales | U19: YTD | V19: % To Sales | W19: =O19 -> May-26 | X19: % To Sales | Y19: YTD | Z19: % To Sales | AA19: InterUnit Elimination | AB19: =C19 -> May-26 | AC19: % To Sales | AD19: YTD | AE19: % To Sales | AG19: =AB19 -> May-26 | AH19: % To Sales | AI19: YTD | AJ19: % To Sales | AL19: =AG19 -> May-26 | AM19: % To Sales | AN19: YTD | AO19: % To Sales | AQ19: =AL19 -> May-26 | AR19: % To Sales | AS19: YTD | AT19: % To Sales | AU19: =AQ19 -> May-26 | AV19: % To Sales | AW19: YTD | AX19: % To Sales | AY19: InterUnit Elimination | AZ19: =AU19 -> May-26 | BA19: % To Sales | BB19: YTD | BC19: % To Sales | BE19: =AZ19 -> May-26 | BF19: % To Sales | BG19: YTD | BH19: % To Sales | BI19: =BE19 -> May-26 | BJ19: % To Sales | BK19: YTD | BL19: % To Sales | BM19: =BE19 -> May-26 | BN19: % To Sales | BO19: YTD | BP19: % To Sales | BQ19: Inter Unit Elimination | BR19: =BM19 -> May-26 | BS19: % To Sales | BT19: YTD | BU19: % To Sales | BW19: =BM19 -> May-26 | BX19: % To Sales | BY19: YTD | BZ19: % To Sales | CB19: Inter Company Elimination During the month | CC19: Inter Company Elimination YTD | CE19: =BR19 -> May-26 | CF19: % To Sales | CG19: YTD | CH19: % To Sales
C21: PIL I | G21: PIL II | K21: PIL III | O21: HPBL4 | S21: PIL HO | W21: HCP | AB21: PIL & HCP Consol | AG21: OSWAL - KASEZ | AL21: PLASTENE POLYFILM LTD. | AQ21: K P WOVEN PVT LTD - UNIT - I | AU21: K P WOVEN PVT LTD - UNIT -III | AZ21: K P WOVEN PVT LTD - CONSOLIDATED | BE21: HCP PLASTENE BULKPACK LTD. - UNIT - I | BI21: HCP PLASTENE BULKPACK LTD. - UNIT - II | BM21: HCP PLASTENE BULKPACK LTD. - UNIT - III | BR21: HCP PLASTENE BULKPACK LTD - CONSOLIDATED | BW21: OCPL | CE21: GROUP CONSOLIDATED
B22: Revenue from operations
B23: Sale of finished goods | C23: =E23-'Apr-26'!E23 -> 2048.0603 | D23: =C23/$C$46*100% -> 0.65558118 | E23: =-SUMIF('05.conso TB'!A:A,'May-26'!B23,'05.conso TB'!R:R)/10^5 -> 4945.3445 | F23: =E23/$E$46*100% -> 0.76539717 | G23: =I23-'Apr-26'!I23 -> 1059.1801 | H23: =G23/$G$46*100% -> 0.79745099 | I23: =-SUMIF('05.conso TB'!A:A,'May-26'!B23,'05.conso TB'!S:S)/10^5 -> 2073.1202 | J23: =I23/$I$46*100% -> 0.82609095 | K23: =M23-'Apr-26'!M23 -> 0 | L23: =K23/$C$46*100% -> 0 | M23: =-SUMIF('05.conso TB'!A:A,'May-26'!B23,'05.conso TB'!T:T)/10^5 -> 0 | N23: =M23/$C$46*100% -> 0 | O23: =Q23-'Apr-26'!Q23 -> 1225.1445 | P23: =O23/$O$46*100% -> 0.98638587 | Q23: =-SUMIF('05.conso TB'!A:A,'May-26'!B23,'05.conso TB'!U:U)/10^5 -> 2147.1778 | R23: =Q23/$Q$46*100% -> 0.98546637 | S23: =U23-'Apr-26'!U23 -> 0 | T23: =S23/$S$46*100% -> 0 | U23: =SUMIF('05.conso TB'!A:A,'May-26'!B23,'05.conso TB'!V:V) -> 0 | V23: =U23/$U$46*100% -> 0 | W23: =Y23-'Apr-26'!Y23 -> 0 | X23: =W23/$W$46*100% -> 0 | Y23: =-SUMIF('05.conso TB'!A:A,'May-26'!B23,'05.conso TB'!G:G)/10^5 -> 0 | Z23: =Y23/$Y$46*100% -> 0 | AA23: 317.57266 | AB23: =AD23-'Apr-26'!AD23 -> 4141.1887 | AC23: =AB23/$AB$46*100% -> 0.44908491 | AD23: =E23+I23+M23+Q23+U23+Y23-AA23 -> 8848.0699 | AE23: =AD23/$AD$46*100% -> 0.61219768 | AG23: =AI23-'Apr-26'!AI23 -> 95.60983 | AH23: =AG23/$AG$46*100% -> 0.26015644 | AI23: =-SUMIF('05.conso TB'!A:A,'May-26'!B23,'05.conso TB'!Q:Q)/10^5 -> 184.39779 | AJ23: =AI23/$AI$46*100% -> 0.2498606 | AL23: =AN23-'Apr-26'!AN23 -> 653.79373 | AM23: =AL23/$AL$46*100% -> 0.55207972 | AN23: =-SUMIF('05.conso TB'!A:A,'May-26'!B23,'05.conso TB'!W:W)/10^5 -> 1478.0791 | AO23: =AN23/$AN$46*100% -> 0.63645888 | AQ23: =AS23-'Apr-26'!AS23 -> 1982.7336 | AR23: =AQ23/$AQ$46*100% -> 0.97248742 | AS23: =-SUMIF('05.conso TB'!A:A,'May-26'!B23,'05.conso TB'!M:M)/10^5 -> 3773.3651 | AT23: =AS23/$AS$46*100% -> 0.97489384 | AU23: =AW23-'Apr-26'!AW23 -> -2.2135648 | AV23: =AU23/$AU$46*100% -> -0.0022216101 | AW23: =-SUMIF('05.conso TB'!A:A,'May-26'!B23,'05.conso TB'!P:P)/10^5 -> -4.5173012 | AX23: =AW23/$AW$46*100% -> -0.0024454424 | AY23: 0 | AZ23: =BB23-'Apr-26'!BB23 -> 1980.52 | BA23: =AZ23/$AZ$46*100% -> 0.65251593 | BB23: =AS23+AW23 -> 3768.8478 | BC23: =BB23/$BB$46*100% -> 0.6591462 | BE23: =BG23-'Apr-26'!BG23 -> 2505.1055 | BF23: =BE23/$BE$46*100% -> 0.89630582 | BG23: =-SUMIF('05.conso TB'!A:A,'May-26'!B23,'05.conso TB'!H:H)/10^5 -> 3942.6624 | BH23: =BG23/$BG$46*100% -> 0.83901799 | BI23: =BK23-'Apr-26'!BK23 -> 19.219115 | BJ23: =BI23/$BI$46*100% -> 1 | BK23: =-SUMIF('05.conso TB'!A:A,'May-26'!B23,'05.conso TB'!I:I)/10^5 -> 38.599737 | BL23: =BK23/$BK$46*100% -> 1.0000004 | BM23: =BO23-'Apr-26'!BO23 -> 0 | BN23: =BM23/$C$46*100% -> 0 | BO23: =-SUMIF('05.conso TB'!A:A,'May-26'!B23,'05.conso TB'!J:J)/10^5 -> 0 | BP23: =BO23/$C$46*100% -> 0 | BQ23: 0 | BR23: =BT23-'Apr-26'!BT23 -> 2524.3247 | BS23: =BR23/$BR$46*100% -> 0.95455775 | BT23: =BG23+BK23+BO23-BQ23 -> 3981.2621 | BU23: =BT23/$BT$46*100% -> 0.88714051 | BW23: =BY23-'Apr-26'!BY23 -> -5.448775 | BX23: =BW23/$BW$46*100% -> -0.012040756 | BY23: =-SUMIF('05.conso TB'!A:A,'May-26'!B23,'05.conso TB'!L:L)/10^5 -> -9.883575 | BZ23: =BY23/$BY$46*100% -> -0.0045738579 | CB23: =CC23-'Apr-26'!CC23 -> 4547.8678 | CC23: 9013.7446 | CE23: =AB23+AG23+AL23+AZ23+BR23+BW23-CA23 -> 9389.9881 | CF23: =CE23/$CE$46*100% -> 0.5554441 | CG23: =AD23+AI23+AN23+BB23+BT23+BY23-CC23 -> 9237.0285 | CH23: =CG23/$CG$46*100% -> 0.75530694
B24: Sale of traded goods | C24: =E24-'Apr-26'!E24 -> 955.64633 | D24: =C24/$C$46*100% -> 0.30590102 | E24: =-SUMIF('05.conso TB'!A:A,'May-26'!B24,'05.conso TB'!R:R)/10^5 -> 1352.4291 | F24: =E24/$E$46*100% -> 0.20931714 | G24: =I24-'Apr-26'!I24 -> 96.525998 | H24: =G24/$G$46*100% -> 0.072673904 | I24: =-SUMIF('05.conso TB'!A:A,'May-26'!B24,'05.conso TB'!S:S)/10^5 -> 216.41929 | J24: =I24/$I$46*100% -> 0.086238134 | K24: =M24-'Apr-26'!M24 -> 0 | L24: =K24/$C$46*100% -> 0 | M24: =-SUMIF('05.conso TB'!A:A,'May-26'!B24,'05.conso TB'!T:T) -> 0 | N24: =M24/$C$46*100% -> 0 | O24: =Q24-'Apr-26'!Q24 -> 16.909453 | P24: =O24/$O$46*100% -> 0.013614105 | Q24: =-SUMIF('05.conso TB'!A:A,'May-26'!B24,'05.conso TB'!U:U)/10^5 -> 31.66651 | R24: =Q24/$Q$46*100% -> 0.014533627 | S24: =U24-'Apr-26'!U24 -> 0 | T24: =S24/$S$46*100% -> 0 | U24: =-SUMIF('05.conso TB'!A:A,'May-26'!B24,'05.conso TB'!V:V)/10^5 -> 48.765062 | V24: =U24/$U$46*100% -> 1.0004615 | W24: =Y24-'Apr-26'!Y24 -> 3763.6996 | X24: =W24/$W$46*100% -> 1.0119789 | Y24: =-SUMIF('05.conso TB'!A:A,'May-26'!B24,'05.conso TB'!G:G)/10^5 -> 3837.7156 | Z24: =Y24/$Y$46*100% -> 1.0116251 | AA24: 286.05227 | AB24: =AD24-'Apr-26'!AD24 -> 4808.5836 | AC24: =AB24/$AB$46*100% -> 0.52145954 | AD24: =E24+I24+M24+Q24+U24+Y24-AA24 -> 5200.9433 | AE24: =AD24/$AD$46*100% -> 0.3598531 | AG24: =AI24-'Apr-26'!AI24 -> 0 | AH24: =AG24/$AG$46*100% -> 0 | AI24: =-SUMIF('05.conso TB'!A:A,'May-26'!B24,'05.conso TB'!Q:Q)/10^5 -> 0 | AJ24: =AI24/$AI$46*100% -> 0 | AL24: =AN24-'Apr-26'!AN24 -> 288.92677 | AM24: =AL24/$AL$46*100% -> 0.24397697 | AN24: =-SUMIF('05.conso TB'!A:A,'May-26'!B24,'05.conso TB'!W:W)/10^5 -> 418.00919 | AO24: =AN24/$AN$46*100% -> 0.1799942 | AQ24: =AS24-'Apr-26'!AS24 -> 6.9177273 | AR24: =AQ24/$AQ$46*100% -> 0.0033929938 | AS24: =-SUMIF('05.conso TB'!A:A,'May-26'!B24,'05.conso TB'!M:M)/10^5 -> 47.998801 | AT24: =AS24/$AS$46*100% -> 0.012401062 | AU24: =AW24-'Apr-26'!AW24 -> 998.58378 | AV24: =AU24/$C$46*100% -> 0.31964524 | AW24: =-SUMIF('05.conso TB'!A:A,'May-26'!B24,'05.conso TB'!P:P)/10^5 -> 1851.7416 | AX24: =AW24/$AW$46*100% -> 1.0024409 | AZ24: =BB24-'Apr-26'!BB24 -> 1005.5015 | BA24: =AZ24/$AZ$46*100% -> 0.33127954 | BB24: =AS24+AW24 -> 1899.7404 | BC24: =BB24/$BB$46*100% -> 0.33225185 | BE24: =BG24-'Apr-26'!BG24 -> 280.77199 | BF24: =BE24/$BE$46*100% -> 0.10045787 | BG24: =-SUMIF('05.conso TB'!A:A,'May-26'!B24,'05.conso TB'!H:H)/10^5 -> 701.17177 | BH24: =BG24/$BG$46*100% -> 0.14921281 | BI24: =BK24-'Apr-26'!BK24 -> 0 | BJ24: =BI24/$BI$46*100% -> 0 | BK24: =-SUMIF('05.conso TB'!A:A,'May-26'!B24,'05.conso TB'!I:I)/10^5 -> 0 | BL24: =BK24/$BK$46*100% -> 0 | BM24: =BO24-'Apr-26'!BO24 -> 0 | BN24: =BM24/$C$46*100% -> 0 | BO24: =-SUMIF('05.conso TB'!A:A,'May-26'!B24,'05.conso TB'!J:J)/10^5 -> 0 | BP24: =BO24/$C$46*100% -> 0 | BQ24: 250.06819 | BR24: =BT24-'Apr-26'!BT24 -> 111.12664 | BS24: =BR24/$BR$46*100% -> 0.04202185 | BT24: =BG24+BK24+BO24-BQ24 -> 451.10358 | BU24: =BT24/$BT$46*100% -> 0.10051894 | BW24: =BY24-'Apr-26'!BY24 -> 450.37712 | BX24: =BW24/$BW$46*100% -> 0.99524777 | BY24: =-SUMIF('05.conso TB'!A:A,'May-26'!B24,'05.conso TB'!L:L)/10^5 -> 2161.2577 | BZ24: =BY24/$BY$46*100% -> 1.0001731 | CB24: =CC24-'Apr-26'!CC24 -> 4633.0065 | CC24: 7261.0698 | CE24: =AB24+AG24+AL24+AZ24+BR24+BW24-CA24 -> 6664.5157 | CF24: =CE24/$CE$46*100% -> 0.39422477 | CG24: =AD24+AI24+AN24+BB24+BT24+BY24-CC24 -> 2869.9844 | CH24: =CG24/$CG$46*100% -> 0.23467711
B25: Total Revenue from operations | C25: =SUM(C23:C24) -> 3003.7067 | D25: =SUM(D23:D24) -> 0.9614822 | E25: =SUM(E23:E24) -> 6297.7736 | F25: =E25/$E$46*100% -> 0.97471431 | G25: =SUM(G23:G24) -> 1155.7061 | H25: =G25/$G$46*100% -> 0.8701249 | I25: =SUM(I23:I24) -> 2289.5395 | J25: =I25/$I$46*100% -> 0.91232908 | K25: =SUM(K23:K24) -> 0 | L25: =SUM(L23:L24) -> 0 | M25: =SUM(M23:M24) -> 0 | N25: =SUM(N23:N24) -> 0 | O25: =SUM(O23:O24) -> 1242.0539 | P25: =O25/$O$46*100% -> 0.99999998 | Q25: =SUM(Q23:Q24) -> 2178.8443 | R25: =Q25/$Q$46*100% -> 0.99999999 | S25: =SUM(S23:S24) -> 0 | T25: =S25/$S$46*100% -> 0 | U25: =SUM(U23:U24) -> 48.765062 | V25: =U25/$U$46*100% -> 1.0004615 | W25: =SUM(W23:W24) -> 3763.6996 | X25: =W25/$W$46*100% -> 1.0119789 | Y25: =SUM(Y23:Y24) -> 3837.7156 | Z25: =Y25/$Y$46*100% -> 1.0116251 | AA25: =SUM(AA23:AA24) -> 603.62492 | AB25: =SUM(AB23:AB24) -> 8949.7723 | AC25: =AB25/$AB$46*100% -> 0.97054444 | AD25: =SUM(AD23:AD24) -> 14049.013 | AE25: =AD25/$AD$46*100% -> 0.97205078 | AG25: =SUM(AG23:AG24) -> 95.60983 | AH25: =AG25/$AG$46*100% -> 0.26015644 | AI25: =SUM(AI23:AI24) -> 184.39779 | AJ25: =SUM(AJ23:AJ24) -> 0.2498606 | AL25: =SUM(AL23:AL24) -> 942.7205 | AM25: =AL25/$AL$46*100% -> 0.79605669 | AN25: =SUM(AN23:AN24) -> 1896.0883 | AO25: =SUM(AO23:AO24) -> 0.81645308 | AQ25: =SUM(AQ23:AQ24) -> 1989.6513 | AR25: =AQ25/$AQ$46*100% -> 0.97588041 | AS25: =SUM(AS23:AS24) -> 3821.3639 | AT25: =SUM(AT23:AT24) -> 0.9872949 | AU25: =SUM(AU23:AU24) -> 996.37022 | AV25: =SUM(AV23:AV24) -> 0.31742363 | AW25: =SUM(AW23:AW24) -> 1847.2243 | AX25: =SUM(AX23:AX24) -> 0.99999545 | AY25: =SUM(AY23:AY24) -> 0 | AZ25: =SUM(AZ23:AZ24) -> 2986.0215 | BA25: =AZ25/$AZ$46*100% -> 0.98379547 | BB25: =SUM(BB23:BB24) -> 5668.5882 | BC25: =SUM(BC23:BC24) -> 0.99139805 | BE25: =SUM(BE23:BE24) -> 2785.8775 | BF25: =BE25/$BE$46*100% -> 0.99676369 | BG25: =SUM(BG23:BG24) -> 4643.8342 | BH25: =SUM(BH23:BH24) -> 0.9882308 | BI25: =SUM(BI23:BI24) -> 19.219115 | BJ25: =BI25/$BI$46*100% -> 1 | BK25: =SUM(BK23:BK24) -> 38.599737 | BL25: =SUM(BL23:BL24) -> 1.0000004 | BM25: =SUM(BM23:BM24) -> 0 | BN25: =SUM(BN23:BN24) -> 0 | BO25: =SUM(BO23:BO24) -> 0 | BP25: =SUM(BP23:BP24) -> 0 | BQ25: =SUM(BQ23:BQ24) -> 250.06819 | BR25: =SUM(BR23:BR24) -> 2635.4513 | BS25: =BR25/$BR$46*100% -> 0.9965796 | BT25: =BG25+BK25+BO25-BQ25 -> 4432.3657 | BU25: =BT25/$BT$46*100% -> 0.98765945 | BW25: =SUM(BW23:BW24) -> 444.92835 | BX25: =BW25/$BW$46*100% -> 0.98320701 | BY25: =SUM(BY23:BY24) -> 2151.3742 | BZ25: =BY25/$BY$46*100% -> 0.99559924 | CB25: =SUM(CB23:CB24) -> 9180.8743 | CC25: =SUM(CC23:CC24) -> 16274.814 | CE25: =SUM(CE23:CE24) -> 16054.504 | CF25: =CE25/$CE$46*100% -> 0.94966887 | CG25: =SUM(CG23:CG24) -> 12107.013 | CH25: =CG25/$CG$46*100% -> 0.98998404
B26: Sale of services | F26: =E26/$E$46*100% -> 0 | H26: =G26/$G$46*100% -> 0 | J26: =I26/$I$46*100% -> 0 | P26: =O26/$O$46*100% -> 0 | R26: =Q26/$Q$46*100% -> 0 | T26: =S26/$S$46*100% -> 0 | V26: =U26/$U$46*100% -> 0 | X26: =W26/$W$46*100% -> 0 | Z26: =Y26/$Y$46*100% -> 0 | AC26: =AB26/$AB$46*100% -> 0 | AE26: =AD26/$AD$46*100% -> 0 | AH26: =AG26/$AG$46*100% -> 0 | AM26: =AL26/$AL$46*100% -> 0 | AR26: =AQ26/$AQ$46*100% -> 0 | BA26: =AZ26/$AZ$46*100% -> 0 | BF26: =BE26/$BE$46*100% -> 0 | BJ26: =BI26/$BI$46*100% -> 0 | BS26: =BR26/$BR$46*100% -> 0 | BT26: =BG26+BK26+BO26-BQ26 -> 0 | BU26: =BT26/$BT$46*100% -> 0 | BX26: =BW26/$BW$46*100% -> 0 | BZ26: =BY26/$BY$46*100% -> 0 | CF26: =CE26/$CE$46*100% -> 0 | CH26: =CG26/$CG$46*100% -> 0
B27: Income from Jobwork charges | C27: =E27-'Apr-26'!E27 -> 104.42654 | D27: =C27/$C$46*100% -> 0.033426787 | E27: =-SUMIF('05.conso TB'!A:A,'May-26'!B27,'05.conso TB'!R:R)/10^5 -> 138.36163 | F27: =E27/$E$46*100% -> 0.021414403 | G27: =I27-'Apr-26'!I27 -> 158.09572 | H27: =G27/$G$46*100% -> 0.11902941 | I27: =-SUMIF('05.conso TB'!A:A,'May-26'!B27,'05.conso TB'!S:S)/10^5 -> 196.36106 | J27: =I27/$I$46*100% -> 0.078245388 | K27: =M27-'Apr-26'!M27 -> 0 | L27: =K27/$C$46*100% -> 0 | M27: =-SUMIF('05.conso TB'!A:A,'May-26'!B27,'05.conso TB'!T:T) -> 0 | N27: =M27/$C$46*100% -> 0 | O27: =Q27-'Apr-26'!Q27 -> 0 | P27: =O27/$O$46*100% -> 0 | Q27: =-SUMIF('05.conso TB'!A:A,'May-26'!B27,'05.conso TB'!U:U)/10^5 -> 0 | R27: =Q27/$Q$46*100% -> 0 | S27: =U27-'Apr-26'!U27 -> 0 | T27: =S27/$S$46*100% -> 0 | U27: =-SUMIF('05.conso TB'!A:A,'May-26'!B27,'05.conso TB'!V:V)/10^5 -> 0 | V27: =U27/$U$46*100% -> 0 | W27: =Y27-'Apr-26'!Y27 -> 0 | X27: =W27/$W$46*100% -> 0 | Y27: =-SUMIF('05.conso TB'!A:A,'May-26'!B27,'05.conso TB'!G:G)/10^5 -> 0 | Z27: =Y27/$Y$46*100% -> 0 | AB27: =AD27-'Apr-26'!AD27 -> 262.52226 | AC27: =AB27/$AB$46*100% -> 0.028468827 | AD27: =E27+I27+M27+Q27+U27+Y27 -> 334.7227 | AE27: =AD27/$AD$46*100% -> 0.023159453 | AG27: =AI27-'Apr-26'!AI27 -> 271.89915 | AH27: =AG27/$AG$46*100% -> 0.73984355 | AI27: =-SUMIF('05.conso TB'!A:A,'May-26'!B27,'05.conso TB'!Q:Q)/10^5 -> 553.60487 | AJ27: =AI27/$AI$46*100% -> 0.75013939 | AL27: =AN27-'Apr-26'!AN27 -> 235.35333 | AM27: =AL27/$AL$46*100% -> 0.19873822 | AN27: =-SUMIF('05.conso TB'!A:A,'May-26'!B27,'05.conso TB'!W:W)/10^5 -> 418.92558 | AO27: =AN27/$AN$46*100% -> 0.1803888 | AQ27: =AS27-'Apr-26'!AS27 -> 51.17576 | AR27: =AQ27/$AQ$46*100% -> 0.02510059 | AS27: =-SUMIF('05.conso TB'!A:A,'May-26'!B27,'05.conso TB'!M:M)/10^5 -> 51.17576 | AT27: =AS27/$AS$46*100% -> 0.013221867 | AU27: =AW27-'Apr-26'!AW27 -> 0 | AV27: =AU27/$C$46*100% -> 0 | AW27: =-SUMIF('05.conso TB'!A:A,'May-26'!B27,'05.conso TB'!P:P)/10^5 -> 0 | AX27: =AW27/$AW$46*100% -> 0 | AZ27: =BB27-'Apr-26'!BB27 -> 51.17576 | BA27: =AZ27/$AZ$46*100% -> 0.016860723 | BB27: =AS27+AW27 -> 51.17576 | BC27: =BB27/$BB$46*100% -> 0.0089502971 | BE27: =BG27-'Apr-26'!BG27 -> 8.799365 | BF27: =BE27/$BE$46*100% -> 0.0031483392 | BG27: =-SUMIF('05.conso TB'!A:A,'May-26'!B27,'05.conso TB'!H:H)/10^5 -> 54.608609 | BH27: =BG27/$BG$46*100% -> 0.011620981 | BI27: =BK27-'Apr-26'!BK27 -> 0 | BJ27: =BI27/$BI$46*100% -> 0 | BK27: =-SUMIF('05.conso TB'!A:A,'May-26'!B27,'05.conso TB'!I:I)/10^5 -> 0 | BL27: =BK27/$BK$46*100% -> 0 | BM27: =BO27-'Apr-26'!BO27 -> 0 | BN27: =BM27/$C$46*100% -> 0 | BO27: =-SUMIF('05.conso TB'!A:A,'May-26'!B27,'05.conso TB'!J:J)/10^5 -> 0 | BP27: =BO27/$C$46*100% -> 0 | BQ27: 0 | BR27: =BT27-'Apr-26'!BT27 -> 8.799365 | BS27: =BR27/$BR$46*100% -> 0.0033274254 | BT27: =BG27+BK27+BO27-BQ27 -> 54.608609 | BU27: =BT27/$BT$46*100% -> 0.01216838 | BW27: =BY27-'Apr-26'!BY27 -> 0 | BX27: =BW27/$BW$46*100% -> 0 | BY27: =-SUMIF('05.conso TB'!A:A,'May-26'!B27,'05.conso TB'!L:L)/10^5 -> 0 | BZ27: =BY27/$BY$46*100% -> 0 | CB27: =CC27-'Apr-26'!CC27 -> 848.4175 | CC27: 1375.3983 | CE27: =AB27+AG27+AL27+AZ27+BR27+BW27-CA27 -> 829.74987 | CF27: =CE27/$CE$46*100% -> 0.049082029 | CG27: =AD27+AI27+AN27+BB27+BT27+BY27-CC27 -> 37.639178 | CH27: =CG27/$CG$46*100% -> 0.0030777357
B28: Total Sales of services | C28: =E28-'Apr-26'!E28 -> 104.42654 | D28: =SUM(D27) -> 0.033426787 | E28: =SUM(E27) -> 138.36163 | F28: =E28/$E$46*100% -> 0.021414403 | G28: =I28-'Apr-26'!I28 -> 158.09572 | H28: =G28/$G$46*100% -> 0.11902941 | I28: =SUM(I27) -> 196.36106 | J28: =I28/$I$46*100% -> 0.078245388 | K28: =M28-'Apr-26'!M28 -> 0 | L28: =SUM(L27) -> 0 | M28: =SUM(M27) -> 0 | N28: =SUM(N27) -> 0 | O28: =Q28-'Apr-26'!Q28 -> 0 | P28: =O28/$O$46*100% -> 0 | Q28: =Q27 -> 0 | R28: =Q28/$Q$46*100% -> 0 | S28: =U28-'Apr-26'!U28 -> 0 | T28: =S28/$S$46*100% -> 0 | U28: =-SUMIF('05.conso TB'!A:A,'May-26'!B28,'05.conso TB'!V:V)/10^5 -> 0 | V28: =U28/$U$46*100% -> 0 | W28: =Y28-'Apr-26'!Y28 -> 0 | X28: =W28/$W$46*100% -> 0 | Y28: =-SUMIF('05.conso TB'!A:A,'May-26'!B28,'05.conso TB'!G:G)/10^5 -> 0 | Z28: =Y28/$Y$46*100% -> 0 | AA28: =SUM(AA27) -> 0 | AB28: =AD28-'Apr-26'!AD28 -> 262.52226 | AC28: =AB28/$AB$46*100% -> 0.028468827 | AD28: =SUM(AD27) -> 334.7227 | AE28: =AD28/$AD$46*100% -> 0.023159453 | AG28: =AI28-'Apr-26'!AI28 -> 271.89915 | AH28: =AG28/$AG$46*100% -> 0.73984355 | AI28: =SUM(AI27) -> 553.60487 | AJ28: =SUM(AJ27) -> 0.75013939 | AL28: =AN28-'Apr-26'!AN28 -> 235.35333 | AM28: =AL28/$AL$46*100% -> 0.19873822 | AN28: =AN27 -> 418.92558 | AO28: =SUM(AO27) -> 0.1803888 | AP28: =AQ28/$AQ$1*10^5 -> 8.5717952 | AQ28: =AS28-'Apr-26'!AS28 -> 51.17576 | AR28: =AQ28/$AQ$46*100% -> 0.02510059 | AS28: =SUM(AS27) -> 51.17576 | AT28: =SUM(AT27) -> 0.013221867 | AU28: =AW28-'Apr-26'!AW28 -> 0 | AV28: =SUM(AV27) -> 0 | AW28: =SUM(AW27) -> 0 | AX28: =SUM(AX27) -> 0 | AZ28: =BB28-'Apr-26'!BB28 -> 51.17576 | BA28: =AZ28/$AZ$46*100% -> 0.016860723 | BB28: =SUM(BB27) -> 51.17576 | BC28: =SUM(BC27) -> 0.0089502971 | BE28: =BG28-'Apr-26'!BG28 -> 8.799365 | BF28: =BE28/$BE$46*100% -> 0.0031483392 | BG28: =SUM(BG27) -> 54.608609 | BH28: =SUM(BH27) -> 0.011620981 | BI28: =BK28-'Apr-26'!BK28 -> 0 | BJ28: =BI28/$BI$46*100% -> 0 | BK28: =SUM(BK27) -> 0 | BL28: =SUM(BL27) -> 0 | BM28: =BO28-'Apr-26'!BO28 -> 0 | BN28: =SUM(BN27) -> 0 | BO28: =SUM(BO27) -> 0 | BP28: =SUM(BP27) -> 0 | BQ28: =BQ27 -> 0 | BR28: =BT28-'Apr-26'!BT28 -> 8.799365 | BS28: =BR28/$BR$46*100% -> 0.0033274254 | BT28: =BG28+BK28+BO28-BQ28 -> 54.608609 | BU28: =BT28/$BT$46*100% -> 0.01216838 | BW28: =BY28-'Apr-26'!BY28 -> 0 | BX28: =BW28/$BW$46*100% -> 0 | BY28: =SUM(BY27) -> 0 | BZ28: =BY28/$BY$46*100% -> 0 | CB28: =CC28-'Apr-26'!CC28 -> 848.4175 | CC28: =SUM(CC27) -> 1375.3983 | CE28: =SUM(CE27) -> 829.74987 | CF28: =CE28/$CE$46*100% -> 0.049082029 | CG28: =SUM(CG27) -> 37.639178 | CH28: =CG28/$CG$46*100% -> 0.0030777357
B29: Other operating revenue | C29: =E29-'Apr-26'!E29 -> 0 | F29: =E29/$E$46*100% -> 0 | G29: =I29-'Apr-26'!I29 -> 0 | H29: =G29/$G$46*100% -> 0 | J29: =I29/$I$46*100% -> 0 | K29: =M29-'Apr-26'!M29 -> 0 | O29: =Q29-'Apr-26'!Q29 -> 0 | P29: =O29/$O$46*100% -> 0 | Q29: =-SUMIF('05.conso TB'!A:A,'May-26'!B29,'05.conso TB'!U:U)/10^5 -> 0 | R29: =Q29/$Q$46*100% -> 0 | S29: =U29-'Apr-26'!U29 -> 0 | T29: =S29/$S$46*100% -> 0 | U29: =-SUMIF('05.conso TB'!A:A,'May-26'!B29,'05.conso TB'!V:V)/10^5 -> 0 | V29: =U29/$U$46*100% -> 0 | W29: =Y29-'Apr-26'!Y29 -> 0 | X29: =W29/$W$46*100% -> 0 | Y29: =-SUMIF('05.conso TB'!A:A,'May-26'!B29,'05.conso TB'!G:G)/10^5 -> 0 | Z29: =Y29/$Y$46*100% -> 0 | AB29: =AD29-'Apr-26'!AD29 -> 0 | AC29: =AB29/$AB$46*100% -> 0 | AE29: =AD29/$AD$46*100% -> 0 | AG29: =AI29-'Apr-26'!AI29 -> 0 | AH29: =AG29/$AG$46*100% -> 0 | AI29: =-SUMIF('05.conso TB'!A:A,'May-26'!B29,'05.conso TB'!Q:Q)/10^5 -> 0 | AL29: =AN29-'Apr-26'!AN29 -> 0 | AM29: =AL29/$AL$46*100% -> 0 | AN29: =-SUMIF('05.conso TB'!A:A,'May-26'!B29,'05.conso TB'!W:W)/10^5 -> 0 | AQ29: =AS29-'Apr-26'!AS29 -> 0 | AR29: =AQ29/$AQ$46*100% -> 0 | AU29: =AW29-'Apr-26'!AW29 -> 0 | AZ29: =BB29-'Apr-26'!BB29 -> 0 | BA29: =AZ29/$AZ$46*100% -> 0 | BE29: =BG29-'Apr-26'!BG29 -> 0 | BF29: =BE29/$BE$46*100% -> 0 | BI29: =BK29-'Apr-26'!BK29 -> 0 | BJ29: =BI29/$BI$46*100% -> 0 | BM29: =BO29-'Apr-26'!BO29 -> 0 | BR29: =BT29-'Apr-26'!BT29 -> 0 | BS29: =BR29/$BR$46*100% -> 0 | BT29: =BG29+BK29+BO29-BQ29 -> 0 | BU29: =BT29/$BT$46*100% -> 0 | BW29: =BY29-'Apr-26'!BY29 -> 0 | BX29: =BW29/$BW$46*100% -> 0 | BZ29: =BY29/$BY$46*100% -> 0 | CB29: =CD29-'Apr-26'!CD29 -> 0 | CF29: =CE29/$CE$46*100% -> 0 | CH29: =CG29/$CG$46*100% -> 0
B30: Export incentives | C30: =E30-'Apr-26'!E30 -> 0 | D30: =C30/$C$46*100% -> 0 | E30: =-SUMIF('05.conso TB'!A:A,'May-26'!B30,'05.conso TB'!R:R)/10^5 -> 0 | F30: =E30/$E$46*100% -> 0 | G30: =I30-'Apr-26'!I30 -> 0 | H30: =G30/$G$46*100% -> 0 | I30: =-SUMIF('05.conso TB'!A:A,'May-26'!B30,'05.conso TB'!S:S)/10^5 -> 0 | J30: =I30/$I$46*100% -> 0 | K30: =M30-'Apr-26'!M30 -> 0 | L30: =K30/$C$46*100% -> 0 | M30: =-SUMIF('05.conso TB'!A:A,'May-26'!B30,'05.conso TB'!T:T) -> 0 | N30: =M30/$C$46*100% -> 0 | O30: =Q30-'Apr-26'!Q30 -> 0 | P30: =O30/$O$46*100% -> 0 | Q30: =-SUMIF('05.conso TB'!A:A,'May-26'!B30,'05.conso TB'!U:U)/10^5 -> 0 | R30: =Q30/$Q$46*100% -> 0 | S30: =U30-'Apr-26'!U30 -> 0 | T30: =S30/$S$46*100% -> 0 | U30: =-SUMIF('05.conso TB'!A:A,'May-26'!B30,'05.conso TB'!V:V)/10^5 -> 0 | V30: =U30/$U$46*100% -> 0 | W30: =Y30-'Apr-26'!Y30 -> 0 | X30: =W30/$W$46*100% -> 0 | Y30: =-SUMIF('05.conso TB'!A:A,'May-26'!B30,'05.conso TB'!G:G)/10^5 -> 0 | Z30: =Y30/$Y$46*100% -> 0 | AB30: =AD30-'Apr-26'!AD30 -> 0 | AC30: =AB30/$AB$46*100% -> 0 | AD30: =E30+I30+M30+Q30+U30+Y30 -> 0 | AE30: =AD30/$AD$46*100% -> 0 | AG30: =AI30-'Apr-26'!AI30 -> 0 | AH30: =AG30/$AG$46*100% -> 0 | AI30: =-SUMIF('05.conso TB'!A:A,'May-26'!B30,'05.conso TB'!Q:Q)/10^5 -> 0 | AJ30: =AI30/$AI$46*100% -> 0 | AL30: =AN30-'Apr-26'!AN30 -> 0 | AM30: =AL30/$AL$46*100% -> 0 | AN30: =-SUMIF('05.conso TB'!A:A,'May-26'!B30,'05.conso TB'!W:W)/10^5 -> 0 | AO30: =AN30/$AN$46*100% -> 0 | AQ30: =AS30-'Apr-26'!AS30 -> 0 | AR30: =AQ30/$AQ$46*100% -> 0 | AS30: =-SUMIF('05.conso TB'!A:A,'May-26'!B30,'05.conso TB'!M:M)/10^5 -> 0 | AT30: =AS30/$AS$46*100% -> 0 | AU30: =AW30-'Apr-26'!AW30 -> 0 | AV30: =AU30/$C$46*100% -> 0 | AW30: =-SUMIF('05.conso TB'!A:A,'May-26'!B30,'05.conso TB'!P:P)/10^5 -> 0 | AX30: =AW30/$AW$46*100% -> 0 | AZ30: =BB30-'Apr-26'!BB30 -> 0 | BA30: =AZ30/$AZ$46*100% -> 0 | BB30: =AS30+AW30 -> 0 | BC30: =BB30/$BB$46*100% -> 0 | BE30: =BG30-'Apr-26'!BG30 -> 0 | BF30: =BE30/$BE$46*100% -> 0 | BG30: =-SUMIF('05.conso TB'!A:A,'May-26'!B30,'05.conso TB'!H:H)/10^5 -> 0.21065 | BH30: =BG30/$BG$46*100% -> 4.4827359e-05 | BI30: =BK30-'Apr-26'!BK30 -> 0 | BJ30: =BI30/$BI$46*100% -> 0 | BK30: =-SUMIF('05.conso TB'!A:A,'May-26'!B30,'05.conso TB'!I:I)/10^5 -> 0 | BL30: =BK30/$BK$46*100% -> 0 | BM30: =BO30-'Apr-26'!BO30 -> 0 | BN30: =BM30/$C$46*100% -> 0 | BO30: =-SUMIF('05.conso TB'!A:A,'May-26'!B30,'05.conso TB'!J:J)/10^5 -> 0 | BP30: =BO30/$C$46*100% -> 0 | BR30: =BT30-'Apr-26'!BT30 -> 0 | BS30: =BR30/$BR$46*100% -> 0 | BT30: =BG30+BK30+BO30-BQ30 -> 0.21065 | BU30: =BT30/$BT$46*100% -> 4.6938921e-05 | BW30: =BY30-'Apr-26'!BY30 -> 0 | BX30: =BW30/$BW$46*100% -> 0 | BY30: =-SUMIF('05.conso TB'!A:A,'May-26'!B30,'05.conso TB'!L:L)/10^5 -> 0 | BZ30: =BY30/$BY$46*100% -> 0 | CB30: =CD30-'Apr-26'!CD30 -> 0 | CE30: =AB30+AG30+AL30+AZ30+BR30+BW30 -> 0 | CF30: =CE30/$CE$46*100% -> 0 | CG30: =AD30+AI30+AN30+BB30+BT30+BY30 -> 0.21065 | CH30: =CG30/$CG$46*100% -> 1.7224739e-05
B31: Commission income | C31: =E31-'Apr-26'!E31 -> 0 | D31: =C31/$C$46*100% -> 0 | E31: =-SUMIF('05.conso TB'!A:A,'May-26'!B31,'05.conso TB'!R:R) -> 0 | F31: =E31/$E$46*100% -> 0 | G31: =I31-'Apr-26'!I31 -> 0 | H31: =G31/$G$46*100% -> 0 | I31: =-SUMIF('05.conso TB'!A:A,'May-26'!B31,'05.conso TB'!S:S)/10^5 -> 0 | J31: =I31/$I$46*100% -> 0 | K31: =M31-'Apr-26'!M31 -> 7.41585 | L31: =K31/$C$46*100% -> 0.002373803 | M31: =-SUMIF('05.conso TB'!A:A,'May-26'!B31,'05.conso TB'!T:T)/10^5 -> 26.462942 | N31: =M31/$C$46*100% -> 0.0084707498 | O31: =Q31-'Apr-26'!Q31 -> 0 | P31: =O31/$O$46*100% -> 0 | Q31: =-SUMIF('05.conso TB'!A:A,'May-26'!B31,'05.conso TB'!U:U)/10^5 -> 0 | R31: =Q31/$Q$46*100% -> 0 | S31: =U31-'Apr-26'!U31 -> 0 | T31: =S31/$S$46*100% -> 0 | U31: =-SUMIF('05.conso TB'!A:A,'May-26'!B31,'05.conso TB'!V:V)/10^5 -> 0 | V31: =U31/$U$46*100% -> 0 | W31: =Y31-'Apr-26'!Y31 -> 0 | X31: =W31/$W$46*100% -> 0 | Y31: =-SUMIF('05.conso TB'!A:A,'May-26'!B31,'05.conso TB'!G:G)/10^5 -> 0 | Z31: =Y31/$Y$46*100% -> 0 | AB31: =AD31-'Apr-26'!AD31 -> 7.41585 | AC31: =AB31/$AB$46*100% -> 0.00080420057 | AD31: =E31+I31+M31+Q31+U31+Y31 -> 26.462942 | AE31: =AD31/$AD$46*100% -> 0.0018309701 | AG31: =AI31-'Apr-26'!AI31 -> 0 | AH31: =AG31/$AG$46*100% -> 0 | AI31: =-SUMIF('05.conso TB'!A:A,'May-26'!B31,'05.conso TB'!Q:Q)/10^5 -> 0 | AJ31: =AI31/$AI$46*100% -> 0 | AL31: =AN31-'Apr-26'!AN31 -> 0 | AM31: =AL31/$AL$46*100% -> 0 | AN31: =-SUMIF('05.conso TB'!A:A,'May-26'!B31,'05.conso TB'!W:W)/10^5 -> 0 | AO31: =AN31/$AN$46*100% -> 0 | AQ31: =AS31-'Apr-26'!AS31 -> 0 | AR31: =AQ31/$AQ$46*100% -> 0 | AS31: =-SUMIF('05.conso TB'!A:A,'May-26'!B31,'05.conso TB'!M:M)/10^5 -> 0 | AT31: =AS31/$AS$46*100% -> 0 | AU31: =AW31-'Apr-26'!AW31 -> 0 | AV31: =AU31/$C$46*100% -> 0 | AW31: =-SUMIF('05.conso TB'!A:A,'May-26'!B31,'05.conso TB'!P:P)/10^5 -> 0 | AX31: =AW31/$AW$46*100% -> 0 | AZ31: =BB31-'Apr-26'!BB31 -> 0 | BA31: =AZ31/$AZ$46*100% -> 0 | BB31: =AS31+AW31 -> 0 | BC31: =BB31/$BB$46*100% -> 0 | BE31: =BG31-'Apr-26'!BG31 -> 0 | BF31: =BE31/$BE$46*100% -> 0 | BG31: =-SUMIF('05.conso TB'!A:A,'May-26'!B31,'05.conso TB'!H:H)/10^5 -> 0 | BH31: =BG31/$BG$46*100% -> 0 | BI31: =BK31-'Apr-26'!BK31 -> 0 | BJ31: =BI31/$BI$46*100% -> 0 | BK31: =-SUMIF('05.conso TB'!A:A,'May-26'!B31,'05.conso TB'!I:I)/10^5 -> 0 | BL31: =BK31/$BK$46*100% -> 0 | BM31: =BO31-'Apr-26'!BO31 -> 0 | BN31: =BM31/$C$46*100% -> 0 | BO31: =-SUMIF('05.conso TB'!A:A,'May-26'!B31,'05.conso TB'!J:J)/10^5 -> 0 | BP31: =BO31/$C$46*100% -> 0 | BR31: =BT31-'Apr-26'!BT31 -> 0 | BS31: =BR31/$BR$46*100% -> 0 | BT31: =BG31+BK31+BO31-BQ31 -> 0 | BU31: =BT31/$BT$46*100% -> 0 | BW31: =BY31-'Apr-26'!BY31 -> 0 | BX31: =BW31/$BW$46*100% -> 0 | BY31: =-SUMIF('05.conso TB'!A:A,'May-26'!B31,'05.conso TB'!L:L)/10^5 -> 0 | BZ31: =BY31/$BY$46*100% -> 0 | CB31: =CD31-'Apr-26'!CD31 -> 0 | CE31: =AB31+AG31+AL31+AZ31+BR31+BW31 -> 7.41585 | CF31: =CE31/$CE$46*100% -> 0.0004386683 | CG31: =AD31+AI31+AN31+BB31+BT31+BY31 -> 26.462942 | CH31: =CG31/$CG$46*100% -> 0.0021638608
B32: Scrap sales | C32: =E32-'Apr-26'!E32 -> 0 | D32: =C32/$C$46*100% -> 0 | E32: =-SUMIF('05.conso TB'!A:A,'May-26'!B32,'05.conso TB'!R:R) -> 0 | F32: =E32/$E$46*100% -> 0 | G32: =I32-'Apr-26'!I32 -> 0 | H32: =G32/$G$46*100% -> 0 | I32: =-SUMIF('05.conso TB'!A:A,'May-26'!B32,'05.conso TB'!S:S)/10^5 -> 0 | J32: =I32/$I$46*100% -> 0 | K32: =M32-'Apr-26'!M32 -> 0 | L32: =K32/$C$46*100% -> 0 | M32: =-SUMIF('05.conso TB'!A:A,'May-26'!B32,'05.conso TB'!T:T) -> 0 | N32: =M32/$C$46*100% -> 0 | O32: =Q32-'Apr-26'!Q32 -> 0 | P32: =O32/$O$46*100% -> 0 | Q32: =-SUMIF('05.conso TB'!A:A,'May-26'!B32,'05.conso TB'!U:U)/10^5 -> 0 | R32: =Q32/$Q$46*100% -> 0 | S32: =U32-'Apr-26'!U32 -> 0 | T32: =S32/$S$46*100% -> 0 | U32: =-SUMIF('05.conso TB'!A:A,'May-26'!B32,'05.conso TB'!V:V)/10^5 -> 0 | V32: =U32/$U$46*100% -> 0 | W32: =Y32-'Apr-26'!Y32 -> 0 | X32: =W32/$W$46*100% -> 0 | Y32: =-SUMIF('05.conso TB'!A:A,'May-26'!B32,'05.conso TB'!G:G)/10^5 -> 0 | Z32: =Y32/$Y$46*100% -> 0 | AB32: =AD32-'Apr-26'!AD32 -> 0 | AC32: =AB32/$AB$46*100% -> 0 | AD32: =E32+I32+M32+Q32+U32+Y32 -> 0 | AE32: =AD32/$AD$46*100% -> 0 | AG32: =AI32-'Apr-26'!AI32 -> 0 | AH32: =AG32/$AG$46*100% -> 0 | AI32: =-SUMIF('05.conso TB'!A:A,'May-26'!B32,'05.conso TB'!Q:Q)/10^5 -> 0 | AJ32: =AI32/$AI$46*100% -> 0 | AL32: =AN32-'Apr-26'!AN32 -> 0 | AM32: =AL32/$AL$46*100% -> 0 | AN32: =-SUMIF('05.conso TB'!A:A,'May-26'!B32,'05.conso TB'!W:W)/10^5 -> 0 | AO32: =AN32/$AN$46*100% -> 0 | AQ32: =AS32-'Apr-26'!AS32 -> 0 | AR32: =AQ32/$AQ$46*100% -> 0 | AS32: =-SUMIF('05.conso TB'!A:A,'May-26'!B32,'05.conso TB'!M:M)/10^5 -> 0 | AT32: =AS32/$AS$46*100% -> 0 | AU32: =AW32-'Apr-26'!AW32 -> 0 | AV32: =AU32/$C$46*100% -> 0 | AW32: =-SUMIF('05.conso TB'!A:A,'May-26'!B32,'05.conso TB'!P:P)/10^5 -> 0 | AX32: =AW32/$AW$46*100% -> 0 | AZ32: =BB32-'Apr-26'!BB32 -> 0 | BA32: =AZ32/$AZ$46*100% -> 0 | BB32: =AS32+AW32 -> 0 | BC32: =BB32/$BB$46*100% -> 0 | BE32: =BG32-'Apr-26'!BG32 -> 0 | BF32: =BE32/$BE$46*100% -> 0 | BG32: =-SUMIF('05.conso TB'!A:A,'May-26'!B32,'05.conso TB'!H:H)/10^5 -> 0 | BH32: =BG32/$BG$46*100% -> 0 | BI32: =BK32-'Apr-26'!BK32 -> 0 | BJ32: =BI32/$BI$46*100% -> 0 | BK32: =-SUMIF('05.conso TB'!A:A,'May-26'!B32,'05.conso TB'!I:I)/10^5 -> 0 | BL32: =BK32/$BK$46*100% -> 0 | BM32: =BO32-'Apr-26'!BO32 -> 0 | BN32: =BM32/$C$46*100% -> 0 | BO32: =-SUMIF('05.conso TB'!A:A,'May-26'!B32,'05.conso TB'!J:J)/10^5 -> 0 | BP32: =BO32/$C$46*100% -> 0 | BR32: =BT32-'Apr-26'!BT32 -> 0 | BS32: =BR32/$BR$46*100% -> 0 | BT32: =BG32+BK32+BO32-BQ32 -> 0 | BU32: =BT32/$BT$46*100% -> 0 | BW32: =BY32-'Apr-26'!BY32 -> 0 | BX32: =BW32/$BW$46*100% -> 0 | BY32: =-SUMIF('05.conso TB'!A:A,'May-26'!B32,'05.conso TB'!L:L)/10^5 -> 0 | BZ32: =BY32/$BY$46*100% -> 0 | CB32: =CD32-'Apr-26'!CD32 -> 0 | CE32: =AB32+AG32+AL32+AZ32+BR32+BW32 -> 0 | CF32: =CE32/$CE$46*100% -> 0 | CG32: =AD32+AI32+AN32+BB32+BT32+BY32 -> 0 | CH32: =CG32/$CG$46*100% -> 0
B33: Total Other operating revenue | C33: =SUM(C30:C32) -> 0 | D33: =SUM(D30:D32) -> 0 | E33: =SUM(E30:E32) -> 0 | F33: =E33/$E$46*100% -> 0 | G33: =SUM(G30:G32) -> 0 | H33: =G33/$G$46*100% -> 0 | I33: =-SUMIF('05.conso TB'!A:A,'May-26'!B33,'05.conso TB'!S:S)/10^5 -> 0 | J33: =I33/$I$46*100% -> 0 | K33: =SUM(K30:K32) -> 7.41585 | L33: =SUM(L30:L32) -> 0.002373803 | M33: =SUM(M30:M32) -> 26.462942 | N33: =SUM(N30:N32) -> 0.0084707498 | O33: =SUM(O30:O32) -> 0 | P33: =O33/$O$46*100% -> 0 | Q33: =SUM(Q30:Q32) -> 0 | R33: =Q33/$Q$46*100% -> 0 | S33: =SUM(S30:S32) -> 0 | T33: =S33/$S$46*100% -> 0 | U33: =SUM(U30:U32) -> 0 | V33: =U33/$U$46*100% -> 0 | W33: =SUM(W30:W32) -> 0 | X33: =W33/$W$46*100% -> 0 | Y33: =SUM(Y30:Y32) -> 0 | Z33: =Y33/$Y$46*100% -> 0 | AA33: =SUM(AA30:AA32) -> 0 | AB33: =SUM(AB30:AB32) -> 7.41585 | AC33: =AB33/$AB$46*100% -> 0.00080420057 | AD33: =SUM(AD30:AD32) -> 26.462942 | AE33: =AD33/$AD$46*100% -> 0.0018309701 | AG33: =SUM(AG30:AG32) -> 0 | AH33: =AG33/$AG$46*100% -> 0 | AI33: =SUM(AI30:AI32) -> 0 | AJ33: =SUM(AJ30:AJ32) -> 0 | AL33: =SUM(AL30:AL32) -> 0 | AM33: =AL33/$AL$46*100% -> 0 | AN33: =SUM(AN30:AN32) -> 0 | AO33: =SUM(AO30:AO32) -> 0 | AP33: =AQ33/$AQ$1*10^5 -> 0 | AQ33: =SUM(AQ30:AQ32) -> 0 | AR33: =AQ33/$AQ$46*100% -> 0 | AS33: =SUM(AS30:AS32) -> 0 | AT33: =SUM(AT30:AT32) -> 0 | AU33: =SUM(AU30:AU32) -> 0 | AV33: =SUM(AV30:AV32) -> 0 | AW33: =SUM(AW30:AW32) -> 0 | AX33: =SUM(AX30:AX32) -> 0 | AZ33: =SUM(AZ30:AZ32) -> 0 | BA33: =AZ33/$AZ$46*100% -> 0 | BB33: =SUM(BB30:BB32) -> 0 | BC33: =SUM(BC30:BC32) -> 0 | BE33: =SUM(BE30:BE32) -> 0 | BF33: =BE33/$BE$46*100% -> 0 | BG33: =SUM(BG30:BG32) -> 0.21065 | BH33: =SUM(BH30:BH32) -> 4.4827359e-05 | BI33: =SUM(BI30:BI32) -> 0 | BJ33: =BI33/$BI$46*100% -> 0 | BK33: =SUM(BK30:BK32) -> 0 | BL33: =SUM(BL30:BL32) -> 0 | BM33: =SUM(BM30:BM32) -> 0 | BN33: =SUM(BN30:BN32) -> 0 | BO33: =SUM(BO30:BO32) -> 0 | BP33: =SUM(BP30:BP32) -> 0 | BR33: =SUM(BR30:BR32) -> 0 | BS33: =BR33/$BR$46*100% -> 0 | BT33: =BG33+BK33+BO33-BQ33 -> 0.21065 | BU33: =BT33/$BT$46*100% -> 4.6938921e-05 | BW33: =SUM(BW30:BW32) -> 0 | BX33: =BW33/$BW$46*100% -> 0 | BY33: =SUM(BY30:BY32) -> 0 | BZ33: =BY33/$BY$46*100% -> 0 | CB33: =SUM(CB30:CB32) -> 0 | CE33: =SUM(CE30:CE32) -> 7.41585 | CF33: =CE33/$CE$46*100% -> 0.0004386683 | CG33: =SUM(CG30:CG32) -> 26.673592 | CH33: =CG33/$CG$46*100% -> 0.0021810855
B34: Other income | F34: =E34/$E$46*100% -> 0 | H34: =G34/$G$46*100% -> 0 | I34: =-SUMIF('05.conso TB'!A:A,'May-26'!B34,'05.conso TB'!S:S)/10^5 -> 0 | J34: =I34/$I$46*100% -> 0 | P34: =O34/$O$46*100% -> 0 | R34: =Q34/$Q$46*100% -> 0 | T34: =S34/$S$46*100% -> 0 | V34: =U34/$U$46*100% -> 0 | X34: =W34/$W$46*100% -> 0 | Z34: =Y34/$Y$46*100% -> 0 | AC34: =AB34/$AB$46*100% -> 0 | AE34: =AD34/$AD$46*100% -> 0 | AH34: =AG34/$AG$46*100% -> 0 | AM34: =AL34/$AL$46*100% -> 0 | AR34: =AQ34/$AQ$46*100% -> 0 | BA34: =AZ34/$AZ$46*100% -> 0 | BF34: =BE34/$BE$46*100% -> 0 | BJ34: =BI34/$BI$46*100% -> 0 | BS34: =BR34/$BR$46*100% -> 0 | BT34: =BG34+BK34+BO34-BQ34 -> 0 | BU34: =BT34/$BT$46*100% -> 0 | BX34: =BW34/$BW$46*100% -> 0 | BZ34: =BY34/$BY$46*100% -> 0 | CF34: =CE34/$CE$46*100% -> 0 | CH34: =CG34/$CG$46*100% -> 0
B35: Wind mill income | C35: =E35-'Apr-26'!E35 -> 12.60319 | D35: =C35/$C$46*100% -> 0.0040342631 | E35: =-SUMIF('05.conso TB'!A:A,'May-26'!B35,'05.conso TB'!R:R)/10^5 -> 18.60616 | F35: =E35/$E$46*100% -> 0.0028796987 | G35: =I35-'Apr-26'!I35 -> 11.2517 | H35: =G35/$G$46*100% -> 0.0084713443 | I35: =-SUMIF('05.conso TB'!A:A,'May-26'!B35,'05.conso TB'!S:S)/10^5 -> 20.50025 | J35: =I35/$I$46*100% -> 0.0081688803 | K35: =M35-'Apr-26'!M35 -> 0 | L35: =K35/$C$46*100% -> 0 | M35: =-SUMIF('05.conso TB'!A:A,'May-26'!B35,'05.conso TB'!T:T)/10^5 -> 0 | N35: =M35/$C$46*100% -> 0 | O35: =Q35-'Apr-26'!Q35 -> 0 | P35: =O35/$O$46*100% -> 0 | Q35: =-SUMIF('05.conso TB'!A:A,'May-26'!B35,'05.conso TB'!U:U)/10^5 -> 0 | R35: =Q35/$Q$46*100% -> 0 | S35: =U35-'Apr-26'!U35 -> 0 | T35: =S35/$S$46*100% -> 0 | U35: =-SUMIF('05.conso TB'!A:A,'May-26'!B35,'05.conso TB'!V:V)/10^5 -> 0 | V35: =U35/$U$46*100% -> 0 | W35: =Y35-'Apr-26'!Y35 -> 0 | X35: =W35/$W$46*100% -> 0 | Y35: =-SUMIF('05.conso TB'!A:A,'May-26'!B35,'05.conso TB'!G:G)/10^5 -> 0 | Z35: =Y35/$Y$46*100% -> 0 | AB35: =AD35-'Apr-26'!AD35 -> 23.85489 | AC35: =AB35/$AB$46*100% -> 0.0025869072 | AD35: =E35+I35+M35+Q35+U35+Y35 -> 39.10641 | AE35: =AD35/$AD$46*100% -> 0.0027057713 | AG35: =AI35-'Apr-26'!AI35 -> 0 | AH35: =AG35/$AG$46*100% -> 0 | AI35: =-SUMIF('05.conso TB'!A:A,'May-26'!B35,'05.conso TB'!Q:Q)/10^5 -> 0 | AJ35: =AI35/$AI$46*100% -> 0 | AL35: =AN35-'Apr-26'!AN35 -> 0 | AM35: =AL35/$AL$46*100% -> 0 | AN35: =-SUMIF('05.conso TB'!A:A,'May-26'!B35,'05.conso TB'!W:W)/10^5 -> 0 | AO35: =AN35/$AN$46*100% -> 0 | AQ35: =AS35-'Apr-26'!AS35 -> 0 | AR35: =AQ35/$AQ$46*100% -> 0 | AS35: =-SUMIF('05.conso TB'!A:A,'May-26'!B35,'05.conso TB'!M:M)/10^5 -> 0 | AT35: =AS35/$AS$46*100% -> 0 | AU35: =AW35-'Apr-26'!AW35 -> 0 | AV35: =AU35/$C$46*100% -> 0 | AW35: =-SUMIF('05.conso TB'!A:A,'May-26'!B35,'05.conso TB'!P:P)/10^5 -> 0 | AX35: =AW35/$AW$46*100% -> 0 | AZ35: =BB35-'Apr-26'!BB35 -> 0 | BA35: =AZ35/$AZ$46*100% -> 0 | BB35: =AS35+AW35 -> 0 | BC35: =BB35/$BB$46*100% -> 0 | BE35: =BG35-'Apr-26'!BG35 -> 0 | BF35: =BE35/$BE$46*100% -> 0 | BG35: =-SUMIF('05.conso TB'!A:A,'May-26'!B35,'05.conso TB'!H:H)/10^5 -> 0 | BH35: =BG35/$BG$46*100% -> 0 | BI35: =BK35-'Apr-26'!BK35 -> 0 | BJ35: =BI35/$BI$46*100% -> 0 | BK35: =-SUMIF('05.conso TB'!A:A,'May-26'!B35,'05.conso TB'!I:I)/10^5 -> 0 | BL35: =BK35/$BK$46*100% -> 0 | BM35: =BO35-'Apr-26'!BO35 -> 0 | BN35: =BM35/$C$46*100% -> 0 | BO35: =-SUMIF('05.conso TB'!A:A,'May-26'!B35,'05.conso TB'!J:J)/10^5 -> 0 | BP35: =BO35/$C$46*100% -> 0 | BR35: =BT35-'Apr-26'!BT35 -> 0 | BS35: =BR35/$BR$46*100% -> 0 | BT35: =BG35+BK35+BO35-BQ35 -> 0 | BU35: =BT35/$BT$46*100% -> 0 | BW35: =BY35-'Apr-26'!BY35 -> 0 | BX35: =BW35/$BW$46*100% -> 0 | BY35: =-SUMIF('05.conso TB'!A:A,'May-26'!B35,'05.conso TB'!L:L)/10^5 -> 0 | BZ35: =BY35/$BY$46*100% -> 0 | CB35: =CD35-'Apr-26'!CD35 -> 0 | CE35: =AB35+AG35+AL35+AZ35+BR35+BW35 -> 23.85489 | CF35: =CE35/$CE$46*100% -> 0.0014110836 | CG35: =AD35+AI35+AN35+BB35+BT35+BY35 -> 39.10641 | CH35: =CG35/$CG$46*100% -> 0.0031977105
B36: Interest income: | C36: =E36-'Apr-26'!E36 -> 0 | D36: =C36/$C$46*100% -> 0 | E36: =-SUMIF('05.conso TB'!A:A,'May-26'!B36,'05.conso TB'!R:R)/10^5 -> 0 | F36: =E36/$E$46*100% -> 0 | G36: =I36-'Apr-26'!I36 -> 0 | H36: =G36/$G$46*100% -> 0 | I36: =-SUMIF('05.conso TB'!A:A,'May-26'!B36,'05.conso TB'!S:S)/10^5 -> 0 | J36: =I36/$I$46*100% -> 0 | K36: =M36-'Apr-26'!M36 -> 0 | L36: =K36/$C$46*100% -> 0 | M36: =-SUMIF('05.conso TB'!A:A,'May-26'!B36,'05.conso TB'!T:T)/10^5 -> 0 | N36: =M36/$C$46*100% -> 0 | O36: =Q36-'Apr-26'!Q36 -> 0 | P36: =O36/$O$46*100% -> 0 | Q36: =-SUMIF('05.conso TB'!A:A,'May-26'!B36,'05.conso TB'!U:U)/10^5 -> 0 | R36: =Q36/$Q$46*100% -> 0 | S36: =U36-'Apr-26'!U36 -> 0 | T36: =S36/$S$46*100% -> 0 | U36: =-SUMIF('05.conso TB'!A:A,'May-26'!B36,'05.conso TB'!V:V)/10^5 -> 0 | V36: =U36/$U$46*100% -> 0 | W36: =Y36-'Apr-26'!Y36 -> 0 | X36: =W36/$W$46*100% -> 0 | Y36: =-SUMIF('05.conso TB'!A:A,'May-26'!B36,'05.conso TB'!G:G)/10^5 -> 0 | Z36: =Y36/$Y$46*100% -> 0 | AB36: =AD36-'Apr-26'!AD36 -> 0 | AC36: =AB36/$AB$46*100% -> 0 | AD36: =E36+I36+M36+Q36+U36+Y36 -> 0 | AE36: =AD36/$AD$46*100% -> 0 | AG36: =AI36-'Apr-26'!AI36 -> 0 | AH36: =AG36/$AG$46*100% -> 0 | AI36: =-SUMIF('05.conso TB'!A:A,'May-26'!B36,'05.conso TB'!Q:Q)/10^5 -> 0 | AJ36: =AI36/$AI$46*100% -> 0 | AL36: =AN36-'Apr-26'!AN36 -> 0 | AM36: =AL36/$AL$46*100% -> 0 | AN36: =-SUMIF('05.conso TB'!A:A,'May-26'!B36,'05.conso TB'!W:W)/10^5 -> 0 | AO36: =AN36/$AN$46*100% -> 0 | AQ36: =AS36-'Apr-26'!AS36 -> 0 | AR36: =AQ36/$AQ$46*100% -> 0 | AS36: =-SUMIF('05.conso TB'!A:A,'May-26'!B36,'05.conso TB'!M:M)/10^5 -> 0 | AT36: =AS36/$AS$46*100% -> 0 | AU36: =AW36-'Apr-26'!AW36 -> 0 | AV36: =AU36/$C$46*100% -> 0 | AW36: =-SUMIF('05.conso TB'!A:A,'May-26'!B36,'05.conso TB'!P:P)/10^5 -> 0 | AX36: =AW36/$AW$46*100% -> 0 | AZ36: =BB36-'Apr-26'!BB36 -> 0 | BA36: =AZ36/$AZ$46*100% -> 0 | BB36: =AS36+AW36 -> 0 | BC36: =BB36/$BB$46*100% -> 0 | BE36: =BG36-'Apr-26'!BG36 -> 0 | BF36: =BE36/$BE$46*100% -> 0 | BG36: =-SUMIF('05.conso TB'!A:A,'May-26'!B36,'05.conso TB'!H:H)/10^5 -> 0 | BH36: =BG36/$BG$46*100% -> 0 | BI36: =BK36-'Apr-26'!BK36 -> 0 | BJ36: =BI36/$BI$46*100% -> 0 | BK36: =-SUMIF('05.conso TB'!A:A,'May-26'!B36,'05.conso TB'!I:I)/10^5 -> 0 | BL36: =BK36/$BK$46*100% -> 0 | BM36: =BO36-'Apr-26'!BO36 -> 0 | BN36: =BM36/$C$46*100% -> 0 | BO36: =-SUMIF('05.conso TB'!A:A,'May-26'!B36,'05.conso TB'!J:J)/10^5 -> 0 | BP36: =BO36/$C$46*100% -> 0 | BR36: =BT36-'Apr-26'!BT36 -> 0 | BS36: =BR36/$BR$46*100% -> 0 | BT36: =BG36+BK36+BO36-BQ36 -> 0 | BU36: =BT36/$BT$46*100% -> 0 | BW36: =BY36-'Apr-26'!BY36 -> 0 | BX36: =BW36/$BW$46*100% -> 0 | BY36: =-SUMIF('05.conso TB'!A:A,'May-26'!B36,'05.conso TB'!L:L)/10^5 -> 0 | BZ36: =BY36/$BY$46*100% -> 0 | CB36: =CD36-'Apr-26'!CD36 -> 0 | CE36: =AB36+AG36+AL36+AZ36+BR36+BW36 -> 0 | CF36: =CE36/$CE$46*100% -> 0 | CG36: =AD36+AI36+AN36+BB36+BT36+BY36 -> 0 | CH36: =CG36/$CG$46*100% -> 0
B37: - on fixed deposits with Banks | C37: =E37-'Apr-26'!E37 -> 0.30794 | D37: =C37/$C$46*100% -> 9.8571153e-05 | E37: =-SUMIF('05.conso TB'!A:A,'May-26'!B37,'05.conso TB'!R:R)/10^5 -> 1.07873 | F37: =E37/$E$46*100% -> 0.00016695639 | G37: =I37-'Apr-26'!I37 -> 0 | H37: =G37/$G$46*100% -> 0 | I37: =-SUMIF('05.conso TB'!A:A,'May-26'!B37,'05.conso TB'!S:S)/10^5 -> 0 | J37: =I37/$I$46*100% -> 0 | K37: =M37-'Apr-26'!M37 -> 0 | L37: =K37/$C$46*100% -> 0 | M37: =-SUMIF('05.conso TB'!A:A,'May-26'!B37,'05.conso TB'!T:T)/10^5 -> 0 | N37: =M37/$C$46*100% -> 0 | O37: =Q37-'Apr-26'!Q37 -> 0 | P37: =O37/$O$46*100% -> 0 | Q37: =-SUMIF('05.conso TB'!A:A,'May-26'!B37,'05.conso TB'!U:U)/10^5 -> 0 | R37: =Q37/$Q$46*100% -> 0 | S37: =U37-'Apr-26'!U37 -> 0 | T37: =S37/$S$46*100% -> 0 | U37: =-SUMIF('05.conso TB'!A:A,'May-26'!B37,'05.conso TB'!V:V)/10^5 -> 0 | V37: =U37/$U$46*100% -> 0 | W37: =Y37-'Apr-26'!Y37 -> 0 | X37: =W37/$W$46*100% -> 0 | Y37: =-SUMIF('05.conso TB'!A:A,'May-26'!B37,'05.conso TB'!G:G)/10^5 -> 0 | Z37: =Y37/$Y$46*100% -> 0 | AB37: =AD37-'Apr-26'!AD37 -> 0.30794 | AC37: =AB37/$AB$46*100% -> 3.3394085e-05 | AD37: =E37+I37+M37+Q37+U37+Y37 -> 1.07873 | AE37: =AD37/$AD$46*100% -> 7.4637295e-05 | AG37: =AI37-'Apr-26'!AI37 -> 0 | AH37: =AG37/$AG$46*100% -> 0 | AI37: =-SUMIF('05.conso TB'!A:A,'May-26'!B37,'05.conso TB'!Q:Q)/10^5 -> 0 | AJ37: =AI37/$AI$46*100% -> 0 | AL37: =AN37-'Apr-26'!AN37 -> 6.1641 | AM37: =AL37/$AL$46*100% -> 0.0052051197 | AN37: =-SUMIF('05.conso TB'!A:A,'May-26'!B37,'05.conso TB'!W:W)/10^5 -> 7.33435 | AO37: =AN37/$AN$46*100% -> 0.0031581614 | AQ37: =AS37-'Apr-26'!AS37 -> 0 | AR37: =AQ37/$AQ$46*100% -> 0 | AS37: =-SUMIF('05.conso TB'!A:A,'May-26'!B37,'05.conso TB'!M:M)/10^5 -> 0 | AT37: =AS37/$AS$46*100% -> 0 | AU37: =AW37-'Apr-26'!AW37 -> 0 | AV37: =AU37/$C$46*100% -> 0 | AW37: =-SUMIF('05.conso TB'!A:A,'May-26'!B37,'05.conso TB'!P:P)/10^5 -> 0 | AX37: =AW37/$AW$46*100% -> 0 | AZ37: =BB37-'Apr-26'!BB37 -> 0 | BA37: =AZ37/$AZ$46*100% -> 0 | BB37: =AS37+AW37 -> 0 | BC37: =BB37/$BB$46*100% -> 0 | BE37: =BG37-'Apr-26'!BG37 -> 0 | BF37: =BE37/$BE$46*100% -> 0 | BG37: =-SUMIF('05.conso TB'!A:A,'May-26'!B37,'05.conso TB'!H:H)/10^5 -> 0 | BH37: =BG37/$BG$46*100% -> 0 | BI37: =BK37-'Apr-26'!BK37 -> 0 | BJ37: =BI37/$BI$46*100% -> 0 | BK37: =-SUMIF('05.conso TB'!A:A,'May-26'!B37,'05.conso TB'!I:I)/10^5 -> 0 | BL37: =BK37/$BK$46*100% -> 0 | BM37: =BO37-'Apr-26'!BO37 -> 0 | BN37: =BM37/$C$46*100% -> 0 | BO37: =-SUMIF('05.conso TB'!A:A,'May-26'!B37,'05.conso TB'!J:J)/10^5 -> 0 | BP37: =BO37/$C$46*100% -> 0 | BR37: =BT37-'Apr-26'!BT37 -> 0 | BS37: =BR37/$BR$46*100% -> 0 | BT37: =BG37+BK37+BO37-BQ37 -> 0 | BU37: =BT37/$BT$46*100% -> 0 | BW37: =BY37-'Apr-26'!BY37 -> 0 | BX37: =BW37/$BW$46*100% -> 0 | BY37: =-SUMIF('05.conso TB'!A:A,'May-26'!B37,'05.conso TB'!L:L)/10^5 -> 0 | BZ37: =BY37/$BY$46*100% -> 0 | CB37: =CD37-'Apr-26'!CD37 -> 0 | CE37: =AB37+AG37+AL37+AZ37+BR37+BW37 -> 6.47204 | CF37: =CE37/$CE$46*100% -> 0.00038283929 | CG37: =AD37+AI37+AN37+BB37+BT37+BY37 -> 8.41308 | CH37: =CG37/$CG$46*100% -> 0.00068793311
B38: - from others | C38: =E38-'Apr-26'!E38 -> 0 | D38: =C38/$C$46*100% -> 0 | E38: =-SUMIF('05.conso TB'!A:A,'May-26'!B38,'05.conso TB'!R:R)/10^5 -> 0 | F38: =E38/$E$46*100% -> 0 | G38: =I38-'Apr-26'!I38 -> 0 | H38: =G38/$G$46*100% -> 0 | I38: =-SUMIF('05.conso TB'!A:A,'May-26'!B38,'05.conso TB'!S:S)/10^5 -> 0 | J38: =I38/$I$46*100% -> 0 | K38: =M38-'Apr-26'!M38 -> 0 | L38: =K38/$C$46*100% -> 0 | M38: =-SUMIF('05.conso TB'!A:A,'May-26'!B38,'05.conso TB'!T:T)/10^5 -> 0 | N38: =M38/$C$46*100% -> 0 | O38: =Q38-'Apr-26'!Q38 -> 0 | P38: =O38/$O$46*100% -> 0 | Q38: =-SUMIF('05.conso TB'!A:A,'May-26'!B38,'05.conso TB'!U:U)/10^5 -> 0 | R38: =Q38/$Q$46*100% -> 0 | S38: =U38-'Apr-26'!U38 -> 0 | T38: =S38/$S$46*100% -> 0 | U38: =-SUMIF('05.conso TB'!A:A,'May-26'!B38,'05.conso TB'!V:V)/10^5 -> 0 | V38: =U38/$U$46*100% -> 0 | W38: =Y38-'Apr-26'!Y38 -> 0 | X38: =W38/$W$46*100% -> 0 | Y38: =-SUMIF('05.conso TB'!A:A,'May-26'!B38,'05.conso TB'!G:G)/10^5 -> 0 | Z38: =Y38/$Y$46*100% -> 0 | AB38: =AD38-'Apr-26'!AD38 -> 0 | AC38: =AB38/$AB$46*100% -> 0 | AD38: =E38+I38+M38+Q38+U38+Y38 -> 0 | AE38: =AD38/$AD$46*100% -> 0 | AG38: =AI38-'Apr-26'!AI38 -> 0 | AH38: =AG38/$AG$46*100% -> 0 | AI38: =-SUMIF('05.conso TB'!A:A,'May-26'!B38,'05.conso TB'!Q:Q)/10^5 -> 0 | AJ38: =AI38/$AI$46*100% -> 0 | AL38: =AN38-'Apr-26'!AN38 -> 0 | AM38: =AL38/$AL$46*100% -> 0 | AN38: =-SUMIF('05.conso TB'!A:A,'May-26'!B38,'05.conso TB'!W:W)/10^5 -> 0 | AO38: =AN38/$AN$46*100% -> 0 | AQ38: =AS38-'Apr-26'!AS38 -> 0 | AR38: =AQ38/$AQ$46*100% -> 0 | AS38: =-SUMIF('05.conso TB'!A:A,'May-26'!B38,'05.conso TB'!M:M)/10^5 -> 0 | AT38: =AS38/$AS$46*100% -> 0 | AU38: =AW38-'Apr-26'!AW38 -> 0 | AV38: =AU38/$C$46*100% -> 0 | AW38: =-SUMIF('05.conso TB'!A:A,'May-26'!B38,'05.conso TB'!P:P)/10^5 -> 0 | AX38: =AW38/$AW$46*100% -> 0 | AZ38: =BB38-'Apr-26'!BB38 -> 0 | BA38: =AZ38/$AZ$46*100% -> 0 | BB38: =AS38+AW38 -> 0 | BC38: =BB38/$BB$46*100% -> 0 | BE38: =BG38-'Apr-26'!BG38 -> 0 | BF38: =BE38/$BE$46*100% -> 0 | BG38: =-SUMIF('05.conso TB'!A:A,'May-26'!B38,'05.conso TB'!H:H)/10^5 -> 0 | BH38: =BG38/$BG$46*100% -> 0 | BI38: =BK38-'Apr-26'!BK38 -> 0 | BJ38: =BI38/$BI$46*100% -> 0 | BK38: =-SUMIF('05.conso TB'!A:A,'May-26'!B38,'05.conso TB'!I:I)/10^5 -> 0 | BL38: =BK38/$BK$46*100% -> 0 | BM38: =BO38-'Apr-26'!BO38 -> 0 | BN38: =BM38/$C$46*100% -> 0 | BO38: =-SUMIF('05.conso TB'!A:A,'May-26'!B38,'05.conso TB'!J:J)/10^5 -> 0 | BP38: =BO38/$C$46*100% -> 0 | BR38: =BT38-'Apr-26'!BT38 -> 0 | BS38: =BR38/$BR$46*100% -> 0 | BT38: =BG38+BK38+BO38-BQ38 -> 0 | BU38: =BT38/$BT$46*100% -> 0 | BW38: =BY38-'Apr-26'!BY38 -> 0 | BX38: =BW38/$BW$46*100% -> 0 | BY38: =-SUMIF('05.conso TB'!A:A,'May-26'!B38,'05.conso TB'!L:L)/10^5 -> 0 | BZ38: =BY38/$BY$46*100% -> 0 | CB38: =CD38-'Apr-26'!CD38 -> 0 | CE38: =AB38+AG38+AL38+AZ38+BR38+BW38 -> 0 | CF38: =CE38/$CE$46*100% -> 0 | CG38: =AD38+AI38+AN38+BB38+BT38+BY38 -> 0 | CH38: =CG38/$CG$46*100% -> 0
B39: Rent Income | C39: =E39-'Apr-26'!E39 -> 2.34013 | D39: =C39/$C$46*100% -> 0.00074907226 | E39: =-SUMIF('05.conso TB'!A:A,'May-26'!B39,'05.conso TB'!R:R)/10^5 -> 4.68026 | F39: =E39/$E$46*100% -> 0.00072436971 | G39: =I39-'Apr-26'!I39 -> 0 | H39: =G39/$G$46*100% -> 0 | I39: =-SUMIF('05.conso TB'!A:A,'May-26'!B39,'05.conso TB'!S:S)/10^5 -> 0 | J39: =I39/$I$46*100% -> 0 | K39: =M39-'Apr-26'!M39 -> 0 | L39: =K39/$C$46*100% -> 0 | M39: =-SUMIF('05.conso TB'!A:A,'May-26'!B39,'05.conso TB'!T:T)/10^5 -> 0 | N39: =M39/$C$46*100% -> 0 | O39: =Q39-'Apr-26'!Q39 -> 0 | P39: =O39/$O$46*100% -> 0 | Q39: =-SUMIF('05.conso TB'!A:A,'May-26'!B39,'05.conso TB'!U:U)/10^5 -> 0 | R39: =Q39/$Q$46*100% -> 0 | S39: =U39-'Apr-26'!U39 -> 0 | T39: =S39/$S$46*100% -> 0 | U39: =-SUMIF('05.conso TB'!A:A,'May-26'!B39,'05.conso TB'!V:V)/10^5 -> 0 | V39: =U39/$U$46*100% -> 0 | W39: =Y39-'Apr-26'!Y39 -> 0.45 | X39: =W39/$W$46*100% -> 0.00012099544 | Y39: =-SUMIF('05.conso TB'!A:A,'May-26'!B39,'05.conso TB'!G:G)/10^5 -> 0.9 | Z39: =Y39/$Y$46*100% -> 0.00023724077 | AB39: =AD39-'Apr-26'!AD39 -> 2.79013 | AC39: =AB39/$AB$46*100% -> 0.0003025714 | AD39: =E39+I39+M39+Q39+U39+Y39 -> 5.58026 | AE39: =AD39/$AD$46*100% -> 0.00038609801 | AG39: =AI39-'Apr-26'!AI39 -> 0 | AH39: =AG39/$AG$46*100% -> 0 | AI39: =-SUMIF('05.conso TB'!A:A,'May-26'!B39,'05.conso TB'!Q:Q)/10^5 -> 0 | AJ39: =AI39/$AI$46*100% -> 0 | AL39: =AN39-'Apr-26'!AN39 -> 0 | AM39: =AL39/$AL$46*100% -> 0 | AN39: =-SUMIF('05.conso TB'!A:A,'May-26'!B39,'05.conso TB'!W:W)/10^5 -> 0 | AO39: =AN39/$AN$46*100% -> 0 | AQ39: =AS39-'Apr-26'!AS39 -> -2 | AR39: =AQ39/$AQ$46*100% -> -0.00098095623 | AS39: =-SUMIF('05.conso TB'!A:A,'May-26'!B39,'05.conso TB'!M:M)/10^5 -> -2 | AT39: =AS39/$AS$46*100% -> -0.00051672383 | AU39: =AW39-'Apr-26'!AW39 -> 0 | AV39: =AU39/$C$46*100% -> 0 | AW39: =-SUMIF('05.conso TB'!A:A,'May-26'!B39,'05.conso TB'!P:P)/10^5 -> 0 | AX39: =AW39/$AW$46*100% -> 0 | AZ39: =BB39-'Apr-26'!BB39 -> -2 | BA39: =AZ39/$AZ$46*100% -> -0.00065893395 | BB39: =AS39+AW39 -> -2 | BC39: =BB39/$BB$46*100% -> -0.00034978658 | BE39: =BG39-'Apr-26'!BG39 -> 0.24 | BF39: =BE39/$BE$46*100% -> 8.5869993e-05 | BG39: =-SUMIF('05.conso TB'!A:A,'May-26'!B39,'05.conso TB'!H:H)/10^5 -> 0.48 | BH39: =BG39/$BG$46*100% -> 0.00010214637 | BI39: =BK39-'Apr-26'!BK39 -> 0 | BJ39: =BI39/$BI$46*100% -> 0 | BK39: =-SUMIF('05.conso TB'!A:A,'May-26'!B39,'05.conso TB'!I:I)/10^5 -> 0 | BL39: =BK39/$BK$46*100% -> 0 | BM39: =BO39-'Apr-26'!BO39 -> 0 | BN39: =BM39/$C$46*100% -> 0 | BO39: =-SUMIF('05.conso TB'!A:A,'May-26'!B39,'05.conso TB'!J:J)/10^5 -> 0 | BP39: =BO39/$C$46*100% -> 0 | BR39: =BT39-'Apr-26'!BT39 -> 0.24 | BS39: =BR39/$BR$46*100% -> 9.0754515e-05 | BT39: =BG39+BK39+BO39-BQ39 -> 0.48 | BU39: =BT39/$BT$46*100% -> 0.0001069579 | BW39: =BY39-'Apr-26'!BY39 -> 0 | BX39: =BW39/$BW$46*100% -> 0 | BY39: =-SUMIF('05.conso TB'!A:A,'May-26'!B39,'05.conso TB'!L:L)/10^5 -> 0 | BZ39: =BY39/$BY$46*100% -> 0 | CB39: =CC39-'Apr-26'!CC39 -> 4.69 | CC39: 7.38 | CE39: =AB39+AG39+AL39+AZ39+BR39+BW39 -> 1.03013 | CF39: =CE39/$CE$46*100% -> 6.0935075e-05 | CG39: =AD39+AI39+AN39+BB39+BT39+BY39 -> 4.06026 | CH39: =CG39/$CG$46*100% -> 0.00033200532
