Workbook

Sheet JOb Out Loss
A1: ChallanNo | B1: sysdate | C1: Company Name | D1: NatureProc | E1: DescriptionGoods | F1: Identification | G1: QtyDesc | H1: ItemUnit | I1: ItemQty | J1: ItemValue | K1: TotalAmt | L1: VehicalNo | M1: LRNo | N1: TransportName | P1: Avg. Rate | R1: Cl. Rate | T1: Profit / (Loss)
T123: =R123-P123 -> 0
T124: =R124-P124 -> 0
T125: =R125-P125 -> 0
P160: =SUM(P2:P159) -> 0 | R160: =SUM(R2:R159) -> 0 | T160: =SUM(T2:T159) -> 0

Sheet Sheet11
B1: Plastene India Limited Unit - II (PIA) | F1: Date | I1: 8
C2: Monthly Budget | I2: Till Date Budget | M2: Actual
B5: PP | C5: =+D5/$D$14 -> 0.65188 | D5: 488910 | E5: 70.31 | F5: =E5*D5 -> 34375262 | H5: =+I5/$I$14 -> 0.65188 | I5: =+D5/31*$I$1 -> 126170.32 | J5: =+E5 -> 70.31 | K5: =J5*I5 -> 8871035.4 | M5: =+N5/$N$14 -> #REF! | N5: =#REF! -> #REF! | O5: =#REF! -> #REF! | P5: =O5*N5 -> #REF! | Q5: =+N5-I5 -> #REF! | R5: =+O5-J5 -> #REF! | S5: =+P5-K5 -> #REF!
B6: Filler | C6: =+D6/$D$14 -> 0.075 | D6: 56250 | E6: 26.5 | F6: =E6*D6 -> 1490625 | H6: =+I6/$I$14 -> 0.075 | I6: =+D6/31*$I$1 -> 14516.129 | J6: =+E6 -> 26.5 | K6: =J6*I6 -> 384677.42 | M6: =+N6/$N$14 -> #REF! | N6: =#REF! -> #REF! | O6: =FillerSoltex!Y6 -> #REF! | P6: =O6*N6 -> #REF! | Q6: =+N6-I6 -> #REF! | R6: =+O6-J6 -> #REF! | S6: =+P6-K6 -> #REF!
B7: MB | C7: =+D7/$D$14 -> 0.005 | D7: 3750 | E7: 170 | F7: =E7*D7 -> 637500 | H7: =+I7/$I$14 -> 0.005 | I7: =+D7/31*$I$1 -> 967.74194 | J7: =+E7 -> 170 | K7: =J7*I7 -> 164516.13 | M7: =+N7/$N$14 -> #REF! | N7: =#REF! -> #REF! | O7: =MB!Y6 -> #REF! | P7: =O7*N7 -> #REF! | Q7: =+N7-I7 -> #REF! | R7: =+O7-J7 -> #REF! | S7: =+P7-K7 -> #REF!
B8: UV | C8: =+D8/$D$14 -> 0.018373333 | D8: 13780 | E8: 171 | F8: =E8*D8 -> 2356380 | H8: =+I8/$I$14 -> 0.018373333 | I8: =+D8/31*$I$1 -> 3556.129 | J8: =+E8 -> 171 | K8: =J8*I8 -> 608098.06 | M8: =+N8/$N$14 -> #REF! | N8: =#REF! -> #REF! | O8: =UV!Y6 -> #REF! | P8: =O8*N8 -> #REF! | Q8: =+N8-I8 -> #REF! | R8: =+O8-J8 -> #REF! | S8: =+P8-K8 -> #REF!
B9: HDPE | C9: =+D9/$D$14 -> 0.0012466667 | D9: 935 | E9: 80.41 | F9: =E9*D9 -> 75183.35 | H9: =+I9/$I$14 -> 0.0012466667 | I9: =+D9/31*$I$1 -> 241.29032 | J9: =+E9 -> 80.41 | K9: =J9*I9 -> 19402.155 | M9: =+N9/$N$14 -> #REF! | N9: =#REF! -> #REF! | O9: =#REF! -> #REF! | P9: =O9*N9 -> #REF! | Q9: =+N9-I9 -> #REF! | R9: =+O9-J9 -> #REF! | S9: =+P9-K9 -> #REF!
B10: LLDPE | C10: =+D10/$D$14 -> 0.029753333 | D10: 22315 | E10: 67.9 | F10: =E10*D10 -> 1515188.5 | H10: =+I10/$I$14 -> 0.029753333 | I10: =+D10/31*$I$1 -> 5758.7097 | J10: =+E10 -> 67.9 | K10: =J10*I10 -> 391016.39 | M10: =+N10/$N$14 -> #REF! | N10: =#REF! -> #REF! | O10: =#REF! -> #REF! | P10: =O10*N10 -> #REF! | Q10: =+N10-I10 -> #REF! | R10: =+O10-J10 -> #REF! | S10: =+P10-K10 -> #REF!
B11: LDPE | D11: 0 | J11: =+E11 -> 0 | M11: =+N11/$N$14 -> #REF! | N11: =#REF! -> #REF! | O11: =LLDP!Z6 -> #REF! | P11: =O11*N11 -> #REF! | Q11: =+N11-I11 -> #REF! | R11: =+O11-J11 -> #REF! | S11: =+P11-K11 -> #REF!
B12: RP-Purchase | D12: 64060 | E12: 60 | F12: =E12*D12 -> 3843600 | I12: =+D12/31*$I$1 -> 16531.613 | J12: =+E12 -> 60 | K12: =J12*I12 -> 991896.77 | N12: =#REF! -> #REF! | O12: =+P12/N12 -> #REF! | P12: =RP!T35 -> 452640 | Q12: =+N12-I12 -> #REF! | R12: =+O12-J12 -> #REF! | S12: =+P12-K12 -> -539256.77
B13: RP-Self | C13: =+(D12+D13)/$D$14 -> 0.21874667 | D13: 100000 | E13: 0 | F13: =E13*D13 -> 0 | H13: =+(I12+I13)/$I$14 -> 0.21874667 | I13: =+D13/31*$I$1 -> 25806.452 | J13: =+E13 -> 0 | K13: =J13*I13 -> 0 | M13: =+(N12+N13)/$N$14 -> #REF! | N13: =#REF!-N12 -> #REF! | O13: 0 | P13: =O13*N13 -> #REF! | S13: =+P13-K13 -> #REF!
D14: =SUM(D5:D13) -> 750000 | E14: =F14/D14 -> 59.058319 | F14: =SUM(F5:F13) -> 44293739 | I14: =SUM(I5:I13) -> 193548.39 | J14: =+K14/I14 -> 59.058319 | K14: =SUM(K5:K13) -> 11430642 | N14: =SUM(N5:N13) -> #REF! | O14: =+P14/N14 -> #REF! | P14: =SUM(P5:P13) -> #REF! | Q14: =+N14-I14 -> #REF! | R14: =+O14-J14 -> #REF! | S14: =+P14-K14 -> #REF!
B16: Tape waste | C16: 0.02 | D16: =D14*C16 -> 15000 | H16: =+I16/I14 -> 0.02 | I16: =I14*C16 -> 3870.9677 | M16: =+N16/N14 -> #REF! | N16: =#REF! -> #REF!
B17: Net Plant Production | D17: =D14-D16 -> 735000 | I17: =I14-I16 -> 189677.42 | N17: =N14-N16 -> #REF!
B18: Weaving wastage | C18: 0.02 | D18: =D17*C18 -> 14700 | H18: =+I18/I17 -> 0.02 | I18: =I17*C18 -> 3793.5484 | M18: =+N18/N17 -> #REF! | N18: =#REF!+#REF!+#REF! -> #REF!
B19: Net Fabric Production | D19: =D17-D18 -> 720300 | I19: =I17-I18 -> 185883.87 | N19: =N17-N18 -> #REF!
B21: Lamination-PP | D21: 36000 | E21: 77.597 | F21: =E21*D21 -> 2793492 | I21: =+D21/31*$I$1 -> 9290.3226 | J21: =+E21 -> 77.597 | K21: =J21*I21 -> 720901.16 | N21: =#REF! -> #REF! | O21: =#REF! -> #REF! | P21: =O21*N21 -> #REF! | Q21: =+N21-I21 -> #REF! | R21: =+O21-J21 -> #REF! | S21: =+P21-K21 -> #REF!
B22: LDPE | D22: 6870 | E22: 79.615 | F22: =E22*D22 -> 546955.05 | I22: =+D22/31*$I$1 -> 1772.9032 | J22: =+E22 -> 79.615 | K22: =J22*I22 -> 141149.69 | N22: =#REF! -> #REF! | O22: =LLDP!Z6 -> #REF! | P22: =O22*N22 -> #REF! | Q22: =+N22-I22 -> #REF! | R22: =+O22-J22 -> #REF! | S22: =+P22-K22 -> #REF!
B23: MB | D23: 260 | E23: 170 | F23: =E23*D23 -> 44200 | I23: =+D23/31*$I$1 -> 67.096774 | J23: =+E23 -> 170 | K23: =J23*I23 -> 11406.452 | N23: =#REF! -> #REF! | O23: =O7 -> #REF! | P23: =O23*N23 -> #REF! | Q23: =+N23-I23 -> #REF! | R23: =+O23-J23 -> #REF! | S23: =+P23-K23 -> #REF!
B24: Filler | D24: 325 | E24: 26.5 | F24: =E24*D24 -> 8612.5 | I24: =+D24/31*$I$1 -> 83.870968 | J24: =+E24 -> 26.5 | K24: =J24*I24 -> 2222.5806 | N24: =#REF! -> #REF! | O24: =O6 -> #REF! | P24: =O24*N24 -> #REF! | Q24: =+N24-I24 -> #REF! | R24: =+O24-J24 -> #REF! | S24: =+P24-K24 -> #REF!
B25: Lamination-RMC | D25: =SUM(D21:D24) -> 43455 | I25: =SUM(I21:I24) -> 11214.194 | N25: =SUM(N21:N24) -> #REF! | Q25: =+N25-I25 -> #REF! | R25: =+O25-J25 -> 0 | S25: =+P25-K25 -> 0
B26: Wastage | C26: 0.2 | D26: =D25*C26 -> 8691 | H26: =+I26/I25 -> 0.2 | I26: =I25*C26 -> 2242.8387 | M26: =+N26/N25 -> #REF! | N26: =#REF! -> #REF! | Q26: =+N26-I26 -> #REF! | R26: =+O26-J26 -> 0 | S26: =+P26-K26 -> 0
B27: Total After Lamination | D27: =D19+D25-D26 -> 755064 | E27: =F27/D25 -> 78.086746 | F27: =SUM(F21:F26) -> 3393259.5 | I27: =I19+I25-I26 -> 194855.23 | J27: =K27/I25 -> 78.086746 | K27: =SUM(K21:K26) -> 875679.88 | N27: =N19+N25-N26 -> #REF! | O27: =P27/N25 -> #REF! | P27: =SUM(P21:P26) -> #REF! | Q27: =+N27-I27 -> #REF! | R27: =+O27-J27 -> #REF! | S27: =+P27-K27 -> #REF!
B29: Yarn | D29: 51550 | E29: 120 | F29: =E29*D29 -> 6186000 | I29: =+D29/31*$I$1 -> 13303.226 | J29: =+E29 -> 120 | K29: =J29*I29 -> 1596387.1 | N29: =#REF!-#REF! -> #REF! | O29: =Yarn!AB6 -> #REF! | P29: =O29*N29 -> #REF! | Q29: =+N29-I29 -> #REF! | R29: =+O29-J29 -> #REF! | S29: =+P29-K29 -> #REF!
B30: Liner Bags | D30: 13330 | E30: 100 | F30: =E30*D30 -> 1333000 | I30: =+D30/31*$I$1 -> 3440 | J30: =+E30 -> 100 | K30: =J30*I30 -> 344000 | N30: =#REF!+#REF! -> #REF! | O30: =#REF! -> #REF! | P30: =O30*N30 -> #REF! | Q30: =+N30-I30 -> #REF! | R30: =+O30-J30 -> #REF! | S30: =+P30-K30 -> #REF!
B31: Film | D31: 1775 | E31: 110 | F31: =E31*D31 -> 195250 | I31: =+D31/31*$I$1 -> 458.06452 | J31: =+E31 -> 110 | K31: =J31*I31 -> 50387.097 | N31: =#REF!+#REF! -> #REF! | O31: 0 | P31: =O31*N31 -> #REF! | Q31: =+N31-I31 -> #REF! | R31: =+O31-J31 -> -110 | S31: =+P31-K31 -> #REF!
B32: Other RM | D32: =SUM(D29:D31) -> 66655 | E32: =F32/D32 -> 115.734 | F32: =SUM(F29:F31) -> 7714250 | I32: =SUM(I29:I31) -> 17201.29 | J32: =K32/I32 -> 115.734 | K32: =SUM(K29:K31) -> 1990774.2 | N32: =SUM(N29:N31) -> #REF! | O32: =P32/N32 -> #REF! | P32: =SUM(P29:P31) -> #REF! | Q32: =+N32-I32 -> #REF! | R32: =+O32-J32 -> #REF! | S32: =+P32-K32 -> #REF!
B33: Total After Other RM | D33: =D27+D32 -> 821719 | I33: =I27+I32 -> 212056.52 | N33: =N27+N32 -> #REF! | Q33: =+N33-I33 -> #REF! | R33: =+O33-J33 -> 0 | S33: =+P33-K33 -> 0
A34: 511364 | B34: FIBC wastage | C34: 0.12 | D34: =A34*C34 -> 61363.68 | H34: =+A34/31*I1 -> 131964.9 | I34: =C34*H34 -> 15835.788 | M34: =+N34/#REF! -> #REF! | N34: =#REF!+#REF! -> #REF! | Q34: =+N34-I34 -> #REF! | R34: =+O34-J34 -> 0 | S34: =+P34-K34 -> 0
Q35: =+N35-I35 -> 0 | R35: =+O35-J35 -> 0 | S35: =+P35-K35 -> 0
B36: Net After All wastage | D36: =D33-D34 -> 760355.32 | I36: =I33-I34 -> 196220.73 | N36: =N33-N34 -> #REF! | Q36: =+N36-I36 -> #REF! | R36: =+O36-J36 -> 0 | S36: =+P36-K36 -> 0
Q37: =+N37-I37 -> 0 | R37: =+O37-J37 -> 0 | S37: =+P37-K37 -> 0
B38: Plant Waste | D38: =D16 -> 15000 | I38: =I16 -> 3870.9677 | N38: =N16 -> #REF! | Q38: =+N38-I38 -> #REF! | R38: =+O38-J38 -> 0 | S38: =+P38-K38 -> 0
B39: Looms Waste | D39: =D18 -> 14700 | I39: =I18 -> 3793.5484 | N39: =N18 -> #REF! | Q39: =+N39-I39 -> #REF! | R39: =+O39-J39 -> 0 | S39: =+P39-K39 -> 0
B40: Lamination Waste | D40: =D26 -> 8691 | I40: =I26 -> 2242.8387 | N40: =N26 -> #REF! | Q40: =+N40-I40 -> #REF! | R40: =+O40-J40 -> 0 | S40: =+P40-K40 -> 0
B41: Fibc Waste | D41: =D34 -> 61363.68 | I41: =I34 -> 15835.788 | N41: =N34 -> #REF! | Q41: =+N41-I41 -> #REF! | R41: =+O41-J41 -> 0 | S41: =+P41-K41 -> 0
B42: Total Waste | C42: =+D42/D54 -> 0.13123716 | D42: =SUM(D38:D41) -> 99754.68 | H42: =+I42/I54 -> 0.13123716 | I42: =SUM(I38:I41) -> 25743.143 | M42: =+N42/N54 -> #REF! | N42: =SUM(N38:N41) -> #REF! | Q42: =+N42-I42 -> #REF! | R42: =+O42-J42 -> 0 | S42: =+P42-K42 -> 0
B43: Sale of waste | D43: =D42-D45 -> -245.32 | E43: 20 | F43: =E43*D43 -> -4906.4 | I43: =I42-I45 -> -63.308387 | J43: =+E43 -> 20 | K43: =J43*I43 -> -1266.1677 | N43: =#REF! -> #REF! | O43: =+P43/N43 -> #REF! | P43: =Sheet3!L12+Sheet3!L13 -> 119400 | Q43: =+N43-I43 -> #REF! | R43: =+O43-J43 -> #REF! | S43: =+P43-K43 -> 120666.17
B44: Wastage Purchase | N44: =-#REF! -> #REF! | O44: =+P44/N44 -> #REF! | P44: =-Wastage!AD21 -> 0 | Q44: =+N44-I44 -> #REF! | R44: =+O44-J44 -> #REF! | S44: =+P44-K44 -> 0
B45: Send to RP | D45: =D13 -> 100000 | E45: 0 | F45: =E45*D45 -> 0 | I45: =I13 -> 25806.452 | J45: =+E45 -> 0 | K45: =J45*I45 -> 0 | N45: =#REF!-#REF! -> #REF! | P45: =O45*N45 -> #REF! | Q45: =+N45-I45 -> #REF! | R45: =+O45-J45 -> 0 | S45: =+P45-K45 -> #REF!
...

Sheet Budget
F1: 10
B2: Monthly Budget | F2: Budget till Date | J2: Actual | N2: Variance
B3: Qty | C3: Avg. Rate | D3: Amount | F3: Qty | G3: Avg. Rate | H3: Amount | J3: Qty | K3: Avg. Rate | L3: Amount | N3: Qty | P3: Amount
A4: Sales | B4: =Sheet11!D43+Sheet11!D46+Sheet11!D48 -> 760110 | C4: =+D4/B4 -> 129.3205 | D4: =Sheet11!F43+Sheet11!F46+Sheet11!F48 -> 98297803 | F4: =B4/31*F1 -> 245196.77 | G4: =+C4 -> 129.3205 | H4: =+F4*G4 -> 31708969 | J4: =SUM(J5:J7) -> #REF! | K4: =L4/J4 -> #REF! | L4: =SUM(L5:L7) -> #REF! | N4: =+J4-F4 -> #REF! | O4: =+P4/J4 -> #REF! | P4: =+L4-H4 -> #REF! | W4: 44677903 | X4: =+L4-W4 -> #REF!
A5: Trading Sale | J5: ='PUR-SALE'!#REF! -> #REF! | K5: =+L5/J5 -> #REF! | L5: ='PUR-SALE'!#REF! -> #REF! | W5: 13975498 | X5: =+L5-W5 -> #REF!
A6: Inter Unit Sale | J6: ='PUR-SALE'!#REF! -> #REF! | K6: =+L6/J6 -> #REF! | L6: ='PUR-SALE'!#REF! -> #REF! | W6: 18303636 | X6: =+L6-W6 -> #REF!
A7: Other Sales | J7: =Sheet3!J22-J5-J6 -> #REF! | K7: =+L7/J7 -> #REF! | L7: =Sheet3!L22-L5-L6 -> #REF! | W7: 12398769 | X7: =+L7-W7 -> #REF!
A9: RMC | B9: =+Sheet11!D14-Sheet11!D13+Sheet11!D25+Sheet11!D32 -> 760110 | C9: =+D9/B9 -> 72.88583 | D9: =Sheet11!F14+Sheet11!F27+Sheet11!F32 -> 55401248 | F9: =B9/31*F1 -> 245196.77 | G9: =+C9 -> 72.88583 | H9: =+F9*G9 -> 17871370 | J9: =SUM(J10:J12) -> #REF! | K9: =L9/J9 -> #REF! | L9: =SUM(L10:L12) -> #REF! | N9: =+J9-F9 -> #REF! | O9: =+P9/(J9+J10+J11) -> #REF! | P9: =+L9-H9 -> #REF! | W9: 36261657 | X9: =+L9-W9 -> #REF!
A10: Trading Purchase | J10: ='PUR-SALE'!#REF! -> #REF! | K10: =L10/J10 -> #REF! | L10: ='PUR-SALE'!#REF! -> #REF! | Q10: =+J10-J5 -> #REF! | W10: 15116340 | X10: =+L10-W10 -> #REF!
A11: Inter Unit Purchase | J11: ='PUR-SALE'!#REF! -> #REF! | K11: =L11/J11 -> #REF! | L11: ='PUR-SALE'!#REF!-L22-L23 -> #REF! | W11: 13737148 | X11: =+L11-W11 -> #REF!
A12: Other RMC | J12: =(Sheet3!F17*1000)-J10-J11 -> #REF! | K12: =L12/J12 -> #REF! | L12: =Sheet3!E17*100000-L10-L11-L22-L23 -> #REF! | W12: 7408168.8 | X12: =+L12-W12 -> #REF!
A14: NET ADDITION | B14: =B4 -> 760110 | C14: =C4-C9 -> 56.434667 | D14: =+D4-D9 -> 42896555 | F14: =F4 -> 245196.77 | G14: =G4-G9 -> 56.434667 | H14: =+H4-H9 -> 13837598 | J14: =+J4-J9 -> #REF! | K14: =K4-K9 -> #REF! | L14: =+L4-L9 -> #REF! | P14: =+P4-P9 -> #REF! | W14: 8416246.4 | X14: =+L14-W14 -> #REF!
A16: Salary | D16: 15000000 | H16: =D16/31*$F$1 -> 4838709.7 | L16: =Sheet6!E39 -> #REF! | P16: =+L16-H16 -> #REF! | W16: 3727653.9 | X16: =+L16-W16 -> #REF!
A17: Power | D17: 7000000 | H17: =D17/31*$F$1 -> 2258064.5 | L17: =Sheet6!E38 -> #REF! | P17: =+L17-H17 -> #REF! | W17: 1631584.2 | X17: =+L17-W17 -> #REF!
A18: Consumables | D18: 2500000 | H18: =D18/31*$F$1 -> 806451.61 | L18: =Sheet6!E40 -> #REF! | P18: =+L18-H18 -> #REF! | W18: 558284.88 | X18: =+L18-W18 -> #REF!
A19: Job Charges | L19: =Sheet6!E41 -> #REF! | P19: =+L19-H19 -> #REF! | W19: 49428 | X19: =+L19-W19 -> #REF!
A20: Other Expenses | D20: 2000000 | H20: =D20/31*$F$1 -> 645161.29 | L20: =Sheet6!E42-#REF! -> #REF! | P20: =+L20-H20 -> #REF! | W20: 724676.82 | X20: =+L20-W20 -> #REF!
A21: Export Expenses | D21: 3000000 | H21: =D21/31*$F$1 -> 967741.94 | L21: =#REF! -> #REF! | P21: =+L21-H21 -> #REF! | W21: 379997.75 | X21: =+L21-W21 -> #REF!
A22: Custom Duty on RM Pur | L22: =(6.31*99000)+(6.03*99000) -> 1221660 | P22: =+L22-H22 -> 1221660
A23: RM Inter Co. PUR Exp. | L23: =155995+471701.8 -> 627696.8 | P23: =+L23-H23 -> 627696.8 | W23: 780734.5 | X23: =+L23-W23 -> -153037.7
A24: MEIS Benefit | D24: -2076444.5 | H24: =D24/31*$F$1 -> -669820.8 | L24: =Sheet6!E43 -> #REF! | P24: =+L24-H24 -> #REF! | W24: -664193 | X24: =+L24-W24 -> #REF!
A25: Exchange Rate Differences | D25: -2000000 | H25: =D25/31*$F$1 -> -645161.29 | L25: =Sheet6!E46 -> #REF! | P25: =+L25-H25 -> #REF! | W25: -179034.71 | X25: =+L25-W25 -> #REF!
A26: Advance License Income | L26: =-#REF! -> #REF! | P26: =+L26-H26 -> #REF!
A27: Income From Windmill | L27: =-#REF! -> #REF!
A29: TOTAL EXPENSE | B29: =B4 -> 760110 | C29: =+D29/B29 -> 33.447206 | D29: =SUM(D16:D28) -> 25423556 | F29: =F4 -> 245196.77 | G29: =+H29/F29 -> 33.447206 | H29: =SUM(H16:H28) -> 8201146.9 | J29: =J4 -> #REF! | K29: =+L29/J29 -> #REF! | L29: =SUM(L16:L28) -> #REF! | N29: =N4 -> #REF! | O29: =+P29/J29 -> #REF! | P29: =SUM(P16:P28) -> #REF! | W29: 7009132.3 | X29: =+L29-W29 -> #REF!
A31: NET EBDITA | B31: =B4 -> 760110 | C31: =+D31/B31 -> 22.987461 | D31: =D14-D29 -> 17472999 | F31: =F4 -> 245196.77 | G31: =+G14-G29 -> 22.987461 | H31: =H14-H29 -> 5636451.3 | J31: =J4 -> #REF! | K31: =+K14-K29 -> #REF! | L31: =L14-L29 -> #REF! | N31: =N4 -> #REF! | O31: =+P31/J31 -> #REF! | P31: =+P14-P29 -> #REF! | W31: 1407114.1 | X31: =+L31-W31 -> #REF!
A35: Inter Co. Purchase | L35: =-'PUR-SALE'!#REF! -> #REF!
A36: Inter Co. Sale | L36: ='PUR-SALE'!#REF! -> #REF! | S36: =4095-460-270 -> 3365 | T36: 357.06 | U36: =+S36*T36 -> 1201506.9
A37: Trading Impact | L37: =-'PUR-SALE'!#REF! -> #REF! | S37: =4095-460-270 -> 3365 | T37: =#REF! -> #REF! | U37: =+S37*T37 -> #REF!
A38: Advance Lic. Benefit on Trading Trx. | L38: =-('PUR-SALE'!#REF!+'PUR-SALE'!#REF!+'PUR-SALE'!#REF!+'PUR-SALE'!#REF!)*1.1*6 -> #REF!
A39: RM Price Reduction Impact | L39: =#REF! -> #REF! | S39: =+S36-S37 -> 0 | T39: =+T36-T37 -> #REF! | U39: =+U36-U37 -> #REF!
A40: Oswal MEIS Benefit | L40: =#REF! -> #REF!
A41: Total Impact of Above | L41: =SUM(L35:L40) -> #REF!
L43: =+L31+L39 -> #REF!
L45: =L31+L23+L39 -> #REF!
A49: Export | J49: =#REF! -> #REF!
A50: Eligible Import | J50: =+J49*1.1 -> #REF!
A51: Actual Import | J51: 49500
J52: =+J50-J51 -> #REF!
J53: 6
...

Sheet PUR-SALE

Sheet Sheet6
B3: Particulars | C3: Qty | D3: Rate | E3: Amount
B4: Sales | C4: Qty | D4: Rate | E4: Value
B5: PP WOVEN BIG BAGS / SACKS | C5: ='New Working'!B5 -> 306664.9 | D5: ='New Working'!C5 -> 157.96893 | E5: ='New Working'!D5 -> 48443526
B6: PP Woven Fabrics(FG) | C6: ='New Working'!B6 -> 85056.5 | D6: ='New Working'!C6 -> 105.13316 | E6: ='New Working'!D6 -> 8942258.9
B7: PP Laminated Fabric | C7: ='New Working'!B7 -> 40640.5 | D7: ='New Working'!C7 -> 103.30194 | E7: ='New Working'!D7 -> 4198242.7
B8: REPROCESS GRANULES (FG) | C8: ='New Working'!B8 -> 14100 | D8: ='New Working'!C8 -> 20 | E8: ='New Working'!D8 -> 282000
B9: PP TAPE / YARN | C9: ='New Working'!B9 -> 0 | D9: ='New Working'!C9 -> #DIV/0! | E9: ='New Working'!D9 -> 0
B10: PP Fabric Wastage | C10: ='New Working'!B10 -> 0 | D10: ='New Working'!C10 -> #DIV/0! | E10: ='New Working'!D10 -> 0
B11: PP Tape Wastage | C11: ='New Working'!B11 -> 7960 | D11: ='New Working'!C11 -> 15 | E11: ='New Working'!D11 -> 119400
B12: PP WEBBING (FG) | C12: ='New Working'!B12 -> 12228.8 | D12: ='New Working'!C12 -> 103.29697 | E12: ='New Working'!D12 -> 1263198
B13: Filler | C13: ='New Working'!B13 -> 8500 | D13: ='New Working'!C13 -> 29.5 | E13: ='New Working'!D13 -> 250750
B14: Master Batch | C14: ='New Working'!B14 -> 500 | D14: ='New Working'!C14 -> 141 | E14: ='New Working'!D14 -> 70500
B15: LLDPE GRANULES | C15: ='New Working'!B15 -> 125 | D15: ='New Working'!C15 -> 68.248 | E15: ='New Working'!D15 -> 8531
B16: Pp Granuales | C16: ='New Working'!B16 -> 18000 | D16: ='New Working'!C16 -> 75.863889 | E16: ='New Working'!D16 -> 1365550
B17: LLDPE BAGS (LINER) | C17: ='New Working'!B17 -> 0 | D17: ='New Working'!C17 -> #DIV/0! | E17: ='New Working'!D17 -> 0
C18: ='New Working'!B18 -> 0 | D18: ='New Working'!C18 -> #DIV/0! | E18: ='New Working'!D18 -> 0
B20: TOTAL SALE | C20: =SUM(C5:C17) -> 493775.7 | D20: =E20/C20 -> 131.52522 | E20: =SUM(E5:E17) -> 64943957
B21: Less: Avg. RMC Cost of the Material Consumed | C21: ='New Working'!B75 -> #REF! | D21: ='New Working'!C75 -> #REF! | E21: =+C21*D21 -> #REF!
B23: Value Addition on Sales (A) | C23: =+C20 -> 493775.7 | D23: =+D20-D21 -> #REF! | E23: =C23*D23 -> #REF!
B25: Sock Impact
B26: Op. Stock Impact | C26: ='New Working'!B118 -> #REF! | D26: =-'New Working'!C119 -> #REF! | E26: =C26*D26 -> #REF!
B27: Current Month Proccessed Stock Impact
B28: Tape | C28: =-#REF!-#REF! -> #REF! | D28: 15 | E28: =C28*D28 -> #REF!
B29: Unlaminated Fabric | C29: =-#REF!-#REF!-#REF! -> #REF! | D29: 36 | E29: =C29*D29 -> #REF!
B30: Laminated Fabric | C30: =-#REF!-#REF! -> #REF! | D30: 36 | E30: =C30*D30 -> #REF!
B31: Webbing | C31: =-#REF!-#REF! -> #REF! | D31: 36 | E31: =C31*D31 -> #REF!
B32: FIBC | C32: =-#REF! -> #REF! | D32: 80 | E32: =C32*D32 -> #REF!
B33: Small Bags | C33: =-#REF! -> #REF! | D33: 70 | E33: =C33*D33 -> #REF!
B34: RM Stock Impact | E34: 1571475.4
B36: Total Stock Impact (B) | C36: =$C$23 -> 493775.7 | D36: =E36/C36 -> #REF! | E36: =SUM(E26:E35) -> #REF!
B38: Power | C38: =$C$23 -> 493775.7 | D38: =E38/C38 -> #REF! | E38: ='New Working'!D79 -> #REF!
B39: Salary | C39: =$C$23 -> 493775.7 | D39: =E39/C39 -> #REF! | E39: ='New Working'!D80 -> #REF!
B40: Consumables and Stores | C40: =$C$23 -> 493775.7 | D40: =E40/C40 -> #REF! | E40: ='New Working'!D81 -> #REF!
B41: Job Charges | C41: =$C$23 -> 493775.7 | D41: =E41/C41 -> #REF! | E41: ='New Working'!D82 -> #REF!
B42: Other | C42: =$C$23 -> 493775.7 | D42: =E42/C42 -> #REF! | E42: ='New Working'!D83 -> #REF!
B43: MEIS Benefit | C43: =$C$23 -> 493775.7 | D43: =E43/C43 -> #REF! | E43: =-'New Working'!D89 -> #REF!
B44: Import Duty on Excess Material | C44: =$C$23 -> 493775.7 | D44: =E44/C44 -> #REF! | E44: =-'New Working'!D90 -> #REF!
B45: Income from Windmill | C45: =$C$23 -> 493775.7 | D45: =E45/C45 -> 0 | E45: 0
B46: Exchange Rate Benefit | C46: =$C$23 -> 493775.7 | D46: =E46/C46 -> #REF! | E46: =-'New Working'!D92 -> #REF!
B48: Total Expenses (C ) | E48: =SUM(E38:E47) -> #REF!
...

Sheet Sheet5
A3: Item Name | B3: Opening Balance | C3: Inward | F3: Outward | I3: Closing Balance | J3: Qty At Job Worker | K3: Rate | L3: Value
C4: Purchase | D4: Production | E4: Received Job IN | F4: Sale | G4: Issue / Consumption | H4: Sent To Job OUT
A6: SF
A7: R.P. GRANULES | B7: ='ERP STOCK'!B7 -> 36409.13 | C7: ='ERP STOCK'!C7 -> 11390 | D7: ='ERP STOCK'!D7 -> 173100 | E7: ='ERP STOCK'!E7 -> 28116.2 | F7: ='ERP STOCK'!F7 -> 49171.2 | G7: ='ERP STOCK'!G7 -> 174000 | H7: ='ERP STOCK'!H7 -> 0 | I7: ='ERP STOCK'!I7 -> 25844.13 | ... L7: ='ERP STOCK'!L7 -> 1292206.5
B8: =#REF! -> #REF! | C8: =#REF! -> #REF! | D8: =#REF! -> #REF! | E8: =#REF! -> #REF! | F8: =#REF! -> #REF! | G8: =#REF! -> #REF! | H8: =#REF! -> #REF! | I8: =#REF! -> #REF!
B9: =+B7-B8 -> #REF! | C9: =+C7-C8 -> #REF! | D9: =+D7-D8 -> #REF! | E9: =+E7-E8 -> #REF! | F9: =+F7-F8 -> #REF! | G9: =+G7-G8 -> #REF! | H9: =+H7-H8 -> #REF! | I9: =+I7-I8 -> #REF!
A10: PP/HD TAPE | B10: ='ERP STOCK'!B8 -> 182370.98 | C10: ='ERP STOCK'!C8 -> 5495.1 | D10: ='ERP STOCK'!D8 -> 690008.29 | E10: ='ERP STOCK'!E8 -> 8597.3 | F10: ='ERP STOCK'!F8 -> 10.6 | G10: ='ERP STOCK'!G8 -> 705935.42 | H10: ='ERP STOCK'!H8 -> 0 | I10: ='ERP STOCK'!I8 -> 180525.65 | ... L10: ='ERP STOCK'!L8 -> 1624730.8
B11: =#REF! -> #REF! | C11: =#REF! -> #REF! | D11: =#REF! -> #REF! | E11: =#REF! -> #REF! | F11: =#REF! -> #REF! | G11: =#REF! -> #REF! | H11: =#REF! -> #REF! | I11: =#REF! -> #REF!
B12: =+B10-B11 -> #REF! | C12: =+C10-C11 -> #REF! | D12: =+D10-D11 -> #REF! | E12: =+E10-E11 -> #REF! | F12: =+F10-F11 -> #REF! | G12: =+G10-G11 -> #REF! | H12: =+H10-H11 -> #REF! | I12: =+I10-I11 -> #REF!
A13: UL FABRIC | B13: ='ERP STOCK'!B9 -> 5623632.4 | C13: ='ERP STOCK'!C9 -> 73519 | D13: ='ERP STOCK'!D9 -> 578465 | E13: ='ERP STOCK'!E9 -> 176380.3 | F13: ='ERP STOCK'!F9 -> 213703.5 | G13: ='ERP STOCK'!G9 -> 428251.45 | H13: ='ERP STOCK'!H9 -> 128775.9 | I13: ='ERP STOCK'!I9 -> 5681265.8 | ... L13: ='ERP STOCK'!L9 -> 90900253
B14: =#REF! -> #REF! | C14: =#REF! -> #REF! | D14: =#REF! -> #REF! | E14: =#REF! -> #REF! | F14: =#REF! -> #REF! | G14: =#REF! -> #REF! | H14: =#REF! -> #REF! | I14: =#REF! -> #REF!
B15: =+B13-B14 -> #REF! | C15: =+C13-C14 -> #REF! | D15: =+D13-D14 -> #REF! | E15: =+E13-E14 -> #REF! | F15: =+F13-F14 -> #REF! | G15: =+G13-G14 -> #REF! | H15: =+H13-H14 -> #REF! | I15: =+I13-I14 -> #REF!
A16: LAMINETED FABRIC | B16: ='ERP STOCK'!B10 -> 771450.44 | C16: ='ERP STOCK'!C10 -> 3003.4 | D16: ='ERP STOCK'!D10 -> 275216.2 | E16: ='ERP STOCK'!E10 -> 68732.7 | F16: ='ERP STOCK'!F10 -> 115312.1 | G16: ='ERP STOCK'!G10 -> 245377.7 | H16: ='ERP STOCK'!H10 -> 14916.3 | I16: ='ERP STOCK'!I10 -> 742796.64 | ... L16: ='ERP STOCK'!L10 -> 15598729
B17: =#REF! -> #REF! | C17: =#REF! -> #REF! | D17: =#REF! -> #REF! | E17: =#REF! -> #REF! | F17: =#REF! -> #REF! | G17: =#REF! -> #REF! | H17: =#REF! -> #REF! | I17: =#REF! -> #REF!
B18: =+B16-B17 -> #REF! | C18: =+C16-C17 -> #REF! | D18: =+D16-D17 -> #REF! | E18: =+E16-E17 -> #REF! | F18: =+F16-F17 -> #REF! | G18: =+G16-G17 -> #REF! | H18: =+H16-H17 -> #REF! | I18: =+I16-I17 -> #REF!
A19: WEBBING | B19: ='ERP STOCK'!B11 -> 682335.87 | C19: ='ERP STOCK'!C11 -> 2804.7 | D19: ='ERP STOCK'!D11 -> 114635.1 | E19: ='ERP STOCK'!E11 -> 4950.5 | F19: ='ERP STOCK'!F11 -> 27043.2 | G19: ='ERP STOCK'!G11 -> 88553.3 | H19: ='ERP STOCK'!H11 -> 3777.4 | I19: ='ERP STOCK'!I11 -> 685352.27 | ... L19: ='ERP STOCK'!L11 -> 10965636
B20: =#REF! -> #REF! | C20: =#REF! -> #REF! | D20: =#REF! -> #REF! | E20: =#REF! -> #REF! | F20: =#REF! -> #REF! | G20: =#REF! -> #REF! | H20: =#REF! -> #REF! | I20: =#REF! -> #REF!
B21: =+B19-B20 -> #REF! | C21: =+C19-C20 -> #REF! | D21: =+D19-D20 -> #REF! | E21: =+E19-E20 -> #REF! | F21: =+F19-F20 -> #REF! | G21: =+G19-G20 -> #REF! | H21: =+H19-H20 -> #REF! | I21: =+I19-I20 -> #REF!
A22: TAPE WASTE | B22: ='ERP STOCK'!B12 -> -151002.69 | C22: ='ERP STOCK'!C12 -> 0 | D22: ='ERP STOCK'!D12 -> 42534 | E22: ='ERP STOCK'!E12 -> 0 | F22: ='ERP STOCK'!F12 -> 0 | G22: ='ERP STOCK'!G12 -> 179189 | H22: ='ERP STOCK'!H12 -> 0 | I22: ='ERP STOCK'!I12 -> -287657.69 | ... L22: ='ERP STOCK'!L12 -> -4314865.3
A23: PP WASTE | B23: ='ERP STOCK'!B19 -> -21868 | C23: ='ERP STOCK'!C19 -> 0 | D23: ='ERP STOCK'!D19 -> 0 | E23: ='ERP STOCK'!E19 -> 0 | F23: ='ERP STOCK'!F19 -> 3978 | G23: ='ERP STOCK'!G19 -> 0 | H23: ='ERP STOCK'!H19 -> 0 | I23: ='ERP STOCK'!I19 -> -25846 | ... L23: ='ERP STOCK'!L19 -> -387690
A24: FABRIC WASTE | B24: ='ERP STOCK'!B13 -> -38316.75 | C24: ='ERP STOCK'!C13 -> 38647.85 | D24: ='ERP STOCK'!D13 -> 71320.42 | E24: ='ERP STOCK'!E13 -> 64792.2 | F24: ='ERP STOCK'!F13 -> 18635 | G24: ='ERP STOCK'!G13 -> 179189 | H24: ='ERP STOCK'!H13 -> 0 | I24: ='ERP STOCK'!I13 -> -61380.28 | ... L24: ='ERP STOCK'!L13 -> -920704.2
B25: =#REF! -> #REF! | C25: =#REF! -> #REF! | D25: =#REF! -> #REF! | E25: =#REF! -> #REF! | F25: =#REF! -> #REF! | G25: =#REF! -> #REF! | H25: =#REF! -> #REF! | I25: =#REF! -> #REF!
B26: =+B22+B23+B24-B25 -> #REF! | C26: =+C22+C23+C24-C25 -> #REF! | D26: =+D22+D23+D24-D25 -> #REF! | E26: =+E22+E23+E24-E25 -> #REF! | F26: =+F22+F23+F24-F25 -> #REF! | G26: =+G22+G23+G24-G25 -> #REF! | H26: =+H22+H23+H24-H25 -> #REF! | I26: =+I22+I23+I24-I25 -> #REF!
A27: PP MF YARN | B27: ='ERP STOCK'!B14 -> 44360.71 | C27: ='ERP STOCK'!C14 -> 35352.2 | D27: ='ERP STOCK'!D14 -> 0 | E27: ='ERP STOCK'!E14 -> 2433.24 | F27: ='ERP STOCK'!F14 -> 176.4 | G27: ='ERP STOCK'!G14 -> 33533.3 | H27: ='ERP STOCK'!H14 -> 6496.6 | I27: ='ERP STOCK'!I14 -> 41939.85 | ... L27: ='ERP STOCK'!L14 -> 5255956.6
A28: Crimp Yarn (Texurise Yarn) | B28: ='ERP STOCK'!B15 -> -12123.14 | C28: ='ERP STOCK'!C15 -> 0 | D28: ='ERP STOCK'!D15 -> 0 | E28: ='ERP STOCK'!E15 -> 0 | F28: ='ERP STOCK'!F15 -> 2013.74 | G28: ='ERP STOCK'!G15 -> 0 | H28: ='ERP STOCK'!H15 -> 0 | I28: ='ERP STOCK'!I15 -> -14136.88 | ... L28: ='ERP STOCK'!L15 -> -1574046.1
A29: PP FABRILATED YARN(TAPE) | B29: ='ERP STOCK'!B18 -> -10553.18 | C29: ='ERP STOCK'!C18 -> 5834.3 | D29: ='ERP STOCK'!D18 -> 1723.26 | E29: ='ERP STOCK'!E18 -> 2164.8 | F29: ='ERP STOCK'!F18 -> 0 | G29: ='ERP STOCK'!G18 -> 14882 | H29: ='ERP STOCK'!H18 -> 0 | I29: ='ERP STOCK'!I18 -> -15712.82 | ... L29: ='ERP STOCK'!L18 -> -1637171.1
A30: Filler Cord | B30: ='ERP STOCK'!B22 -> 17502.87 | C30: ='ERP STOCK'!C22 -> 8104.91 | D30: ='ERP STOCK'!D22 -> 1955.6 | E30: ='ERP STOCK'!E22 -> 0 | F30: ='ERP STOCK'!F22 -> 0 | G30: ='ERP STOCK'!G22 -> 9192 | H30: ='ERP STOCK'!H22 -> 0 | I30: ='ERP STOCK'!I22 -> 18371.38 | ... L30: ='ERP STOCK'!L22 -> 220456.56
B31: =#REF! -> #REF! | C31: =#REF! -> #REF! | D31: =#REF! -> #REF! | E31: =#REF! -> #REF! | F31: =#REF! -> #REF! | G31: =#REF! -> #REF! | H31: =#REF! -> #REF! | I31: =#REF! -> #REF!
B32: =+B27+B28+B29+B30-B31 -> #REF! | C32: =+C27+C28+C29+C30-C31 -> #REF! | D32: =+D27+D28+D29+D30-D31 -> #REF! | E32: =+E27+E28+E29+E30-E31 -> #REF! | F32: =+F27+F28+F29+F30-F31 -> #REF! | G32: =+G27+G28+G29+G30-G31 -> #REF! | H32: =+H27+H28+H29+H30-H31 -> #REF! | I32: =+I27+I28+I29+I30-I31 -> #REF!
A33: LLDPE Liner Bags | B33: ='ERP STOCK'!B16 -> 28833.32 | C33: ='ERP STOCK'!C16 -> 19858.6 | D33: ='ERP STOCK'!D16 -> 0 | E33: ='ERP STOCK'!E16 -> 0 | F33: ='ERP STOCK'!F16 -> 0 | G33: ='ERP STOCK'!G16 -> 26234 | H33: ='ERP STOCK'!H16 -> 20708.6 | I33: ='ERP STOCK'!I16 -> 1749.32 | ... L33: ='ERP STOCK'!L16 -> 226584.16
B34: =#REF! -> #REF! | C34: =#REF! -> #REF! | D34: =#REF! -> #REF! | E34: =#REF! -> #REF! | F34: =#REF! -> #REF! | G34: =#REF! -> #REF! | H34: =#REF! -> #REF! | I34: =#REF! -> #REF!
B35: =+B33-B34 -> #REF! | C35: =+C33-C34 -> #REF! | D35: =+D33-D34 -> #REF! | E35: =+E33-E34 -> #REF! | F35: =+F33-F34 -> #REF! | G35: =+G33-G34 -> #REF! | H35: =+H33-H34 -> #REF! | I35: =+I33-I34 -> #REF!
A36: LLDPE Film | B36: ='ERP STOCK'!B17 -> 26898.11 | C36: ='ERP STOCK'!C17 -> 1315.84 | D36: ='ERP STOCK'!D17 -> 0 | E36: ='ERP STOCK'!E17 -> 0 | F36: ='ERP STOCK'!F17 -> 0 | G36: ='ERP STOCK'!G17 -> 1307.89 | H36: ='ERP STOCK'!H17 -> 1111.09 | I36: ='ERP STOCK'!I17 -> 25794.97 | ... L36: ='ERP STOCK'!L17 -> 3001532.1
B37: =#REF! -> #REF! | C37: =#REF! -> #REF! | D37: =#REF! -> #REF! | E37: =#REF! -> #REF! | F37: =#REF! -> #REF! | G37: =#REF! -> #REF! | H37: =#REF! -> #REF! | I37: =#REF! -> #REF!
B38: =B36-B37 -> #REF! | C38: =C36-C37 -> #REF! | D38: =D36-D37 -> #REF! | E38: =E36-E37 -> #REF! | F38: =F36-F37 -> #REF! | G38: =G36-G37 -> #REF! | H38: =H36-H37 -> #REF! | I38: =I36-I37 -> #REF!
A39: MB | B39: ='ERP STOCK'!B20 -> 6045.179 | C39: ='ERP STOCK'!C20 -> 7573.9 | D39: ='ERP STOCK'!D20 -> 0 | E39: ='ERP STOCK'!E20 -> 50 | F39: ='ERP STOCK'!F20 -> 2800 | G39: ='ERP STOCK'!G20 -> 3934.985 | H39: ='ERP STOCK'!H20 -> 0 | I39: ='ERP STOCK'!I20 -> 6934.094 | ... L39: ='ERP STOCK'!L20 -> 1196058
B40: =#REF! -> #REF! | C40: =#REF! -> #REF! | D40: =#REF! -> #REF! | E40: =#REF! -> #REF! | F40: =#REF! -> #REF! | G40: =#REF! -> #REF! | H40: =#REF! -> #REF! | I40: =#REF! -> #REF!
B41: =+B39-B40 -> #REF! | C41: =+C39-C40 -> #REF! | D41: =+D39-D40 -> #REF! | E41: =+E39-E40 -> #REF! | F41: =+F39-F40 -> #REF! | G41: =+G39-G40 -> #REF! | H41: =+H39-H40 -> #REF! | I41: =+I39-I40 -> #REF!
A42: UV | B42: ='ERP STOCK'!B21 -> 34787.135 | C42: ='ERP STOCK'!C21 -> 15045 | D42: ='ERP STOCK'!D21 -> 0 | E42: ='ERP STOCK'!E21 -> 0 | F42: ='ERP STOCK'!F21 -> 0 | G42: ='ERP STOCK'!G21 -> 13989.215 | H42: ='ERP STOCK'!H21 -> 0 | I42: ='ERP STOCK'!I21 -> 35842.92 | ... L42: ='ERP STOCK'!L21 -> 6136551.6
B43: =#REF! -> #REF! | C43: =#REF! -> #REF! | D43: =#REF! -> #REF! | E43: =#REF! -> #REF! | F43: =#REF! -> #REF! | G43: =#REF! -> #REF! | H43: =#REF! -> #REF! | I43: =#REF! -> #REF!
...

Sheet New Working
A1: PLASTENE INDIA LIMITED UNIT - II
A2: EBDITA from 1st Dec 2019 to 14th Dec 2019
A3: Sales | B3: Qty | C3: Rate | D3: Value
A4: Plastic Used Bags | B4: =Sheet3!J6 -> 0 | C4: =D4/B4 -> #DIV/0! | D4: =Sheet3!L6 -> 0
A5: PP WOVEN BIG BAGS / SACKS | B5: =Sheet3!J7 -> 306664.9 | C5: =D5/B5 -> 157.96893 | D5: =Sheet3!L7 -> 48443526
A6: PP Woven Fabrics(FG) | B6: =Sheet3!J8 -> 85056.5 | C6: =D6/B6 -> 105.13316 | D6: =Sheet3!L8 -> 8942258.9
A7: PP Laminated Fabric | B7: =Sheet3!J9 -> 40640.5 | C7: =D7/B7 -> 103.30194 | D7: =Sheet3!L9 -> 4198242.7
A8: REPROCESS GRANULES (FG) | B8: =Sheet3!J10 -> 14100 | C8: =D8/B8 -> 20 | D8: =Sheet3!L10 -> 282000
A9: PP TAPE / YARN | B9: =Sheet3!J11 -> 0 | C9: =D9/B9 -> #DIV/0! | D9: =Sheet3!L11 -> 0
A10: PP Fabric Wastage | B10: =Sheet3!J12 -> 0 | C10: =D10/B10 -> #DIV/0! | D10: =Sheet3!L12 -> 0
A11: PP Tape Wastage | B11: =Sheet3!J13 -> 7960 | C11: =D11/B11 -> 15 | D11: =Sheet3!L13 -> 119400
A12: PP WEBBING (FG) | B12: =Sheet3!J14 -> 12228.8 | C12: =D12/B12 -> 103.29697 | D12: =Sheet3!L14 -> 1263198
A13: Filler | B13: =Sheet3!J15 -> 8500 | C13: =D13/B13 -> 29.5 | D13: =Sheet3!L15 -> 250750
A14: Master Batch | B14: =Sheet3!J16 -> 500 | C14: =D14/B14 -> 141 | D14: =Sheet3!L16 -> 70500
A15: LLDPE GRANULES | B15: =Sheet3!J17 -> 125 | C15: =D15/B15 -> 68.248 | D15: =Sheet3!L17 -> 8531
... A18: LDPE GRANUALES | B18: =Sheet3!J20 -> 0 | C18: =D18/B18 -> #DIV/0! | D18: =Sheet3!L20 -> 0
A20: TOTAL SALE | B20: =SUM(B4:B19) -> 493775.7 | C20: =D20/B20 -> 131.52522 | D20: =SUM(D4:D19) -> 64943957
A24: Raw Material Consumption | B24: Qty | C24: Rate | D24: Value | E24: Rate Ref
A25: For Tape Plant
A26: PP | B26: =#REF! -> #REF! | C26: =#REF! -> #REF! | D26: =B26*C26 -> #REF! | E26: FIFO
A27: Filler | B27: =#REF! -> #REF! | C27: =FillerSoltex!Y6 -> #REF! | D27: =B27*C27 -> #REF! | E27: FIFO
A28: MB | B28: =#REF! -> #REF! | C28: =MB!Y6 -> #REF! | D28: =B28*C28 -> #REF! | E28: FIFO
A29: UV | B29: =#REF! -> #REF! | C29: =UV!Y6 -> #REF! | D29: =B29*C29 -> #REF! | E29: FIFO
A30: HDPE | B30: =#REF! -> #REF! | C30: =#REF! -> #REF! | D30: =B30*C30 -> #REF! | E30: FIFO
A31: LLDPE | B31: =#REF! -> #REF! | C31: =#REF! -> #REF! | D31: =B31*C31 -> #REF! | E31: FIFO
A32: RP | B32: =#REF!*0 -> #REF! | C32: 0 | D32: =B32*C32 -> #REF! | E32: Wastage
A34: TOTAL PLANT CONSUMPTION | B34: =SUM(B26:B33) -> #REF! | C34: =D34/B34 -> #REF! | D34: =SUM(D26:D33) -> #REF!
A36: For Yarn
A37: Yarn | B37: =SUMIF(#REF!,"YARN",#REF!) -> #REF! | C37: =D37/B37 -> #REF! | D37: =SUMIF(#REF!,"YARN",#REF!) -> #REF! | E37: FIFO
A39: For Lamination
A40: PP | B40: =#REF! -> #REF! | C40: =#REF! -> #REF! | D40: =B40*C40 -> #REF! | E40: FIFO
A41: LDPE | B41: =#REF! -> #REF! | C41: =LLDP!Z6 -> #REF! | D41: =B41*C41 -> #REF! | E41: FIFO
A42: MB | B42: =#REF! -> #REF! | C42: =MB!Y6 -> #REF! | D42: =B42*C42 -> #REF! | E42: FIFO
A43: Filler | B43: =#REF! -> #REF! | C43: =FillerSoltex!Y6 -> #REF! | D43: =B43*C43 -> #REF! | E43: FIFO
A44: UV | C44: =UV!Y6 -> #REF! | D44: =B44*C44 -> #REF! | E44: FIFO
A45: RP | D45: =B45*C45 -> 0 | E45: FIFO
A47: OUTSIDE PURCHASE
A48: Fabric UL | B48: =SUMIF(#REF!,"UL FABRIC",#REF!) -> #REF! | C48: =D48/B48 -> #REF! | D48: =SUMIF(#REF!,"UL FABRIC",#REF!) -> #REF! | E48: Pur Rate
A49: FIBC | B49: =SUMIF(#REF!,"FIBC",#REF!) -> #REF! | C49: =D49/B49 -> #REF! | D49: =SUMIF(#REF!,"FIBC",#REF!) -> #REF! | E49: Pur Rate
A50: Film | B50: =SUMIF(#REF!,"FILM",#REF!) -> #REF! | C50: =D50/B50 -> #REF! | D50: =SUMIF(#REF!,"FILM",#REF!) -> #REF! | E50: Pur Rate
...

Sheet ERP STOCK
A3: Item Name | B3: Opening Balance | C3: Inward | F3: Outward | I3: Closing Balance | J3: Qty At Job Worker | K3: Rate | L3: Value
C4: Purchase | D4: Production | E4: Received Job IN | F4: Sale | G4: Issue / Consumption | H4: Sent To Job OUT
A5: 29-02-2020
A6: SF
A7: R.P. GRANULES | B7: 36409.13 | C7: 11390 | D7: 173100 | E7: 28116.2 | F7: 49171.2 | G7: 174000 | H7: 0 | I7: 25844.13 | J7: 40500 | K7: 50 | L7: 1292206.5
A8: PP/HD TAPE | B8: 182370.98 | C8: 5495.1 | D8: 690008.29 | E8: 8597.3 | F8: 10.6 | G8: 705935.42 | H8: 0 | I8: 180525.65 | J8: 89833.87 | K8: 9 | L8: 1624730.8
A9: UL FABRIC | B9: 5623632.4 | C9: 73519 | D9: 578465 | E9: 176380.3 | F9: 213703.5 | G9: 428251.45 | H9: 128775.9 | I9: 5681265.8 | J9: 519703.9 | K9: 16 | L9: 90900253
A10: LAMINETED FABRIC | B10: 771450.44 | C10: 3003.4 | D10: 275216.2 | E10: 68732.7 | F10: 115312.1 | G10: 245377.7 | H10: 14916.3 | I10: 742796.64 | J10: 274076.48 | K10: 21 | L10: 15598729
A11: WEBBING | B11: 682335.87 | C11: 2804.7 | D11: 114635.1 | E11: 4950.5 | F11: 27043.2 | G11: 88553.3 | H11: 3777.4 | I11: 685352.27 | J11: 146015.04 | K11: 16 | L11: 10965636
A12: TAPE WASTE | B12: -151002.69 | C12: 0 | D12: 42534 | E12: 0 | F12: 0 | G12: 179189 | H12: 0 | I12: -287657.69 | J12: 0 | K12: 15 | L12: -4314865.3
A13: FABRIC WASTE | B13: -38316.75 | C13: 38647.85 | D13: 71320.42 | E13: 64792.2 | F13: 18635 | G13: 179189 | H13: 0 | I13: -61380.28 | J13: 132065 | K13: 15 | L13: -920704.2
A14: PP MF YARN | B14: 44360.71 | C14: 35352.2 | D14: 0 | E14: 2433.24 | F14: 176.4 | G14: 33533.3 | H14: 6496.6 | I14: 41939.85 | J14: 155020.37 | K14: 125.32 | L14: 5255956.6
A15: Crimp Yarn (Texurise Yarn) | B15: -12123.14 | C15: 0 | D15: 0 | E15: 0 | F15: 2013.74 | G15: 0 | H15: 0 | I15: -14136.88 | J15: 13651.03 | K15: 111.34 | L15: -1574046.1
A16: LLDPE Liner Bags | B16: 28833.32 | C16: 19858.6 | D16: 0 | E16: 0 | F16: 0 | G16: 26234 | H16: 20708.6 | I16: 1749.32 | J16: 172321.68 | K16: 129.53 | L16: 226584.16
A17: LLDPE Film | B17: 26898.11 | C17: 1315.84 | D17: 0 | E17: 0 | F17: 0 | G17: 1307.89 | H17: 1111.09 | I17: 25794.97 | J17: 1999.09 | K17: 116.36 | L17: 3001532.1
A18: PP FABRILATED YARN(TAPE) | B18: -10553.18 | C18: 5834.3 | D18: 1723.26 | E18: 2164.8 | F18: 0 | G18: 14882 | H18: 0 | I18: -15712.82 | J18: 21942.25 | K18: 104.19 | L18: -1637171.1
... A22: Filler Cord | B22: 17502.87 | C22: 8104.91 | D22: 1955.6 | E22: 0 | F22: 0 | G22: 9192 | H22: 0 | I22: 18371.38 | J22: 746.1 | K22: 12 | L22: 220456.56
A23: Total | B23: 7220762.4 | C23: 227944.8 | D23: 1948957.9 | E23: 356217.24 | F23: 432843.74 | G23: 2103569.3 | H23: 175785.89 | I23: 7041683.4 | J23: 1568583.8 | L23: 1.2758422e+08
A25: FG
A26: PP/ HDPE BAGS | B26: 2758.6 | C26: 0 | D26: 17602 | E26: 0 | F26: 22274 | G26: 0 | H26: 0 | I26: -1913.4 | J26: 0 | K26: 85.68 | L26: -163933.41
A27: PP BAGS | B27: 8807.4 | C27: 1253.9 | D27: 0 | E27: 0 | F27: 0 | G27: 0 | H27: 0 | I27: 10061.3 | J27: 0 | K27: 0 | L27: 0
A28: PP WOVEN BIG BAGS | B28: 267536.18 | C28: 18506 | D28: 481097 | E28: 175106.5 | F28: 520652.9 | G28: 0 | H28: 0 | I28: 421592.78 | J28: 815 | K28: 158.33 | L28: 66749398
A29: Total | B29: 279102.18 | C29: 19759.9 | D29: 498699 | E29: 175106.5 | F29: 542926.9 | G29: 0 | H29: 0 | I29: 429740.68 | J29: 815 | L29: 66585464
A31: CN
A32: All Ink | B32: 12133 | C32: 270 | D32: 0 | E32: 0 | F32: 0 | G32: 530 | H32: 0 | I32: 11873 | J32: 340 | K32: 202.41 | L32: 2403269.9
A33: Thinner | B33: 10403.3 | C33: 2210 | D33: 0 | E33: 0 | F33: 0 | G33: 1680 | H33: 0 | I33: 10933.3 | J33: 510 | K33: 75.83 | L33: 829064.14
A34: Total | B34: 22536.3 | C34: 2480 | D34: 0 | E34: 0 | F34: 0 | G34: 2210 | H34: 0 | I34: 22806.3 | J34: 850 | L34: 3232334
A36: RM
A37: PP | B37: 136400.33 | C37: 963286 | D37: 0 | E37: 13500 | F37: 213775 | G37: 483033.14 | H37: 306195 | I37: 110183.19 | J37: 3560688.4 | K37: 72.83 | L37: 8024422.6
A38: LDPE | B38: 31719.681 | C38: 8100 | D38: 0 | E38: 0 | F38: 0 | G38: 10859.25 | H38: 2550 | I38: 26410.431 | J38: 23206.99 | K38: 101.34 | L38: 2676324.4
A39: LLDPE | B39: 14658.539 | C39: 23000 | D39: 0 | E39: 0 | F39: 2600 | G39: 17509.25 | H39: 350 | I39: 17199.289 | J39: 75037.28 | K39: 89.66 | L39: 1542131.2
A40: HDPE | B40: 1093.32 | C40: 0 | D40: 0 | E40: 0 | F40: 0 | G40: 158.75 | H40: 0 | I40: 934.57 | J40: 5030 | K40: 92.85 | L40: 86774.82
A41: FILLER | B41: 55988.7 | C41: 64175 | D41: 0 | E41: 0 | F41: 14425 | G41: 51317.2 | H41: 5530 | I41: 48891.5 | J41: 83289.34 | K41: 31.19 | L41: 1524747.1
A42: OTHER | B42: 3770.46 | C42: 277.32 | D42: 0 | E42: 0 | F42: 0 | G42: 0 | H42: 0 | I42: 4047.78 | J42: 0 | K42: 0 | L42: 0
A43: Total | B43: 243631.03 | C43: 1058838.3 | D43: 0 | E43: 13500 | F43: 230800 | G43: 562877.59 | H43: 314625 | I43: 207666.76 | J43: 3747252 | L43: 13854400

Sheet Sheet3
D1: 20
A2: SN | B2: Particulars | C2: Budget | E2: Actual
C3: Jan-20 | D3: Upto Date | E3: Upto Date | F3: Kg (in Ton) | G3: Rate per Kg
A4: A | B4: Quantitative Details - MT
A5: 1 | B5: Capacity | C5: 900 | D5: =C5/31*$D$1 -> 580.64516 | E5: =D5 -> 580.64516 | I5: Item Name | J5: Quantity | K5: Rate | L5: Amount | O5: Values
A6: =A5+1 -> 2 | B6: Production | C6: 800 | D6: =C6/31*$D$1 -> 516.12903 | E6: =#REF!/1000 -> #REF! | N6: Item Name | O6: Sum of Quantity | P6: Sum of Amount
A7: =A6+1 -> 3 | B7: Utilization (%) | C7: =C6/C5 -> 0.88888889 | D7: =D6/D5 -> 0.88888889 | E7: =E6/E5 -> #REF! | I7: PP WOVEN BIG BAGS / SACKS | J7: =+GETPIVOTDATA("Sum of Quantity",$N$5,"Item Name","PP WOVEN BIG BAGS / SACKS")+GETPIVOTDATA("Sum of Quantity",$N$5,"Item Name","Pp Woven Bgas(FG)") -> 306664.9 | K7: =L7/J7 -> 157.96893 | L7: =+GETPIVOTDATA("Sum of Amount",$N$5,"Item Name","PP WOVEN BIG BAGS / SACKS")+GETPIVOTDATA("Sum of Amount",$N$5,"Item Name","Pp Woven Bgas(FG)") -> 48443526 | N7: PP WOVEN BIG BAGS / SACKS | O7: 300706.8 | P7: 47512219
A8: =A7+1 -> 4 | B8: Opening Stock | C8: 0 | D8: 0 | E8: =(#REF!+#REF!)/1000 -> #REF! | I8: PP Woven Fabrics(FG) | J8: =GETPIVOTDATA("Sum of Quantity",$N$5,"Item Name","PP Woven Fabrics(FG)") -> 85056.5 | K8: =L8/J8 -> 105.13316 | L8: =GETPIVOTDATA("Sum of Amount",$N$5,"Item Name","PP Woven Fabrics(FG)") -> 8942258.9 | N8: PP Woven Fabrics(FG) | O8: 85056.5 | P8: 8942258.9
A9: =A8+1 -> 5 | B9: Sales | C9: =C6 -> 800 | D9: =C9/31*$D$1 -> 516.12903 | E9: =#REF!/1000 -> #REF! | I9: PP Laminated Fabric | J9: =GETPIVOTDATA("Sum of Quantity",$N$5,"Item Name","PP Laminated Fabric") -> 40640.5 | K9: =L9/J9 -> 103.30194 | L9: =GETPIVOTDATA("Sum of Amount",$N$5,"Item Name","PP Laminated Fabric") -> 4198242.7 | N9: REPROCESS GRANULES (FG) | O9: 14100 | P9: 282000
A10: =A9+1 -> 6 | B10: Closing Stock | C10: 0 | D10: 0 | E10: =(#REF!+#REF!)/1000 -> #REF! | I10: REPROCESS GRANULES (FG) | J10: =GETPIVOTDATA("Sum of Quantity",$N$5,"Item Name","REPROCESS GRANULES (FG)") -> 14100 | K10: =L10/J10 -> 20 | L10: =GETPIVOTDATA("Sum of Amount",$N$5,"Item Name","REPROCESS GRANULES (FG)") -> 282000 | N10: PP Laminated Fabric | O10: 40640.5 | P10: 4198242.7
A11: B | B11: Revenue | I11: PP TAPE / YARN | J11: 0 | K11: =L11/J11 -> #DIV/0! | L11: 0 | N11: PP WEBBING (FG) | O11: 12228.8 | P11: 1263198
A12: 1 | B12: Sales | C12: 1117.55 | D12: =C12/31*$D$1 -> 721 | E12: =Sheet2!B3/100000 -> #REF! | F12: =$J$22/1000 -> 493.7757 | G12: =+E12/F12*100 -> #REF! | I12: PP Fabric Wastage | K12: =L12/J12 -> #DIV/0! | N12: Pp Wastage | O12: 7960 | P12: 119400
A13: 2 | B13: Increase / Decrease in Stock | C13: 0 | D13: =C13/31*$D$1 -> 0 | I13: PP Tape Wastage | J13: =GETPIVOTDATA("Sum of Quantity",$N$5,"Item Name","Pp Wastage") -> 7960 | K13: =L13/J13 -> 15 | L13: =GETPIVOTDATA("Sum of Amount",$N$5,"Item Name","Pp Wastage") -> 119400 | N13: Pp Granuales | O13: 18000 | P13: 1365550
A14: 3 | B14: Other Income | C14: 0 | D14: =C14/31*$D$1 -> 0 | E14: =(Sheet2!B15+Sheet2!B27)/100000 -> #REF! | F14: =F12 -> 493.7757 | G14: =+E14/F14*100 -> #REF! | I14: PP WEBBING (FG) | J14: =GETPIVOTDATA("Sum of Quantity",$N$5,"Item Name","PP WEBBING (FG)") -> 12228.8 | K14: =L14/J14 -> 103.29697 | L14: =GETPIVOTDATA("Sum of Amount",$N$5,"Item Name","PP WEBBING (FG)") -> 1263198 | N14: Filler | O14: 8500 | P14: 250750
B15: Total | C15: =SUM(C12:C14) -> 1117.55 | D15: =SUM(D12:D14) -> 721 | E15: =SUM(E12:E14) -> #REF! | G15: =SUM(G12:G14) -> #REF! | I15: Filler | J15: =GETPIVOTDATA("Sum of Quantity",$N$5,"Item Name","Filler") -> 8500 | K15: =L15/J15 -> 29.5 | L15: =GETPIVOTDATA("Sum of Amount",$N$5,"Item Name","Filler") -> 250750 | N15: Master Batch | O15: 500 | P15: 70500
A16: C | B16: Eexpenses | I16: Master Batch | J16: =GETPIVOTDATA("Sum of Quantity",$N$5,"Item Name","Master Batch") -> 500 | K16: =L16/J16 -> 141 | L16: =GETPIVOTDATA("Sum of Amount",$N$5,"Item Name","Master Batch") -> 70500 | N16: LLDPE GRANULES | O16: 125 | P16: 8531
A17: 1 | B17: Raw Material | C17: 540.75 | D17: =C17/31*$D$1 -> 348.87097 | E17: =#REF!/100000 -> #REF! | F17: =#REF!/1000 -> #REF! | G17: =+E17/F17*100 -> #REF! | I17: LLDPE GRANULES | J17: =GETPIVOTDATA("Sum of Quantity",$N$5,"Item Name","LLDPE GRANULES") -> 125 | K17: =L17/J17 -> 68.248 | L17: =GETPIVOTDATA("Sum of Amount",$N$5,"Item Name","LLDPE GRANULES") -> 8531 | N17: Pp Woven Bgas(FG) | O17: 5958.1 | P17: 931307
A18: =A17+1 -> 2 | B18: Power | C18: 61.285 | D18: =C18/31*$D$1 -> 39.53871 | E18: =Sheet2!B44/100000 -> #REF! | F18: =F12 -> 493.7757 | G18: =+E18/F18*100 -> #REF! | I18: Pp Granuales | J18: =GETPIVOTDATA("Sum of Quantity",$N$5,"Item Name","Pp Granuales") -> 18000 | K18: =L18/J18 -> 75.863889 | L18: =GETPIVOTDATA("Sum of Amount",$N$5,"Item Name","Pp Granuales") -> 1365550 | N18: Grand Total | O18: 493775.7 | P18: 64943957
A19: =A18+1 -> 3 | B19: Labour | C19: 158.62 | D19: =C19/31*$D$1 -> 102.33548 | E19: =Sheet2!B42/100000 -> #REF! | F19: =F18 -> 493.7757 | G19: =+E19/F19*100 -> #REF! | I19: LLDPE BAGS (LINER) | K19: =L19/J19 -> #DIV/0!
A20: =A19+1 -> 4 | B20: RP | C20: 14.42 | D20: =C20/31*$D$1 -> 9.3032258 | E20: 0 | F20: =F19 -> 493.7757 | G20: =+E20/F20*100 -> 0 | I20: LDPE GRANULES | K20: =L20/J20 -> #DIV/0!
A21: =A20+1 -> 5 | B21: Stores | C21: 14.42 | D21: =C21/31*$D$1 -> 9.3032258 | E21: =Sheet2!B34/100000 -> #REF! | F21: =F20 -> 493.7757 | G21: =+E21/F21*100 -> #REF!
A22: =A21+1 -> 6 | B22: Consumables | C22: 10.815 | D22: =C22/31*$D$1 -> 6.9774194 | E22: 0 | F22: =F21 -> 493.7757 | G22: =+E22/F22*100 -> 0 | I22: TOTAL | J22: =SUM(J6:J21) -> 493775.7 | K22: =L22/J22 -> 131.52522 | L22: =SUM(L6:L21) -> 64943957
A23: 7 | B23: Jobwork | C23: 0 | D23: 0 | E23: =Sheet2!B45/100000 -> #REF! | F23: =F22 -> 493.7757 | G23: =+E23/F23*100 -> #REF! | J23: =J22-GETPIVOTDATA("Sum of Quantity",$N$5) -> 0 | L23: =L22-GETPIVOTDATA("Sum of Amount",$N$5) -> 0
A24: 8 | B24: Other Expenses | C24: 0 | D24: 0 | E24: =(Sheet2!B46+Sheet2!B54+Sheet2!B61)/100000 -> #REF! | F24: =#REF!/1000 -> #REF! | G24: =+E24/F24*100 -> #REF! | J24: =+J8+J9 -> 125697 | K24: =+L24/J24 -> 104.54109 | L24: =+L8+L9 -> 13140502
B25: Total | C25: =SUM(C17:C24) -> 800.31 | D25: =SUM(D17:D24) -> 516.32903 | E25: =SUM(E17:E24) -> #REF! | G25: =SUM(G17:G24) -> #REF!
A26: D | B26: EBIDTA | C26: =C15-C25 -> 317.24 | D26: =D15-D25 -> 204.67097 | E26: =E15-E25 -> #REF! | G26: =G15-G25 -> #REF!
B27: EBIDTA Margin - % | C27: =C26/C12 -> 0.28387097 | D27: =D26/D12 -> 0.28387097 | E27: =E26/E12 -> #REF! | G27: =G26/G12 -> #REF!
O28: =+GETPIVOTDATA("Sum of Quantity",$N$5)-J22 -> 0 | P28: =+GETPIVOTDATA("Sum of Amount",$N$5)-L22 -> 0
E29: =#REF!/100000 -> #REF! | P29: =GETPIVOTDATA("Sum of Amount",$N$5)/GETPIVOTDATA("Sum of Quantity",$N$5) -> 131.52522
E30: =+E26-E29 -> #REF!
O32: =+J22-GETPIVOTDATA("Sum of Quantity",$N$5) -> 0 | P32: =+L22-GETPIVOTDATA("Sum of Amount",$N$5) -> 0
C35: RM | D35: JW | E35: WIP&FG
B36: OP. Stock | C36: =#REF!/1000 -> #REF! | D36: =(#REF!++#REF!)/1000 -> #REF! | E36: =#REF!/1000 -> #REF!
B37: Purchase | C37: =(#REF!+#REF!)/1000 -> #REF! | D37: =(#REF!+#REF!)/1000 -> #REF!
D38: =(#REF!+#REF!)/1000 -> #REF!
B39: Closing Stock | C39: =#REF!/1000 -> #REF! | D39: =(#REF!+#REF!)/1000 -> #REF! | E39: =#REF!/1000 -> #REF!
E41: =+E39-E36 -> #REF!
E42: =+E41*165 -> #REF!

Sheet Sheet2
A1: Particulars | B1: Amount Rs. | D1: Jul | E1: Aug
A3: Sale of finished goods | B3: =#REF! -> #REF!
A4: Sale of traded goods | B4: 0
A5: Total Revenue from operations | B5: =SUM(B3:B4) -> #REF! | D5: 115693026 | E5: 150815314
A6: Sale of services
A7: Income from Jobwork charges | B7: 0
A8: Total Sales of services | B8: =SUM(B7) -> 0
A9: Other operating revenue
A10: Export incentives | B10: =#REF! -> #REF! | D10: 1429262 | E10: 2578757
A11: Stores sales | B11: =-#REF! -> #REF!
A12: Advance License Receivable | B12: =#REF! -> #REF!
A13: Commission income | B13: 0
A14: Scrap sales | B14: 0
A15: Total Other operating revenue | B15: =SUM(B10:B14) -> #REF! | D15: =SUM(D10:D14) -> 1429262 | E15: =SUM(E10:E14) -> 2578757
A16: Other income
A17: Wind mill income | B17: =#REF! -> #REF! | D17: 258868 | E17: 289012
A18: Interest income: | B18: 0
A19: - on fixed deposits with Banks | B19: 0
A20: - from others | B20: 0
A21: Rent Income
A22: Advance License Utilization | B22: 0
A23: Profit on sale of fixed assets | B23: 0
A24: Profit on sale of investments | B24: 0
A25: Sundry balance written off
A26: Miscellaneous income | B26: 0 | D26: 0 | E26: 0
A27: Total Other income | B27: =SUM(B17:B26) -> #REF! | D27: =SUM(E17:E26) -> 289012 | E27: =SUM(D17:D26) -> 258868
A28: Total Turnover | B28: =B5+B8+B15+B27 -> #REF! | D28: =D5+D8+D15+E27 -> 117381156 | E28: =E5+E8+E15+D27 -> 153683083
B29: 0
A30: Cost of Goods
A31: Cost of materials consumed | B31: =SUM(#REF!)+C31 -> #REF! | C31: =SUMIF(#REF!,"Add: Purchase expenses",#REF!) -> #REF! | D31: 71292822 | E31: 111910571
A32: Purchase of stock-in-trade | B32: 0
A33: Changes in inventory of finished goods and work-in-progress | B33: =SUM(#REF!) -> #REF! | D33: -3450754 | E33: -5251988
A34: Stores, Spares & Consumables | B34: =#REF! -> #REF! | D34: 1844344 | E34: 743991
A35: Total Cost of goods | B35: =SUM(B31:B34) -> #REF! | D35: =SUM(D31:D34) -> 69686412 | E35: =SUM(E31:E34) -> 107402574
A36: Employee benefit expenses
A37: Salaries, wages and bonus | B37: =SUMIF(#REF!,A37,#REF!)+#REF! -> #REF! | D37: 13443755 | E37: 13987529
A38: Contribution to provident and other funds
A39: Gratuity Expenses
A40: Staff welfare expenses | B40: =SUMIF(#REF!,A40,#REF!) -> #REF!
A41: Labour charges
...

Sheet Sheet1
B1: Tape | G1: Lamination | J1: Loom | M1: Yarn | P1: Webbing | S1: Webbing
B3: Unlaminated Fabric | D3: =IFERROR(VLOOKUP(B3,#REF!,15,0),0) -> 0 | G3: =IFERROR(VLOOKUP(B3,#REF!,3,0),0) -> 0 | H3: =G3*D3 -> 0
B4: Yarn | D4: =IFERROR(VLOOKUP(B4,#REF!,15,0),0) -> 0 | P4: =IFERROR(VLOOKUP(B4,#REF!,7,0),0) -> 0 | Q4: =P4*D4 -> 0 | S4: =IFERROR(VLOOKUP(B4,#REF!,10,0),0) -> 0 | T4: =S4*D4 -> 0
B5: Laminated Fabric | D5: =IFERROR(VLOOKUP(B5,#REF!,15,0),0) -> 0
B6: Webbing | D6: =IFERROR(VLOOKUP(B6,#REF!,15,0),0) -> 0
B7: Tape | D7: =IFERROR(VLOOKUP(B7,#REF!,15,0),0) -> 0 | J7: =IFERROR(VLOOKUP(B7,#REF!,4,0),0) -> 0 | K7: =J7*D7 -> 0 | P7: =IFERROR(VLOOKUP(B7,#REF!,7,0),0) -> 0 | Q7: =P7*D7 -> 0 | S7: =IFERROR(VLOOKUP(B7,#REF!,10,0),0) -> 0 | T7: =S7*D7 -> 0
D8: =IFERROR(VLOOKUP(B8,#REF!,15,0),0) -> 0
A9: =C9/$C$27 -> #REF! | B9: PP 30SG | C9: =IFERROR(VLOOKUP(B9,#REF!,2,0),0) -> 0 | D9: =IFERROR(VLOOKUP(B9,#REF!,15,0),0) -> 0 | E9: =C9*D9 -> 0 | G9: =IFERROR(VLOOKUP(B9,#REF!,3,0),0) -> 0 | H9: =G9*D9 -> 0 | J9: =IFERROR(VLOOKUP(B9,#REF!,4,0),0) -> 0 | K9: =J9*D9 -> 0 | M9: =IFERROR(VLOOKUP(B9,#REF!,6,0),0) -> 0 | N9: =M9*D9 -> 0 | P9: =IFERROR(VLOOKUP(B9,#REF!,7,0),0) -> 0 | Q9: =P9*D9 -> 0 | S9: =IFERROR(VLOOKUP(B9,#REF!,10,0),0) -> 0 | T9: =S9*D9 -> 0
A10: =C10/$C$27 -> #REF! | B10: PP 462 | C10: =IFERROR(VLOOKUP(B10,#REF!,2,0),0) -> 0 | D10: =IFERROR(VLOOKUP(B10,#REF!,15,0),0) -> 0 | E10: =C10*D10 -> 0 | G10: =IFERROR(VLOOKUP(B10,#REF!,3,0),0) -> 0 | H10: =G10*D10 -> 0 | J10: =IFERROR(VLOOKUP(B10,#REF!,4,0),0) -> 0 | K10: =J10*D10 -> 0 | M10: =IFERROR(VLOOKUP(B10,#REF!,6,0),0) -> 0 | N10: =M10*D10 -> 0 | P10: =IFERROR(VLOOKUP(B10,#REF!,7,0),0) -> 0 | Q10: =P10*D10 -> 0 | S10: =IFERROR(VLOOKUP(B10,#REF!,10,0),0) -> 0 | T10: =S10*D10 -> 0
A11: =C11/$C$27 -> #REF! | B11: Filer Soltex | C11: =IFERROR(VLOOKUP(B11,#REF!,2,0),0) -> 0 | D11: =IFERROR(VLOOKUP(B11,#REF!,15,0),0) -> 0 | E11: =C11*D11 -> 0 | G11: =IFERROR(VLOOKUP(B11,#REF!,3,0),0) -> 0 | H11: =G11*D11 -> 0 | J11: =IFERROR(VLOOKUP(B11,#REF!,4,0),0) -> 0 | K11: =J11*D11 -> 0 | M11: =IFERROR(VLOOKUP(B11,#REF!,6,0),0) -> 0 | N11: =M11*D11 -> 0 | P11: =IFERROR(VLOOKUP(B11,#REF!,7,0),0) -> 0 | Q11: =P11*D11 -> 0 | S11: =IFERROR(VLOOKUP(B11,#REF!,10,0),0) -> 0 | T11: =S11*D11 -> 0
A12: =C12/$C$27 -> #REF! | B12: UV | C12: =IFERROR(VLOOKUP(B12,#REF!,2,0),0) -> 0 | D12: =IFERROR(VLOOKUP(B12,#REF!,15,0),0) -> 0 | E12: =C12*D12 -> 0 | G12: =IFERROR(VLOOKUP(B12,#REF!,3,0),0) -> 0 | H12: =G12*D12 -> 0 | J12: =IFERROR(VLOOKUP(B12,#REF!,4,0),0) -> 0 | K12: =J12*D12 -> 0 | M12: =IFERROR(VLOOKUP(B12,#REF!,6,0),0) -> 0 | N12: =M12*D12 -> 0 | P12: =IFERROR(VLOOKUP(B12,#REF!,7,0),0) -> 0 | Q12: =P12*D12 -> 0 | S12: =IFERROR(VLOOKUP(B12,#REF!,10,0),0) -> 0 | T12: =S12*D12 -> 0
A13: =C13/$C$27 -> #REF! | B13: MB | C13: =IFERROR(VLOOKUP(B13,#REF!,2,0),0) -> 0 | D13: =IFERROR(VLOOKUP(B13,#REF!,15,0),0) -> 0 | E13: =C13*D13 -> 0 | G13: =IFERROR(VLOOKUP(B13,#REF!,3,0),0) -> 0 | H13: =G13*D13 -> 0 | J13: =IFERROR(VLOOKUP(B13,#REF!,4,0),0) -> 0 | K13: =J13*D13 -> 0 | M13: =IFERROR(VLOOKUP(B13,#REF!,6,0),0) -> 0 | N13: =M13*D13 -> 0 | P13: =IFERROR(VLOOKUP(B13,#REF!,7,0),0) -> 0 | Q13: =P13*D13 -> 0 | S13: =IFERROR(VLOOKUP(B13,#REF!,10,0),0) -> 0 | T13: =S13*D13 -> 0
A14: =C14/$C$27 -> #REF! | B14: LD | C14: =IFERROR(VLOOKUP(B14,#REF!,2,0),0) -> 0 | D14: =IFERROR(VLOOKUP(B14,#REF!,15,0),0) -> 0 | E14: =C14*D14 -> 0 | G14: =IFERROR(VLOOKUP(B14,#REF!,3,0),0) -> 0 | H14: =G14*D14 -> 0 | J14: =IFERROR(VLOOKUP(B14,#REF!,4,0),0) -> 0 | K14: =J14*D14 -> 0 | M14: =IFERROR(VLOOKUP(B14,#REF!,6,0),0) -> 0 | N14: =M14*D14 -> 0 | P14: =IFERROR(VLOOKUP(B14,#REF!,7,0),0) -> 0 | Q14: =P14*D14 -> 0 | S14: =IFERROR(VLOOKUP(B14,#REF!,10,0),0) -> 0 | T14: =S14*D14 -> 0
A15: =C15/$C$27 -> #REF! | B15: LLDPE | C15: =IFERROR(VLOOKUP(B15,#REF!,2,0),0) -> 0 | D15: =IFERROR(VLOOKUP(B15,#REF!,15,0),0) -> 0 | E15: =C15*D15 -> 0 | G15: =IFERROR(VLOOKUP(B15,#REF!,3,0),0) -> 0 | H15: =G15*D15 -> 0 | J15: =IFERROR(VLOOKUP(B15,#REF!,4,0),0) -> 0 | K15: =J15*D15 -> 0 | M15: =IFERROR(VLOOKUP(B15,#REF!,6,0),0) -> 0 | N15: =M15*D15 -> 0 | P15: =IFERROR(VLOOKUP(B15,#REF!,7,0),0) -> 0 | Q15: =P15*D15 -> 0 | S15: =IFERROR(VLOOKUP(B15,#REF!,10,0),0) -> 0 | T15: =S15*D15 -> 0
A16: =C16/$C$27 -> #REF! | B16: HDPE | C16: =IFERROR(VLOOKUP(B16,#REF!,2,0),0) -> 0 | D16: =IFERROR(VLOOKUP(B16,#REF!,15,0),0) -> 0 | E16: =C16*D16 -> 0 | G16: =IFERROR(VLOOKUP(B16,#REF!,3,0),0) -> 0 | H16: =G16*D16 -> 0 | J16: =IFERROR(VLOOKUP(B16,#REF!,4,0),0) -> 0 | K16: =J16*D16 -> 0 | M16: =IFERROR(VLOOKUP(B16,#REF!,6,0),0) -> 0 | N16: =M16*D16 -> 0 | P16: =IFERROR(VLOOKUP(B16,#REF!,7,0),0) -> 0 | Q16: =P16*D16 -> 0 | S16: =IFERROR(VLOOKUP(B16,#REF!,10,0),0) -> 0 | T16: =S16*D16 -> 0
A17: =C17/$C$27 -> #REF! | B17: LLDPE FILM | C17: =IFERROR(VLOOKUP(B17,#REF!,2,0),0) -> 0 | D17: =IFERROR(VLOOKUP(B17,#REF!,15,0),0) -> 0 | E17: =C17*D17 -> 0 | G17: =IFERROR(VLOOKUP(B17,#REF!,3,0),0) -> 0 | H17: =G17*D17 -> 0 | J17: =IFERROR(VLOOKUP(B17,#REF!,4,0),0) -> 0 | K17: =J17*D17 -> 0 | M17: =IFERROR(VLOOKUP(B17,#REF!,6,0),0) -> 0 | N17: =M17*D17 -> 0 | P17: =IFERROR(VLOOKUP(B17,#REF!,7,0),0) -> 0 | Q17: =P17*D17 -> 0 | S17: =IFERROR(VLOOKUP(B17,#REF!,10,0),0) -> 0 | T17: =S17*D17 -> 0
A18: =C18/$C$27 -> #REF! | B18: Multiliyer Laminated Film | C18: =IFERROR(VLOOKUP(B18,#REF!,2,0),0) -> 0 | D18: =IFERROR(VLOOKUP(B18,#REF!,15,0),0) -> 0 | E18: =C18*D18 -> 0 | G18: =IFERROR(VLOOKUP(B18,#REF!,3,0),0) -> 0 | H18: =G18*D18 -> 0 | J18: =IFERROR(VLOOKUP(B18,#REF!,4,0),0) -> 0 | K18: =J18*D18 -> 0 | M18: =IFERROR(VLOOKUP(B18,#REF!,6,0),0) -> 0 | N18: =M18*D18 -> 0 | P18: =IFERROR(VLOOKUP(B18,#REF!,7,0),0) -> 0 | Q18: =P18*D18 -> 0 | S18: =IFERROR(VLOOKUP(B18,#REF!,10,0),0) -> 0 | T18: =S18*D18 -> 0
A19: =C19/$C$27 -> #REF! | B19: Filler cord | C19: =IFERROR(VLOOKUP(B19,#REF!,2,0),0) -> 0 | D19: =IFERROR(VLOOKUP(B19,#REF!,15,0),0) -> 0 | E19: =C19*D19 -> 0 | G19: =IFERROR(VLOOKUP(B19,#REF!,3,0),0) -> 0 | H19: =G19*D19 -> 0 | J19: =IFERROR(VLOOKUP(B19,#REF!,4,0),0) -> 0 | K19: =J19*D19 -> 0 | M19: =IFERROR(VLOOKUP(B19,#REF!,6,0),0) -> 0 | N19: =M19*D19 -> 0 | P19: =IFERROR(VLOOKUP(B19,#REF!,7,0),0) -> 0 | Q19: =P19*D19 -> 0 | S19: =IFERROR(VLOOKUP(B19,#REF!,10,0),0) -> 0 | T19: =S19*D19 -> 0
A20: =C20/$C$27 -> #REF! | B20: Rop | C20: =IFERROR(VLOOKUP(B20,#REF!,2,0),0) -> 0 | D20: =IFERROR(VLOOKUP(B20,#REF!,15,0),0) -> 0 | E20: =C20*D20 -> 0 | G20: =IFERROR(VLOOKUP(B20,#REF!,3,0),0) -> 0 | H20: =G20*D20 -> 0 | J20: =IFERROR(VLOOKUP(B20,#REF!,4,0),0) -> 0 | K20: =J20*D20 -> 0 | M20: =IFERROR(VLOOKUP(B20,#REF!,6,0),0) -> 0 | N20: =M20*D20 -> 0 | P20: =IFERROR(VLOOKUP(B20,#REF!,7,0),0) -> 0 | Q20: =P20*D20 -> 0 | S20: =IFERROR(VLOOKUP(B20,#REF!,10,0),0) -> 0 | T20: =S20*D20 -> 0
... A24: =C24/$C$27 -> #REF! | B24: RP | C24: =IFERROR(VLOOKUP(B24,#REF!,2,0),0) -> 0 | D24: =IFERROR(VLOOKUP(B24,#REF!,15,0),0) -> 0 | E24: =C24*D24 -> 0 | G24: =IFERROR(VLOOKUP(B24,#REF!,3,0),0) -> 0 | H24: =G24*D24 -> 0 | J24: =IFERROR(VLOOKUP(B24,#REF!,4,0),0) -> 0 | K24: =J24*D24 -> 0 | M24: =IFERROR(VLOOKUP(B24,#REF!,6,0),0) -> 0 | N24: =M24*D24 -> 0 | P24: =IFERROR(VLOOKUP(B24,#REF!,7,0),0) -> 0 | Q24: =P24*D24 -> 0 | S24: =IFERROR(VLOOKUP(B24,#REF!,10,0),0) -> 0 | T24: =S24*D24 -> 0
C25: =SUM(C3:C24) -> 0 | E25: =SUM(E3:E24) -> 0 | G25: =SUM(G3:G24) -> 0 | H25: =SUM(H3:H24) -> 0 | J25: =SUM(J3:J24) -> 0 | K25: =SUM(K3:K24) -> 0 | M25: =SUM(M3:M24) -> 0 | N25: =SUM(N3:N24) -> 0 | P25: =SUM(P3:P24) -> 0 | Q25: =SUM(Q3:Q24) -> 0 | S25: =SUM(S3:S24) -> 0 | T25: =SUM(T3:T24) -> 0
B26: Wastage | C26: =#REF! -> #REF! | G26: =#REF! -> #REF! | J26: =#REF! -> #REF! | M26: =#REF! -> #REF! | P26: =#REF! -> #REF! | S26: =#REF! -> #REF!
C27: =C25-C26 -> #REF! | D27: =IFERROR(E27/C27,0) -> 0 | E27: =SUM(E25:E26) -> 0 | G27: =G25-G26 -> #REF! | H27: =SUM(H25:H26) -> 0 | J27: =J25-J26 -> #REF! | K27: =SUM(K25:K26) -> 0 | M27: =M25-M26 -> #REF! | N27: =SUM(N25:N26) -> 0 | P27: =P25-P26 -> #REF! | Q27: =SUM(Q25:Q26) -> 0 | S27: =S25-S26 -> #REF! | T27: =SUM(T25:T26) -> 0
H28: =IFERROR(H27/G27,0) -> 0 | K28: =IFERROR(K27/J27,0) -> 0 | N28: =IFERROR(N27/M27,0) -> 0 | Q28: =IFERROR(Q27/P27,0) -> 0 | T28: =IFERROR(T27/S27,0) -> 0

Sheet Report
A1: Plasten India Limited (Unit - 1)
A2: EBDITA SUMMERY FOR THE PERIOD OF 20th Aug 2026
A4: Particulars | B4: Qty | C4: Rate | D4: 20th Aug-26
A5: Sales
A6: MFG Goods | B6: ='Cons Prod'!B16 -> 112139.2 | C6: =D6/B6 -> 128.76043 | D6: ='Cons Prod'!D16 -> 14439092
A7: Traded goods | C7: =D7/B7 -> #DIV/0!
A8: Job Income
A10: Total Income | B10: =SUM(B6:B9) -> 112139.2 | D10: =SUM(D6:D9) -> 14439092
A12: Cost of Materials Consumed | B12: =B6 -> 112139.2 | C12: =D12/B12 -> 112.82942 | D12: ='Cons Prod'!I21 -> 12652601
A13: Cost of goods sold of traded goods | B13: =B7 -> 0 | C13: =D13/B13 -> #DIV/0!
A14: Job work Charges
A15: Total | D15: =SUM(D12:D14) -> 12652601
A17: Delta | C17: =D17/D10 -> 0.123726 | D17: =+D10-D15 -> 1786491
A18: Traded Delta Margin % | C18: =D18/D7 -> #DIV/0! | D18: =D7-D13 -> 0
A19: Process Delta Margin % | C19: =D19/D6 -> 0.123726 | D19: =D6-D12 -> 1786491
A21: Exchange Rate Difference | C21: =D21/$D$10 -> 0
A22: Salary(inc Pf and all) | C22: =D22/$D$10 -> 0.041756035 | D22: 602919.22
A23: Power | C23: =D23/$D$10 -> 0.024883144 | D23: 359290 | Q23: 8.44
A24: Stores & Consumables | C24: =D24/$D$10 -> 0.0096043389 | D24: ='Consumables and Stores'!I71 -> 138677.93
A25: Factory Rent Expense | C25: =D25/$D$10 -> 0
A27: Total Direct Expenses | C27: =D27/D10 -> 0.076243518 | D27: =SUM(D21:D26) -> 1100887.1
A28: Gross Margin | C28: =D28/D10 -> 0.04748248 | D28: =D17-D27 -> 685603.88
A30: Administrative & Selling Expense
A31: Insurance | D31: 16667
A32: Freight outward expense | D32: 75000
A33: Other Admin Expense | D33: 66667
A34: Total Admin & Selling Expense | D34: =SUM(D31:D33) -> 158334
A37: Net EBIDATA | C37: =D37/D10 -> 0.036516832 | D37: =D28-D34 -> 527269.88
A38: Finanace Cost | D38: =5000000/31*1 -> 161290.32
A39: Depreciation | D39: =1800000/31*1 -> 58064.516
A40: Net PBT | C40: =D40/D10 -> 0.021325098 | D40: =+D37-D38-D39 -> 307915.05
A42: EBIDATA/kg | D42: =(D37-D18)/B6 -> 4.701923
A43: PBT/kg | D43: =(D40-D18)/B6 -> 2.7458288

Sheet Cons Prod
A2: Production | F2: Consumption
A4: Item Name | B4: Qty | C4: Rate | D4: Value | F4: Item Name | G4: Qty | H4: Rate | I4: Value
A5: PP Tape | B5: 31373.4 | C5: =H12 -> 119.58 | D5: =B5*C5 -> 3751631.2 | F5: PP Granule | G5: =27175+1725+24+2700 -> 31624 | H5: 109.58 | I5: =G5*H5 -> 3465357.9
A6: PP Fabric | B6: 26119 | C6: =H13 -> 129.58 | D6: =B6*C6 -> 3384500 | F6: Filler | G6: =25+1861.3 -> 1886.3 | H6: 37.39 | I6: =G6*H6 -> 70528.757
A7: PP Laminated Fabric | B7: 9745 | C7: =H14 -> 134.58 | D7: =B7*C7 -> 1311482.1 | F7: MB | G7: =75+1139.3+76 -> 1290.3 | H7: 213.89 | I7: =G7*H7 -> 275982.27
A8: PP Webbing | B8: 3896.8 | C8: =H15 -> 129.58 | D8: =B8*C8 -> 504947.34 | F8: LDPE Granule | G8: =2925+305 -> 3230 | H8: 131.71 | I8: =G8*H8 -> 425423.3
A9: PP Filament Yarn | B9: 2716 | C9: =H16 -> 154.55 | D9: =B9*C9 -> 419757.8 | F9: LLDPE Granule | G9: 6068 | H9: 136.4 | I9: =G9*H9 -> 827675.2
A10: LLDPE Film | B10: 10521 | C10: =H17 -> 156.4 | D10: =B10*C10 -> 1645484.4 | F10: HDPE Granule | H10: 141.8 | I10: =G10*H10 -> 0
A11: LLDPE Bags | B11: 7528 | C11: 195.34 | D11: =B11*C11 -> 1470519.5 | F11: RP Granule | G11: =1438+1674.8+133 -> 3245.8 | H11: 28 | I11: =G11*H11 -> 90882.4
A12: FIBC Bags | B12: 5723 | C12: 218.32 | D12: =B12*C12 -> 1249445.4 | F12: PP Tape | G12: =26491+3234.8 -> 29725.8 | H12: =H5+10 -> 119.58 | I12: =G12*H12 -> 3554611.2
A13: BOPP Bags | B13: 1770 | C13: 232.2 | D13: =B13*C13 -> 410994 | F13: PP Fabric | G13: =4286.1+8034 -> 12320.1 | H13: =H5+20 -> 129.58 | I13: =G13*H13 -> 1596438.6
A14: RP Granule | B14: 7625 | C14: 28 | D14: =B14*C14 -> 213500 | F14: PP Laminated Fabric | G14: 1595.01 | H14: =H5+25 -> 134.58 | I14: =G14*H14 -> 214656.45
A15: Wastage | B15: =113+10+2669+372+400+249+477+734+60+38 -> 5122 | C15: 15 | D15: =B15*C15 -> 76830 | F15: PP Webbing | G15: 918.45 | H15: =H5+20 -> 129.58 | I15: =G15*H15 -> 119012.75
A16: Total | B16: =SUM(B5:B15) -> 112139.2 | D16: =SUM(D5:D15) -> 14439092 | F16: PP Filament Yarn | G16: =918.45+700 -> 1618.45 | H16: 154.55 | I16: =G16*H16 -> 250131.45
F17: LLDPE Film | G17: 10197 | H17: =H9+20 -> 156.4 | I17: =G17*H17 -> 1594810.8
F18: BOPP Film | H18: 215.33 | I18: =G18*H18 -> 0
F19: Craft Paper | G19: =423.99+258 -> 681.99 | H19: 74.81 | I19: =G19*H19 -> 51019.672
F20: Wastage | G20: 7738 | H20: 15 | I20: =G20*H20 -> 116070
F21: Total | G21: =SUM(G5:G20) -> 112139.2 | I21: =SUM(I5:I20) -> 12652601 | K21: =B16-G21 -> 0

Sheet Sheet4

Sheet Consumables and Stores
