Workbook

Sheet EBIDTA
B3: Name of the Company : - PIL II (2026-27)
B5: Particulars | C5: AUG.26 | D5: % | E5: JULY.26 | F5: % | G5: JUNE.26 | H5: % | I5: MAY.26 | J5: % | K5: APRIL.26 | L5: % | M5: YTD AUG.26 | N5: % | O5: YTD JULY.26 | P5: % | Q5: YTD JUNE.26 | R5: % | S5: YTD MAY.26 | T5: % | U5: YTD APRIL.26 | V5: % | X5: Particulars | Y5: AUG.26 | Z5: JULY.26 | AA5: JUNE.26 | AB5: MAY.26 | AC5: APRIL.26
B6: Revenue from operations | X6: Inventory at the beginning of the year:
B7: Sale of finished goods | C7: =M7-O7 -> 1.757614e+08 | D7: =(C7/$C$29) -> 0.93955573 | E7: =O7-Q7 -> 1.25302e+08 | F7: =(E7/$E$29) -> 0.87134389 | G7: =Q7-S7 -> 1.4869568e+08 | H7: =(G7/$G$29) -> 0.85856398 | I7: =S7-U7 -> 1.0546501e+08 | J7: =(I7/$I$29) -> 0.79593019 | K7: =U7 -> 1.0167291e+08 | L7: =(K7/$K$29) -> 0.86065216 | M7: =-SUMIF('TB AUG'!H:H,EBIDTA!B7,'TB AUG'!G:G) -> 6.56897e+08 | N7: =(M7/$M$29) -> 0.87040464 | O7: =-SUMIF('TB JULY'!H:H,EBIDTA!B7,'TB JULY'!G:G) -> 4.8113561e+08 | P7: =(O7/$O$29) -> 0.84761532 | Q7: =-SUMIF('TB JUNE'!H:H,EBIDTA!B7,'TB JUNE'!G:G)-3481490 -> 3.558336e+08 | R7: =(Q7/$Q$29) -> 0.83956438 | S7: =-SUMIF('TB MAy'!H:H,EBIDTA!B7,'TB MAy'!G:G) -> 2.0713792e+08 | T7: =(S7/$S$29) -> 0.82643574 | U7: =-SUMIF('TB April'!H:H,EBIDTA!B7,'TB April'!G:G) -> 1.0167291e+08 | V7: =(U7/$U$29) -> 0.86065216 | X7: Opening Stock of Raw material | Y7: =Z7 -> 77707440 | Z7: =AA7 -> 77707440 | AA7: =AB7 -> 77707440 | AB7: =AC7 -> 77707440 | AC7: ='Stock Sheet'!O7 -> 77707440
B8: Sale of traded goods | C8: =M8-O8 -> 9952350.6 | D8: =(C8/$C$29) -> 0.053201603 | E8: =O8-Q8 -> 12225702 | F8: =(E8/$E$29) -> 0.085016925 | G8: =Q8-S8 -> 10882375 | H8: =(G8/$G$29) -> 0.062834476 | I8: =S8-U8 -> 10072600 | J8: =(I8/$I$29) -> 0.076016551 | K8: =U8 -> 11569330 | L8: =(K8/$K$29) -> 0.097933347 | M8: =-SUMIF('TB AUG'!H:H,EBIDTA!B8,'TB AUG'!G:G) -> 54702357 | N8: =(M8/$M$29) -> 0.072481965 | O8: =-SUMIF('TB JULY'!H:H,EBIDTA!B8,'TB JULY'!G:G) -> 44750007 | P8: =(O8/$O$29) -> 0.078835968 | Q8: =-SUMIF('TB JUNE'!H:H,EBIDTA!B8,'TB JUNE'!G:G) -> 32524304 | R8: =(Q8/$Q$29) -> 0.07673881 | S8: =-SUMIF('TB MAy'!H:H,EBIDTA!B8,'TB MAy'!G:G) -> 21641929 | T8: =(S8/$S$29) -> 0.086346642 | U8: =-SUMIF('TB April'!H:H,EBIDTA!B8,'TB April'!G:G) -> 11569330 | V8: =(U8/$U$29) -> 0.097933347 | X8: Opening Stock of Packing material | AC8: 0
B9: Total Revenue from operations | C9: =SUM(C7:C8) -> 1.8571375e+08 | D9: =(C9/$C$29) -> 0.99275733 | E9: =SUM(E7:E8) -> 1.3752771e+08 | F9: =(E9/$E$29) -> 0.95636081 | G9: =SUM(G7:G8) -> 1.5957806e+08 | H9: =(G9/$G$29) -> 0.92139846 | I9: =SUM(I7:I8) -> 1.1553761e+08 | J9: =(I9/$I$29) -> 0.87194674 | K9: =SUM(K7:K8) -> 1.1324224e+08 | L9: =(K9/$K$29) -> 0.95858551 | M9: =SUM(M7:M8) -> 7.1159936e+08 | N9: =(M9/$M$29) -> 0.9428866 | O9: =SUM(O7:O8) -> 5.2588561e+08 | P9: =(O9/$O$29) -> 0.92645129 | Q9: =SUM(Q7:Q8) -> 3.8835791e+08 | R9: =(Q9/$Q$29) -> 0.91630319 | S9: =SUM(S7:S8) -> 2.2877985e+08 | T9: =(S9/$S$29) -> 0.91278238 | U9: =SUM(U7:U8) -> 1.1324224e+08 | V9: =(U9/$U$29) -> 0.95858551
B10: Total Revenue from operations | X10: Add: Purchase of raw materials | Y10: =SUMIF('TB AUG'!H:H,EBIDTA!X10,'TB AUG'!G:G) -> 5.1662432e+08 | Z10: =SUMIF('TB JULY'!H:H,EBIDTA!X10,'TB JULY'!G:G) -> 4.0021117e+08 | AA10: =SUMIF('TB JUNE'!H:H,EBIDTA!X10,'TB JUNE'!G:G) -> 2.8747383e+08 | AB10: =SUMIF('TB MAy'!H:H,EBIDTA!X10,'TB MAy'!G:G) -> 1.5756703e+08 | AC10: =SUMIF('TB April'!H:H,EBIDTA!X10,'TB April'!G:G) -> 80181243
B11: Income from Jobwork charges | C11: =M11-O11 -> 0 | E11: =O11-Q11 -> 4751781.3 | G11: =Q11-S11 -> 11688561 | I11: =S11-U11 -> 15809572 | K11: =U11 -> 3826534.5 | M11: =-SUMIF('TB AUG'!H:H,EBIDTA!B11,'TB AUG'!G:G) -> 36076449 | O11: =-SUMIF('TB JULY'!H:H,EBIDTA!B11,'TB JULY'!G:G) -> 36076449 | Q11: =-SUMIF('TB JUNE'!H:H,EBIDTA!B11,'TB JUNE'!G:G) -> 31324668 | S11: =-SUMIF('TB MAy'!H:H,EBIDTA!B11,'TB MAy'!G:G) -> 19636106 | U11: =-SUMIF('TB April'!H:H,EBIDTA!B11,'TB April'!G:G) -> 3826534.5 | X11: Add: Purchase of packing materials | Y11: =SUMIF('TB AUG'!H:H,EBIDTA!X11,'TB AUG'!G:G) -> 4772132 | Z11: =SUMIF('TB JULY'!H:H,EBIDTA!X11,'TB JULY'!G:G) -> 3303596.5 | AA11: =SUMIF('TB JUNE'!H:H,EBIDTA!X11,'TB JUNE'!G:G) -> 2396644.8 | AB11: =SUMIF('TB MAy'!H:H,EBIDTA!X11,'TB MAy'!G:G) -> 1107541.5 | AC11: =SUMIF('TB April'!H:H,EBIDTA!X11,'TB April'!G:G) -> 242543
B12: Total Sales of services | C12: =SUM(C11:C11) -> 0 | E12: =SUM(E11:E11) -> 4751781.3 | F12: =(E12/$E$29) -> 0.03304365 | G12: =SUM(G11:G11) -> 11688561 | H12: =(G12/$G$29) -> 0.06748937 | I12: =SUM(I11:I11) -> 15809572 | J12: =(I12/$I$29) -> 0.1193127 | K12: =SUM(K11:K11) -> 3826534.5 | L12: =(K12/$K$29) -> 0.032391274 | M12: =SUM(M11:M11) -> 36076449 | N12: =(M12/$M$29) -> 0.04780218 | O12: =SUM(O11:O11) -> 36076449 | P12: =(O12/$O$29) -> 0.063555785 | Q12: =SUM(Q11:Q11) -> 31324668 | R12: =(Q12/$Q$29) -> 0.073908352 | S12: =SUM(S11:S11) -> 19636106 | T12: =(S12/$S$29) -> 0.078343839 | U12: =SUM(U11:U11) -> 3826534.5 | V12: =(U12/$U$29) -> 0.032391274 | X12: Add: Purchase expenses | Y12: =SUMIF('TB AUG'!H:H,EBIDTA!X12,'TB AUG'!G:G) -> -4951292.1 | Z12: =SUMIF('TB JULY'!H:H,EBIDTA!X12,'TB JULY'!G:G) -> -5173159.5 | AA12: =SUMIF('TB JUNE'!H:H,EBIDTA!X12,'TB JUNE'!G:G) -> -5279942.8 | AB12: =SUMIF('TB MAy'!H:H,EBIDTA!X12,'TB MAy'!G:G) -> -5071469.4 | AC12: =SUMIF('TB April'!H:H,EBIDTA!X12,'TB April'!G:G) -> -343851.1
B13: Other operating revenue | X13: Closing Stock of Raw material | Y13: ='Stock Sheet'!T7 -> 74301595 | Z13: ='Stock Sheet'!S7 -> 94257895 | AA13: ='Stock Sheet'!R7 -> 1.1366536e+08 | AB13: ='Stock Sheet'!Q7 -> 86126945 | AC13: ='Stock Sheet'!P7 -> 78518481
B14: Export incentives | C14: =M14-O14 -> 0 | E14: =O14-Q14 -> 0 | G14: =Q14-S14 -> 0 | I14: =S14-U14 -> 0 | K14: =U14 -> 0 | M14: =-SUMIF('TB AUG'!H:H,EBIDTA!B14,'TB AUG'!G:G) -> 0 | O14: =-SUMIF('TB JULY'!H:H,EBIDTA!B14,'TB JULY'!G:G) -> 0 | Q14: =-SUMIF('TB JUNE'!H:H,EBIDTA!B14,'TB JUNE'!G:G) -> 0 | S14: =-SUMIF('TB MAy'!H:H,EBIDTA!B14,'TB MAy'!G:G) -> 0 | U14: =-SUMIF('TB April'!H:H,EBIDTA!B14,'TB April'!G:G) -> 0 | X14: Closing Stock of Packing material | AC14: 0
B15: Commission income | C15: =M15-O15 -> 0 | E15: =O15-Q15 -> 0 | G15: =Q15-S15 -> 0 | I15: =S15-U15 -> 0 | K15: =U15 -> 0 | M15: =-SUMIF('TB AUG'!H:H,EBIDTA!B15,'TB AUG'!G:G) -> 0 | O15: =-SUMIF('TB JULY'!H:H,EBIDTA!B15,'TB JULY'!G:G) -> 0 | Q15: =-SUMIF('TB JUNE'!H:H,EBIDTA!B15,'TB JUNE'!G:G) -> 0 | S15: =-SUMIF('TB MAy'!H:H,EBIDTA!B15,'TB MAy'!G:G) -> 0 | U15: =-SUMIF('TB April'!H:H,EBIDTA!B15,'TB April'!G:G) -> 0 | X15: Total Cost of material consumed | Y15: =Y7+Y8+Y10+Y11+Y12-Y13 -> 5.1985101e+08 | Z15: =Z7+Z8+Z10+Z11+Z12-Z13 -> 3.8179115e+08 | AA15: =AA7+AA8+AA10+AA11+AA12-AA13 -> 2.4863261e+08 | AB15: =AB7+AB8+AB10+AB11+AB12-AB13 -> 1.451836e+08 | AC15: =AC7+AC8+AC10+AC11+AC12-AC13 -> 79268895
B16: Sales - Waste & Scrape | C16: =M16-O16 -> 15360 | E16: =O16-Q16 -> 87210 | G16: =Q16-S16 -> 175750 | I16: =S16-U16 -> 33000 | K16: =U16 -> 141100 | M16: =-SUMIF('TB AUG'!H:H,EBIDTA!B16,'TB AUG'!G:G) -> 452420 | O16: =-SUMIF('TB JULY'!H:H,EBIDTA!B16,'TB JULY'!G:G) -> 437060 | Q16: =-SUMIF('TB JUNE'!H:H,EBIDTA!B16,'TB JUNE'!G:G) -> 349850 | S16: =-SUMIF('TB MAy'!H:H,EBIDTA!B16,'TB MAy'!G:G) -> 174100 | U16: =-SUMIF('TB April'!H:H,EBIDTA!B16,'TB April'!G:G) -> 141100
B17: Total Other operating revenue | C17: =SUM(C14:C16) -> 15360 | D17: =(C17/$C$29) -> 8.2108907e-05 | E17: =SUM(E14:E16) -> 87210 | F17: =(E17/$E$29) -> 0.00060645399 | G17: =SUM(G14:G16) -> 175750 | H17: =(G17/$G$29) -> 0.0010147747 | I17: =SUM(I14:I16) -> 33000 | J17: =(I17/$I$29) -> 0.00024904655 | K17: =SUM(K14:K16) -> 141100 | L17: =(K17/$K$29) -> 0.001194399 | M17: =SUM(M14:M16) -> 452420 | N17: =(M17/$M$29) -> 0.0005994676 | O17: =SUM(O14:O16) -> 437060 | P17: =(O17/$O$29) -> 0.00076996744 | Q17: =SUM(Q14:Q16) -> 349850 | R17: =(Q17/$Q$29) -> 0.00082544649 | S17: =SUM(S14:S16) -> 174100 | T17: =(S17/$S$29) -> 0.00069462154 | U17: =SUM(U14:U16) -> 141100 | V17: =(U17/$U$29) -> 0.001194399 | X17: Changes in inventory of finished goods and work-in-progress
B18: Other income | X18: Inventory at the beginning of the year:
B19: Interest income: | X19: Opening Work-in-progress | AC19: 0
B20: - on fixed deposits with Banks | E20: =O20-Q20 -> 0 | G20: =Q20-S20 -> 0 | I20: =S20-U20 -> 0 | K20: =U20 -> 0 | O20: =-SUMIF('TB JULY'!H:H,EBIDTA!B20,'TB JULY'!G:G) -> 0 | Q20: =-SUMIF('TB JUNE'!H:H,EBIDTA!B20,'TB JUNE'!G:G) -> 0 | S20: =-SUMIF('TB MAy'!H:H,EBIDTA!B20,'TB MAy'!G:G) -> 0 | U20: =-SUMIF('TB April'!H:H,EBIDTA!B20,'TB April'!G:G) -> 0 | X20: Opening Stock of Finished goods | Y20: =Z20 -> 1.4832757e+08 | Z20: =AA20 -> 1.4832757e+08 | AA20: =AB20 -> 1.4832757e+08 | AB20: =AC20 -> 1.4832757e+08 | AC20: ='Stock Sheet'!O12 -> 1.4832757e+08
B21: Wind mill income | C21: =M21-O21 -> 1339516 | E21: =O21-Q21 -> 1436462 | G21: =Q21-S21 -> 1748780 | I21: =S21-U21 -> 1125170 | K21: =U21 -> 924855 | M21: =-SUMIF('TB AUG'!H:H,EBIDTA!B21,'TB AUG'!G:G) -> 6574783 | O21: =-SUMIF('TB JULY'!H:H,EBIDTA!B21,'TB JULY'!G:G) -> 5235267 | Q21: =-SUMIF('TB JUNE'!H:H,EBIDTA!B21,'TB JUNE'!G:G) -> 3798805 | S21: =-SUMIF('TB MAy'!H:H,EBIDTA!B21,'TB MAy'!G:G) -> 2050025 | U21: =-SUMIF('TB April'!H:H,EBIDTA!B21,'TB April'!G:G) -> 924855
B22: Rent Income | C22: =M22-O22 -> 0 | E22: =O22-Q22 -> 0 | G22: =Q22-S22 -> 0 | I22: =S22-U22 -> 0 | K22: =U22 -> 0 | M22: =-SUMIF('TB AUG'!H:H,EBIDTA!B22,'TB AUG'!G:G) -> 0 | O22: =-SUMIF('TB JULY'!H:H,EBIDTA!B22,'TB JULY'!G:G) -> 0 | Q22: =-SUMIF('TB JUNE'!H:H,EBIDTA!B22,'TB JUNE'!G:G) -> 0 | S22: =-SUMIF('TB MAy'!H:H,EBIDTA!B22,'TB MAy'!G:G) -> 0 | U22: =-SUMIF('TB April'!H:H,EBIDTA!B22,'TB April'!G:G) -> 0 | X22: Less:Inventory at the end of the year:
B23: Advance License Utilization | C23: =M23-O23 -> 0 | E23: =O23-Q23 -> 0 | G23: =Q23-S23 -> 0 | I23: =S23-U23 -> 0 | K23: =U23 -> 0 | M23: =-SUMIF('TB AUG'!H:H,EBIDTA!B23,'TB AUG'!G:G) -> 0 | O23: =-SUMIF('TB JULY'!H:H,EBIDTA!B23,'TB JULY'!G:G) -> 0 | Q23: =-SUMIF('TB JUNE'!H:H,EBIDTA!B23,'TB JUNE'!G:G) -> 0 | S23: =-SUMIF('TB MAy'!H:H,EBIDTA!B23,'TB MAy'!G:G) -> 0 | U23: =-SUMIF('TB April'!H:H,EBIDTA!B23,'TB April'!G:G) -> 0 | X23: Closing Stock of Finished goods | Y23: ='Stock Sheet'!T12 -> 1.682779e+08 | Z23: ='Stock Sheet'!S12 -> 1.6497889e+08 | AA23: ='Stock Sheet'!R12 -> 1.2634864e+08 | AB23: ='Stock Sheet'!Q12 -> 1.485899e+08 | AC23: ='Stock Sheet'!P12 -> 1.6407355e+08
B24: Profit on sale of fixed assets | C24: =M24-O24 -> 0 | E24: =O24-Q24 -> 0 | G24: =Q24-S24 -> 0 | I24: =S24-U24 -> 0 | K24: =U24 -> 0 | M24: =-SUMIF('TB AUG'!H:H,EBIDTA!B24,'TB AUG'!G:G) -> 0 | O24: =-SUMIF('TB JULY'!H:H,EBIDTA!B24,'TB JULY'!G:G) -> 0 | Q24: =-SUMIF('TB JUNE'!H:H,EBIDTA!B24,'TB JUNE'!G:G) -> 0 | S24: =-SUMIF('TB MAy'!H:H,EBIDTA!B24,'TB MAy'!G:G) -> 0 | U24: =-SUMIF('TB April'!H:H,EBIDTA!B24,'TB April'!G:G) -> 0 | X24: Closing Work-in-progress
B25: Profit on sale of investments | C25: =M25-O25 -> 0 | E25: =O25-Q25 -> 0 | G25: =Q25-S25 -> 0 | I25: =S25-U25 -> 0 | K25: =U25 -> 0 | M25: =-SUMIF('TB AUG'!H:H,EBIDTA!B25,'TB AUG'!G:G) -> 0 | O25: =-SUMIF('TB JULY'!H:H,EBIDTA!B25,'TB JULY'!G:G) -> 0 | Q25: =-SUMIF('TB JUNE'!H:H,EBIDTA!B25,'TB JUNE'!G:G) -> 0 | S25: =-SUMIF('TB MAy'!H:H,EBIDTA!B25,'TB MAy'!G:G) -> 0 | U25: =-SUMIF('TB April'!H:H,EBIDTA!B25,'TB April'!G:G) -> 0 | X25: Net change in inventory | Y25: =(Y19+Y20)-(Y23+Y24) -> -19950330 | Z25: =(Z19+Z20)-(Z23+Z24) -> -16651324 | AA25: =(AA19+AA20)-(AA23+AA24) -> 21978930 | AB25: =(AB19+AB20)-(AB23+AB24) -> -262331.51 | AC25: =(AC19+AC20)-(AC23+AC24) -> -15745984
B26: Sundry balance written off | C26: =M26-O26 -> 0 | E26: =O26-Q26 -> 0 | G26: =Q26-S26 -> 0 | I26: =S26-U26 -> 0 | K26: =U26 -> 0 | M26: =-SUMIF('TB AUG'!H:H,EBIDTA!B26,'TB AUG'!G:G) -> 0 | O26: =-SUMIF('TB JULY'!H:H,EBIDTA!B26,'TB JULY'!G:G) -> 0 | Q26: =-SUMIF('TB JUNE'!H:H,EBIDTA!B26,'TB JUNE'!G:G) -> 0 | S26: =-SUMIF('TB MAy'!H:H,EBIDTA!B26,'TB MAy'!G:G) -> 0 | U26: =-SUMIF('TB April'!H:H,EBIDTA!B26,'TB April'!G:G) -> 0
B27: Miscellaneous income | C27: =M27-O27 -> 0 | E27: =O27-Q27 -> 0 | G27: =Q27-S27 -> 0 | I27: =S27-U27 -> 0 | K27: =U27 -> 0 | M27: =-SUMIF('TB AUG'!H:H,EBIDTA!B27,'TB AUG'!G:G) -> 0 | O27: =-SUMIF('TB JULY'!H:H,EBIDTA!B27,'TB JULY'!G:G) -> 0 | Q27: =-SUMIF('TB JUNE'!H:H,EBIDTA!B27,'TB JUNE'!G:G) -> 0 | S27: =-SUMIF('TB MAy'!H:H,EBIDTA!B27,'TB MAy'!G:G) -> 0 | U27: =-SUMIF('TB April'!H:H,EBIDTA!B27,'TB April'!G:G) -> 0 | X27: Stores, Spares & Consumables
B28: Total Other income | C28: =SUM(C21:C27) -> 1339516 | D28: =(C28/$C$29) -> 0.0071605595 | E28: =SUM(E21:E27) -> 1436462 | F28: =(E28/$E$29) -> 0.0099890851 | G28: =SUM(G21:G27) -> 1748780 | H28: =(G28/$G$29) -> 0.010097398 | I28: =SUM(I21:I27) -> 1125170 | J28: =(I28/$I$29) -> 0.0084915061 | K28: =SUM(K21:K27) -> 924855 | L28: =(K28/$K$29) -> 0.0078288153 | M28: =SUM(M21:M27) -> 6574783 | N28: =(M28/$M$29) -> 0.0087117487 | O28: =SUM(O21:O27) -> 5235267 | P28: =(O28/$O$29) -> 0.009222956 | Q28: =SUM(Q21:Q27) -> 3798805 | R28: =(Q28/$Q$29) -> 0.0089630134 | S28: =SUM(S21:S27) -> 2050025 | T28: =(S28/$S$29) -> 0.0081791586 | U28: =SUM(U21:U27) -> 924855 | X28: Inventory at the beginning of the year:
B29: Total Turnover | C29: =M29-O29 -> 1.8706862e+08 | D29: =(C29/$C$29) -> 1 | E29: =O29-Q29 -> 1.4380316e+08 | F29: =(E29/$E$29) -> 1 | G29: =Q29-S29 -> 1.7319115e+08 | H29: =(G29/$G$29) -> 1 | I29: =I9+I12+I17+I28 -> 1.3250535e+08 | J29: =(I29/$I$29) -> 1 | K29: =K9+K12+K17+K28 -> 1.1813473e+08 | L29: =(K29/$K$29) -> 1 | M29: =M9+M12+M17+M28 -> 7.5470301e+08 | N29: =(M29/$M$29) -> 1 | O29: =O9+O12+O17+O28 -> 5.6763439e+08 | P29: =(O29/$O$29) -> 1 | Q29: =Q9+Q12+Q17+Q28 -> 4.2383123e+08 | R29: =(Q29/$Q$29) -> 1 | S29: =S9+S12+S17+S28 -> 2.5064008e+08 | T29: =(S29/$S$29) -> 1 | U29: =U9+U12+U17+U28 -> 1.1813473e+08 | V29: =(U29/$U$29) -> 1 | X29: Opening Stock of Consumables | Y29: =Z29 -> 12016718 | Z29: =AA29 -> 12016718 | AA29: =AB29 -> 12016718 | AB29: =AC29 -> 12016718 | AC29: ='Stock Sheet'!O18 -> 12016718
B30: Cost of Goods
B31: Cost of materials consumed | C31: =M31-O31 -> 1.3805986e+08 | D31: =(C31/$C$29) -> 0.73801721 | E31: =O31-Q31 -> 1.3315854e+08 | F31: =(E31/$E$29) -> 0.92597783 | G31: =Q31-S31 -> 1.0344901e+08 | H31: =(G31/$G$29) -> 0.59731121 | I31: =S31-U31 -> 65914703 | J31: =(I31/$I$29) -> 0.49744936 | K31: =U31 -> 79268895 | L31: =(K31/$K$29) -> 0.67100414 | M31: =Y15 -> 5.1985101e+08 | N31: =(M31/$M$29) -> 0.68881534 | O31: =Z15 -> 3.8179115e+08 | P31: =(O31/$O$29) -> 0.67260045 | Q31: =AA15 -> 2.4863261e+08 | R31: =(Q31/$Q$29) -> 0.58663117 | S31: =AB15 -> 1.451836e+08 | T31: =(S31/$S$29) -> 0.57925131 | U31: =AC15 -> 79268895 | V31: =(U31/$U$29) -> 0.67100414 | X31: Add: Purchase of Stores, Spares & Consumables | Y31: =SUMIF('TB AUG'!H:H,EBIDTA!X31,'TB AUG'!G:G) -> 12959545 | Z31: =SUMIF('TB JULY'!H:H,EBIDTA!X31,'TB JULY'!G:G) -> 9666619.3 | AA31: =SUMIF('TB JUNE'!H:H,EBIDTA!X31,'TB JUNE'!G:G) -> 6631758.2 | AB31: =SUMIF('TB MAy'!H:H,EBIDTA!X31,'TB MAy'!G:G) -> 4416212.6 | AC31: =SUMIF('TB April'!H:H,EBIDTA!X31,'TB April'!G:G) -> 2842163.1
B32: Purchase of stock-in-trade | C32: =M32-O32 -> 0 | D32: =(C32/$C$29) -> 0 | E32: =O32-Q32 -> 0 | F32: =(E32/$E$29) -> 0 | G32: =Q32-S32 -> 0 | H32: =(G32/$G$29) -> 0 | I32: =S32-U32 -> 0 | J32: =(I32/$I$29) -> 0 | K32: =U32 -> 0 | L32: =(K32/$K$29) -> 0 | M32: 0 | N32: =(M32/$M$29) -> 0 | O32: 0 | P32: =(O32/$O$29) -> 0 | Q32: 0 | R32: =(Q32/$Q$29) -> 0 | S32: 0 | T32: =(S32/$S$29) -> 0 | U32: 0
B33: Changes in inventory of finished goods and work-in-progress | C33: =M33-O33 -> -3299006.2 | D33: =(C33/$C$29) -> -0.017635273 | E33: =O33-Q33 -> -38630254 | F33: =(E33/$E$29) -> -0.26863286 | G33: =Q33-S33 -> 22241261 | H33: =(G33/$G$29) -> 0.12842031 | I33: =S33-U33 -> 15483652 | J33: =(I33/$I$29) -> 0.11685303 | K33: =U33 -> -15745984 | L33: =(K33/$K$29) -> -0.13328835 | M33: =Y25 -> -19950330 | N33: =(M33/$M$29) -> -0.026434677 | O33: =Z25 -> -16651324 | P33: =(O33/$O$29) -> -0.029334593 | Q33: =AA25 -> 21978930 | R33: =(Q33/$Q$29) -> 0.05185774 | S33: =AB25 -> -262331.51 | T33: =(S33/$S$29) -> -0.0010466463 | U33: =AC25 -> -15745984 | V33: =(U33/$U$29) -> -0.13328835 | X33: Less:
B34: Stores, Spares & Consumables | C34: =M34-O34 -> 2990934.3 | D34: =(C34/$C$29) -> 0.015988434 | E34: =O34-Q34 -> 2629987.5 | F34: =(E34/$E$29) -> 0.018288802 | G34: =Q34-S34 -> 2569804.8 | H34: =(G34/$G$29) -> 0.014837968 | I34: =S34-U34 -> 1450495.3 | J34: =(I34/$I$29) -> 0.010946692 | K34: =U34 -> 3033090.2 | L34: =(K34/$K$29) -> 0.025674838 | M34: =Y35 -> 12674312 | N34: =(M34/$M$29) -> 0.016793774 | O34: =Z35 -> 9683377.7 | P34: =(O34/$O$29) -> 0.017059181 | Q34: =AA35 -> 7053390.2 | R34: =(Q34/$Q$29) -> 0.016641978 | S34: =AB35 -> 4483585.4 | T34: =(S34/$S$29) -> 0.017888541 | U34: =AC35 -> 3033090.2 | V34: =(U34/$U$29) -> 0.025674838 | X34: Closing Stock of Consumables | Y34: ='Stock Sheet'!T18 -> 12301950 | Z34: ='Stock Sheet'!S18 -> 11999959 | AA34: ='Stock Sheet'!R18 -> 11595086 | AB34: ='Stock Sheet'!Q18 -> 11949345 | AC34: ='Stock Sheet'!P18 -> 11825791
B35: Total Cost of goods | C35: =C31+C33+C34 -> 1.3775179e+08 | D35: =(C35/$C$29) -> 0.73637037 | E35: =E31+E33+E34 -> 97158271 | F35: =(E35/$E$29) -> 0.67563377 | G35: =G31+G33+G34 -> 1.2826008e+08 | H35: =(G35/$G$29) -> 0.74056949 | I35: =I31+I33+I34 -> 82848850 | J35: =(I35/$I$29) -> 0.62524909 | K35: =K31+K33+K34 -> 66556001 | L35: =(K35/$K$29) -> 0.56339063 | M35: =M31+M33+M34 -> 5.1257499e+08 | N35: =(M35/$M$29) -> 0.67917443 | O35: =O31+O33+O34 -> 3.748232e+08 | P35: =(O35/$O$29) -> 0.66032504 | Q35: =Q31+Q33+Q34 -> 2.7766493e+08 | R35: =(Q35/$Q$29) -> 0.65513089 | S35: =S31+S33+S34 -> 1.4940485e+08 | T35: =(S35/$S$29) -> 0.59609321 | U35: =U31+U33+U34 -> 66556001 | V35: =(U35/$U$29) -> 0.56339063 | X35: Cost of Consumables | Y35: =Y29+Y31-Y34 -> 12674312 | Z35: =Z29+Z31-Z34 -> 9683377.7 | AA35: =AA29+AA31-AA34 -> 7053390.2 | AB35: =AB29+AB31-AB34 -> 4483585.4 | AC35: =AC29+AC31-AC34 -> 3033090.2
B36: Employee benefit expenses
B37: Salaries, wages and bonus | C37: =M37-O37 -> 11740568 | E37: =O37-Q37 -> 10633350 | G37: =Q37-S37 -> 9187414 | I37: =S37-U37 -> 8858477 | K37: =U37 -> 9680145 | M37: =SUMIF('TB AUG'!H:H,EBIDTA!B37,'TB AUG'!G:G) -> 50099954 | O37: =SUMIF('TB JULY'!H:H,EBIDTA!B37,'TB JULY'!G:G) -> 38359386 | Q37: =SUMIF('TB JUNE'!H:H,EBIDTA!B37,'TB JUNE'!G:G) -> 27726036 | S37: =SUMIF('TB MAy'!H:H,EBIDTA!B37,'TB MAy'!G:G) -> 18538622 | U37: =SUMIF('TB April'!H:H,EBIDTA!B37,'TB April'!G:G) -> 9680145 | Z37: =+Z35-AA35 -> 2629987.5 | AA37: =+AA35-AB35 -> 2569804.8
B38: Contribution to provident and other funds | C38: =M38-O38 -> 363996 | E38: =O38-Q38 -> 318445 | G38: =Q38-S38 -> 274895 | I38: =S38-U38 -> 300205 | K38: =U38 -> 336927 | M38: =SUMIF('TB AUG'!H:H,EBIDTA!B38,'TB AUG'!G:G) -> 1594468 | O38: =SUMIF('TB JULY'!H:H,EBIDTA!B38,'TB JULY'!G:G) -> 1230472 | Q38: =SUMIF('TB JUNE'!H:H,EBIDTA!B38,'TB JUNE'!G:G) -> 912027 | S38: =SUMIF('TB MAy'!H:H,EBIDTA!B38,'TB MAy'!G:G) -> 637132 | U38: =SUMIF('TB April'!H:H,EBIDTA!B38,'TB April'!G:G) -> 336927
B39: Gratuity Expenses | C39: =M39-O39 -> 0 | E39: =O39-Q39 -> 0 | G39: =Q39-S39 -> 0 | I39: =S39-U39 -> 0 | K39: =U39 -> 0 | M39: =SUMIF('TB AUG'!H:H,EBIDTA!B39,'TB AUG'!G:G) -> 0 | O39: =SUMIF('TB JULY'!H:H,EBIDTA!B39,'TB JULY'!G:G) -> 0 | Q39: =SUMIF('TB JUNE'!H:H,EBIDTA!B39,'TB JUNE'!G:G) -> 0 | S39: =SUMIF('TB MAy'!H:H,EBIDTA!B39,'TB MAy'!G:G) -> 0 | U39: =SUMIF('TB April'!H:H,EBIDTA!B39,'TB April'!G:G) -> 0
B40: Staff welfare expenses | C40: =M40-O40 -> 346099 | E40: =O40-Q40 -> 277118.2 | G40: =Q40-S40 -> 249437.1 | I40: =S40-U40 -> 230048.9 | K40: =U40 -> 217546 | M40: =SUMIF('TB AUG'!H:H,EBIDTA!B40,'TB AUG'!G:G) -> 1320249.2 | O40: =SUMIF('TB JULY'!H:H,EBIDTA!B40,'TB JULY'!G:G) -> 974150.2 | Q40: =SUMIF('TB JUNE'!H:H,EBIDTA!B40,'TB JUNE'!G:G) -> 697032 | S40: =SUMIF('TB MAy'!H:H,EBIDTA!B40,'TB MAy'!G:G) -> 447594.9 | U40: =SUMIF('TB April'!H:H,EBIDTA!B40,'TB April'!G:G) -> 217546
B41: Labour charges | C41: =M41-O41 -> 12679628 | E41: =O41-Q41 -> 11226592 | G41: =Q41-S41 -> 8715902.1 | I41: =S41-U41 -> 6926989.8 | K41: =U41 -> 8006908 | M41: =SUMIF('TB AUG'!H:H,EBIDTA!B41,'TB AUG'!G:G) -> 47556020 | O41: =SUMIF('TB JULY'!H:H,EBIDTA!B41,'TB JULY'!G:G) -> 34876392 | Q41: =SUMIF('TB JUNE'!H:H,EBIDTA!B41,'TB JUNE'!G:G) -> 23649800 | S41: =SUMIF('TB MAy'!H:H,EBIDTA!B41,'TB MAy'!G:G) -> 14933898 | U41: =SUMIF('TB April'!H:H,EBIDTA!B41,'TB April'!G:G) -> 8006908
B42: Total Employee benefit expenses | C42: =SUM(C37:C41) -> 25130291 | D42: =(C42/$C$29) -> 0.13433729 | E42: =SUM(E37:E41) -> 22455505 | F42: =(E42/$E$29) -> 0.15615446 | G42: =SUM(G37:G41) -> 18427648 | H42: =(G42/$G$29) -> 0.10640064 | I42: =SUM(I37:I41) -> 16315721 | J42: =(I42/$I$29) -> 0.12313254 | K42: =SUM(K37:K41) -> 18241526 | L42: =(K42/$K$29) -> 0.1544129 | M42: =SUM(M37:M41) -> 1.0057069e+08 | O42: =SUM(O37:O41) -> 75440400 | Q42: =SUM(Q37:Q41) -> 52984895 | R42: =(Q42/$Q$29) -> 0.12501414 | S42: =SUM(S37:S41) -> 34557247 | T42: =(S42/$S$29) -> 0.13787598 | U42: =SUM(U37:U41) -> 18241526 | V42: =(U42/$U$29) -> 0.1544129
B43: Manufacturing Expenses
...

Sheet Stock Sheet
C3: Stock sheet from Apr-24 to Mar-24
B5: Raw Material | O5: 26-27
B6: op.Stock | C6: 45383 | D6: MAY | E6: 45444 | F6: july.24 | G6: 45505 | H6: 45536 | I6: 45566 | J6: 45597 | K6: 45627 | L6: 45658 | M6: 45689 | N6: 45717 | O6: Op,stock 01.04.26 | P6: 46113 | Q6: MAY.26 | R6: 46174 | S6: july.2 | T6: 46235 | U6: 46266 | V6: 46296 | W6: 46327 | X6: 46357 | Y6: 46388 | Z6: 46419 | AA6: 46447
C7: 40885502 | D7: 44690515 | E7: 59879823 | F7: 58718633 | G7: 60867855 | H7: 58655299 | I7: 49973632 | J7: 52326500 | K7: 51493051 | L7: 44011790 | M7: 61248778 | N7: 59069210 | O7: 77707440 | P7: 78518481 | Q7: 86126945 | R7: 1.1366536e+08 | S7: 94257895 | T7: 74301595
B10: Finesh Material
B11: op.Stock | C11: 45383 | D11: MAY | E11: 45444 | F11: july.24 | G11: 45505 | H11: 45536 | I11: 45566 | J11: 45597 | K11: 45627 | L11: 45658 | M11: 45689 | N11: 45717 | O11: Op,stock 01.04.26 | P11: 46113 | Q11: MAY.26 | R11: 46174 | S11: july.2 | T11: 46235 | U11: 46266 | V11: 46296 | W11: 46327 | X11: 46357 | Y11: 46388 | Z11: 46419 | AA11: 46447
C12: 76985434 | D12: 73682752 | E12: 84421689 | F12: 87270138 | G12: 98165150 | H12: 1.1481412e+08 | I12: 109540747 | J12: 92932583 | K12: 1.0876437e+08 | L12: 1.1692796e+08 | M12: 1.203563e+08 | N12: 1.2409052e+08 | O12: 1.4832757e+08 | P12: 1.6407355e+08 | Q12: 1.485899e+08 | R12: 1.2634864e+08 | S12: 1.6497889e+08 | T12: 1.682779e+08
B15: Stores Spares
B16: op.Stock | C16: 45383 | D16: MAY | E16: 45444 | F16: july.24 | G16: 45505 | H16: 45536 | I16: 45566 | J16: 45597 | K16: 45627 | L16: 45658 | M16: 45689 | N16: 45717 | O16: Op,stock 01.04.26 | P16: 46113 | Q16: MAY.26 | R16: 46174 | S16: july.2 | T16: 46235 | U16: 46266 | V16: 46296 | W16: 46327 | X16: 46357 | Y16: 46388 | Z16: 46419 | AA16: 46447
C18: 11212574 | D18: 11398463 | E18: 11966098 | F18: 11807893 | G18: 12281943 | H18: 11290716 | I18: 11937270 | J18: 11725252 | K18: 11462964 | L18: 10929459 | M18: 11096995 | N18: 10973564 | O18: 12016718 | P18: 11825791 | Q18: 11949345 | R18: 11595086 | S18: 11999959 | T18: 12301950

Sheet MASTER 26 27
A4: Perticulars | B4: GROUP
A5: Duty Clearing Account | B5: Not Applicable
A6: Bank CA SCB 23305216958 | B6: Not Applicable
A7: Bank CA SCB 23391238420 | B7: Not Applicable
A8: Bank EEFC SCB 23305153697 | B8: Not Applicable
A9: Bank CA SCB 23305127882 | B9: Not Applicable
A10: Bank CA SBI EEFC USD 40471492269 | B10: Not Applicable
A11: Bank CA SBI 31342060288 | B11: Not Applicable
A12: Bank CA HDFC 60330005874 | B12: Not Applicable
A13: Bank CA HDFC 60330005840 | B13: Not Applicable
A14: CGST Input | B14: Not Applicable
A15: Bank CA BOB 26160500000026 | B15: Not Applicable
... A1298: Profit And Loss Account | B1298: Not Applicable

Sheet TB April
B1: Plastene India Limited (Unit -II)
B2: 01-Apr-2026 30-Apr-2026
C3: Transaction | E3: 0
A4: Perticulars | B4: Opening | C4: Debit | D4: Credit | E4: Closing | F4: Provisin | G4: Total | H4: Group Name
A5: Duty Clearing Account | E5: 0 | F5: 0 | G5: =+E5+F5 -> 0 | H5: =VLOOKUP(A5,'MASTER 26 27'!A:B,2,0) -> Not Applicable
A6: TCS on Purchase | B6: 127789.26 | E6: 127789.26 | F6: 0 | G6: =+E6+F6 -> 127789.26 | H6: =VLOOKUP(A6,'MASTER 26 27'!A:B,2,0) -> Not Applicable
A7: TCS on Purchase 17-18 | B7: 650 | E7: 650 | F7: 0 | G7: =+E7+F7 -> 650 | H7: =VLOOKUP(A7,'MASTER 26 27'!A:B,2,0) -> Not Applicable
A8: TCS On Purchase 19-20 | B8: 6228 | E8: 6228 | F8: 0 | G8: =+E8+F8 -> 6228 | H8: =VLOOKUP(A8,'MASTER 26 27'!A:B,2,0) -> Not Applicable
A9: TCS On Purchase 20-21 | B9: 473797.97 | E9: 473797.97 | F9: 0 | G9: =+E9+F9 -> 473797.97 | H9: =VLOOKUP(A9,'MASTER 26 27'!A:B,2,0) -> Not Applicable
A10: TCS On Purchase 21-22 | B10: 196345.38 | E10: 196345.38 | F10: 0 | G10: =+E10+F10 -> 196345.38 | H10: =VLOOKUP(A10,'MASTER 26 27'!A:B,2,0) -> Not Applicable
A11: TCS On Purchase 22-23 | B11: 8936.56 | E11: 8936.56 | F11: 0 | G11: =+E11+F11 -> 8936.56 | H11: =VLOOKUP(A11,'MASTER 26 27'!A:B,2,0) -> Not Applicable
A12: TCS On Purchase 23-24 | B12: 8213.71 | E12: 8213.71 | F12: 0 | G12: =+E12+F12 -> 8213.71 | H12: =VLOOKUP(A12,'MASTER 26 27'!A:B,2,0) -> Not Applicable
A13: Tcs On Purchase 25-26 | B13: 1806.82 | E13: 1806.82 | F13: 0 | G13: =+E13+F13 -> 1806.82 | H13: =VLOOKUP(A13,'MASTER 26 27'!A:B,2,0) -> Not Applicable
A14: TDS Receivable 2018-19 | B14: 681686 | E14: 681686 | F14: 0 | G14: =+E14+F14 -> 681686 | H14: =VLOOKUP(A14,'MASTER 26 27'!A:B,2,0) -> Not Applicable
A15: TDS Receivable 2019-20 | B15: 157074.42 | E15: 157074.42 | F15: 0 | G15: =+E15+F15 -> 157074.42 | H15: =VLOOKUP(A15,'MASTER 26 27'!A:B,2,0) -> Not Applicable
A16: TDS Receivable 2020-21 | B16: 167632.97 | E16: 167632.97 | F16: 0 | G16: =+E16+F16 -> 167632.97 | H16: =VLOOKUP(A16,'MASTER 26 27'!A:B,2,0) -> Not Applicable
A17: TDS Receivable 2021-22 | B17: 256416 | E17: 256416 | F17: 0 | G17: =+E17+F17 -> 256416 | H17: =VLOOKUP(A17,'MASTER 26 27'!A:B,2,0) -> Not Applicable
... A21: Tds Receivable 2025-26 | B21: 2359808.6 | E21: 2359808.6 | F21: 0 | G21: =+E21+F21 -> 2359808.6 | H21: =VLOOKUP(A21,'MASTER 26 27'!A:B,2,0) -> Not Applicable
A22: Tds Receivable 2026-27 | C22: 116856.4 | E22: 116856.4 | F22: 0 | G22: =+E22+F22 -> 116856.4 | H22: Not Applicable
A23: Bank CA BOB 25380200000233 | B23: -185354 | E23: -185354 | F23: 0 | G23: =+E23+F23 -> -185354 | H23: =VLOOKUP(A23,'MASTER 26 27'!A:B,2,0) -> Not Applicable
A24: Bank CA BOB 26160500000026 | B24: -3.371752e+09 | C24: 57955875 | D24: 1.0315683e+08 | E24: -3.4169529e+09 | F24: 0 | G24: =+E24+F24 -> -3.4169529e+09 | H24: =VLOOKUP(A24,'MASTER 26 27'!A:B,2,0) -> Not Applicable
A25: Bank CA HDFC 60330005840 | B25: -33335575 | E25: -33335575 | F25: 0 | G25: =+E25+F25 -> -33335575 | H25: =VLOOKUP(A25,'MASTER 26 27'!A:B,2,0) -> Not Applicable
A26: Bank CA HDFC 60330005874 | B26: -9.7321637e+08 | E26: -9.7321637e+08 | F26: 0 | G26: =+E26+F26 -> -9.7321637e+08 | H26: =VLOOKUP(A26,'MASTER 26 27'!A:B,2,0) -> Not Applicable
A27: Bank CA SBI 31342060288 | B27: -1.4161945e+08 | E27: -1.4161945e+08 | F27: 0 | G27: =+E27+F27 -> -1.4161945e+08 | H27: =VLOOKUP(A27,'MASTER 26 27'!A:B,2,0) -> Not Applicable
A28: Bank CA SBI EEFC USD 40471492269 | B28: 1.0393953e+08 | C28: 3246442.1 | E28: 1.0718597e+08 | F28: 0 | G28: =+E28+F28 -> 1.0718597e+08 | H28: =VLOOKUP(A28,'MASTER 26 27'!A:B,2,0) -> Not Applicable
A29: Bank CA SCB 23305127882 | B29: 4.1760664e+08 | E29: 4.1760664e+08 | F29: 0 | G29: =+E29+F29 -> 4.1760664e+08 | H29: =VLOOKUP(A29,'MASTER 26 27'!A:B,2,0) -> Not Applicable
A30: Bank CA SCB 23305216958 | B30: -1.5436525e+08 | E30: -1.5436525e+08 | F30: 0 | G30: =+E30+F30 -> -1.5436525e+08 | H30: =VLOOKUP(A30,'MASTER 26 27'!A:B,2,0) -> Not Applicable
A31: Bank CA SCB 23391238420 | B31: 1070438.6 | E31: 1070438.6 | F31: 0 | G31: =+E31+F31 -> 1070438.6 | H31: =VLOOKUP(A31,'MASTER 26 27'!A:B,2,0) -> Not Applicable
A32: Bank EEFC SCB 23305153697 | B32: 6687573.3 | E32: 6687573.3 | F32: 0 | G32: =+E32+F32 -> 6687573.3 | H32: =VLOOKUP(A32,'MASTER 26 27'!A:B,2,0) -> Not Applicable
A33: Cash in Hand-Factory | B33: 7980.76 | C33: 300000 | D33: 200041 | E33: 107939.76 | F33: 0 | G33: =+E33+F33 -> 107939.76 | H33: =VLOOKUP(A33,'MASTER 26 27'!A:B,2,0) -> Not Applicable
A34: Cash in Hand-HO | B34: 4950 | E34: 4950 | F34: 0 | G34: =+E34+F34 -> 4950 | H34: =VLOOKUP(A34,'MASTER 26 27'!A:B,2,0) -> Not Applicable
A35: Stock In Hand- Temp Ledger | B35: 178885102 | E35: 178885102 | F35: 0 | G35: =+E35+F35 -> 178885102 | H35: =VLOOKUP(A35,'MASTER 26 27'!A:B,2,0) -> Not Applicable
A36: Investment In Shares Of Gopala Polyplast Limited | B36: 5000000 | E36: 5000000 | F36: 0 | G36: =+E36+F36 -> 5000000 | H36: =VLOOKUP(A36,'MASTER 26 27'!A:B,2,0) -> Not Applicable
A37: Licenses MEIS (Stock) | B37: -2993657.1 | E37: -2993657.1 | F37: 0 | G37: =+E37+F37 -> -2993657.1 | H37: =VLOOKUP(A37,'MASTER 26 27'!A:B,2,0) -> Not Applicable
A38: CGST Input | B38: 59787.81 | C38: 3988156.5 | E38: 4047944.3 | F38: 0 | G38: =+E38+F38 -> 4047944.3 | H38: =VLOOKUP(A38,'MASTER 26 27'!A:B,2,0) -> Not Applicable
A39: GST Credit-Non Eligible | E39: 0 | F39: 0 | G39: =+E39+F39 -> 0 | H39: =VLOOKUP(A39,'MASTER 26 27'!A:B,2,0) -> Not Applicable
A40: IGST Input | B40: 0.04 | C40: 136374.48 | E40: 136374.52 | F40: 0 | G40: =+E40+F40 -> 136374.52 | H40: =VLOOKUP(A40,'MASTER 26 27'!A:B,2,0) -> Not Applicable
A41: SGST Input | B41: 59787.81 | C41: 3988156.5 | E41: 4047944.3 | F41: 0 | G41: =+E41+F41 -> 4047944.3 | H41: =VLOOKUP(A41,'MASTER 26 27'!A:B,2,0) -> Not Applicable
A42: IGST Refund Receivable Under Rebate | B42: 1259702.3 | E42: 1259702.3 | F42: 0 | G42: =+E42+F42 -> 1259702.3 | H42: =VLOOKUP(A42,'MASTER 26 27'!A:B,2,0) -> Not Applicable
A43: Plastene India Ltd - Ho-For Gst Balance Only | B43: 20043511 | E43: 20043511 | F43: 0 | G43: =+E43+F43 -> 20043511 | H43: =VLOOKUP(A43,'MASTER 26 27'!A:B,2,0) -> Not Applicable
...

Sheet TB MAy
B1: Plastene India Limited (Unit -II)
B2: 01-Apr-2026 31-May-2026
C3: Transaction
A4: Perticulars | B4: Opening | C4: Debit | D4: Credit | E4: Closing | F4: Provisin | G4: Total | H4: Group Name
A5: TCS on Purchase | B5: 127789.26 | E5: 127789.26 | F5: 0 | G5: =+E5+F5 -> 127789.26 | H5: =VLOOKUP(A5,'TB April'!A:H,8,0) -> Not Applicable
A6: TCS on Purchase 17-18 | B6: 650 | E6: 650 | F6: 0 | G6: =+E6+F6 -> 650 | H6: =VLOOKUP(A6,'TB April'!A:H,8,0) -> Not Applicable
A7: TCS On Purchase 19-20 | B7: 6228 | E7: 6228 | F7: 0 | G7: =+E7+F7 -> 6228 | H7: =VLOOKUP(A7,'TB April'!A:H,8,0) -> Not Applicable
A8: TCS On Purchase 20-21 | B8: 473797.97 | E8: 473797.97 | F8: 0 | G8: =+E8+F8 -> 473797.97 | H8: =VLOOKUP(A8,'TB April'!A:H,8,0) -> Not Applicable
A9: TCS On Purchase 21-22 | B9: 196345.38 | E9: 196345.38 | F9: 0 | G9: =+E9+F9 -> 196345.38 | H9: =VLOOKUP(A9,'TB April'!A:H,8,0) -> Not Applicable
A10: TCS On Purchase 22-23 | B10: 8936.56 | E10: 8936.56 | F10: 0 | G10: =+E10+F10 -> 8936.56 | H10: =VLOOKUP(A10,'TB April'!A:H,8,0) -> Not Applicable
A11: TCS On Purchase 23-24 | B11: 8213.71 | E11: 8213.71 | F11: 0 | G11: =+E11+F11 -> 8213.71 | H11: =VLOOKUP(A11,'TB April'!A:H,8,0) -> Not Applicable
A12: Tcs On Purchase 25-26 | B12: 1806.82 | E12: 1806.82 | F12: 0 | G12: =+E12+F12 -> 1806.82 | H12: =VLOOKUP(A12,'TB April'!A:H,8,0) -> Not Applicable
A13: TDS Receivable 2018-19 | B13: 681686 | E13: 681686 | F13: 0 | G13: =+E13+F13 -> 681686 | H13: =VLOOKUP(A13,'TB April'!A:H,8,0) -> Not Applicable
A14: TDS Receivable 2019-20 | B14: 157074.42 | E14: 157074.42 | F14: 0 | G14: =+E14+F14 -> 157074.42 | H14: =VLOOKUP(A14,'TB April'!A:H,8,0) -> Not Applicable
A15: TDS Receivable 2020-21 | B15: 167632.97 | E15: 167632.97 | F15: 0 | G15: =+E15+F15 -> 167632.97 | H15: =VLOOKUP(A15,'TB April'!A:H,8,0) -> Not Applicable
A16: TDS Receivable 2021-22 | B16: 256416 | E16: 256416 | F16: 0 | G16: =+E16+F16 -> 256416 | H16: =VLOOKUP(A16,'TB April'!A:H,8,0) -> Not Applicable
... A20: Tds Receivable 2025-26 | B20: 2359808.6 | E20: 2359808.6 | F20: 0 | G20: =+E20+F20 -> 2359808.6 | H20: =VLOOKUP(A20,'TB April'!A:H,8,0) -> Not Applicable
A21: Tds Receivable 2026-27 | C21: 510382.57 | E21: 510382.57 | F21: 0 | G21: =+E21+F21 -> 510382.57 | H21: =VLOOKUP(A21,'TB April'!A:H,8,0) -> Not Applicable
A22: Bank CA BOB 25380200000233 | B22: -185354 | E22: -185354 | F22: 0 | G22: =+E22+F22 -> -185354 | H22: =VLOOKUP(A22,'TB April'!A:H,8,0) -> Not Applicable
A23: Bank CA BOB 26160500000026 | B23: -3.371752e+09 | C23: 1.0584574e+08 | D23: 1.8739175e+08 | E23: -3.453298e+09 | F23: 0 | G23: =+E23+F23 -> -3.453298e+09 | H23: =VLOOKUP(A23,'TB April'!A:H,8,0) -> Not Applicable
A24: Bank CA HDFC 60330005840 | B24: -33335575 | E24: -33335575 | F24: 0 | G24: =+E24+F24 -> -33335575 | H24: =VLOOKUP(A24,'TB April'!A:H,8,0) -> Not Applicable
A25: Bank CA HDFC 60330005874 | B25: -9.7321637e+08 | E25: -9.7321637e+08 | F25: 0 | G25: =+E25+F25 -> -9.7321637e+08 | H25: =VLOOKUP(A25,'TB April'!A:H,8,0) -> Not Applicable
A26: Bank CA SBI 31342060288 | B26: -1.4161945e+08 | E26: -1.4161945e+08 | F26: 0 | G26: =+E26+F26 -> -1.4161945e+08 | H26: =VLOOKUP(A26,'TB April'!A:H,8,0) -> Not Applicable
A27: Bank CA SBI EEFC USD 40471492269 | B27: 1.0926139e+08 | C27: 10715178 | E27: 1.1997657e+08 | F27: 0 | G27: =+E27+F27 -> 1.1997657e+08 | H27: =VLOOKUP(A27,'TB April'!A:H,8,0) -> Not Applicable
A28: Bank CA SCB 23305127882 | B28: 4.1760664e+08 | E28: 4.1760664e+08 | F28: 0 | G28: =+E28+F28 -> 4.1760664e+08 | H28: =VLOOKUP(A28,'TB April'!A:H,8,0) -> Not Applicable
A29: Bank CA SCB 23305216958 | B29: -1.5436525e+08 | E29: -1.5436525e+08 | F29: 0 | G29: =+E29+F29 -> -1.5436525e+08 | H29: =VLOOKUP(A29,'TB April'!A:H,8,0) -> Not Applicable
A30: Bank CA SCB 23391238420 | B30: 1070438.6 | E30: 1070438.6 | F30: 0 | G30: =+E30+F30 -> 1070438.6 | H30: =VLOOKUP(A30,'TB April'!A:H,8,0) -> Not Applicable
A31: Bank EEFC SCB 23305153697 | B31: 6687573.3 | E31: 6687573.3 | F31: 0 | G31: =+E31+F31 -> 6687573.3 | H31: =VLOOKUP(A31,'TB April'!A:H,8,0) -> Not Applicable
A32: Cash in Hand-Factory | B32: 7980.76 | C32: 400000 | D32: 403681 | E32: 4299.76 | F32: 0 | G32: =+E32+F32 -> 4299.76 | H32: =VLOOKUP(A32,'TB April'!A:H,8,0) -> Not Applicable
A33: Cash in Hand-HO | B33: 4950 | D33: 513 | E33: 4437 | F33: 0 | G33: =+E33+F33 -> 4437 | H33: =VLOOKUP(A33,'TB April'!A:H,8,0) -> Not Applicable
A34: RODTEP SCRIPT | C34: 37291 | E34: 37291 | F34: 0 | G34: =+E34+F34 -> 37291 | H34: Not Applicable
A35: Stock In Hand- Temp Ledger | B35: 178885102 | E35: 178885102 | F35: 0 | G35: =+E35+F35 -> 178885102 | H35: =VLOOKUP(A35,'TB April'!A:H,8,0) -> Not Applicable
A36: Investment In Shares Of Gopala Polyplast Limited | B36: 5000000 | E36: 5000000 | F36: 0 | G36: =+E36+F36 -> 5000000 | H36: =VLOOKUP(A36,'TB April'!A:H,8,0) -> Not Applicable
A37: Licenses MEIS (Stock) | B37: -2993657.1 | E37: -2993657.1 | F37: 0 | G37: =+E37+F37 -> -2993657.1 | H37: =VLOOKUP(A37,'TB April'!A:H,8,0) -> Not Applicable
A38: CGST Input | B38: 30184.23 | C38: 8981272 | D38: 3990955.5 | E38: 5020500.7 | F38: 0 | G38: =+E38+F38 -> 5020500.7 | H38: =VLOOKUP(A38,'TB April'!A:H,8,0) -> Not Applicable
A39: GST Credit-Non Eligible | F39: 0 | G39: =+E39+F39 -> 0 | H39: =VLOOKUP(A39,'TB April'!A:H,8,0) -> Not Applicable
A40: IGST Input | B40: 0.04 | C40: 2120011.6 | D40: 158550.48 | E40: 1961461.2 | F40: 0 | G40: =+E40+F40 -> 1961461.2 | H40: =VLOOKUP(A40,'TB April'!A:H,8,0) -> Not Applicable
A41: SGST Input | B41: 30184.23 | C41: 8981272 | D41: 3990955.5 | E41: 5020500.7 | F41: 0 | G41: =+E41+F41 -> 5020500.7 | H41: =VLOOKUP(A41,'TB April'!A:H,8,0) -> Not Applicable
A42: IGST Refund Receivable Under Rebate | B42: 1259702.3 | E42: 1259702.3 | F42: 0 | G42: =+E42+F42 -> 1259702.3 | H42: =VLOOKUP(A42,'TB April'!A:H,8,0) -> Not Applicable
A43: Plastene India Ltd - Ho-For Gst Balance Only | B43: 20192591 | C43: 8112687.5 | D43: 7910261.5 | E43: 20395017 | F43: 0 | G43: =+E43+F43 -> 20395017 | H43: =VLOOKUP(A43,'TB April'!A:H,8,0) -> Not Applicable
...

Sheet TB JUNE
B1: Plastene India Limited (Unit -II)
B2: 01-Apr-2026 30-Jun-2026
C3: Transaction
A4: Perticulars | B4: Opening | C4: Debit | D4: Credit | E4: Closing | F4: Provisin | G4: Total | H4: Group Name
A5: TCS on Purchase | B5: 127789.26 | E5: 127789.26 | F5: 0 | G5: =+E5+F5 -> 127789.26 | H5: =VLOOKUP(A5,'TB MAy'!A:H,8,0) -> Not Applicable
A6: TCS on Purchase 17-18 | B6: 650 | E6: 650 | F6: 0 | G6: =+E6+F6 -> 650 | H6: =VLOOKUP(A6,'TB MAy'!A:H,8,0) -> Not Applicable
A7: TCS On Purchase 19-20 | B7: 6228 | E7: 6228 | F7: 0 | G7: =+E7+F7 -> 6228 | H7: =VLOOKUP(A7,'TB MAy'!A:H,8,0) -> Not Applicable
A8: TCS On Purchase 20-21 | B8: 473797.97 | E8: 473797.97 | F8: 0 | G8: =+E8+F8 -> 473797.97 | H8: =VLOOKUP(A8,'TB MAy'!A:H,8,0) -> Not Applicable
A9: TCS On Purchase 21-22 | B9: 196345.38 | E9: 196345.38 | F9: 0 | G9: =+E9+F9 -> 196345.38 | H9: =VLOOKUP(A9,'TB MAy'!A:H,8,0) -> Not Applicable
A10: TCS On Purchase 22-23 | B10: 8936.56 | E10: 8936.56 | F10: 0 | G10: =+E10+F10 -> 8936.56 | H10: =VLOOKUP(A10,'TB MAy'!A:H,8,0) -> Not Applicable
A11: TCS On Purchase 23-24 | B11: 8213.71 | E11: 8213.71 | F11: 0 | G11: =+E11+F11 -> 8213.71 | H11: =VLOOKUP(A11,'TB MAy'!A:H,8,0) -> Not Applicable
A12: Tcs On Purchase 25-26 | B12: 1806.82 | E12: 1806.82 | F12: 0 | G12: =+E12+F12 -> 1806.82 | H12: =VLOOKUP(A12,'TB MAy'!A:H,8,0) -> Not Applicable
A13: TDS Receivable 2018-19 | B13: 681686 | E13: 681686 | F13: 0 | G13: =+E13+F13 -> 681686 | H13: =VLOOKUP(A13,'TB MAy'!A:H,8,0) -> Not Applicable
A14: TDS Receivable 2019-20 | B14: 157074.42 | E14: 157074.42 | F14: 0 | G14: =+E14+F14 -> 157074.42 | H14: =VLOOKUP(A14,'TB MAy'!A:H,8,0) -> Not Applicable
A15: TDS Receivable 2020-21 | B15: 167632.97 | E15: 167632.97 | F15: 0 | G15: =+E15+F15 -> 167632.97 | H15: =VLOOKUP(A15,'TB MAy'!A:H,8,0) -> Not Applicable
A16: TDS Receivable 2021-22 | B16: 256416 | E16: 256416 | F16: 0 | G16: =+E16+F16 -> 256416 | H16: =VLOOKUP(A16,'TB MAy'!A:H,8,0) -> Not Applicable
... A20: Tds Receivable 2025-26 | B20: 2359808.6 | E20: 2359808.6 | F20: 0 | G20: =+E20+F20 -> 2359808.6 | H20: =VLOOKUP(A20,'TB MAy'!A:H,8,0) -> Not Applicable
A21: Tds Receivable 2026-27 | C21: 850762.18 | E21: 850762.18 | F21: 0 | G21: =+E21+F21 -> 850762.18 | H21: =VLOOKUP(A21,'TB MAy'!A:H,8,0) -> Not Applicable
A22: Bank CA BOB 25380200000233 | B22: -185354 | E22: -185354 | F22: 0 | G22: =+E22+F22 -> -185354 | H22: =VLOOKUP(A22,'TB MAy'!A:H,8,0) -> Not Applicable
A23: Bank CA BOB 26160500000026 | B23: -3.371692e+09 | C23: 2.4001263e+08 | D23: 3.4822028e+08 | E23: -3.4798996e+09 | F23: 0 | G23: =+E23+F23 -> -3.4798996e+09 | H23: =VLOOKUP(A23,'TB MAy'!A:H,8,0) -> Not Applicable
A24: Bank CA HDFC 60330005840 | B24: -33335575 | E24: -33335575 | F24: 0 | G24: =+E24+F24 -> -33335575 | H24: =VLOOKUP(A24,'TB MAy'!A:H,8,0) -> Not Applicable
A25: Bank CA HDFC 60330005874 | B25: -9.7321637e+08 | E25: -9.7321637e+08 | F25: 0 | G25: =+E25+F25 -> -9.7321637e+08 | H25: =VLOOKUP(A25,'TB MAy'!A:H,8,0) -> Not Applicable
A26: Bank CA SBI 31342060288 | B26: -1.4161945e+08 | E26: -1.4161945e+08 | F26: 0 | G26: =+E26+F26 -> -1.4161945e+08 | H26: =VLOOKUP(A26,'TB MAy'!A:H,8,0) -> Not Applicable
A27: Bank CA SBI EEFC USD 40471492269 | B27: 1.0926139e+08 | C27: 19498634 | E27: 1.2876003e+08 | F27: 0 | G27: =+E27+F27 -> 1.2876003e+08 | H27: =VLOOKUP(A27,'TB MAy'!A:H,8,0) -> Not Applicable
A28: Bank CA SCB 23305127882 | B28: 4.1760664e+08 | E28: 4.1760664e+08 | F28: 0 | G28: =+E28+F28 -> 4.1760664e+08 | H28: =VLOOKUP(A28,'TB MAy'!A:H,8,0) -> Not Applicable
A29: Bank CA SCB 23305216958 | B29: -1.5436525e+08 | E29: -1.5436525e+08 | F29: 0 | G29: =+E29+F29 -> -1.5436525e+08 | H29: =VLOOKUP(A29,'TB MAy'!A:H,8,0) -> Not Applicable
A30: Bank CA SCB 23391238420 | B30: 1070438.6 | E30: 1070438.6 | F30: 0 | G30: =+E30+F30 -> 1070438.6 | H30: =VLOOKUP(A30,'TB MAy'!A:H,8,0) -> Not Applicable
A31: Bank EEFC SCB 23305153697 | B31: 6687573.3 | E31: 6687573.3 | F31: 0 | G31: =+E31+F31 -> 6687573.3 | H31: =VLOOKUP(A31,'TB MAy'!A:H,8,0) -> Not Applicable
A32: Cash in Hand-Factory | B32: 7980.76 | C32: 700000 | D32: 608143 | E32: 99837.76 | F32: 0 | G32: =+E32+F32 -> 99837.76 | H32: =VLOOKUP(A32,'TB MAy'!A:H,8,0) -> Not Applicable
A33: Cash in Hand-HO | B33: 4950 | D33: 513 | E33: 4437 | F33: 0 | G33: =+E33+F33 -> 4437 | H33: =VLOOKUP(A33,'TB MAy'!A:H,8,0) -> Not Applicable
A34: RODTEP SCRIPT | C34: 888121 | D34: 850830 | E34: 37291 | F34: 0 | G34: =+E34+F34 -> 37291 | H34: =VLOOKUP(A34,'TB MAy'!A:H,8,0) -> Not Applicable
A35: Stock In Hand- Temp Ledger | B35: 178885102 | E35: 178885102 | F35: 0 | G35: =+E35+F35 -> 178885102 | H35: =VLOOKUP(A35,'TB MAy'!A:H,8,0) -> Not Applicable
A36: Investment In Shares Of Gopala Polyplast Limited | B36: 5000000 | E36: 5000000 | F36: 0 | G36: =+E36+F36 -> 5000000 | H36: =VLOOKUP(A36,'TB MAy'!A:H,8,0) -> Not Applicable
A37: Licenses MEIS (Stock) | B37: -2993657.1 | E37: -2993657.1 | F37: 0 | G37: =+E37+F37 -> -2993657.1 | H37: =VLOOKUP(A37,'TB MAy'!A:H,8,0) -> Not Applicable
A38: CGST Input | B38: 2497.6 | C38: 19755778 | D38: 8938291.1 | E38: 10819984 | F38: 0 | G38: =+E38+F38 -> 10819984 | H38: =VLOOKUP(A38,'TB MAy'!A:H,8,0) -> Not Applicable
A39: GST Credit-Non Eligible | C39: 20957.7 | D39: 20957.7 | F39: 0 | G39: =+E39+F39 -> 0 | H39: =VLOOKUP(A39,'TB MAy'!A:H,8,0) -> Not Applicable
A40: IGST INPUT | B40: 0.04 | C40: 3225164.5 | D40: 2212813.6 | E40: 1012350.9 | F40: 0 | G40: =+E40+F40 -> 1012350.9 | H40: =VLOOKUP(A40,'TB MAy'!A:H,8,0) -> Not Applicable
A41: SGST Input | B41: 2497.6 | C41: 19755778 | D41: 8938291.1 | E41: 10819984 | F41: 0 | G41: =+E41+F41 -> 10819984 | H41: =VLOOKUP(A41,'TB MAy'!A:H,8,0) -> Not Applicable
A42: IGST Refund Receivable Under Rebate | B42: 1259702.3 | C42: 3981618.9 | E42: 5241321.2 | F42: 0 | G42: =+E42+F42 -> 5241321.2 | H42: =VLOOKUP(A42,'TB MAy'!A:H,8,0) -> Not Applicable
A43: Plastene India Ltd - Ho-For Gst Balance Only | B43: 20247964 | C43: 20044202 | D43: 23149644 | E43: 17142522 | F43: 0 | G43: =+E43+F43 -> 17142522 | H43: =VLOOKUP(A43,'TB MAy'!A:H,8,0) -> Not Applicable
...

Sheet TB JULY
B1: Plastene India Limited (Unit -II)
B2: 01-Apr-2026 31-Jul-2026
C3: Transaction
A4: Perticulars | B4: Opening | C4: Debit | D4: Credit | E4: Closing | F4: Provisin | G4: Total | H4: Group Name
A5: Tds Receivable 2026-27 | C5: 996302.51 | D5: 48.2 | E5: 996254.31 | F5: 0 | G5: =+E5+F5 -> 996254.31 | H5: =VLOOKUP(A5,'TB JUNE'!A:H,8,0) -> Not Applicable
A6: Bank CA SCB 23305216958 | B6: -1.5436525e+08 | E6: -1.5436525e+08 | F6: 0 | G6: =+E6+F6 -> -1.5436525e+08 | H6: =VLOOKUP(A6,'TB JUNE'!A:H,8,0) -> Not Applicable
A7: Bank CA SCB 23391238420 | B7: 1070438.6 | E7: 1070438.6 | F7: 0 | G7: =+E7+F7 -> 1070438.6 | H7: =VLOOKUP(A7,'TB JUNE'!A:H,8,0) -> Not Applicable
A8: Bank EEFC SCB 23305153697 | B8: 6687573.3 | E8: 6687573.3 | F8: 0 | G8: =+E8+F8 -> 6687573.3 | H8: =VLOOKUP(A8,'TB JUNE'!A:H,8,0) -> Not Applicable
A9: Tds Receivable 2025-26 | B9: 2359808.6 | E9: 2359808.6 | F9: 0 | G9: =+E9+F9 -> 2359808.6 | H9: =VLOOKUP(A9,'TB JUNE'!A:H,8,0) -> Not Applicable
A10: Tds Receivable 2024-25 | B10: 753208.69 | E10: 753208.69 | F10: 0 | G10: =+E10+F10 -> 753208.69 | H10: =VLOOKUP(A10,'TB JUNE'!A:H,8,0) -> Not Applicable
A11: TDS Receivable 2023-24 | B11: 723178.82 | E11: 723178.82 | F11: 0 | G11: =+E11+F11 -> 723178.82 | H11: =VLOOKUP(A11,'TB JUNE'!A:H,8,0) -> Not Applicable
A12: TDS Receivable 2022-23 | B12: 822958.41 | E12: 822958.41 | F12: 0 | G12: =+E12+F12 -> 822958.41 | H12: =VLOOKUP(A12,'TB JUNE'!A:H,8,0) -> Not Applicable
A13: TDS Receivable 2021-22 | B13: 256416 | E13: 256416 | F13: 0 | G13: =+E13+F13 -> 256416 | H13: =VLOOKUP(A13,'TB JUNE'!A:H,8,0) -> Not Applicable
A14: TDS Receivable 2020-21 | B14: 167632.97 | E14: 167632.97 | F14: 0 | G14: =+E14+F14 -> 167632.97 | H14: =VLOOKUP(A14,'TB JUNE'!A:H,8,0) -> Not Applicable
A15: TDS Receivable 2019-20 | B15: 157074.42 | E15: 157074.42 | F15: 0 | G15: =+E15+F15 -> 157074.42 | H15: =VLOOKUP(A15,'TB JUNE'!A:H,8,0) -> Not Applicable
A16: TDS Receivable 2018-19 | B16: 681686 | E16: 681686 | F16: 0 | G16: =+E16+F16 -> 681686 | H16: =VLOOKUP(A16,'TB JUNE'!A:H,8,0) -> Not Applicable
A17: Tcs On Purchase 26-27 | C17: 5474.76 | E17: 5474.76 | F17: 0 | G17: =+E17+F17 -> 5474.76 | H17: Not Applicable
A18: Tcs On Purchase 25-26 | B18: 1806.82 | E18: 1806.82 | F18: 0 | G18: =+E18+F18 -> 1806.82 | H18: =VLOOKUP(A18,'TB JUNE'!A:H,8,0) -> Not Applicable
A19: TCS On Purchase 23-24 | B19: 8213.71 | E19: 8213.71 | F19: 0 | G19: =+E19+F19 -> 8213.71 | H19: =VLOOKUP(A19,'TB JUNE'!A:H,8,0) -> Not Applicable
A20: TCS On Purchase 22-23 | B20: 8936.56 | E20: 8936.56 | F20: 0 | G20: =+E20+F20 -> 8936.56 | H20: =VLOOKUP(A20,'TB JUNE'!A:H,8,0) -> Not Applicable
A21: TCS On Purchase 21-22 | B21: 196345.38 | E21: 196345.38 | F21: 0 | G21: =+E21+F21 -> 196345.38 | H21: =VLOOKUP(A21,'TB JUNE'!A:H,8,0) -> Not Applicable
A22: Licenses DFIA (Stock) | B22: -484344 | E22: -484344 | F22: 0 | G22: =+E22+F22 -> -484344 | H22: =VLOOKUP(A22,'TB JUNE'!A:H,8,0) -> Not Applicable
A23: TCS On Purchase 20-21 | B23: 473797.97 | E23: 473797.97 | F23: 0 | G23: =+E23+F23 -> 473797.97 | H23: =VLOOKUP(A23,'TB JUNE'!A:H,8,0) -> Not Applicable
A24: TCS On Purchase 19-20 | B24: 6228 | E24: 6228 | F24: 0 | G24: =+E24+F24 -> 6228 | H24: =VLOOKUP(A24,'TB JUNE'!A:H,8,0) -> Not Applicable
A25: TCS on Purchase 17-18 | B25: 650 | E25: 650 | F25: 0 | G25: =+E25+F25 -> 650 | H25: =VLOOKUP(A25,'TB JUNE'!A:H,8,0) -> Not Applicable
A26: TCS on Purchase | B26: 127789.26 | E26: 127789.26 | F26: 0 | G26: =+E26+F26 -> 127789.26 | H26: =VLOOKUP(A26,'TB JUNE'!A:H,8,0) -> Not Applicable
A27: House Rent Deposit | B27: 106300 | E27: 106300 | F27: 0 | G27: =+E27+F27 -> 106300 | H27: =VLOOKUP(A27,'TB JUNE'!A:H,8,0) -> Not Applicable
A28: Bank CA SCB 23305127882 | B28: 4.1760664e+08 | E28: 4.1760664e+08 | F28: 0 | G28: =+E28+F28 -> 4.1760664e+08 | H28: =VLOOKUP(A28,'TB JUNE'!A:H,8,0) -> Not Applicable
A29: Plastene Infrastructure Ltd | B29: -400000 | E29: -400000 | F29: 0 | G29: =+E29+F29 -> -400000 | H29: =VLOOKUP(A29,'TB JUNE'!A:H,8,0) -> Not Applicable
... A35: Security deposit- Rent | B35: 311200 | E35: 311200 | F35: 0 | G35: =+E35+F35 -> 311200 | H35: =VLOOKUP(A35,'TB JUNE'!A:H,8,0) -> Not Applicable
A36: Bank CA SBI EEFC USD 40471492269 | B36: 1.0926139e+08 | C36: 22617751 | E36: 1.3187914e+08 | F36: 0 | G36: =+E36+F36 -> 1.3187914e+08 | H36: =VLOOKUP(A36,'TB JUNE'!A:H,8,0) -> Not Applicable
A37: Bank CA SBI 31342060288 | B37: -1.4161945e+08 | E37: -1.4161945e+08 | F37: 0 | G37: =+E37+F37 -> -1.4161945e+08 | H37: =VLOOKUP(A37,'TB JUNE'!A:H,8,0) -> Not Applicable
A38: Bank CA HDFC 60330005874 | B38: -9.7321637e+08 | E38: -9.7321637e+08 | F38: 0 | G38: =+E38+F38 -> -9.7321637e+08 | H38: =VLOOKUP(A38,'TB JUNE'!A:H,8,0) -> Not Applicable
A39: Bank CA HDFC 60330005840 | B39: -33335575 | E39: -33335575 | F39: 0 | G39: =+E39+F39 -> -33335575 | H39: =VLOOKUP(A39,'TB JUNE'!A:H,8,0) -> Not Applicable
A40: Bank CA BOB 26160500000026 | B40: -3.371692e+09 | C40: 3.2011223e+08 | D40: 4.6913379e+08 | E40: -3.5207135e+09 | F40: 0 | G40: =+E40+F40 -> -3.5207135e+09 | H40: =VLOOKUP(A40,'TB JUNE'!A:H,8,0) -> Not Applicable
A41: Cash in Hand-Factory | B41: 7980.76 | C41: 840719 | D41: 813374 | E41: 35325.76 | F41: 0 | G41: =+E41+F41 -> 35325.76 | H41: =VLOOKUP(A41,'TB JUNE'!A:H,8,0) -> Not Applicable
A42: Cash in Hand-HO | B42: 4950 | D42: 808 | E42: 4142 | F42: 0 | G42: =+E42+F42 -> 4142 | H42: =VLOOKUP(A42,'TB JUNE'!A:H,8,0) -> Not Applicable
A43: RODTEP SCRIPT | C43: 888121 | D43: 850830 | E43: 37291 | F43: 0 | G43: =+E43+F43 -> 37291 | H43: =VLOOKUP(A43,'TB JUNE'!A:H,8,0) -> Not Applicable
A44: Stock In Hand- Temp Ledger | B44: 178885102 | E44: 178885102 | F44: 0 | G44: =+E44+F44 -> 178885102 | H44: =VLOOKUP(A44,'TB JUNE'!A:H,8,0) -> Not Applicable
A45: Investment In Shares Of Gopala Polyplast Limited | B45: 5000000 | E45: 5000000 | F45: 0 | G45: =+E45+F45 -> 5000000 | H45: =VLOOKUP(A45,'TB JUNE'!A:H,8,0) -> Not Applicable
...

Sheet TB AUG
B3: Plastene India Limited (Unit -II)
B4: 01-Apr-2026 31-Aug-2026
A5: Perticulars | B5: Opening | C5: Debit | D5: Credit | E5: Closing | F5: Provisin | G5: Total | H5: Group Name
A6: Duty Clearing Account | C6: 2951082 | E6: 2951082 | F6: 0 | G6: =E6+F6 -> 2951082 | H6: =VLOOKUP(A6,'TB JULY'!A:H,8,0) -> Not Applicable
A7: TCS on Purchase | B7: 127789.26 | E7: 127789.26 | F7: 0 | G7: =E7+F7 -> 127789.26 | H7: =VLOOKUP(A7,'TB JULY'!A:H,8,0) -> Not Applicable
A8: TCS on Purchase 17-18 | B8: 650 | E8: 650 | F8: 0 | G8: =E8+F8 -> 650 | H8: =VLOOKUP(A8,'TB JULY'!A:H,8,0) -> Not Applicable
A9: TCS On Purchase 19-20 | B9: 6228 | E9: 6228 | F9: 0 | G9: =E9+F9 -> 6228 | H9: =VLOOKUP(A9,'TB JULY'!A:H,8,0) -> Not Applicable
A10: TCS On Purchase 20-21 | B10: 473797.97 | E10: 473797.97 | F10: 0 | G10: =E10+F10 -> 473797.97 | H10: =VLOOKUP(A10,'TB JULY'!A:H,8,0) -> Not Applicable
A11: TCS On Purchase 21-22 | B11: 196345.38 | E11: 196345.38 | F11: 0 | G11: =E11+F11 -> 196345.38 | H11: =VLOOKUP(A11,'TB JULY'!A:H,8,0) -> Not Applicable
A12: TCS On Purchase 22-23 | B12: 8936.56 | E12: 8936.56 | F12: 0 | G12: =E12+F12 -> 8936.56 | H12: =VLOOKUP(A12,'TB JULY'!A:H,8,0) -> Not Applicable
A13: TCS On Purchase 23-24 | B13: 8213.71 | E13: 8213.71 | F13: 0 | G13: =E13+F13 -> 8213.71 | H13: =VLOOKUP(A13,'TB JULY'!A:H,8,0) -> Not Applicable
A14: Tcs On Purchase 25-26 | B14: 1806.82 | E14: 1806.82 | F14: 0 | G14: =E14+F14 -> 1806.82 | H14: =VLOOKUP(A14,'TB JULY'!A:H,8,0) -> Not Applicable
A15: Tcs On Purchase 26-27 | C15: 5474.76 | E15: 5474.76 | F15: 0 | G15: =E15+F15 -> 5474.76 | H15: =VLOOKUP(A15,'TB JULY'!A:H,8,0) -> Not Applicable
A16: TDS Receivable 2018-19 | B16: 681686 | E16: 681686 | F16: 0 | G16: =E16+F16 -> 681686 | H16: =VLOOKUP(A16,'TB JULY'!A:H,8,0) -> Not Applicable
A17: TDS Receivable 2019-20 | B17: 157074.42 | E17: 157074.42 | F17: 0 | G17: =E17+F17 -> 157074.42 | H17: =VLOOKUP(A17,'TB JULY'!A:H,8,0) -> Not Applicable
A18: TDS Receivable 2020-21 | B18: 167632.97 | E18: 167632.97 | F18: 0 | G18: =E18+F18 -> 167632.97 | H18: =VLOOKUP(A18,'TB JULY'!A:H,8,0) -> Not Applicable
A19: TDS Receivable 2021-22 | B19: 256416 | E19: 256416 | F19: 0 | G19: =E19+F19 -> 256416 | H19: =VLOOKUP(A19,'TB JULY'!A:H,8,0) -> Not Applicable
A20: TDS Receivable 2022-23 | B20: 822958.41 | E20: 822958.41 | F20: 0 | G20: =E20+F20 -> 822958.41 | H20: =VLOOKUP(A20,'TB JULY'!A:H,8,0) -> Not Applicable
A21: TDS Receivable 2023-24 | B21: 723178.82 | E21: 723178.82 | F21: 0 | G21: =E21+F21 -> 723178.82 | H21: =VLOOKUP(A21,'TB JULY'!A:H,8,0) -> Not Applicable
A22: Tds Receivable 2024-25 | B22: 753208.69 | E22: 753208.69 | F22: 0 | G22: =E22+F22 -> 753208.69 | H22: =VLOOKUP(A22,'TB JULY'!A:H,8,0) -> Not Applicable
A23: Tds Receivable 2025-26 | B23: 2359808.6 | C23: 4194 | E23: 2364002.6 | F23: 0 | G23: =E23+F23 -> 2364002.6 | H23: =VLOOKUP(A23,'TB JULY'!A:H,8,0) -> Not Applicable
A24: Tds Receivable 2026-27 | C24: 1127199.2 | D24: 48.2 | E24: 1127151 | F24: 0 | G24: =E24+F24 -> 1127151 | H24: =VLOOKUP(A24,'TB JULY'!A:H,8,0) -> Not Applicable
A25: Bank CA BOB 26160500000026 | B25: -3.371692e+09 | C25: 3.7296058e+08 | D25: 5.9657039e+08 | E25: -3.5953018e+09 | F25: 0 | G25: =E25+F25 -> -3.5953018e+09 | H25: =VLOOKUP(A25,'TB JULY'!A:H,8,0) -> Not Applicable
A26: Bank CA HDFC 60330005840 | B26: -33335575 | E26: -33335575 | F26: 0 | G26: =E26+F26 -> -33335575 | H26: =VLOOKUP(A26,'TB JULY'!A:H,8,0) -> Not Applicable
A27: Bank CA HDFC 60330005874 | B27: -9.7321637e+08 | E27: -9.7321637e+08 | F27: 0 | G27: =E27+F27 -> -9.7321637e+08 | H27: =VLOOKUP(A27,'TB JULY'!A:H,8,0) -> Not Applicable
A28: Bank CA SBI 31342060288 | B28: -1.4161945e+08 | E28: -1.4161945e+08 | F28: 0 | G28: =E28+F28 -> -1.4161945e+08 | H28: =VLOOKUP(A28,'TB JULY'!A:H,8,0) -> Not Applicable
A29: Bank CA SBI EEFC USD 40471492269 | B29: 1.0926139e+08 | C29: 22617751 | E29: 1.3187914e+08 | F29: 0 | G29: =E29+F29 -> 1.3187914e+08 | H29: =VLOOKUP(A29,'TB JULY'!A:H,8,0) -> Not Applicable
A30: Bank CA SCB 23305127882 | B30: 4.1760664e+08 | E30: 4.1760664e+08 | F30: 0 | G30: =E30+F30 -> 4.1760664e+08 | H30: =VLOOKUP(A30,'TB JULY'!A:H,8,0) -> Not Applicable
A31: Bank CA SCB 23305216958 | B31: -1.5436525e+08 | E31: -1.5436525e+08 | F31: 0 | G31: =E31+F31 -> -1.5436525e+08 | H31: =VLOOKUP(A31,'TB JULY'!A:H,8,0) -> Not Applicable
A32: Bank CA SCB 23391238420 | B32: 1070438.6 | E32: 1070438.6 | F32: 0 | G32: =E32+F32 -> 1070438.6 | H32: =VLOOKUP(A32,'TB JULY'!A:H,8,0) -> Not Applicable
A33: Bank EEFC SCB 23305153697 | B33: 6687573.3 | E33: 6687573.3 | F33: 0 | G33: =E33+F33 -> 6687573.3 | H33: =VLOOKUP(A33,'TB JULY'!A:H,8,0) -> Not Applicable
A34: Cash in Hand-Factory | B34: 7980.76 | C34: 1157169 | D34: 1065936 | E34: 99213.76 | F34: 0 | G34: =E34+F34 -> 99213.76 | H34: =VLOOKUP(A34,'TB JULY'!A:H,8,0) -> Not Applicable
A35: Cash in Hand-HO | B35: 4950 | D35: 808 | E35: 4142 | F35: 0 | G35: =E35+F35 -> 4142 | H35: =VLOOKUP(A35,'TB JULY'!A:H,8,0) -> Not Applicable
A36: Stock In Hand- Temp Ledger | B36: 178885102 | E36: 178885102 | F36: 0 | G36: =E36+F36 -> 178885102 | H36: =VLOOKUP(A36,'TB JULY'!A:H,8,0) -> Not Applicable
A37: Investment In Shares Of Gopala Polyplast Limited | B37: 5000000 | E37: 5000000 | F37: 0 | G37: =E37+F37 -> 5000000 | H37: =VLOOKUP(A37,'TB JULY'!A:H,8,0) -> Not Applicable
A38: Licenses MEIS (Stock) | B38: -2993657.1 | E38: -2993657.1 | F38: 0 | G38: =E38+F38 -> -2993657.1 | H38: =VLOOKUP(A38,'TB JULY'!A:H,8,0) -> Not Applicable
A39: RoDtep Receivable | C39: 888121 | E39: 888121 | F39: 0 | G39: =E39+F39 -> 888121 | H39: Not Applicable
A40: CGST Input | B40: 0.01 | C40: 32619228 | D40: 26765931 | E40: 5853297.8 | F40: 0 | G40: =E40+F40 -> 5853297.8 | H40: =VLOOKUP(A40,'TB JULY'!A:H,8,0) -> Not Applicable
A41: GST Credit-Non Eligible | C41: 49823.9 | D41: 49823.9 | F41: 0 | G41: =E41+F41 -> 0 | H41: =VLOOKUP(A41,'TB JULY'!A:H,8,0) -> Not Applicable
A42: IGST Input | B42: 0.04 | C42: 4689661.1 | D42: 4037307.6 | E42: 652353.54 | F42: 0 | G42: =E42+F42 -> 652353.54 | H42: =VLOOKUP(A42,'TB JULY'!A:H,8,0) -> Not Applicable
...
