Workbook

Sheet ERP Data
C1: 1 | D1: 2 | E1: 3 | F1: 4 | G1: 5 | H1: 6 | I1: 7 | J1: 8 | K1: 9 | L1: 10 | M1: 11 | N1: 12 | O1: 13 | P1: 14 | Q1: 15 | R1: 16 | S1: 17 | T1: 18 | U1: 19 | V1: 20 | W1: 21 | X1: 22 | Y1: 23 | Z1: 24 | AA1: 25
A2: CompanyName | B2: MainGroup | C2: SubGroupName | D2: Op.Factory Owned | E2: Op.Factory JW (Others) | F2: Op.At JW (Own) | G2: Branch Tfr Recd | H2: Purchase | I2: Warehouse Inwards | J2: Recd from JW (Own) | K2: Recd For JW (Others) | L2: Sales | M2: Br Transfer Sent | N2: Sent for JW (Own) | O2: Return JW(Others) | P2: Total Production Own+JW | Q2: Total Consumption Own+JW | R2: Production at JW | S2: Consumption At JW | T2: Production Of JW | U2: Consumption Of JW | V2: Stock Adjustment Entry | W2: Net Production Own | X2: Net Consumption Own | Y2: Cl.Factory Owned | Z2: Cl.Factory JW (Others) | AA2: Cl.At JW (Own)
A3: K.P. WOVEN PRIVATE LIMITED | B3: RM | C3: FIBC Accessories | D3: 13723.2 | E3: 0 | F3: 0 | G3: 0 | H3: 1699.3 | I3: 0 | J3: 0 | K3: 0 | L3: 203.5 | M3: 0 | N3: 0 | O3: 0 | P3: 0 | Q3: 0 | R3: 0 | S3: 0 | T3: 0 | U3: 0 | V3: 0 | W3: 0 | X3: 0 | Y3: 15219 | Z3: 0 | AA3: 0
A4: K.P. WOVEN PRIVATE LIMITED | B4: RM | C4: Filler | D4: 9644.448 | E4: 0 | F4: 35 | G4: 0 | H4: 30000 | I4: 0 | J4: 0 | K4: 0 | L4: 0 | M4: 0 | N4: 140 | O4: 0 | P4: 0 | Q4: 16902.86 | R4: 0 | S4: 121.17 | T4: 0 | U4: 0 | V4: 0 | W4: 0 | X4: 16902.86 | Y4: 22601.588 | Z4: 0 | AA4: 53.83
A5: K.P. WOVEN PRIVATE LIMITED | B5: RM | C5: LDPE Granules | D5: -25907.87 | E5: 100500 | F5: 18 | G5: 0 | H5: 0 | I5: 0 | J5: 0 | K5: 0 | L5: 0 | M5: 0 | N5: 0 | O5: 0 | P5: 0 | Q5: 8480.8 | R5: 0 | S5: 0 | T5: 0 | U5: 1924.4 | V5: 0 | W5: 0 | X5: 6556.4 | Y5: -32464.27 | Z5: 98575.6 | AA5: 18
A6: K.P. WOVEN PRIVATE LIMITED | B6: RM | C6: LLDPE Granules | D6: 6669.387 | E6: 87401.23 | F6: 2666.8 | G6: 0 | H6: 33000 | I6: 0 | J6: 0 | K6: 0 | L6: 0 | M6: 0 | N6: 0 | O6: 0 | P6: 0 | Q6: 19671.74 | R6: 0 | S6: 0 | T6: 0 | U6: 0 | V6: 0 | W6: 0 | X6: 19671.74 | Y6: 19997.647 | Z6: 87401.23 | AA6: 2666.8
A7: K.P. WOVEN PRIVATE LIMITED | B7: RM | C7: Masterbatch | D7: 4286.33 | E7: 0 | F7: 0 | G7: 0 | H7: 3000 | I7: 0 | J7: 0 | K7: 0 | L7: 585 | M7: 0 | N7: 0 | O7: 0 | P7: 0 | Q7: 2082.22 | R7: 0 | S7: 0 | T7: 0 | U7: 0 | V7: 0 | W7: 0 | X7: 2082.22 | Y7: 4619.11 | Z7: 0 | AA7: 0
A8: K.P. WOVEN PRIVATE LIMITED | B8: RM | C8: PP Granules | D8: -57419 | E8: 345682.6 | F8: 135921.79 | G8: 0 | H8: 666050 | I8: 0 | J8: 1500 | K8: 93267 | L8: 337250 | M8: 0 | N8: 6685 | O8: 133500 | P8: 0 | Q8: 440267.2 | R8: 1500 | S8: 62675.73 | T8: 0 | U8: 64245.8 | V8: 0 | W8: 0 | X8: 376021.4 | Y8: -109825.4 | Z8: 241203.8 | AA8: 79931.06
A9: K.P. WOVEN PRIVATE LIMITED | B9: RM | C9: UV MB | D9: 9810.977 | E9: 33000.2 | F9: 67 | G9: 0 | H9: 5100 | I9: 0 | J9: 0 | K9: 2000 | L9: 0 | M9: 0 | N9: 175 | O9: 0 | P9: 0 | Q9: 13476.49 | R9: 0 | S9: 147.64 | T9: 0 | U9: 0 | V9: 0 | W9: 0 | X9: 13476.49 | Y9: 1259.487 | Z9: 35000.2 | AA9: 94.36
A10: K.P. WOVEN PRIVATE LIMITED | B10: SF | C10: HD Lam Fabric | D10: 8302.1 | E10: 0 | F10: 0 | G10: 0 | H10: 1166 | I10: 0 | J10: 0 | K10: 0 | L10: 0 | M10: 0 | N10: 0 | O10: 0 | P10: 0 | Q10: 0 | R10: 0 | S10: 0 | T10: 0 | U10: 0 | V10: 0 | W10: 0 | X10: 0 | Y10: 9468.1 | Z10: 0 | AA10: 0
A11: K.P. WOVEN PRIVATE LIMITED | B11: SF | C11: HD UL Fabric | D11: 5296.7 | E11: 0 | F11: 0 | G11: 0 | H11: 2268.7 | I11: 0 | J11: 7077.4 | K11: 0 | L11: 0 | M11: 0 | N11: 0 | O11: 0 | P11: 9222.9 | Q11: 8182.3 | R11: 7077.4 | S11: 0 | T11: 0 | U11: 0 | V11: 0 | W11: 9222.9 | X11: 8182.3 | Y11: 15683.4 | Z11: 0 | AA11: 0
A12: K.P. WOVEN PRIVATE LIMITED | B12: SF | C12: LDPE/LLDPE Bags | D12: 295706.26 | E12: 0 | F12: 0 | G12: 0 | H12: 39998.89 | I12: 0 | J12: 0 | K12: 0 | L12: 529 | M12: 0 | N12: 0 | O12: 0 | P12: 0 | Q12: 0 | R12: 0 | S12: 0 | T12: 0 | U12: 0 | V12: 0 | W12: 0 | X12: 0 | Y12: 335176.15 | Z12: 0 | AA12: 0
A13: K.P. WOVEN PRIVATE LIMITED | B13: SF | C13: PE Film | D13: -17219.6 | E13: 0 | F13: 0 | G13: 0 | H13: 605 | I13: 0 | J13: 0 | K13: 0 | L13: 0 | M13: 0 | N13: 0 | O13: 0 | P13: 0 | Q13: 0 | R13: 0 | S13: 0 | T13: 0 | U13: 0 | V13: 0 | W13: 0 | X13: 0 | Y13: -16614.6 | Z13: 0 | AA13: 0
A14: K.P. WOVEN PRIVATE LIMITED | B14: SF | C14: Polyester Yarn | D14: 4075.56 | E14: 0 | F14: 0 | G14: 0 | H14: 1550.3 | I14: 0 | J14: 0 | K14: 0 | L14: 212 | M14: 0 | N14: 0 | O14: 0 | P14: 0 | Q14: 0 | R14: 0 | S14: 0 | T14: 0 | U14: 0 | V14: 0 | W14: 0 | X14: 0 | Y14: 5413.86 | Z14: 0 | AA14: 0
... A27: K.P. WOVEN PRIVATE LIMITED | B27: FG | C27: Trading Items | D27: 7.3 | E27: 0 | F27: 0 | G27: 0 | H27: 0 | I27: 0 | J27: 0 | K27: 0 | L27: 0 | M27: 0 | N27: 0 | O27: 0 | P27: 0 | Q27: 0 | R27: 0 | S27: 0 | T27: 0 | U27: 0 | V27: 0 | W27: 0 | X27: 0 | Y27: 7.3 | Z27: 0 | AA27: 0
A28: Total | C28: 0 | D28: 1843054.9 | E28: 570835.75 | F28: 167448.64 | G28: 0 | H28: 1420068.1 | I28: 0 | J28: 73596.33 | K28: 95438.55 | L28: 1283156.1 | M28: 0 | N28: 20775.12 | O28: 199752.51 | P28: 2541871.9 | Q28: 2541402.9 | R28: 73596.33 | S28: 73596.33 | T28: 66170.2 | U28: 66170.2 | V28: 0 | W28: 2475701.7 | X28: 2475232.7 | Y28: 2033257.2 | Z28: 466521.79 | AA28: 114627.43
A29: K.P. WOVEN PRIVATE LIMITED | B29: RM Consumables | C29: FIBC Accessories | D29: 6875.735 | E29: 0 | F29: 0 | G29: 0 | H29: 467.1 | I29: 0 | J29: 0 | K29: 0 | L29: 0 | M29: 0 | N29: 0 | O29: 0 | P29: 0 | Q29: 0 | R29: 0 | S29: 0 | T29: 0 | U29: 0 | V29: 0 | W29: 0 | X29: 0 | Y29: 7342.835 | Z29: 0 | AA29: 0
A30: K.P. WOVEN PRIVATE LIMITED | B30: RM Consumables | C30: Ink | D30: 2600 | E30: 0 | F30: 0 | G30: 0 | H30: 250 | I30: 0 | J30: 0 | K30: 0 | L30: 25 | M30: 0 | N30: 0 | O30: 0 | P30: 0 | Q30: 0 | R30: 0 | S30: 0 | T30: 0 | U30: 0 | V30: 0 | W30: 0 | X30: 0 | Y30: 2825 | Z30: 0 | AA30: 0
A31: K.P. WOVEN PRIVATE LIMITED | B31: RM Consumables | C31: Thinner | D31: 12240 | E31: 0 | F31: 0 | G31: 0 | H31: 2550 | I31: 0 | J31: 0 | K31: 0 | L31: 680 | M31: 0 | N31: 0 | O31: 0 | P31: 0 | Q31: 0 | R31: 0 | S31: 0 | T31: 0 | U31: 0 | V31: 0 | W31: 0 | X31: 0 | Y31: 14110 | Z31: 0 | AA31: 0
A32: Total | C32: 0 | D32: 21715.735 | E32: 0 | F32: 0 | G32: 0 | H32: 3267.1 | I32: 0 | J32: 0 | K32: 0 | L32: 705 | M32: 0 | N32: 0 | O32: 0 | P32: 0 | Q32: 0 | R32: 0 | S32: 0 | T32: 0 | U32: 0 | V32: 0 | W32: 0 | X32: 0 | Y32: 24277.835 | Z32: 0 | AA32: 0

Sheet July - 26
B1: 46204
B2: 1 | C2: 2 | D2: 3 | E2: 4 | F2: 5 | G2: 6 | H2: 7 | I2: 8 | J2: 9 | K2: 10 | L2: 11 | M2: 12 | N2: 13 | O2: 14 | P2: 15 | Q2: 16 | R2: 17 | S2: 18 | T2: 19 | U2: 20 | V2: 21 | W2: 22 | X2: 23 | Y2: 24 | Z2: 25 | AA2: 26 | AB2: 27 | AC2: 28 | AD2: 29 | AE2: 30 | AF2: 31
B3: SubGroupName | C3: Op.Factory Owned | D3: Op.Factory JW (Others) | E3: Op.At JW (Own) | F3: Branch Tfr Recd | G3: Purchase | H3: Warehouse Inwards | I3: Recd from JW (Own) | J3: Recd For JW (Others) | K3: Sales | L3: Br Transfer Sent | M3: Sent for JW (Own) | N3: Return JW(Others) | O3: Total Production Own+JW | P3: Total Consumption Own+JW | Q3: Production at JW | R3: Consumption At JW | S3: Production Of JW | T3: Consumption Of JW | U3: Stock Adjustment Entry | V3: Net Production Own | W3: Net Consumption Own | X3: Cl.Factory Owned | Y3: Cl.Factory JW (Others) | Z3: Cl.At JW (Own) | AA3: RATE CONSIDER | AB3: RATE | AC3: CLOSING AMOUNT FACTORY | AD3: CLOSING AMOUNT JOB OWN | AE3: VALUE
A5: MainGroup | B5: SubGroupName | C5: Op.Factory Owned | D5: Op.Factory JW (Others) | E5: Op.At JW (Own) | F5: Branch Tfr Recd | G5: Purchase | H5: Warehouse Inwards | I5: Recd from JW (Own) | J5: Recd For JW (Others) | K5: Sales | L5: Br Transfer Sent | M5: Sent for JW (Own) | N5: Return JW(Others) | O5: Total Production Own+JW | P5: Total Consumption Own+JW | Q5: Production at JW | R5: Consumption At JW | S5: Production Of JW | T5: Consumption Of JW | U5: Stock Adjustment Entry | V5: Net Production Own | W5: Net Consumption Own | X5: Cl.Factory Owned | Y5: Cl.Factory JW (Others) | Z5: Cl.At JW (Own) | AA5: RATE CONSIDER | AB5: RATE | AC5: CLOSING AMOUNT FACTORY | AD5: CLOSING AMOUNT JOB OWN | AE5: VALUE
A6: RM | B6: FIBC Accessories | C6: 13506.2 | D6: 0 | E6: 0 | F6: 0 | G6: 1699.3 | H6: 0 | I6: 0 | J6: 0 | K6: 203.5 | L6: 0 | M6: 0 | N6: 0 | O6: 0 | P6: 0 | Q6: 0 | R6: 0 | S6: 0 | T6: 0 | U6: 0 | V6: =O6-S6 -> 0 | W6: =P6-T6 -> 0 | X6: =C6+F6+G6+I6-K6-L6-M6-W6+V6 -> 15002 | Y6: =D6+J6-N6+S6-T6 -> 0 | Z6: =E6-I6+M6+Q6-R6 -> 0 | AA6: PURCHASE | AB6: =Purchase!AP869 -> 150 | AC6: =X6*AB6 -> 2250300 | AD6: =Z6*AB6 -> 0
A7: RM | B7: Filler | C7: 9644.34 | D7: 0 | E7: -19.4 | F7: 0 | G7: 30000 | H7: 0 | I7: 0 | J7: 0 | K7: 0 | L7: 0 | M7: 140 | N7: 0 | O7: 0 | P7: 16902.86 | Q7: 0 | R7: 121.17 | S7: 0 | T7: 0 | U7: 0 | V7: =O7-S7 -> 0 | W7: =P7-T7 -> 16902.86 | X7: =C7+F7+G7+I7-K7-L7-M7-W7+V7 -> 22601.48 | Y7: =D7+J7-N7+S7-T7 -> 0 | Z7: =E7-I7+M7+Q7-R7 -> -0.57 | AA7: PURCHASE | AB7: =Purchase!AP871 -> 38 | AC7: =X7*AB7 -> 858856.24 | AD7: =Z7*AB7 -> -21.66
A8: RM | B8: HDPE Granules | C8: -100 | D8: 0 | E8: 0 | F8: 0 | G8: 0 | H8: 0 | I8: 0 | J8: 0 | K8: 0 | L8: 0 | M8: 0 | N8: 0 | O8: 0 | P8: 0 | Q8: 0 | R8: 0 | S8: 0 | T8: 0 | U8: 0 | V8: =O8-S8 -> 0 | W8: =P8-T8 -> 0 | X8: =C8+F8+G8+I8-K8-L8-M8-W8+V8 -> -100 | Y8: =D8+J8-N8+S8-T8 -> 0 | Z8: =E8-I8+M8+Q8-R8 -> 0 | AA8: PURCHASE | AB8: 120 | AC8: =X8*AB8 -> -12000 | AD8: =Z8*AB8 -> 0
A9: RM | B9: LDPE Granules | C9: -25907.87 | D9: 89488.87 | E9: 0 | F9: 0 | G9: 0 | H9: 0 | I9: 0 | J9: 0 | K9: 0 | L9: 0 | M9: 0 | N9: 0 | O9: 0 | P9: 8480.8 | Q9: 0 | R9: 0 | S9: 0 | T9: 1924.4 | U9: 0 | V9: =O9-S9 -> 0 | W9: =P9-T9 -> 6556.4 | X9: =C9+F9+G9+I9-K9-L9-M9-W9+V9 -> -32464.27 | Y9: =D9+J9-N9+S9-T9 -> 87564.47 | Z9: =E9-I9+M9+Q9-R9 -> 0 | AA9: PURCHASE | AB9: 180.76 | AC9: =X9*AB9 -> -5868241.4 | AD9: =Z9*AB9 -> 0
A10: RM | B10: LLDPE Granules | C10: 6669.3 | D10: 36557.3 | E10: 0 | F10: 0 | G10: 33000 | H10: 0 | I10: 0 | J10: 0 | K10: 0 | L10: 0 | M10: 0 | N10: 0 | O10: 0 | P10: 19671.74 | Q10: 0 | R10: 0 | S10: 0 | T10: 0 | U10: 0 | V10: =O10-S10 -> 0 | W10: =P10-T10 -> 19671.74 | X10: =C10+F10+G10+I10-K10-L10-M10-W10+V10 -> 19997.56 | Y10: =D10+J10-N10+S10-T10 -> 36557.3 | Z10: =E10-I10+M10+Q10-R10 -> 0 | AA10: PURCHASE | AB10: =Purchase!AP875 -> 125.52121 | AC10: =X10*AB10 -> 2510118 | AD10: =Z10*AB10 -> 0
A11: RM | B11: Masterbatch | C11: 4286.33 | D11: 0 | E11: 0 | F11: 0 | G11: 3000 | H11: 0 | I11: 0 | J11: 0 | K11: 585 | L11: 0 | M11: 0 | N11: 0 | O11: 0 | P11: 2082.22 | Q11: 0 | R11: 0 | S11: 0 | T11: 0 | U11: 0 | V11: =O11-S11 -> 0 | W11: =P11-T11 -> 2082.22 | X11: =C11+F11+G11+I11-K11-L11-M11-W11+V11 -> 4619.11 | Y11: =D11+J11-N11+S11-T11 -> 0 | Z11: =E11-I11+M11+Q11-R11 -> 0 | AA11: PURCHASE | AB11: =Purchase!AP876 -> 227.41183 | AC11: =X11*AB11 -> 1050440.3 | AD11: =Z11*AB11 -> 0
A12: RM | B12: PP Granules | C12: -57419 | D12: 336200.27 | E12: 135860.59 | F12: 0 | G12: 666050 | H12: 0 | I12: 1500 | J12: 93267 | K12: 337250 | L12: 0 | M12: 6685 | N12: 133500 | O12: 0 | P12: 440267.2 | Q12: 1500 | R12: 62675.73 | S12: 0 | T12: 64245.8 | U12: 0 | V12: =O12-S12 -> 0 | W12: =P12-T12 -> 376021.4 | X12: =C12+F12+G12+I12-K12-L12-M12-W12+V12 -> -109825.4 | Y12: =D12+J12-N12+S12-T12 -> 231721.47 | Z12: =E12-I12+M12+Q12-R12 -> 79869.86 | AA12: PURCHASE | AB12: =Purchase!AP881 -> 83.069598 | AC12: =X12*AB12 -> -9123151.8 | AD12: =Z12*AB12 -> 6634757.1
A13: RM | B13: UV MB | C13: 9810.9 | D13: 34064.2 | E13: 102.4 | F13: 0 | G13: 5100 | H13: 0 | I13: 0 | J13: 2000 | K13: 0 | L13: 0 | M13: 175 | N13: 0 | O13: 0 | P13: 13476.49 | Q13: 0 | R13: 147.64 | S13: 0 | T13: 0 | U13: 0 | V13: =O13-S13 -> 0 | W13: =P13-T13 -> 13476.49 | X13: =C13+F13+G13+I13-K13-L13-M13-W13+V13 -> 1259.41 | Y13: =D13+J13-N13+S13-T13 -> 36064.2 | Z13: =E13-I13+M13+Q13-R13 -> 129.76 | AA13: PURCHASE | AB13: =Purchase!AP886 -> 240 | AC13: =X13*AB13 -> 302258.4 | AD13: =Z13*AB13 -> 31142.4
A14: SF | B14: Films All | C14: -917.5 | D14: 0 | E14: 0 | F14: 0 | G14: 0 | H14: 0 | I14: 0 | J14: 0 | K14: 0 | L14: 0 | M14: 0 | N14: 0 | O14: 0 | P14: 0 | Q14: 0 | R14: 0 | S14: 0 | T14: 0 | U14: 0 | V14: =O14-S14 -> 0 | W14: =P14-T14 -> 0 | X14: =C14+F14+G14+I14-K14-L14-M14-W14+V14 -> -917.5 | Y14: =D14+J14-N14+S14-T14 -> 0 | Z14: =E14-I14+M14+Q14-R14 -> 0 | AB14: 158.62 | AC14: =X14*AB14 -> -145533.85 | AD14: =Z14*AB14 -> 0
A15: SF | B15: HD Lam Fabric | C15: 8302 | D15: 0 | E15: 0 | F15: 0 | G15: 1166 | H15: 0 | I15: 0 | J15: 0 | K15: 0 | L15: 0 | M15: 0 | N15: 0 | O15: 0 | P15: 0 | Q15: 0 | R15: 0 | S15: 0 | T15: 0 | U15: 0 | V15: =O15-S15 -> 0 | W15: =P15-T15 -> 0 | X15: =C15+F15+G15+I15-K15-L15-M15-W15+V15 -> 9468 | Y15: =D15+J15-N15+S15-T15 -> 0 | Z15: =E15-I15+M15+Q15-R15 -> 0 | AA15: PP+20 | AB15: =+AB12+20 -> 103.0696 | AC15: =X15*AB15 -> 975862.95 | AD15: =Z15*AB15 -> 0
A16: SF | B16: HD UL Fabric | C16: 1834.2 | D16: 0 | E16: 0 | F16: 0 | G16: 2268.7 | H16: 0 | I16: 7077.4 | J16: 0 | K16: 0 | L16: 0 | M16: 0 | N16: 0 | O16: 0 | P16: 8182.3 | Q16: 7077.4 | R16: 0 | S16: 0 | T16: 0 | U16: 0 | V16: =O16-S16 -> 0 | W16: =P16-T16 -> 8182.3 | X16: =C16+F16+G16+I16-K16-L16-M16-W16+V16 -> 2998 | Y16: =D16+J16-N16+S16-T16 -> 0 | Z16: =E16-I16+M16+Q16-R16 -> -9.094947e-13 | AA16: PP+20 | AB16: =+AB12+20 -> 103.0696 | AC16: =X16*AB16 -> 309002.65 | AD16: =Z16*AB16 -> -9.3741253e-11
A17: SF | B17: LDPE/LLDPE Bags | C17: 292265.74 | D17: 0 | E17: 0 | F17: 0 | G17: 39518.33 | H17: 0 | I17: 0 | J17: 0 | K17: 529 | L17: 0 | M17: 0 | N17: 0 | O17: 0 | P17: 0 | Q17: 0 | R17: 0 | S17: 0 | T17: 0 | U17: 0 | V17: =O17-S17 -> 0 | W17: =P17-T17 -> 0 | X17: =C17+F17+G17+I17-K17-L17-M17-W17+V17 -> 331255.07 | Y17: =D17+J17-N17+S17-T17 -> 0 | Z17: =E17-I17+M17+Q17-R17 -> 0 | AA17: PURCHASE | AB17: =Purchase!AP874 -> 208.72229 | AC17: =X17*AB17 -> 69140316 | AD17: =Z17*AB17 -> 0
A18: SF | B18: PE Film | C18: 59998.01 | D18: 0 | E18: 0 | F18: 0 | G18: 605 | H18: 0 | I18: 0 | J18: 0 | K18: 0 | L18: 0 | M18: 0 | N18: 0 | O18: 0 | P18: 0 | Q18: 0 | R18: 0 | S18: 0 | T18: 0 | U18: 0 | V18: =O18-S18 -> 0 | W18: =P18-T18 -> 0 | X18: =C18+F18+G18+I18-K18-L18-M18-W18+V18 -> 60603.01 | Y18: =D18+J18-N18+S18-T18 -> 0 | Z18: =E18-I18+M18+Q18-R18 -> 0 | AA18: PURCHASE | AB18: =Purchase!AP878 -> 169.2957 | AC18: =X18*AB18 -> 10259829 | AD18: =Z18*AB18 -> 0
A19: SF | B19: Polyester Yarn | C19: 4075.56 | D19: 0 | E19: 0 | F19: 0 | G19: 1550.3 | H19: 0 | I19: 0 | J19: 0 | K19: 212 | L19: 0 | M19: 0 | N19: 0 | O19: 0 | P19: 0 | Q19: 0 | R19: 0 | S19: 0 | T19: 0 | U19: 0 | V19: =O19-S19 -> 0 | W19: =P19-T19 -> 0 | X19: =C19+F19+G19+I19-K19-L19-M19-W19+V19 -> 5413.86 | Y19: =D19+J19-N19+S19-T19 -> 0 | Z19: =E19-I19+M19+Q19-R19 -> 0 | AB19: =Purchase!AP879 -> 182 | AC19: =X19*AB19 -> 985322.52 | AD19: =Z19*AB19 -> 0 | AE19: =X19*132 -> 714629.52
A20: SF | B20: PP Lam Fabric | C20: -99648.6 | D20: 0 | E20: 2217 | F20: 0 | G20: 55701.8 | H20: 0 | I20: 4759.7 | J20: 0 | K20: 31728.4 | L20: 0 | M20: 0 | N20: 0 | O20: 246154 | P20: 245908.6 | Q20: 4759.7 | R20: 0 | S20: 0 | T20: 0 | U20: 0 | V20: =O20-S20 -> 246154 | W20: =P20-T20 -> 245908.6 | X20: =C20+F20+G20+I20-K20-L20-M20-W20+V20 -> -70670.1 | Y20: =D20+J20-N20+S20-T20 -> 0 | Z20: =E20-I20+M20+Q20-R20 -> 2217 | AA20: ULF+5 | AB20: =+AB22+5 -> 108.0696 | AC20: =X20*AB20 -> -7637289.3 | AD20: =Z20*AB20 -> 239590.3
A21: SF | B21: PP Tapes | C21: 107725.5 | D21: 0 | E21: 0 | F21: 0 | G21: 0 | H21: 0 | I21: 0 | J21: 0 | K21: 0 | L21: 0 | M21: 0 | N21: 0 | O21: 470958.48 | P21: 383734.2 | Q21: 0 | R21: 0 | S21: 0 | T21: 0 | U21: 0 | V21: =O21-S21 -> 470958.48 | W21: =P21-T21 -> 383734.2 | X21: =C21+F21+G21+I21-K21-L21-M21-W21+V21 -> 194949.78 | Y21: =D21+J21-N21+S21-T21 -> 0 | Z21: =E21-I21+M21+Q21-R21 -> 0 | AA21: pp+10 | AB21: =+AB12+10 -> 93.069598 | AC21: =X21*AB21 -> 18143898 | AD21: =Z21*AB21 -> 0
A22: SF | B22: PP UL Fabric | C22: 652256.18 | D22: 11420 | E22: 71222.2 | F22: 0 | G22: 191637.66 | H22: 0 | I22: 50226.04 | J22: 0 | K22: 77733.5 | L22: 0 | M22: 0 | N22: 2484.8 | O22: 273437.2 | P22: 468444.44 | Q22: 50226.04 | R22: 0 | S22: 2484.8 | T22: 0 | U22: 0 | V22: =O22-S22 -> 270952.4 | W22: =P22-T22 -> 468444.44 | X22: =C22+F22+G22+I22-K22-L22-M22-W22+V22 -> 618894.34 | Y22: =D22+J22-N22+S22-T22 -> 11420 | Z22: =E22-I22+M22+Q22-R22 -> 71222.2 | AA22: pp+20 | AB22: =+AB12+20 -> 103.0696 | AC22: =X22*AB22 -> 63789191 | AD22: =Z22*AB22 -> 7340843.5
A23: SF | B23: PP Webbing | C23: 205768.5 | D23: 0 | E23: 5777 | F23: 0 | G23: 9180.6 | H23: 0 | I23: 0 | J23: 0 | K23: 30916.1 | L23: 0 | M23: 0 | N23: 0 | O23: 107879 | P23: 8048 | Q23: 0 | R23: 0 | S23: 0 | T23: 0 | U23: 0 | V23: =O23-S23 -> 107879 | W23: =P23-T23 -> 8048 | X23: =C23+F23+G23+I23-K23-L23-M23-W23+V23 -> 283864 | Y23: =D23+J23-N23+S23-T23 -> 0 | Z23: =E23-I23+M23+Q23-R23 -> 5777 | AA23: pp+20 | AB23: =+AB12+20 -> 103.0696 | AC23: =X23*AB23 -> 29257748 | AD23: =Z23*AB23 -> 595433.07
A24: SF | B24: PP Yarn | C24: 104536.52 | D24: 180.67 | E24: 8757.32 | F24: 0 | G24: 39194.36 | H24: 0 | I24: 9562.39 | J24: 171.55 | K24: 62955.3 | L24: 0 | M24: 13775.12 | N24: 82.31 | O24: 2598 | P24: 15631 | Q24: 9562.39 | R24: 10651.79 | S24: 0 | T24: 0 | U24: 0 | V24: =O24-S24 -> 2598 | W24: =P24-T24 -> 15631 | X24: =C24+F24+G24+I24-K24-L24-M24-W24+V24 -> 63529.85 | Y24: =D24+J24-N24+S24-T24 -> 269.91 | Z24: =E24-I24+M24+Q24-R24 -> 11880.65 | AA24: PURCHASE | AB24: =Purchase!AP885 -> 161.24086 | AC24: =X24*AB24 -> 10243608 | AD24: =Z24*AB24 -> 1915646.3
A25: SF | B25: RP Granules | C25: 55735.3 | D25: -449 | E25: 0 | F25: 0 | G25: 0 | H25: 0 | I25: 0 | J25: 0 | K25: 19000 | L25: 0 | M25: 0 | N25: 0 | O25: 58880 | P25: 29350.67 | Q25: 0 | R25: 0 | S25: 0 | T25: 0 | U25: 0 | V25: =O25-S25 -> 58880 | W25: =P25-T25 -> 29350.67 | X25: =C25+F25+G25+I25-K25-L25-M25-W25+V25 -> 66264.63 | Y25: =D25+J25-N25+S25-T25 -> -449 | Z25: =E25-I25+M25+Q25-R25 -> 0 | AA25: 65 | AB25: 65 | AC25: =X25*AB25 -> 4307201 | AD25: =Z25*AB25 -> 0
A26: SF | B26: Wastage/Scrap | C26: 100459.35 | D26: 0 | E26: 24132 | F26: 0 | G26: 0 | H26: 0 | I26: 470.8 | J26: 0 | K26: 9300 | L26: 0 | M26: 0 | N26: 0 | O26: 110196.6 | P26: 59325 | Q26: 470.8 | R26: 0 | S26: 0 | T26: 0 | U26: 0 | V26: =O26-S26 -> 110196.6 | W26: =P26-T26 -> 59325 | X26: =C26+F26+G26+I26-K26-L26-M26-W26+V26 -> 142501.75 | Y26: =D26+J26-N26+S26-T26 -> 0 | Z26: =E26-I26+M26+Q26-R26 -> 24132 | AA26: 15 | AB26: 15 | AC26: =X26*AB26 -> 2137526.2 | AD26: =Z26*AB26 -> 361980
A27: FG | B27: FIBC Bags | C27: 272370.87 | D27: 0 | E27: 4383 | F27: 0 | G27: 334889.15 | H27: 0 | I27: 0 | J27: 0 | K27: 778444.45 | L27: 0 | M27: 0 | N27: 63685.4 | O27: 521685.8 | P27: 0 | Q27: 0 | R27: 0 | S27: 63685.4 | T27: 0 | U27: 0 | V27: =O27-S27 -> 458000.4 | W27: =P27-T27 -> 0 | X27: =C27+F27+G27+I27-K27-L27-M27-W27+V27 -> 286815.97 | Y27: =D27+J27-N27+S27-T27 -> 0 | Z27: =E27-I27+M27+Q27-R27 -> 4383 | AA27: sale - 5% | AB27: =Purchase!AP870 -> 217.40842 | AC27: =X27*AB27 -> 62356208 | AD27: =Z27*AB27 -> 952901.12
A28: FG | B28: FIBC WIP | C28: 4803.97 | D28: 4016.25 | E28: 0 | F28: 0 | G28: 0 | H28: 0 | I28: 0 | J28: 0 | K28: 0 | L28: 0 | M28: 0 | N28: 0 | O28: 567729.64 | P28: 640013.2 | Q28: 0 | R28: 0 | S28: 0 | T28: 0 | U28: 0 | V28: =O28-S28 -> 567729.64 | W28: =P28-T28 -> 640013.2 | X28: =C28+F28+G28+I28-K28-L28-M28-W28+V28 -> -67479.59 | Y28: =D28+J28-N28+S28-T28 -> 4016.25 | Z28: =E28-I28+M28+Q28-R28 -> 0 | AA28: 125 | AB28: 125 | AC28: =X28*AB28 -> -8434948.7 | AD28: =Z28*AB28 -> 0
A29: FG | B29: HDPE Bags | C29: 559 | D29: 0 | E29: 0 | F29: 0 | G29: 0 | H29: 0 | I29: 0 | J29: 0 | K29: 0 | L29: 0 | M29: 0 | N29: 0 | O29: 0 | P29: 0 | Q29: 0 | R29: 0 | S29: 0 | T29: 0 | U29: 0 | V29: =O29-S29 -> 0 | W29: =P29-T29 -> 0 | X29: =C29+F29+G29+I29-K29-L29-M29-W29+V29 -> 559 | Y29: =D29+J29-N29+S29-T29 -> 0 | Z29: =E29-I29+M29+Q29-R29 -> 0 | AC29: =X29*AB29 -> 0 | AD29: =Z29*AB29 -> 0 | AE29: 74347
A30: FG | B30: PP Bags | C30: 52112.9 | D30: 0 | E30: 0 | F30: 0 | G30: 4.6 | H30: 0 | I30: 0 | J30: 0 | K30: 469 | L30: 0 | M30: 0 | N30: 0 | O30: 0 | P30: 0 | Q30: 0 | R30: 0 | S30: 0 | T30: 0 | U30: 0 | V30: =O30-S30 -> 0 | W30: =P30-T30 -> 0 | X30: =C30+F30+G30+I30-K30-L30-M30-W30+V30 -> 51648.5 | Y30: =D30+J30-N30+S30-T30 -> 0 | Z30: =E30-I30+M30+Q30-R30 -> 0 | AA30: purchase | AB30: =Purchase!AP880 -> 106.6 | AC30: =X30*AB30 -> 5505730.1 | AD30: =Z30*AB30 -> 0
A31: FG | B31: Small Bags WIP | C31: -1362.3 | D31: 0 | E31: 0 | F31: 0 | G31: 0 | H31: 0 | I31: 0 | J31: 0 | K31: 0 | L31: 0 | M31: 0 | N31: 0 | O31: 0 | P31: 0 | Q31: 0 | R31: 0 | S31: 0 | T31: 0 | U31: 0 | V31: =O31-S31 -> 0 | W31: =P31-T31 -> 0 | X31: =C31+F31+G31+I31-K31-L31-M31-W31+V31 -> -1362.3 | Y31: =D31+J31-N31+S31-T31 -> 0 | Z31: =E31-I31+M31+Q31-R31 -> 0 | AC31: =X31*AB31 -> 0 | AD31: =Z31*AB31 -> 0
C33: =SUM(C6:C32) -> 1781365.4 | D33: =SUM(D6:D32) -> 511478.56 | E33: =SUM(E6:E32) -> 252432.11 | F33: =SUM(F6:F32) -> 0 | G33: =SUBTOTAL(9,G6:G31) -> 1414565.8 | H33: =SUM(H6:H32) -> 0 | I33: =SUM(I6:I32) -> 73596.33 | J33: =SUM(J6:J32) -> 95438.55 | K33: =SUM(K6:K32) -> 1349326.3 | L33: =SUM(L6:L32) -> 0 | M33: =SUM(M6:M32) -> 20775.12 | N33: =SUM(N6:N32) -> 199752.51 | O33: =SUM(O6:O32) -> 2359518.7 | ... Y33: =SUM(Y6:Y32) -> 407164.6 | Z33: =E33-I33+M33+Q33-R33 -> 199610.9 | AA33: =SUM(AA6:AA32) -> 205 | AB33: =SUM(AB6:AB32) -> 3187.0675 | AC33: =SUM(AC6:AC32) -> 2.5316225e+08 | AD33: =SUM(AD6:AD31) -> 18072272 | AE33: =SUM(AE6:AE32) -> 788976.52
M35: =E33 -> 252432.11 | N35: =M33+Q33 -> 94371.45 | O35: =+I33+R33 -> 147192.66 | Q35: =M35+N35-(O35) -> 199610.9
M36: Op. | N36: IN | O36: OUT | P36: CL | V36: 2293348.5 | W36: 2293348.5 | X36: 1899426.2 | Y36: 407164.6 | Z36: 199610.9 | AA36: 205 | AB36: 3187.0675 | AC36: 2.5316225e+08 | AD36: 18072272 | AE36: 788976.52
M37: =M35/1000 -> 252.43211 | N37: =N35/1000 -> 94.37145 | O37: =O35/1000 -> 147.19266 | P37: =Q35/1000 -> 199.6109 | V37: PERTICULER | W37: OWN STOCK VALUE | X37: JOB STOCK VALUE | Y37: TOTAL | AD37: =AD36/AC36 -> 0.071386125
V38: RM STOCK | W38: =AC7+AC8+AC9+AC10+AC11+AC12+AC13+AC6 -> -8031420.3 | X38: =AD7+AD8+AD9+AD10+AD11+AD12+AD13+AD6 -> 6665877.9 | Y38: =+X38+W38 -> -1365542.5
V39: SF STOCK | W39: =AC15+AC16+AC17+AC18+AC19+AC20+AC21+AC22+AC23+AC24+AC25+AC26+AC14 -> 2.0176668e+08 | X39: =AD15+AD16+AD17+AD18+AD19+AD20+AD21+AD22+AD23+AD24+AD25+AD26+AD14 -> 10453493 | Y39: =+X39+W39 -> 2.1222017e+08
V40: FG STOCK | W40: =AC28+AC29+AC30+AC31+AC27 -> 59426989 | X40: =AD28+AD29+AD30+AD31+AD27 -> 952901.12 | Y40: =+X40+W40 -> 60379891
V41: TOTAL | W41: =+W40+W39+W38 -> 2.5316225e+08 | X41: =+X40+X39+X38 -> 18072272 | Y41: =+X41+W41 -> 2.7123452e+08
Z42: =+Y41-(AC33+AD33) -> 0

Sheet Stores
B2: 01.10.2025 To 31.11.2025
B3: deptt | C3: Openingstock | D3: OpRate | E3: OpValue | F3: InwardsQty | G3: InwdRate | H3: InwdValue | I3: OutWardsQty | J3: OutRate | K3: Outvalue | L3: closingStk | M3: LatestRate | N3: ClosingAmount | O3: companyname | P3: AvgClosingRate
B4: Packing Material | C4: -8843.35 | D4: 435.3647 | E4: 5392192.8 | F4: 34685.3 | G4: 226.87 | H4: 2090444.6 | I4: 20145.45 | J4: 176.1559 | K4: 1624135.4 | L4: 5696.5 | M4: 390.4271 | N4: 1635048.8 | O4: K.P. WOVEN PRIVATE LIMITED | P4: 1317.3975
B5: Consumables | C5: 3010.2 | D5: 275.7727 | E5: 1349416.4 | F5: 76076 | G5: 114.98 | H5: 906727.53 | I5: 13494.2 | J5: 120.5878 | K5: 399965.68 | L5: 65592 | M5: 306.5801 | N5: 2218849.7 | O5: K.P. WOVEN PRIVATE LIMITED | P5: 58.5955
B6: Stores/Spares | C6: 84168.45 | D6: 1324.5317 | E6: 9410433.4 | F6: 36840 | G6: 194.88 | H6: 1889559.1 | I6: 16711.35 | J6: 144.9915 | K6: 898321.57 | L6: 104297.1 | M6: 1373.6805 | N6: 10507500 | O6: K.P. WOVEN PRIVATE LIMITED | P6: 345.3428
B7: RM Consumables | C7: 646831 | D7: 238.5607 | E7: 2717717.7 | F7: 158770 | G7: 0.58 | H7: 537903 | I7: 116380 | J7: 70.6366 | K7: 533729.08 | L7: 689221 | M7: 269.4729 | N7: 3172400.5 | O7: K.P. WOVEN PRIVATE LIMITED | P7: 73.4612
E8: =+E7+E6+E5+E4 -> 18869760 | H8: =+H7+H6+H5+H4 -> 5424634.2 | K8: =+K7+K6+K5+K4 -> 3456151.7 | N8: =+N7+N6+N5+N4 -> 17533799
B10: 01.11.2025 TO 30.11.2025
B11: deptt | C11: Openingstock | D11: OpRate | E11: OpValue | F11: InwardsQty | G11: InwdRate | H11: InwdValue | I11: OutWardsQty | J11: OutRate | K11: Outvalue | L11: closingStk | M11: LatestRate | N11: ClosingAmount | O11: companyname | P11: AvgClosingRate
B12: Packing Material | C12: 5695.5 | D12: 422.9394 | E12: 3263295.2 | F12: 32099.74 | G12: 125.48 | H12: 1238005.4 | I12: 12897.5 | J12: 305.9244 | K12: 1523715 | L12: 24897.74 | M12: 395.9794 | N12: 1370752.6 | O12: K.P. WOVEN PRIVATE LIMITED | P12: 173.0755
B13: Consumables | C13: 44528 | D13: 226.8315 | E13: 1540114 | F13: 3422 | G13: 49.53 | H13: 600854.24 | I13: 12195 | J13: 83.4371 | K13: 1048254.9 | L13: 35755 | M13: 249.9614 | N13: 1617208.8 | O13: K.P. WOVEN PRIVATE LIMITED | P13: -94.7728
B14: Stores/Spares | C14: 103567.1 | D14: 1172.7689 | E14: 10195140 | F14: 60488.95 | G14: 61.13 | H14: 1890618.7 | I14: 41182.2 | J14: 124.8507 | K14: 1634077.9 | L14: 122873.85 | M14: 1231.2635 | N14: 10733336 | O14: K.P. WOVEN PRIVATE LIMITED | P14: 280.8507
B15: RM Consumables | C15: 689221 | D15: 231.71 | E15: 2794367.9 | F15: 268020 | G15: 48.8 | H15: 1245505.6 | I15: 229493 | J15: 37.1798 | K15: 981457 | L15: 727748 | M15: 257.4202 | N15: 3601710.8 | O15: K.P. WOVEN PRIVATE LIMITED | P15: 98.3583
E16: =+E15+E14+E13+E12 -> 17792917 | H16: =+H15+H14+H13+H12 -> 4974983.9 | K16: =+K15+K14+K13+K12 -> 5187504.8 | N16: =+N15+N14+N13+N12 -> 17323008
B18: 01.12.2025. to 31.12.2025
B19: deptt | C19: Openingstock | D19: OpRate | E19: OpValue | F19: InwardsQty | G19: InwdRate | H19: InwdValue | I19: OutWardsQty | J19: OutRate | K19: Outvalue | L19: closingStk | M19: LatestRate | N19: ClosingAmount | O19: companyname | P19: AvgClosingRate
B20: Packing Material | C20: 2711.74 | D20: 332.3615 | E20: 1219708.3 | F20: 33765 | G20: 168.05 | H20: 1483001.2 | I20: 26351 | J20: 397.1977 | K20: 2072395.8 | L20: 10125.74 | M20: 400.0762 | N20: 690143.5 | O20: K.P. WOVEN PRIVATE LIMITED | P20: 53.9743
B21: Consumables | C21: 12891 | D21: 255.0866 | E21: 1008687.2 | F21: 53760.5 | G21: 116.77 | H21: 750558.82 | I21: 34716.5 | J21: 137.4375 | K21: 1008137.1 | L21: 31935 | M21: 290.2816 | N21: 1166686.7 | O21: K.P. WOVEN PRIVATE LIMITED | P21: 99.4418
B22: Stores/Spares | C22: 121266.3 | D22: 1262.9044 | E22: 9634589.8 | F22: 95617.3 | G22: 343.15 | H22: 3187695.7 | I22: 55104 | J22: 289.2783 | K22: 2761997.5 | L22: 161779.6 | M22: 1381.9821 | N22: 10439864 | O22: K.P. WOVEN PRIVATE LIMITED | P22: 446.268
B23: RM Consumables | C23: 326561 | D23: 209.9592 | E23: 1637367.5 | F23: 293598 | G23: 13.91 | H23: 747755 | I23: 295232 | J23: 179.4073 | K23: 1425028.9 | L23: 324927 | M23: 259.5775 | N23: 1715751.5 | O23: K.P. WOVEN PRIVATE LIMITED | P23: 45.8502
E24: =+E23+E22+E21+E20 -> 13500353 | H24: =+H23+H22+H21+H20 -> 6169010.7 | K24: =+K23+K22+K21+K20 -> 7267559.3 | N24: =+N23+N22+N21+N20 -> 14012445
B26: 01.01.2026 to 31.01.2026
B27: deptt | C27: Openingstock | D27: OpRate | E27: OpValue | F27: InwardsQty | G27: InwdRate | H27: InwdValue | I27: OutWardsQty | J27: OutRate | K27: Outvalue | L27: closingStk | M27: LatestRate | N27: ClosingAmount | O27: companyname | P27: AvgClosingRate
B28: Packing Material | C28: 10845.74 | D28: 318.3153 | E28: 701182.11 | F28: 35489.94 | G28: 348.91 | H28: 1515454.3 | I28: 14185.85 | J28: 170.6153 | K28: 1734967.3 | L28: 32149.83 | M28: 357.4267 | N28: 557674.44 | O28: K.P. WOVEN PRIVATE LIMITED | P28: 275.6921
B29: Consumables | C29: 17349 | D29: 219.5386 | E29: 730520.06 | F29: 47949 | G29: 47.82 | H29: 755738.63 | I29: 16057 | J29: 42.8443 | K29: 571060.22 | L29: 49241 | M29: 242.1273 | N29: 1259255.8 | O29: K.P. WOVEN PRIVATE LIMITED | P29: -66.4835
B30: Stores/Spares | C30: 157773.8 | D30: 1237.3779 | E30: 9762502.5 | F30: 27495.5 | G30: 171.06 | H30: 2006644.6 | I30: 33667.35 | J30: 218.3359 | K30: 2324067.6 | L30: 151601.95 | M30: 1312.4359 | N30: 10025902 | O30: K.P. WOVEN PRIVATE LIMITED | P30: 336.0724
B31: RM Consumables | C31: 323837 | D31: 176.3803 | E31: 1212409.1 | F31: 329565 | G31: 71.04 | H31: 1799834.1 | I31: 253363 | J31: 58.1718 | K31: 842884 | L31: 400039 | M31: 211.3915 | N31: 2015954.5 | O31: K.P. WOVEN PRIVATE LIMITED | P31: 84.8423
E32: =+E31+E30+E29+E28 -> 12406614 | H32: =+H31+H30+H29+H28 -> 6077671.6 | K32: =+K31+K30+K29+K28 -> 5472979.1 | N32: =+N31+N30+N29+N28 -> 13858787
B34: 01.02.2026 TO 28.02.2026
B36: deptt | C36: Openingstock | D36: OpRate | E36: OpValue | F36: InwardsQty | G36: InwdRate | H36: InwdValue | I36: OutWardsQty | J36: OutRate | K36: Outvalue | L36: closingStk | M36: LatestRate | N36: ClosingAmount | O36: companyname | P36: AvgClosingRate
B37: Packing Material | C37: 32149.83 | D37: 258.3656 | E37: 484342.86 | F37: 20645.49 | G37: 135.39 | H37: 1660537.4 | I37: 34500.47 | J37: 256.6625 | K37: 1192686 | L37: 18294.85 | M37: 277.7494 | N37: 1035528.7 | O37: K.P. WOVEN PRIVATE LIMITED | P37: 71.557
B38: Consumables | C38: 49048 | D38: 447.4718 | E38: 914504.24 | F38: 41748 | G38: 312.06 | H38: 1176289.1 | I38: 21965 | J38: 245.7812 | K38: 682190.82 | L38: 68831 | M38: 483.4148 | N38: 1606419.8 | O38: K.P. WOVEN PRIVATE LIMITED | P38: 133.1592
B39: Stores/Spares | C39: 151538.95 | D39: 1206.6102 | E39: 9715646.4 | F39: 39702.33 | G39: 145.34 | H39: 2393465.6 | I39: 23230.1 | J39: 121.336 | K39: 1534427.4 | L39: 168011.18 | M39: 1266.023 | N39: 10981604 | O39: K.P. WOVEN PRIVATE LIMITED | P39: 336.0588
B40: RM Consumables | C40: 399739 | D40: 188.6454 | E40: 1901382 | F40: 157340 | G40: 53.49 | H40: 587768.1 | I40: 371480 | J40: 22.6027 | K40: 1177743.6 | L40: 185599 | M40: 208.4181 | N40: 1441266.4 | O40: K.P. WOVEN PRIVATE LIMITED | P40: 60.9754
E41: =+E37+E38+E39+E40 -> 13015876 | H41: =+H37+H38+H39+H40 -> 5818060.2 | K41: =+K37+K38+K39+K40 -> 4587047.8 | N41: =+N37+N38+N39+N40 -> 15064819
B43: 01.03.2026 to 31.03.2026
B45: deptt | C45: Openingstock | D45: OpRate | E45: OpValue | F45: InwardsQty | G45: InwdRate | H45: InwdValue | I45: OutWardsQty | J45: OutRate | K45: Outvalue | L45: closingStk | M45: LatestRate | N45: ClosingAmount | O45: companyname | P45: AvgClosingRate
B46: Packing Material | C46: 16213.85 | D46: 364.3247 | E46: -3785.56 | F46: 33812.9 | G46: 364.2 | H46: 2170218.2 | I46: 31145.45 | J46: 336.0663 | K46: 1782710.9 | L46: 18881.3 | M46: 380.7926 | N46: 488304.12 | O46: K.P. WOVEN PRIVATE LIMITED | P46: 64.2989
B47: Consumables | C47: 54415.6 | D47: 503.4206 | E47: 1078472.5 | F47: 21963 | G47: 493.17 | H47: 1152708 | I47: 50911 | J47: 429.9613 | K47: 925828.39 | L47: 25467.6 | M47: 647.4132 | N47: 1588563.3 | O47: K.P. WOVEN PRIVATE LIMITED | P47: 277.9983
B48: Stores/Spares | C48: 146325.18 | D48: 1191.602 | E48: 8740342.4 | F48: 41404.6 | G48: 349.91 | H48: 4468463.9 | I48: 48423.93 | J48: 332.6879 | K48: 3317479.6 | L48: 139305.85 | M48: 1309.0951 | N48: 9937508.3 | O48: K.P. WOVEN PRIVATE LIMITED | P48: 375.3867
...

Sheet Purchase
N2: =SUBTOTAL(9,N4:N1000) -> 1414566 | O2: =SUBTOTAL(9,O4:O1000) -> 1.9130107e+08 | AF2: =SUBTOTAL(9,AF4:AF1000) -> 1414565.8 | AK2: =O2/N2 -> 135.23657
B3: Date | C3: Particular | D3: Voucher Type | E3: Voucher No | F3: Type | G3: Invoice No | H3: Invoice Date | I3: Main Grp | J3: Group Name | K3: Sub Grup | L3: purchase Group Name | M3: Item Name | N3: Quantity | O3: Amount | P3: Item Desc | Q3: Bill Amount | R3: CGST Rate | S3: CGST Amt | T3: SGST Rate | U3: SGST Amt | V3: IGST Rate | W3: IGST Amt | X3: Freight GST | Y3: Total GST | Z3: TCS | AA3: GST-IN | AB3: Unit | AC3: HSN Code | AD3: Currencty | AE3: Exc.Rate | AF3: Net Wt | AG3: Country | AH3: GROUP | AI3: 1 | AJ3: 1
B4: 46204 | C4: Eminent Globexim | D4: General Purchase | E4: GNCN 200 | F4: Purchase Withinstate- Stores, Spares & Consumable | G4: EG/2627/20 | H4: 46193 | I4: Packing Material | J4: Packaging Material | K4: Stores & Spares | L4: Consumables | M4: Pp Rope | N4: 262.1 | O4: 40887.6 | P4: Pp Rope | Q4: 43247 | R4: 2.5 | S4: 1029.69 | T4: 2.5 | U4: 1029.69 | V4: 0 | W4: 0 | X4: 0 | Y4: 2059.38 | Z4: 0 | AA4: 24AAIFE9434G1ZE | AB4: Kgs | AC4: 2853 | AD4: Rs. | AE4: 1 | AF4: 0 | AG4: India | AH4: N.A
B5: 46204 | C5: Ginza Machinery Mfg.Co. | D5: General Purchase | E5: GNSP 343 | F5: Purchase Withinstate- Stores, Spares & Consumable | G5: GINZA/26-27/0932 | H5: 46202 | I5: Stores/Spares | J5: Stitching Spares | K5: Stores & Spares | L5: stores & spares | M5: Needle Lever Connecting Rod ( Big Bkt.) # 502690 B | N5: 10 | O5: 5250 | P5: Needle Lever Connecting Rod ( Big Bkt.) # 502690 B | Q5: 18952 | R5: 2.5 | S5: 131.25 | T5: 2.5 | U5: 131.25 | V5: 0 | W5: 0 | X5: 0 | Y5: 262.5 | Z5: 0 | AA5: 24AAAFG5650J1ZJ | AB5: Pcs | AC5: 84529099 | AD5: Rs. | AE5: 1 | AF5: 0 | AG5: India | AH5: N.A
B6: 46204 | C6: Ginza Machinery Mfg.Co. | D6: General Purchase | E6: GNSP 343 | F6: Purchase Withinstate- Stores, Spares & Consumable | G6: GINZA/26-27/0932 | H6: 46202 | I6: Stores/Spares | J6: Stitching Spares | K6: Stores & Spares | L6: stores & spares | M6: Feed Bar Bracket 603616 | N6: 10 | O6: 5250 | P6: Feed Bar Bracket 603616 | Q6: 0 | R6: 2.5 | S6: 131.25 | T6: 2.5 | U6: 131.25 | V6: 0 | W6: 0 | X6: 0 | Y6: 262.5 | Z6: 0 | AA6: 24AAAFG5650J1ZJ | AB6: Pcs | AC6: 84529099 | AD6: Rs. | AE6: 1 | AF6: 0 | AG6: India | AH6: N.A
B7: 46204 | C7: Ginza Machinery Mfg.Co. | D7: General Purchase | E7: GNSP 343 | F7: Purchase Withinstate- Stores, Spares & Consumable | G7: GINZA/26-27/0932 | H7: 46202 | I7: Stores/Spares | J7: Stitching Spares | K7: Stores & Spares | L7: stores & spares | M7: 502683 (Needle Lever Conn. Rod Bkt. (Small ) | N7: 10 | O7: 4550 | P7: 502683 (Needle Lever Conn. Rod Bkt. (Small ) | Q7: 0 | R7: 2.5 | S7: 113.75 | T7: 2.5 | U7: 113.75 | V7: 0 | W7: 0 | X7: 0 | Y7: 227.5 | Z7: 0 | AA7: 24AAAFG5650J1ZJ | AB7: Pcs | AC7: 845290 | AD7: Rs. | AE7: 1 | AF7: 0 | AG7: India | AH7: N.A
B8: 46204 | C8: Ginza Machinery Mfg.Co. | D8: General Purchase | E8: GNSP 343 | F8: Purchase Withinstate- Stores, Spares & Consumable | G8: GINZA/26-27/0932 | H8: 46202 | I8: Stores/Spares | J8: Stitching Spares | K8: Stores & Spares | L8: stores & spares | M8: Looper Avoid Eccentric Fork 603516 | N8: 5 | O8: 2100 | P8: Looper Avoid Eccentric Fork 603516 | Q8: 0 | R8: 2.5 | S8: 75 | T8: 2.5 | U8: 75 | V8: 0 | W8: 0 | X8: 0 | Y8: 150 | Z8: 0 | AA8: 24AAAFG5650J1ZJ | AB8: Pcs | AC8: 84529099 | AD8: Rs. | AE8: 1 | AF8: 0 | AG8: India | AH8: N.A
B9: 46204 | C9: HCP Plastene Bulkpack Limited - Purchase | D9: R.M.P. | E9: RM 239 | F9: Purchase Withinstate - Raw Material | G9: HPBL/D/328 | H9: 46203 | I9: SF | J9: PP/PE Fabric | K9: PP UL Fabric | L9: PP WOVEN FABRIC | M9: PP UL Fabric With UV | N9: 317 | O9: 70342.3 | P9: PP UL Fabric With UV | Q9: 1084907.1 | R9: 9 | S9: 6330.81 | T9: 9 | U9: 6330.81 | V9: 0 | W9: 0 | X9: 0 | Y9: 12661.62 | Z9: 0 | AA9: 24AABCG1282C2Z6 | AB9: Kgs | AC9: 39269080 | AD9: Rs. | AE9: 1 | AF9: 317 | AG9: India | AH9: PP UL Fabric
B10: 46204 | C10: HCP Plastene Bulkpack Limited - Purchase | D10: R.M.P. | E10: RM 239 | F10: Purchase Withinstate - Raw Material | G10: HPBL/D/328 | H10: 46203 | I10: SF | J10: PP/PE Fabric | K10: PP UL Fabric | L10: PP WOVEN FABRIC | M10: PP UL Fabric With UV | N10: 629 | O10: 100577.1 | P10: PP UL Fabric With UV | Q10: 0 | R10: 9 | S10: 9051.94 | T10: 9 | U10: 9051.94 | V10: 0 | W10: 0 | X10: 0 | Y10: 18103.88 | Z10: 0 | AA10: 24AABCG1282C2Z6 | AB10: Kgs | AC10: 39269080 | AD10: Rs. | AE10: 1 | AF10: 629 | AG10: India | AH10: PP UL Fabric
B11: 46204 | C11: HCP Plastene Bulkpack Limited - Purchase | D11: R.M.P. | E11: RM 239 | F11: Purchase Withinstate - Raw Material | G11: HPBL/D/328 | H11: 46203 | I11: SF | J11: PP/PE Fabric | K11: PP UL Fabric | L11: PP WOVEN FABRIC | M11: PP UL Fabric With UV | N11: 4628 | O11: 749273.2 | P11: PP UL Fabric With UV | Q11: 0 | R11: 9 | S11: 67434.59 | T11: 9 | U11: 67434.59 | V11: 0 | W11: 0 | X11: 0 | Y11: 134869.18 | Z11: 0 | AA11: 24AABCG1282C2Z6 | AB11: Kgs | AC11: 39269080 | AD11: Rs. | AE11: 1 | AF11: 4628 | AG11: India | AH11: PP UL Fabric
B12: 46204 | C12: HCP Plastene Bulkpack Limited - Purchase | D12: R.M.P. | E12: RM 241 | F12: Purchase Withinstate - Raw Material | G12: HPBL/D/336 | H12: 46204 | I12: SF | J12: PP/PE Fabric | K12: PP UL Fabric | L12: PP WOVEN FABRIC | M12: PP UL Fabric With UV | N12: 657 | O12: 106368.3 | P12: PP UL Fabric With UV | Q12: 545314.62 | R12: 9 | S12: 9573.15 | T12: 9 | U12: 9573.15 | V12: 0 | W12: 0 | X12: 0 | Y12: 19146.3 | Z12: 0 | AA12: 24AABCG1282C2Z6 | AB12: Kgs | AC12: 39269080 | AD12: Rs. | AE12: 1 | AF12: 657 | AG12: India | AH12: PP UL Fabric
B13: 46204 | C13: HCP Plastene Bulkpack Limited - Purchase | D13: R.M.P. | E13: RM 241 | F13: Purchase Withinstate - Raw Material | G13: HPBL/D/336 | H13: 46204 | I13: SF | J13: PP/PE Fabric | K13: PP Lam Fabric | L13: PP LAMINETED FABRIC | M13: PP Lam Fabric With UV | N13: 2173 | O13: 356154.7 | P13: PP Lam Fabric With UV | Q13: 0 | R13: 9 | S13: 32053.92 | T13: 9 | U13: 32053.92 | V13: 0 | W13: 0 | X13: 0 | Y13: 64107.84 | Z13: 0 | AA13: 24AABCG1282C2Z6 | AB13: Kgs | AC13: 63053300 | AD13: Rs. | AE13: 1 | AF13: 2173 | AG13: India | AH13: PP Lam Fabric
B14: 46204 | C14: Labbdhi Paper Tubes Pvt Ltd | D14: General Purchase | E14: GNPK 121 | F14: Purchase Withinstate- Packing Material | G14: 407/2026-27 | H14: 46203 | I14: Packing Material | J14: Paper Cores | K14: Packing Materials | L14: Packing Materials | M14: Paper Core | N14: 1845 | O14: 66420 | P14: Paper Core | Q14: 78376 | R14: 9 | S14: 5977.8 | T14: 9 | U14: 5977.8 | V14: 0 | W14: 0 | X14: 0 | Y14: 11955.6 | Z14: 0 | AA14: 24AACCL4303N1ZM | AB14: Kgs | AC14: 482290 | AD14: Rs. | AE14: 1 | AF14: 0 | AG14: India | AH14: N.A
B15: 46204 | C15: Lohia Corp Limited - 09AAKCK2932Q1ZU - UP | D15: General Purchase | E15: GNSP 341 | F15: Purchase Interstate- Stores, Spares & Consumable | G15: TG0926110178 | H15: 46199 | I15: Stores/Spares | J15: Cutting Machine Spares | K15: Stores & Spares | L15: stores & spares | M15: Top Pinch Roller Shaft 11169158800 | N15: 1 | O15: 11875 | P15: Top Pinch Roller Shaft 11169158800 | Q15: 26985.42 | R15: 0 | S15: 0 | T15: 0 | U15: 0 | V15: 18 | W15: 2137.5 | X15: 166.32 | Y15: 2303.82 | Z15: 0 | AA15: 09AAKCK2932Q1ZU | AB15: Pcs | AC15: 84799090 | AD15: Rs. | AE15: 1 | AF15: 0 | AG15: India | AH15: N.A
... B28: 46204 | C28: Satyam Stationery Mart | D28: General Purchase | E28: GNPK 124 | F28: Purchase Withinstate- Packing Material | G28: SSM01911 | H28: 46202 | I28: Stores/Spares | J28: Cutter Blades | K28: Packing Materials | L28: Packing Materials | M28: Scissor Plastic Handle | N28: 20 | O28: 1240 | P28: Scissor Plastic Handle | Q28: 1463 | R28: 9 | S28: 111.6 | T28: 9 | U28: 111.6 | V28: 0 | W28: 0 | X28: 0 | Y28: 223.2 | Z28: 0 | AA28: 24AGUPL9792N1Z6 | AB28: Pcs | AC28: 82130000 | AD28: Rs. | AE28: 1 | AF28: 0 | AG28: India | AH28: N.A
B29: 46204 | C29: Shree Ganesh Stereo | D29: General Purchase | E29: GNCN 201 | F29: Purchase Withinstate- Stores, Spares & Consumable | G29: 1184 | H29: 46200 | I29: Consumables | J29: Rubber/Polymer Stereo | K29: Stores & Spares | L29: Consumables | M29: Rubber Stereo | N29: 1 | O29: 84 | P29: Rubber Stereo | Q29: 1010 | R29: 9 | S29: 7.56 | T29: 9 | U29: 7.56 | V29: 0 | W29: 0 | X29: 0 | Y29: 15.12 | Z29: 0 | AA29: 24AHDPC2510M1ZU | AB29: PCS | AC29: 400200 | AD29: Rs. | AE29: 1 | AF29: 0 | AG29: India | AH29: N.A
B30: 46204 | C30: Shree Ganesh Stereo | D30: General Purchase | E30: GNCN 201 | F30: Purchase Withinstate- Stores, Spares & Consumable | G30: 1184 | H30: 46200 | I30: Consumables | J30: Rubber/Polymer Stereo | K30: Stores & Spares | L30: Consumables | M30: Rubber Stereo | N30: 1 | O30: 771.75 | P30: Rubber Stereo | Q30: 0 | R30: 9 | S30: 69.46 | T30: 9 | U30: 69.46 | V30: 0 | W30: 0 | X30: 0 | Y30: 138.92 | Z30: 0 | AA30: 24AHDPC2510M1ZU | AB30: PCS | AC30: 400200 | AD30: Rs. | AE30: 1 | AF30: 0 | AG30: India | AH30: N.A
B31: 46204 | C31: Shree Meter & Heater | D31: General Purchase | E31: GNSP 342 | F31: Purchase Withinstate- Stores, Spares & Consumable | G31: G/0219 | H31: 46203 | I31: Stores/Spares | J31: Heaters | K31: Stores & Spares | L31: stores & spares | M31: Ceramic Heater 300mm(D)X45mm(L) 240 V A.C.2000 W | N31: 5 | O31: 10900 | P31: Ceramic Heater 300mm(D)X45mm(L) 240 V A.C.2000 W | Q31: 13511 | R31: 9 | S31: 981 | T31: 9 | U31: 981 | V31: 0 | W31: 0 | X31: 99 | Y31: 2061 | Z31: 0 | AA31: 24BEGPR0567G1ZH | AB31: Pcs | AC31: 851680 | AD31: Rs. | AE31: 1 | AF31: 0 | AG31: India | AH31: N.A
B32: 46204 | C32: Shree Salareshwar Wood Packers Private Limited. | D32: Purchase | E32: GNPK 122 | F32: Purchase Withinstate- Packing Material | G32: SS/SL/26-27/189 | H32: 46204 | I32: Packing Material | J32: Pallets | K32: Pallets | L32: Packing Materials | M32: Pine Wooden Pallet Design Code STD90110 | N32: 150 | O32: 108750 | P32: Pine Wooden Pallet Design Code STD90110 | Q32: 114188 | R32: 2.5 | S32: 2718.75 | T32: 2.5 | U32: 2718.75 | V32: 0 | W32: 0 | X32: 0 | Y32: 5437.5 | Z32: 0 | AA32: 24ABLCS6579H1ZR | AB32: Pcs | AC32: 44152000 | AD32: Rs. | AE32: 1 | AF32: 0 | AG32: India | AH32: N.A
B33: 46204 | C33: West India Forklift Services | D33: General Purchase | E33: GNSP 344 | F33: Purchase Withinstate- Stores, Spares & Consumable | G33: WI2627/0148 | H33: 46202 | I33: Stores/Spares | J33: Forklift Spares | K33: Stores & Spares | L33: stores & spares | M33: Fog Lamp For Forklift Head Light | N33: 4 | O33: 13040 | P33: Fog Lamp For Forklift Head Light | Q33: 15387 | R33: 9 | S33: 1173.6 | T33: 9 | U33: 1173.6 | V33: 0 | W33: 0 | X33: 0 | Y33: 2347.2 | Z33: 0 | AA33: 24AOQPC4561C2Z7 | AB33: PCS | AC33: 85399090 | AD33: Rs. | AE33: 1 | AF33: 0 | AG33: India | AH33: N.A
B34: 46205 | C34: Arham Cams Pvt Ltd | D34: General Purchase | E34: GNSP 345 | F34: Purchase Withinstate- Stores, Spares & Consumable | G34: GST/50. | H34: 46144 | I34: Stores/Spares | J34: Sulzer Machine Spares | K34: Stores & Spares | L34: stores & spares | M34: Sliding Catch For P7100 Part no.911.801.104 | N34: 100 | O34: 8000 | P34: Sliding Catch For P7100 Part no.911.801.104 | Q34: 26845 | R34: 9 | S34: 720 | T34: 9 | U34: 720 | V34: 0 | W34: 0 | X34: 72 | Y34: 1512 | Z34: 0 | AA34: 24AAICA0799H1ZK | AB34: Pcs | AC34: 844810 | AD34: Rs. | AE34: 1 | AF34: 0 | AG34: India | AH34: N.A
B35: 46205 | C35: Arham Cams Pvt Ltd | D35: General Purchase | E35: GNSP 345 | F35: Purchase Withinstate- Stores, Spares & Consumable | G35: GST/50. | H35: 46144 | I35: Stores/Spares | J35: Sulzer Machine Spares | K35: Stores & Spares | L35: stores & spares | M35: Drive shaft p7100, 911803136 | N35: 1 | O35: 14350 | P35: Drive shaft p7100, 911803136 | Q35: 0 | R35: 9 | S35: 1291.5 | T35: 9 | U35: 1291.5 | V35: 0 | W35: 0 | X35: 72 | Y35: 2655 | Z35: 0 | AA35: 24AAICA0799H1ZK | AB35: Pcs | AC35: 84484990 | AD35: Rs. | AE35: 1 | AF35: 0 | AG35: India | AH35: N.A
B36: 46205 | C36: Dynamic Wooltex | D36: R.M.P. | E36: RM 246 | F36: Purchase Withinstate - Raw Material | G36: 13524 | H36: 46202 | I36: RM | J36: FIBC Accessories | K36: FIBC Accessories | L36: PP WOVEN FABRIC | M36: Non Woven Fabric (Felt) 170Gsm.Pati Cut Length- 2" ( 5 Cm ) (Food Grade Quality) | N36: 1699.3 | O36: 254895 | P36: Non Woven Fabric (Felt) 170Gsm.Pati Cut Length- 2" ( 5 Cm ) (Food Grade Quality) | Q36: 283389.75 | R36: 0 | S36: 0 | T36: 0 | U36: 0 | V36: 5 | W36: 12744.75 | X36: 750 | Y36: 13494.75 | Z36: 0 | AA36: 08ABFPB2251A1ZI | AB36: Kgs | AC36: 58079010 | AD36: Rs. | AE36: 1 | AF36: 1699.3 | AG36: India | AH36: FIBC Accessories
B37: 46205 | C37: J J Plastalloy Pvt Ltd | D37: R.M.P. | E37: RM 245 | F37: Purchase Withinstate - Raw Material | G37: DG-261002398 | H37: 46203 | I37: RM | J37: Granules | K37: Masterbatch | L37: Master batch | M37: MB JJ White WE9381PT | N37: 500 | O37: 89000 | P37: MB JJ White WE9381PT | Q37: 105020 | R37: 9 | S37: 8010 | T37: 9 | U37: 8010 | V37: 0 | W37: 0 | X37: 0 | Y37: 16020 | Z37: 0 | AA37: 24AAACJ5701E1Z5 | AB37: Kgs | AC37: 32064990 | AD37: Rs. | AE37: 1 | AF37: 500 | AG37: India | AH37: Masterbatch
B38: 46205 | C38: Plastene India ltd - Unit 1-Purchase | D38: Purchase | E38: GNPK 125 | F38: Purchase Withinstate- Packing Material | G38: PIL1/D/880 | H38: 46204 | I38: Stores/Spares | J38: MS Structure Items | K38: Packing Materials | L38: Packing Materials | M38: MS Pipe 4 C Class | N38: 255 | O38: 12240 | P38: MS Pipe 4 C Class | Q38: 14430.96 | R38: 9 | S38: 1101.6 | T38: 9 | U38: 1101.6 | V38: 0 | W38: 0 | X38: 0 | Y38: 2203.2 | Z38: 0 | AA38: 24AAACO3087C1ZT | AB38: Kgs | AC38: 73063090 | AD38: Rs. | AE38: 1 | AF38: 0 | AG38: India | AH38: N.A
B39: 46205 | C39: Plastene India ltd - Unit 1-Purchase | D39: R.M.P. | E39: RM 243 | F39: Purchase Withinstate - Raw Material | G39: PIL1/D/879 | H39: 46204 | I39: RM | J39: Granules | K39: PP Granules | L39: PP Granuals | M39: PP Basell 462S | N39: 2000 | O39: 300000 | P39: PP Basell 462S | Q39: 353700 | R39: 9 | S39: 27000 | T39: 9 | U39: 27000 | V39: 0 | W39: 0 | X39: 0 | Y39: 54000 | Z39: 0 | AA39: 24AAACO3087C1ZT | AB39: Kgs | AC39: 39021000 | AD39: Rs. | AE39: 1 | AF39: 2000 | AG39: India | AH39: PP Granules
B40: 46205 | C40: Plastene India ltd - Unit 1-Purchase | D40: R.M.P. | E40: RM 244 | F40: Purchase Withinstate - Raw Material | G40: PIL1/D/881 | H40: 46204 | I40: SF | J40: Liners | K40: LDPE/LLDPE Bags | L40: LLDPE BAGS | M40: LDPE/LLDPE Bags/Liner | N40: 949 | O40: 175707.35 | P40: LDPE/LLDPE Bags/Liner | Q40: 212925.5 | R40: 9 | S40: 15813.66 | T40: 9 | U40: 15813.66 | V40: 0 | W40: 0 | X40: 0 | Y40: 31627.32 | Z40: 0 | AA40: 24AAACO3087C1ZT | AB40: Kgs | AC40: 39200000 | AD40: Rs. | AE40: 1 | AF40: 949 | AG40: India | AH40: LDPE/LLDPE Bags
B41: 46205 | C41: Plastene India ltd - Unit 1-Purchase | D41: R.M.P. | E41: RM 244 | F41: Purchase Withinstate - Raw Material | G41: PIL1/D/881 | H41: 46204 | I41: SF | J41: Liners | K41: LDPE/LLDPE Bags | L41: LLDPE BAGS | M41: LDPE/LLDPE Bags/Liner | N41: 27 | O41: 4891.05 | P41: LDPE/LLDPE Bags/Liner | Q41: 0 | R41: 9 | S41: 440.19 | T41: 9 | U41: 440.19 | V41: 0 | W41: 0 | X41: 0 | Y41: 880.38 | Z41: 0 | AA41: 24AAACO3087C1ZT | AB41: Kgs | AC41: 39200000 | AD41: Rs. | AE41: 1 | AF41: 27 | AG41: India | AH41: LDPE/LLDPE Bags
B42: 46205 | C42: Shree Ganesh Stereo | D42: General Purchase | E42: GNCN 202 | F42: Purchase Withinstate- Stores, Spares & Consumable | G42: 1214 | H42: 46202 | I42: Consumables | J42: Rubber/Polymer Stereo | K42: Stores & Spares | L42: Consumables | M42: Rubber Stereo | N42: 1 | O42: 2832.9 | P42: Rubber Stereo | Q42: 5785 | R42: 9 | S42: 254.96 | T42: 9 | U42: 254.96 | V42: 0 | W42: 0 | X42: 0 | Y42: 509.92 | Z42: 0 | AA42: 24AHDPC2510M1ZU | AB42: PCS | AC42: 400200 | AD42: Rs. | AE42: 1 | AF42: 0 | AG42: India | AH42: N.A
B43: 46205 | C43: Shree Ganesh Stereo | D43: General Purchase | E43: GNCN 202 | F43: Purchase Withinstate- Stores, Spares & Consumable | G43: 1214 | H43: 46202 | I43: Consumables | J43: Rubber/Polymer Stereo | K43: Stores & Spares | L43: Consumables | M43: Rubber Stereo | N43: 1 | O43: 2069.55 | P43: Rubber Stereo | Q43: 0 | R43: 9 | S43: 186.26 | T43: 9 | U43: 186.26 | V43: 0 | W43: 0 | X43: 0 | Y43: 372.52 | Z43: 0 | AA43: 24AHDPC2510M1ZU | AB43: PCS | AC43: 400200 | AD43: Rs. | AE43: 1 | AF43: 0 | AG43: India | AH43: N.A
B44: 46205 | C44: Shri Nakoda Transmission & Electric Co. | D44: General Purchase | E44: GNSP 346 | F44: Purchase Withinstate- Stores, Spares & Consumable | G44: VTV/26-27/1591 | H44: 46197 | I44: Stores/Spares | J44: IT Spares | K44: Stores & Spares | L44: stores & spares | M44: 8 Port Dlink Switch | N44: 20 | O44: 1100 | P44: 8 Port Dlink Switch | Q44: 8575 | R44: 9 | S44: 99 | T44: 9 | U44: 99 | V44: 0 | W44: 0 | X44: 36 | Y44: 234 | Z44: 0 | AA44: 24AFGFS2586E1ZX | AB44: Pcs | AC44: 85176990 | AD44: Rs. | AE44: 1 | AF44: 0 | AG44: India | AH44: N.A
B45: 46205 | C45: Shri Nakoda Transmission & Electric Co. | D45: General Purchase | E45: GNSP 346 | F45: Purchase Withinstate- Stores, Spares & Consumable | G45: VTV/26-27/1591 | H45: 46197 | I45: Stores/Spares | J45: IT Spares | K45: Stores & Spares | L45: stores & spares | M45: 8 Port Dlink Switch | N45: 6 | O45: 342 | P45: 8 Port Dlink Switch | Q45: 0 | R45: 9 | S45: 30.78 | T45: 9 | U45: 30.78 | V45: 0 | W45: 0 | X45: 36 | Y45: 97.56 | Z45: 0 | AA45: 24AFGFS2586E1ZX | AB45: Pcs | AC45: 85176990 | AD45: Rs. | AE45: 1 | AF45: 0 | AG45: India | AH45: N.A
B46: 46205 | C46: Shri Nakoda Transmission & Electric Co. | D46: General Purchase | E46: GNSP 346 | F46: Purchase Withinstate- Stores, Spares & Consumable | G46: VTV/26-27/1591 | H46: 46197 | I46: Stores/Spares | J46: IT Spares | K46: Stores & Spares | L46: stores & spares | M46: 8 Port Dlink Switch | N46: 45 | O46: 5625 | P46: 8 Port Dlink Switch | Q46: 0 | R46: 9 | S46: 506.25 | T46: 9 | U46: 506.25 | V46: 0 | W46: 0 | X46: 36 | Y46: 1048.5 | Z46: 0 | AA46: 24AFGFS2586E1ZX | AB46: Pcs | AC46: 85176990 | AD46: Rs. | AE46: 1 | AF46: 0 | AG46: India | AH46: N.A
B47: 46206 | C47: Axle Steel & Fasteners | D47: General Purchase | E47: GNSP 348 | F47: Purchase Withinstate- Stores, Spares & Consumable | G47: 0524/26-27 | H47: 46204 | I47: Stores/Spares | J47: Hardware Items | K47: Stores & Spares | L47: stores & spares | M47: Allen Bolt 12X40 mm | N47: 30 | O47: 407.232 | P47: Allen Bolt 12X40 mm | Q47: 3507 | R47: 9 | S47: 36.6509 | T47: 9 | U47: 36.6509 | V47: 0 | W47: 0 | X47: 32.4 | Y47: 105.70176 | Z47: 0 | AA47: 24AAYFA5084G1Z4 | AB47: PCS | AC47: 73181500 | AD47: Rs. | AE47: 1 | AF47: 0 | AG47: India | AH47: N.A
B48: 46206 | C48: Axle Steel & Fasteners | D48: General Purchase | E48: GNSP 348 | F48: Purchase Withinstate- Stores, Spares & Consumable | G48: 0524/26-27 | H48: 46204 | I48: Stores/Spares | J48: Hardware Items | K48: Stores & Spares | L48: stores & spares | M48: Grub Screw 12X30 mm ( Ub / Tvs ) | N48: 50 | O48: 422.52 | P48: Grub Screw 12X30 mm ( Ub / Tvs ) | Q48: 0 | R48: 9 | S48: 38.0268 | T48: 9 | U48: 38.0268 | V48: 0 | W48: 0 | X48: 32.4 | Y48: 108.4536 | Z48: 0 | AA48: 24AAYFA5084G1Z4 | AB48: Pcs | AC48: 73181900 | AD48: Rs. | AE48: 1 | AF48: 0 | AG48: India | AH48: N.A
B49: 46206 | C49: Axle Steel & Fasteners | D49: General Purchase | E49: GNSP 348 | F49: Purchase Withinstate- Stores, Spares & Consumable | G49: 0524/26-27 | H49: 46204 | I49: Stores/Spares | J49: Hardware Items | K49: Stores & Spares | L49: stores & spares | M49: Allen Bolt 14X40 mm | N49: 30 | O49: 923.454 | P49: Allen Bolt 14X40 mm | Q49: 0 | R49: 9 | S49: 83.1109 | T49: 9 | U49: 83.1109 | V49: 0 | W49: 0 | X49: 32.4 | Y49: 198.62172 | Z49: 0 | AA49: 24AAYFA5084G1Z4 | AB49: Pcs | AC49: 731819 | AD49: Rs. | AE49: 1 | AF49: 0 | AG49: India | AH49: N.A
B50: 46206 | C50: Axle Steel & Fasteners | D50: General Purchase | E50: GNSP 348 | F50: Purchase Withinstate- Stores, Spares & Consumable | G50: 0524/26-27 | H50: 46204 | I50: Stores/Spares | J50: Hardware Items | K50: Stores & Spares | L50: stores & spares | M50: MS Hex Nipple 1/2" | N50: 3 | O50: 66 | P50: MS Hex Nipple 1/2" | Q50: 0 | R50: 9 | S50: 5.94 | T50: 9 | U50: 5.94 | V50: 0 | W50: 0 | X50: 32.4 | Y50: 44.28 | Z50: 0 | AA50: 24AAYFA5084G1Z4 | AB50: PCS | AC50: 730799 | AD50: Rs. | AE50: 1 | AF50: 0 | AG50: India | AH50: N.A
B51: 46206 | C51: Axle Steel & Fasteners | D51: General Purchase | E51: GNSP 348 | F51: Purchase Withinstate- Stores, Spares & Consumable | G51: 0524/26-27 | H51: 46204 | I51: Stores/Spares | J51: Hardware Items | K51: Stores & Spares | L51: stores & spares | M51: Hyd. Hex Nipple 1" | N51: 3 | O51: 126 | P51: Hyd. Hex Nipple 1" | Q51: 0 | R51: 9 | S51: 11.34 | T51: 9 | U51: 11.34 | V51: 0 | W51: 0 | X51: 32.4 | Y51: 55.08 | Z51: 0 | AA51: 24AAYFA5084G1Z4 | AB51: Pcs | AC51: 73079190 | AD51: Rs. | AE51: 1 | AF51: 0 | AG51: India | AH51: N.A
B52: 46206 | C52: Axle Steel & Fasteners | D52: General Purchase | E52: GNSP 348 | F52: Purchase Withinstate- Stores, Spares & Consumable | G52: 0524/26-27 | H52: 46204 | I52: Stores/Spares | J52: Hardware Items | K52: Stores & Spares | L52: stores & spares | M52: Hydraulic Hex Nipple 2" | N52: 3 | O52: 525 | P52: Hydraulic Hex Nipple 2" | Q52: 0 | R52: 9 | S52: 47.25 | T52: 9 | U52: 47.25 | V52: 0 | W52: 0 | X52: 32.4 | Y52: 126.9 | Z52: 0 | AA52: 24AAYFA5084G1Z4 | AB52: Pcs | AC52: 730700 | AD52: Rs. | AE52: 1 | AF52: 0 | AG52: India | AH52: N.A
B53: 46206 | C53: Axle Steel & Fasteners | D53: General Purchase | E53: GNSP 348 | F53: Purchase Withinstate- Stores, Spares & Consumable | G53: 0524/26-27 | H53: 46204 | I53: Stores/Spares | J53: Hardware Items | K53: Stores & Spares | L53: stores & spares | M53: Grub Screw 10X15 | N53: 100 | O53: 322.14 | P53: Grub Screw 10X15 | Q53: 0 | R53: 9 | S53: 28.9926 | T53: 9 | U53: 28.9926 | V53: 0 | W53: 0 | X53: 32.4 | Y53: 90.3852 | Z53: 0 | AA53: 24AAYFA5084G1Z4 | AB53: Pcs | AC53: 73181900 | AD53: Rs. | AE53: 1 | AF53: 0 | AG53: India | AH53: N.A
...

Sheet Sales
N1: 1283156 | O1: =N2-N1 -> 66170.25
N2: =SUBTOTAL(9,N4:N388) -> 1349326.3 | O2: =SUBTOTAL(9,O4:O388) -> 2.4852181e+08 | AF2: =SUBTOTAL(9,AF4:AF388) -> 1349326.3
B3: Date | C3: Particular | D3: Voucher Type | E3: Voucher No | F3: Type | G3: Invoice No | H3: Invoice Date | I3: Main Grp | J3: Group Name | K3: Sub Grup | L3: sales Group Name | M3: Item Name | N3: Quantity | O3: Amount | P3: Item Desc | Q3: Bill Amount | R3: CGST Rate | S3: CGST Amt | T3: SGST Rate | U3: SGST Amt | V3: IGST Rate | W3: IGST Amt | X3: Freight GST | Y3: Total GST | Z3: TCS | AA3: GST-IN | AB3: Unit | AC3: HSN Code | AD3: Currencty | AE3: Exc.Rate | AF3: Net Wt | AG3: Country | AH3: GROUP | AI3: 1
B4: 46204 | C4: Plastene India ltd - Unit 1-Sales | D4: Sales | E4: 380 | F4: Sales - Within State Manufactured Goods | G4: KPV/D/380 | H4: 46204 | I4: SF | J4: Yarn All | K4: PP Yarn | L4: PP Tape | M4: PP Fibrillated Tape Twisted 3200 MW | N4: 1210 | O4: 182891.5 | P4: MW | Q4: 215629.09 | R4: 9 | S4: 16460.24 | T4: 9 | U4: 16460.24 | V4: 0 | W4: 0 | X4: 0 | Y4: 32920.48 | Z4: 0 | AA4: 24AAACO3087C1ZT | AB4: KGS | AC4: 39199090 | AD4: Rs. | AE4: 1 | AF4: 1210 | AG4: India | AH4: PP Yarn
B5: 46204 | C5: Plastene India ltd - Unit 1-Sales | D5: Sales | E5: 382 | F5: Sales - Within State Manufactured Goods | G5: KPV/D/382 | H5: 46204 | I5: FG | J5: FIBC Bags | K5: FIBC Bags | L5: PP WOVEN BIG BAGS / SACKS | M5: FIBC Bags With UV With Liner | N5: 1241 | O5: 411019.2 | P5: 26.19378/67004952-UN | Q5: 1588073.1 | R5: 9 | S5: 36991.73 | T5: 9 | U5: 36991.73 | V5: 0 | W5: 0 | X5: 0 | Y5: 73983.46 | Z5: 0 | AA5: 24AAACO3087C1ZT | AB5: KGS | AC5: 63053200 | AD5: Rs. | AE5: 1 | AF5: 1241 | AG5: India | AH5: FIBC Bags
B6: 46204 | C6: Plastene India ltd - Unit 1-Sales | D6: Sales | E6: 382 | F6: Sales - Within State Manufactured Goods | G6: KPV/D/382 | H6: 46204 | I6: FG | J6: FIBC Bags | K6: FIBC Bags | L6: PP WOVEN BIG BAGS / SACKS | M6: FIBC Bags With UV Without Liner | N6: 2700.6 | O6: 935946.94 | P6: 26/80122/26131/15.1657-18 | Q6: 0 | R6: 9 | S6: 84235.22 | T6: 9 | U6: 84235.22 | V6: 0 | W6: 0 | X6: 0 | Y6: 168470.44 | Z6: 0 | AA6: 24AAACO3087C1ZT | AB6: KGS | AC6: 63053200 | AD6: Rs. | AE6: 1 | AF6: 2700.6 | AG6: India | AH6: FIBC Bags
B7: 46204 | C7: Plastene India ltd - Unit 1-Sales | D7: Sales | E7: 383 | F7: Sales - Within State Manufactured Goods | G7: KPV/D/383 | H7: 46204 | I7: FG | J7: FIBC Bags | K7: FIBC Bags | L7: PP WOVEN BIG BAGS / SACKS | M7: FIBC Bags With UV Without Liner | N7: 410 | O7: 98748.5 | P7: PIR-260149/4IBC-085-O010 | Q7: 116424.47 | R7: 9 | S7: 8887.36 | T7: 9 | U7: 8887.36 | V7: 0 | W7: 0 | X7: 0 | Y7: 17774.72 | Z7: 0 | AA7: 24AAACO3087C1ZT | AB7: KGS | AC7: 63053200 | AD7: Rs. | AE7: 1 | AF7: 410 | AG7: India | AH7: FIBC Bags
B8: 46204 | C8: Rudra Trading Co. | D8: Sales | E8: 381 | F8: Sales - Interstate - Manufactured Goods | G8: KPV/D/381 | H8: 46204 | I8: SF | J8: RP Granules | K8: RP Granules | L8: PP Granuals | M8: RP Granules | N8: 19000 | O8: 1280600 | P8: RP Granules GRAY | Q8: 1509827.4 | R8: 0 | S8: 0 | T8: 0 | U8: 0 | V8: 18 | W8: 230508 | X8: 0 | Y8: 230508 | Z8: 0 | AA8: 27BCGPD5673M1Z7 | AB8: KGS | AC8: 39029000 | AD8: Rs. | AE8: 1 | AF8: 19000 | AG8: India | AH8: RP Granules
B9: 46204 | C9: Yuan Da Plastic Fabric Corporation | D9: Export Sales | E9: KPW/E/88/26-27 | F9: Sales - Direct Export - Mfg - U/R | G9: KPW/E/88/26-27 | H9: 46204 | I9: FG | J9: FIBC Bags | K9: FIBC Bags | L9: PP WOVEN BIG BAGS / SACKS | M9: FIBC Bags With UV Without Liner | N9: 19021.4 | O9: 4308595.2 | P9: PP WOVEN BIG BAG | Q9: 4308595.2 | R9: 0 | S9: 0 | T9: 0 | U9: 0 | V9: 18 | W9: 775547.14 | X9: 0.17 | Y9: 775547.31 | Z9: 0 | AA9: N.A. | AB9: KGS | AC9: 63053200 | AD9: $ | AE9: 93.6 | AF9: 19021.4 | AG9: USA | AH9: FIBC Bags
B10: 46205 | C10: Conrop S.R.O. | D10: Export Sales | E10: KPW/E/89/26-27 | F10: Sales - Direct Export - Mfg - U/R | G10: KPW/E/89/26-27 | H10: 46205 | I10: SF | J10: PP/PE Fabric | K10: PP UL Fabric | L10: PP WOVEN FABRIC | M10: PP UL Fabric With UV | N10: 20346.2 | O10: 3798377.2 | P10: P WOVEN FABRIC | Q10: 4098074.6 | R10: 0 | S10: 0 | T10: 0 | U10: 0 | V10: 18 | W10: 683707.92 | X10: 53576.66 | Y10: 737284.58 | Z10: 0 | AA10: N.A. | AB10: KGS | AC10: 39269080 | AD10: € | AE10: 106.9 | AF10: 20346.2 | AG10: Czech Republic | AH10: PP UL Fabric
B11: 46205 | C11: HCP Plastene Bulkpack Limited - Sales | D11: Sales | E11: 385 | F11: Sales - Within State - Traded Goods | G11: KPV/D/385 | H11: 46205 | I11: Consumables | J11: Oil & Greases | K11: Stores & Spares | L11: Consumables | M11: White Oil:- 12 No | N11: 420 | O11: 54600 | P11: White Oil:- 12 No | Q11: 64373.4 | R11: 9 | S11: 4914 | T11: 9 | U11: 4914 | V11: 0 | W11: 0 | X11: 0 | Y11: 9828 | Z11: 0 | AA11: 24AABCG1282C2Z6 | AB11: KGS | AC11: 271019 | AD11: Rs. | AE11: 1 | AF11: 420 | AG11: India | AH11: N.A
B12: 46205 | C12: HCP Plastene Bulkpack Limited - Sales | D12: Job Invoice | E12: KPV/D/388 | F12: Job Work Income | G12: KPV/D/388 | H12: 46205 | I12: FG | J12: FIBC Bags | K12: FIBC Bags | L12: PP WOVEN BIG BAGS / SACKS | M12: FIBC Bags With UV Without Liner | N12: 2377.3 | O12: 461695.43 | P12: 26.19398/BH-C573EXP-1 (PP BIG BAGS) | Q12: 4585006.1 | R12: 9 | S12: 41552.59 | T12: 9 | U12: 41552.59 | V12: 0 | W12: 0 | X12: 0 | Y12: 83105.18 | Z12: 0 | AA12: 24AABCG1282C2Z6 | AB12: KGS | AC12: 998852 | AD12: Rs. | AE12: 1 | AF12: 2377.3 | AG12: India | AH12: FIBC Bags
B13: 46205 | C13: HCP Plastene Bulkpack Limited - Sales | D13: Job Invoice | E13: KPV/D/388 | F13: Job Work Income | G13: KPV/D/388 | H13: 46205 | I13: FG | J13: FIBC Bags | K13: FIBC Bags | L13: PP WOVEN BIG BAGS / SACKS | M13: FIBC Bags With UV Without Liner | N13: 5064 | O13: 1004191.2 | P13: 26.19397/BH-C573H (PP BIG BAGS) | Q13: 0 | R13: 9 | S13: 90377.21 | T13: 9 | U13: 90377.21 | V13: 0 | W13: 0 | X13: 0 | Y13: 180754.42 | Z13: 0 | AA13: 24AABCG1282C2Z6 | AB13: KGS | AC13: 998852 | AD13: Rs. | AE13: 1 | AF13: 5064 | AG13: India | AH13: FIBC Bags
B14: 46205 | C14: HCP Plastene Bulkpack Limited - Sales | D14: Job Invoice | E14: KPV/D/388 | F14: Job Work Income | G14: KPV/D/388 | H14: 46205 | I14: FG | J14: FIBC Bags | K14: FIBC Bags | L14: PP WOVEN BIG BAGS / SACKS | M14: FIBC Bags With UV Without Liner | N14: 10334.3 | O14: 2004027.5 | P14: 26.19399/BH-C573SL (PP BIG BAGS) | Q14: 0 | R14: 9 | S14: 180362.47 | T14: 9 | U14: 180362.47 | V14: 0 | W14: 0 | X14: 0 | Y14: 360724.94 | Z14: 0 | AA14: 24AABCG1282C2Z6 | AB14: KGS | AC14: 998852 | AD14: Rs. | AE14: 1 | AF14: 10334.3 | AG14: India | AH14: FIBC Bags
B15: 46205 | C15: HCP Plastene Bulkpack Limited - Sales | D15: Job Invoice | E15: KPV/D/388 | F15: Job Work Income | G15: KPV/D/388 | H15: 46205 | I15: FG | J15: FIBC Bags | K15: FIBC Bags | L15: PP WOVEN BIG BAGS / SACKS | M15: FIBC Bags With UV Without Liner | N15: 835.2 | O15: 165620.16 | P15: 26.19397/BH-C573H (PP BIG BAGS) | Q15: 0 | R15: 9 | S15: 14905.81 | T15: 9 | U15: 14905.81 | V15: 0 | W15: 0 | X15: 0 | Y15: 29811.62 | Z15: 0 | AA15: 24AABCG1282C2Z6 | AB15: KGS | AC15: 998852 | AD15: Rs. | AE15: 1 | AF15: 835.2 | AG15: India | AH15: FIBC Bags
