Workbook
Name __xlnm._FilterDatabase: #REF!
Name __xlnm._FilterDatabase_1: #REF!
Name __xlnm._FilterDatabase_2: #REF!
Name __xlnm.Print_Titles: #REF!
Name __xlnm.Print_Titles_1: #REF!
Name Excel_BuiltIn__FilterDatabase: [1]Debtors!$A$30:$G$221

Sheet JOB OUT
A1: Row Labels | B1: Sum of ItemQty
A2: (blank)
A3: (blank)
A4: Grand Total
E11: companyname | F11: ChallanNo | G11: sysdate | H11: Company Name | I11: NatureProc | J11: DescriptionGoods | K11: Deptt | L11: GroupName | M11: SubGroupName | N11: itemcode | O11: itemname | P11: Identification | Q11: QtyDesc | R11: ItemUnit | S11: ItemQty | T11: ItemValue | U11: TotalAmt | V11: VehicalNo | W11: LRNo | X11: TransportName

Sheet JOB-IN
A1: Row Labels | B1: Sum of Acceptedqty
A2: Parsva Trading | B2: 162.34
A3: Saru Plastics | B3: 848.3
A4: (blank)
A5: Grand Total | B5: 1010.64
G8: CompanyName | H8: Date | I8: srno | J8: Itemcode | K8: Itemname | L8: Indentsubcode | M8: PoNO | N8: OrderQty | O8: Challanqty | P8: Unit | Q8: Recdqty | R8: PendingQty | S8: Acceptedqty | T8: Vehicalno | U8: Partyname | V8: Suppliername | W8: ChallanNo | X8: Challan Date | Y8: category | Z8: subcategory | AA8: MRno | AB8: Rate | AC8: Amount | AD8: BillNo | AE8: Bill Date | AF8: ItemRemarks | AG8: Remarks | AH8: Note | AI8: Transportname | AJ8: Lrnodate | AK8: Discamt | AL8: Discamt1 | AM8: ExciseAmount | AN8: EducessAmount | AO8: HiEducessamount | AP8: InwardVatType | AQ8: Vatamount | AR8: Addvatamount | AS8: Frieght | AT8: Pkgfwd | AU8: Otherchg | AV8: Spdutyname | AW8: Spdutyamt | AX8: Additionalduty | AY8: Billamount | AZ8: Deptt | BA8: GroupName | BB8: SubGroupName | BC8: Deptt Po Indent | BD8: LoginName | BE8: servicetax | BF8: Basic Amount | BG8: GateInwardNo | BH8: GateInwardDate | BI8: VendorGST | BJ8: MRN User | BK8: POUserName | BL8: CGSTPer | BM8: CGSTAmount | BN8: SGSTPer | BO8: SGSTAmount | BP8: IGSTPer | BQ8: IGSTAmount | BR8: RBIllmount | BS8: EWayNo | BT8: EWayDt | BU8: netwt
G9: HCP Plastene Bulkpack Ltd (Unit - IV) | H9: 15-07-2026 | I9: HPBL4/26-27/SII00901 | J9: SMF00147 | K9: PE Labels (Kgs) | L9: No Subcode | M9: No PO | N9: 0 | O9: 102 | P9: Kgs | Q9: 102 | R9: 0 | S9: 102 | T9: GJ24V1087 | U9: Saru Plastics | V9: Saru Plastics | W9: SARU52 | X9: 27-06-2026 | Y9: JOB IN | Z9: SELF | AA9: JBIN-SE 34 | AB9: 0 | AC9: 0 | AD9: SARU52 | AE9: 27-06-2026 | AF9: 0 | AG9: PP Woven Big Bags, | AI9: OWN Vehical | AJ9: . | AK9: 0 | AL9: 0 | AM9: 0 | AN9: 0 | AO9: 0 | AP9: VAT | AQ9: 0 | AR9: 0 | AS9: 0 | AT9: 0 | AU9: 0 | AW9: 0 | AX9: 0 | AY9: 0 | AZ9: SF | BA9: Liners | BB9: LDPE/LLDPE Bags | BC9: SERVICES | BD9: erp | BE9: 0 | BF9: 0 | BG9: JW35 | BH9: 46029 | BI9: 24ACHPM5973F1ZG | BJ9: storepil6 | BL9: 0 | BM9: 0 | BN9: 0 | BO9: 0 | BP9: 0 | BQ9: 0 | BR9: 0 | BS9: . | BT9: 46218.681 | BU9: 102
G10: HCP Plastene Bulkpack Ltd (Unit - IV) | H10: 16-07-2026 | I10: HPBL4/26-27/SII00903 | J10: SMF00147 | K10: PE Labels (Kgs) | L10: No Subcode | M10: No PO | N10: 0 | O10: 72.1 | P10: Kgs | Q10: 72.1 | R10: 0 | S10: 72.1 | T10: GJ24V1087 | U10: Parsva Trading | V10: Parsva Trading | W10: 20 | X10: 46149 | Y10: JOB IN | Z10: SELF | AA10: JBIN-SE 35 | AB10: 0 | AC10: 0 | AD10: 20 | AE10: 46149 | AF10: 0 | AG10: PP Woven Big Bags, | AI10: OWN VEHICLE | AJ10: - | AK10: 0 | AL10: 0 | AM10: 0 | AN10: 0 | AO10: 0 | AP10: VAT | AQ10: 0 | AR10: 0 | AS10: 0 | AT10: 0 | AU10: 0 | AW10: 0 | AX10: 0 | AY10: 0 | AZ10: SF | BA10: Liners | BB10: LDPE/LLDPE Bags | BC10: SERVICES | BD10: erp | BE10: 0 | BF10: 0 | BG10: JW37 | BH10: 46302 | BI10: 24AMOPG6602J2Z0 | BJ10: storepil6 | BL10: 0 | BM10: 0 | BN10: 0 | BO10: 0 | BP10: 0 | BQ10: 0 | BR10: 0 | BS10: - | BT10: 46219.476 | BU10: 72.1
G11: HCP Plastene Bulkpack Ltd (Unit - IV) | H11: 16-07-2026 | I11: HPBL4/26-27/SII00907 | J11: SMF00147 | K11: PE Labels (Kgs) | L11: No Subcode | M11: No PO | N11: 0 | O11: 25 | P11: Kgs | Q11: 25 | R11: 0 | S11: 25 | T11: GJ24V1087 | U11: Saru Plastics | V11: Saru Plastics | W11: SARU054 | X11: 29-06-2026 | Y11: JOB IN | Z11: SELF | AA11: JBIN-SE 36 | AB11: 0 | AC11: 0 | AD11: SARU054 | AE11: 29-06-2026 | AF11: 0 | AG11: PP Woven Big Bags, | AI11: OWN VEHICLE | AJ11: - | AK11: 0 | AL11: 0 | AM11: 0 | AN11: 0 | AO11: 0 | AP11: VAT | AQ11: 0 | AR11: 0 | AS11: 0 | AT11: 0 | AU11: 0 | AW11: 0 | AX11: 0 | AY11: 0 | AZ11: SF | BA11: Liners | BB11: LDPE/LLDPE Bags | BC11: SERVICES | BD11: erp | BE11: 0 | BF11: 0 | BG11: JW36 | BH11: 46029 | BI11: 24ACHPM5973F1ZG | BJ11: storepil6 | BL11: 0 | BM11: 0 | BN11: 0 | BO11: 0 | BP11: 0 | BQ11: 0 | BR11: 0 | BS11: - | BT11: 46219.669 | BU11: 25
G12: HCP Plastene Bulkpack Ltd (Unit - IV) | H12: 16-07-2026 | I12: HPBL4/26-27/SII00908 | J12: SMF00147 | K12: PE Labels (Kgs) | L12: No Subcode | M12: No PO | N12: 0 | O12: 145 | P12: Kgs | Q12: 145 | R12: 0 | S12: 145 | T12: GJ24V1087 | U12: Saru Plastics | V12: Saru Plastics | W12: SARU055 | X12: 46060 | Y12: JOB IN | Z12: SELF | AA12: JBIN-SE 37 | AB12: 0 | AC12: 0 | AD12: SARU055 | AE12: 46060 | AF12: 0 | AG12: PP Woven Big Bags, | AI12: OWN VEHICLE | AJ12: - | AK12: 0 | AL12: 0 | AM12: 0 | AN12: 0 | AO12: 0 | AP12: VAT | AQ12: 0 | AR12: 0 | AS12: 0 | AT12: 0 | AU12: 0 | AW12: 0 | AX12: 0 | AY12: 0 | AZ12: SF | BA12: Liners | BB12: LDPE/LLDPE Bags | BC12: SERVICES | BD12: erp | BE12: 0 | BF12: 0 | BG12: JW38 | BH12: 46302 | BI12: 24ACHPM5973F1ZG | BJ12: storepil6 | BL12: 0 | BM12: 0 | BN12: 0 | BO12: 0 | BP12: 0 | BQ12: 0 | BR12: 0 | BS12: - | BT12: 46219 | BU12: 145
G13: HCP Plastene Bulkpack Ltd (Unit - IV) | H13: 16-07-2026 | I13: HPBL4/26-27/SII00909 | J13: SMF00147 | K13: PE Labels (Kgs) | L13: No Subcode | M13: No PO | N13: 0 | O13: 29 | P13: Kgs | Q13: 29 | R13: 0 | S13: 29 | T13: GJ24V1087 | U13: Saru Plastics | V13: Saru Plastics | W13: SARU057 | X13: 46088 | Y13: JOB IN | Z13: SELF | AA13: JBIN-SE 38 | AB13: 0 | AC13: 0 | AD13: SARU057 | AE13: 46088 | AF13: 0 | AG13: PP Woven Big Bags, | AI13: OWN Vehical | AJ13: . | AK13: 0 | AL13: 0 | AM13: 0 | AN13: 0 | AO13: 0 | AP13: VAT | AQ13: 0 | AR13: 0 | AS13: 0 | AT13: 0 | AU13: 0 | AW13: 0 | AX13: 0 | AY13: 0 | AZ13: SF | BA13: Liners | BB13: LDPE/LLDPE Bags | BC13: SERVICES | BD13: erp | BE13: 0 | BF13: 0 | BG13: JW39 | BH13: 46302 | BI13: 24ACHPM5973F1ZG | BJ13: storepil6 | BL13: 0 | BM13: 0 | BN13: 0 | BO13: 0 | BP13: 0 | BQ13: 0 | BR13: 0 | BS13: . | BT13: 46219 | BU13: 29
G14: HCP Plastene Bulkpack Ltd (Unit - IV) | H14: 16-07-2026 | I14: HPBL4/26-27/SII00910 | J14: SMF00147 | K14: PE Labels (Kgs) | L14: No Subcode | M14: No PO | N14: 0 | O14: 45.3 | P14: Kgs | Q14: 45.3 | R14: 0 | S14: 45.3 | T14: GJ24V1087 | U14: Saru Plastics | V14: Saru Plastics | W14: SARU058 | X14: 46119 | Y14: JOB IN | Z14: SELF | AA14: JBIN-SE 39 | AB14: 0 | AC14: 0 | AD14: SARU058 | AE14: 46119 | AF14: 0 | AG14: PP Woven Big Bags, | AI14: OWN Vehical | AJ14: . | AK14: 0 | AL14: 0 | AM14: 0 | AN14: 0 | AO14: 0 | AP14: VAT | AQ14: 0 | AR14: 0 | AS14: 0 | AT14: 0 | AU14: 0 | AW14: 0 | AX14: 0 | AY14: 0 | AZ14: SF | BA14: Liners | BB14: LDPE/LLDPE Bags | BC14: SERVICES | BD14: erp | BE14: 0 | BF14: 0 | BG14: JW39. | BH14: 46302 | BI14: 24ACHPM5973F1ZG | BJ14: storepil6 | BL14: 0 | BM14: 0 | BN14: 0 | BO14: 0 | BP14: 0 | BQ14: 0 | BR14: 0 | BS14: . | BT14: 46219.717 | BU14: 45.3
G15: HCP Plastene Bulkpack Ltd (Unit - IV) | H15: 16-07-2026 | I15: HPBL4/26-27/SII00911 | J15: SMF00147 | K15: PE Labels (Kgs) | L15: No Subcode | M15: No PO | N15: 0 | O15: 131 | P15: Kgs | Q15: 131 | R15: 0 | S15: 131 | T15: GJ24V1087 | U15: Saru Plastics | V15: Saru Plastics | W15: SARU060 | X15: 46241 | Y15: JOB IN | Z15: SELF | AA15: JBIN-SE 40 | AB15: 0 | AC15: 0 | AD15: SARU060 | AE15: 46241 | AF15: 0 | AG15: PP Woven Big Bags, | AI15: OWN Vehical | AJ15: . | AK15: 0 | AL15: 0 | AM15: 0 | AN15: 0 | AO15: 0 | AP15: VAT | AQ15: 0 | AR15: 0 | AS15: 0 | AT15: 0 | AU15: 0 | AW15: 0 | AX15: 0 | AY15: 0 | AZ15: SF | BA15: Liners | BB15: LDPE/LLDPE Bags | BC15: SERVICES | BD15: erp | BE15: 0 | BF15: 0 | BG15: JW40 | BH15: 46302 | BI15: 24ACHPM5973F1ZG | BJ15: storepil6 | BL15: 0 | BM15: 0 | BN15: 0 | BO15: 0 | BP15: 0 | BQ15: 0 | BR15: 0 | BS15: . | BT15: 46219 | BU15: 131
G16: HCP Plastene Bulkpack Ltd (Unit - IV) | H16: 18-07-2026 | I16: HPBL4/26-27/SII00936 | J16: SMF00147 | K16: PE Labels (Kgs) | L16: No Subcode | M16: No PO | N16: 0 | O16: 28 | P16: Kgs | Q16: 28 | R16: 0 | S16: 28 | T16: GJ24V1087 | U16: Saru Plastics | V16: Saru Plastics | W16: SARU061 | X16: 14-07-2026 | Y16: JOB IN | Z16: SELF | AA16: JBIN-SE 41 | AB16: 0 | AC16: 0 | AD16: SARU061 | AE16: 14-07-2026 | AF16: 0 | AG16: PP Woven Big Bags, | AI16: OWN Vehical | AJ16: . | AK16: 0 | AL16: 0 | AM16: 0 | AN16: 0 | AO16: 0 | AP16: VAT | AQ16: 0 | AR16: 0 | AS16: 0 | AT16: 0 | AU16: 0 | AW16: 0 | AX16: 0 | AY16: 0 | AZ16: SF | BA16: Liners | BB16: LDPE/LLDPE Bags | BC16: SERVICES | BD16: erp | BE16: 0 | BF16: 0 | BG16: 41 | BH16: 18-07-2026 | BI16: 24ACHPM5973F1ZG | BJ16: storepil6 | BL16: 0 | BM16: 0 | BN16: 0 | BO16: 0 | BP16: 0 | BQ16: 0 | BR16: 0 | BS16: . | BT16: 46221.646 | BU16: 28
G17: HCP Plastene Bulkpack Ltd (Unit - IV) | H17: 22-07-2026 | I17: HPBL4/26-27/SII00974 | J17: SMF00147 | K17: PE Labels (Kgs) | L17: No Subcode | M17: No PO | N17: 0 | O17: 37 | P17: Kgs | Q17: 37 | R17: 0 | S17: 37 | T17: GJ24V1087 | U17: Saru Plastics | V17: Saru Plastics | W17: SARU063 | X17: 18-07-2026 | Y17: JOB IN | Z17: SELF | AA17: JBIN-SE 42 | AB17: 0 | AC17: 0 | AD17: SARU063 | AE17: 18-07-2026 | AF17: 0 | AG17: PP Woven Big Bags, | AI17: OWN Vehical | AJ17: . | AK17: 0 | AL17: 0 | AM17: 0 | AN17: 0 | AO17: 0 | AP17: VAT | AQ17: 0 | AR17: 0 | AS17: 0 | AT17: 0 | AU17: 0 | AW17: 0 | AX17: 0 | AY17: 0 | AZ17: SF | BA17: Liners | BB17: LDPE/LLDPE Bags | BC17: SF | BD17: erp | BE17: 0 | BF17: 0 | BG17: 43 | BH17: 22-07-2026 | BI17: 24ACHPM5973F1ZG | BJ17: storepil6 | BL17: 0 | BM17: 0 | BN17: 0 | BO17: 0 | BP17: 0 | BQ17: 0 | BR17: 0 | BS17: . | BT17: 46225.726 | BU17: 37
G18: HCP Plastene Bulkpack Ltd (Unit - IV) | H18: 22-07-2026 | I18: HPBL4/26-27/SII00975 | J18: SMF00147 | K18: PE Labels (Kgs) | L18: No Subcode | M18: No PO | N18: 0 | O18: 69 | P18: Kgs | Q18: 69 | R18: 0 | S18: 69 | T18: GJ24V1087 | U18: Saru Plastics | V18: Saru Plastics | W18: SARU064 | X18: 20-07-2026 | Y18: JOB IN | Z18: SELF | AA18: JBIN-SE 43 | AB18: 0 | AC18: 0 | AD18: SARU064 | AE18: 20-07-2026 | AF18: 0 | AG18: PP Woven Big Bags, | AI18: OWN Vehical | AJ18: . | AK18: 0 | AL18: 0 | AM18: 0 | AN18: 0 | AO18: 0 | AP18: VAT | AQ18: 0 | AR18: 0 | AS18: 0 | AT18: 0 | AU18: 0 | AW18: 0 | AX18: 0 | AY18: 0 | AZ18: SF | BA18: Liners | BB18: LDPE/LLDPE Bags | BC18: SERVICES | BD18: erp | BE18: 0 | BF18: 0 | BG18: 42 | BH18: 21-07-2026 | BI18: 24ACHPM5973F1ZG | BJ18: storepil6 | BL18: 0 | BM18: 0 | BN18: 0 | BO18: 0 | BP18: 0 | BQ18: 0 | BR18: 0 | BS18: . | BT18: 46225.738 | BU18: 0
G19: HCP Plastene Bulkpack Ltd (Unit - IV) | H19: 29-07-2026 | I19: HPBL4/26-27/SII01032 | J19: SMF00147 | K19: PE Labels (Kgs) | L19: No Subcode | M19: No PO | N19: 0 | O19: 112 | P19: Kgs | Q19: 112 | R19: 0 | S19: 112 | T19: GJ12X5422 | U19: Saru Plastics | V19: Saru Plastics | W19: SARU068 | X19: 25-07-2026 | Y19: JOB IN | Z19: SELF | AA19: JBIN-SE 44 | AB19: 0 | AC19: 0 | AD19: SARU068 | AE19: 25-07-2026 | AF19: 0 | AG19: PP Woven Big Bags, | AI19: OWN Vehical | AJ19: . | AK19: 0 | AL19: 0 | AM19: 0 | AN19: 0 | AO19: 0 | AP19: VAT | AQ19: 0 | AR19: 0 | AS19: 0 | AT19: 0 | AU19: 0 | AW19: 0 | AX19: 0 | AY19: 0 | AZ19: SF | BA19: Liners | BB19: LDPE/LLDPE Bags | BC19: SERVICES | BD19: erp | BE19: 0 | BF19: 0 | BG19: 966 | BH19: 25-07-2026 | BI19: 24ACHPM5973F1ZG | BJ19: storepil6 | BL19: 0 | BM19: 0 | BN19: 0 | BO19: 0 | BP19: 0 | BQ19: 0 | BR19: 0 | BS19: . | BT19: 46232.671 | BU19: 112
G20: HCP Plastene Bulkpack Ltd (Unit - IV) | H20: 31-07-2026 | I20: HPBL4/26-27/SII01058 | J20: SMF00147 | K20: PE Labels (Kgs) | L20: No Subcode | M20: No PO | N20: 0 | O20: 61 | P20: Kgs | Q20: 61 | R20: 0 | S20: 61 | T20: GJ24V1087 | U20: Saru Plastics | V20: Saru Plastics | W20: SARU072 | X20: 28-07-2026 | Y20: JOB IN | Z20: SELF | AA20: JBIN-SE 45 | AB20: 0 | AC20: 0 | AD20: SARU072 | AE20: 28-07-2026 | AF20: 0 | AG20: PP Woven Big Bags, | AI20: OWN Vehical | AJ20: . | AK20: 0 | AL20: 0 | AM20: 0 | AN20: 0 | AO20: 0 | AP20: VAT | AQ20: 0 | AR20: 0 | AS20: 0 | AT20: 0 | AU20: 0 | AW20: 0 | AX20: 0 | AY20: 0 | AZ20: SF | BA20: Liners | BB20: LDPE/LLDPE Bags | BC20: SERVICES | BD20: erp | BE20: 0 | BF20: 0 | BG20: 45 | BH20: 30-07-2026 | BI20: 24ACHPM5973F1ZG | BJ20: storepil6 | BL20: 0 | BM20: 0 | BN20: 0 | BO20: 0 | BP20: 0 | BQ20: 0 | BR20: 0 | BS20: . | BT20: 46234.587 | BU20: 0
G21: HCP Plastene Bulkpack Ltd (Unit - IV) | H21: 31-07-2026 | I21: HPBL4/26-27/SII01059 | J21: SMF00147 | K21: PE Labels (Kgs) | L21: No Subcode | M21: No PO | N21: 0 | O21: 48 | P21: Kgs | Q21: 48 | R21: 0 | S21: 48 | T21: GJ24V1087 | U21: Saru Plastics | V21: Saru Plastics | W21: SARU073 | X21: 29-07-2026 | Y21: JOB IN | Z21: SELF | AA21: JBIN-SE 46 | AB21: 0 | AC21: 0 | AD21: SARU073 | AE21: 29-07-2026 | AF21: 0 | AG21: PP Woven Big Bags, | AI21: OWN Vehical | AJ21: . | AK21: 0 | AL21: 0 | AM21: 0 | AN21: 0 | AO21: 0 | AP21: VAT | AQ21: 0 | AR21: 0 | AS21: 0 | AT21: 0 | AU21: 0 | AW21: 0 | AX21: 0 | AY21: 0 | AZ21: SF | BA21: Liners | BB21: LDPE/LLDPE Bags | BC21: SERVICES | BD21: erp | BE21: 0 | BF21: 0 | BG21: 46 | BH21: 30-07-2026 | BI21: 24ACHPM5973F1ZG | BJ21: storepil6 | BL21: 0 | BM21: 0 | BN21: 0 | BO21: 0 | BP21: 0 | BQ21: 0 | BR21: 0 | BS21: . | BT21: 46234.592 | BU21: 0
G22: HCP Plastene Bulkpack Ltd (Unit - IV) | H22: 31-07-2026 | I22: HPBL4/26-27/SII01060 | J22: SMF00147 | K22: PE Labels (Kgs) | L22: No Subcode | M22: No PO | N22: 0 | O22: 16 | P22: Kgs | Q22: 16 | R22: 0 | S22: 16 | T22: GJ24V1087 | U22: Saru Plastics | V22: Saru Plastics | W22: SARU074 | X22: 30-07-2026 | Y22: JOB IN | Z22: SELF | AA22: JBIN-SE 47 | AB22: 0 | AC22: 0 | AD22: SARU074 | AE22: 30-07-2026 | AF22: 0 | AG22: PP Woven Big Bags, | AI22: OWN Vehical | AJ22: . | AK22: 0 | AL22: 0 | AM22: 0 | AN22: 0 | AO22: 0 | AP22: VAT | AQ22: 0 | AR22: 0 | AS22: 0 | AT22: 0 | AU22: 0 | AW22: 0 | AX22: 0 | AY22: 0 | AZ22: SF | BA22: Liners | BB22: LDPE/LLDPE Bags | BC22: SERVICES | BD22: erp | BE22: 0 | BF22: 0 | BG22: 44 | BH22: 30-07-2026 | BI22: 24ACHPM5973F1ZG | BJ22: storepil6 | BL22: 0 | BM22: 0 | BN22: 0 | BO22: 0 | BP22: 0 | BQ22: 0 | BR22: 0 | BS22: . | BT22: 46234.606 | BU22: 0
G23: HCP Plastene Bulkpack Ltd (Unit - IV) | H23: 31-07-2026 | I23: HPBL4/26-27/SII01071 | J23: SMF00147 | K23: PE Labels (Kgs) | L23: No Subcode | M23: No PO | N23: 0 | O23: 90.24 | P23: Kgs | Q23: 90.24 | R23: 0 | S23: 90.24 | T23: gj24v1087 | U23: Parsva Trading | V23: Parsva Trading | W23: 22 | X23: 22-07-2026 | Y23: JOB IN | Z23: SELF | AA23: JBIN-SE 48 | AB23: 0 | AC23: 0 | AD23: 22 | AE23: 22-07-2026 | AF23: 0 | AG23: PP Woven Big Bags, | AI23: OWN Vehical | AJ23: . | AK23: 0 | AL23: 0 | AM23: 0 | AN23: 0 | AO23: 0 | AP23: VAT | AQ23: 0 | AR23: 0 | AS23: 0 | AT23: 0 | AU23: 0 | AW23: 0 | AX23: 0 | AY23: 0 | AZ23: SF | BA23: Liners | BB23: LDPE/LLDPE Bags | BC23: SERVICES | BD23: erp | BE23: 0 | BF23: 0 | BG23: 47.. | BH23: 31-07-2026 | BI23: 24AMOPG6602J2Z0 | BJ23: storepil6 | BL23: 0 | BM23: 0 | BN23: 0 | BO23: 0 | BP23: 0 | BQ23: 0 | BR23: 0 | BS23: . | BT23: 46234.454 | BU23: 0

Sheet Provision & Prepaid Exp
A1: July-2026 Salary and Expense Provision Sheet | H1: PARTICULARS | J1: MT | L1: Avg. Rate
A2: Expense Head | B2: Gross Value | C2: CONTRACTOR SALARY | H2: BUDGETED / PLANNED | J2: 400
A3: Labour Charges | B3: 958550 | C3: LILI MANI CHHUAL SINGH (BKS) | H3: PRODUCTION
B4: 85442 | C4: BHABESH CHHUAL SINGH | H4: FIBC | J4: 481.055 | L4: 228.05 | M4: =+L4*0.95 -> 216.6475
B5: 300087 | C5: DHARAMVEER KUMAR PASWAN | H5: Fabric (Liner Mtr)
B6: 2055603 | C6: DHARAMVEER KUMAR PASWAN (LINE C)
B7: 1151040 | C7: DINESHBHAI KHUMABHAI DESAI | H7: DISPATCH
B8: 109307 | C8: JITENDRASINH B. ZALA | H8: FIBC | J8: 595.287 | L8: 228.05 | M8: =+L8*0.95 -> 216.6475
B9: 800315 | C9: RATAN CHANDRA SARKAR | H9: Fabric
B10: 799650 | C10: SUDHANSHU BARMAN
B11: 1754987 | C11: SAHDEVSINH FATEHSINH JADEJA | H11: PURCHASE
B12: 548964 | C12: RASIDUL MONDAL | H12: Fabric | J12: 382.735 | L12: 145.68118
B13: 0 | C13: DIVYANSHU ENTERPRISES | H13: PP Granules
C14: COMPANY SALARY
H15: Consumable/Store Spares | J15: 5822557.5
A16: Expense Head | B16: Gross Value | C16: Party Name | H16: Packing Material | J16: 1649149.4
A17: P.F. Contribution - Employer | B17: =36500+3200 -> 39700 | C17: Month of July 2026 | D17: Approx
A18: Advocate Fees Exp. | B18: 7500 | C18: Joshi Brothers
A19: Staff Welfare Exp. | B19: 0 | C19: Rahul Govindram
A20: Freight Outward Expense (With GST) | B20: 7189365 | C20: SHIPPING LINE | D20: Approx
A21: C & F Charges-Export | B21: 559820 | C21: SHIPPING LINE | D21: Approx
A22: Freight outward Expenses (RCM_Withinstate) | B22: 12200 | C22: Giriraj Tempo Service
A23: House Keeping Expense | B23: 0 | C23: Laxman Murjibhai Lakhwana
A24: Medical Expense | B24: 2260 | C24: NIMAVAT HOSPITAL
A25: Incentive Expense - Production | B25: 11000 | C25: SS
A26: Mobile & Telephone Expense | B26: 6998 | C26: Vihaan Telecomunication
A27: Freight outward Expenses (RCM_Withinstate) | B27: 0 | C27: Laxman B
A28: Water Charges | B28: 131100 | C28: Krishna Enterprise
A29: FUMIGATION EXPENSES | B29: 0 | C29: SENSATION PEST
A30: Repairs & Maintenance Exp - Computer & Printers | B30: 7050 | C30: VISHWAS ENTERPRISES
A31: VEHICLE HIRE CHARGES | B31: 0 | C31: ARVIND CHAUHAN
A32: WEIGHMENT CHARGES | B32: 0 | C32: SHREE SHYAM WEIGH BRIDGE
A33: SECURITY CHARGES | B33: 0 | C33: INDIAN SECURITY
A34: Testing Charges | B34: =29000+52200 -> 81200 | C34: INDIAN INSTITUE OF PACKAGING-AHMD
A35: Repair & Maintance- Plant & M/c | B35: 0 | C35: Shree Krishnam Rubtech LLP
A36: Freight outward Expenses (RCM_Withinstate) | B36: 9400 | C36: Pareshbhai Khumabhai Desai
B37: =SUM(B3:B36) -> 16621538 | C37: TOTAL AMOUNT

Sheet Sheet7
B2: Delta Conversion Rate for the M/o.Feb-2024
B3: A-SALES | F3: SALES RATE
C5: ITEM NAME | D5: QTY. | E5: AMOUNT | F5: RATE/KGS.
C6: JUMBO BAGS | D6: 406016.1 | E6: 61264012 | F6: =+E6/D6 -> 150.8906
F7: PURCHASE RATE
B9: B-PURCHASE | C9: ITEM NAME | D9: QTY. | E9: AMOUNT | F9: RATE/KGS.
C10: LLDPE BAGS | D10: 49687.4 | E10: 6118732.2 | F10: =+E10/D10 -> 123.14454
C11: LLDPE DOC | D11: 846.1 | E11: 102637.23 | F11: =+E11/D11 -> 121.30626
C12: LLDPE FILM | D12: 909.7 | E12: 104412.64 | F12: =+E12/D12 -> 114.777
C13: PP FILAMENT YARN | D13: 10591.2 | E13: 1396913.7 | F13: =+E13/D13 -> 131.89381
C14: PP LAMINATED WOVEN FABRIC | D14: 31724.2 | E14: 3839698.8 | F14: =+E14/D14 -> 121.03375
C15: PP WOVEN FABRIC | D15: 264543.8 | E15: 30961911 | F15: =+E15/D15 -> 117.03888
C16: PP WEBBING | D16: 57892.5 | E16: 6893788.5 | F16: =+E16/D16 -> 119.07913
D17: =SUM(D10:D16) -> 416194.9 | E17: =SUM(E10:E16) -> 49418094 | F17: =+E17/D17 -> 118.73786
D19: DIFFERENCE (A-B) DELTA | F19: =+F6-F17 -> 32.152733
B21: Month Wise Conversion Rate Sheet-PIL-VI
B22: 2023-24 | C22: RAW MATERIAL PURCHASE | F22: FINISHED FIBC SALES | I22: Delta
B23: Month | C23: QTY | D23: Rate | E23: Amount | F23: QTY | G23: Rate | H23: Amount | I23: Conversion
B24: Nov.23 | C24: 396215.1 | D24: =+E24/C24 -> 111.94216 | E24: 44353173 | F24: 422404.1 | G24: =+H24/F24 -> 162.14543 | H24: 68490895 | I24: =+G24-D24 -> 50.203275
B25: Dec.23 | C25: 425293.1 | D25: =+E25/C25 -> 112.11408 | E25: 47681346 | F25: 308715.72 | G25: =+H25/F25 -> 159.86059 | H25: 49351478 | I25: =+G25-D25 -> 47.746509
B26: Jan.24 | C26: 365699.21 | D26: =+E26/C26 -> 116.0993 | E26: 42457424 | F26: 472444 | G26: =+H26/F26 -> 153.16551 | H26: 72362124 | I26: =+G26-D26 -> 37.066201
B27: Feb.24 | C27: 416194.9 | D27: =+E27/C27 -> 118.73786 | E27: 49418094 | F27: 406016.1 | G27: =+H27/F27 -> 150.8906 | H27: 61264012 | I27: =+G27-D27 -> 32.152733
B28: Mar.24
B29: Total/Av. | C29: =SUM(C24:C28) -> 1603402.3 | D29: =+E29/C29 -> 114.69987 | E29: =SUM(E24:E28) -> 1.8391004e+08 | F29: =SUM(F24:F28) -> 1609579.9 | G29: =+H29/F29 -> 156.23238 | H29: =SUM(H24:H28) -> 2.5146851e+08 | I29: =+G29-D29 -> 41.532515

Sheet Rate Diference
S1: 2024-25 | T1: RAW MATERIAL PURCHASE | W1: FINISHED FIBC SALES | Z1: DELTA | AA1: Production | AB1: FIBC-Sales
B2: RATE DIFF SHEET – JULY-26 | J2: 2026-27 | K2: RAW MATERIAL PURCHASE | N2: FINISHED FIBC SALES | Q2: DELTA | S2: Apr.24 | T2: 456298.1 | U2: =+V2/T2 -> 117.1409 | V2: 53451171 | W2: 498791.3 | X2: =+Y2/W2 -> 158.02997 | Y2: 78823974 | Z2: =+X2-U2 -> 40.889068 | AA2: 356072 | AB2: 498791.3
B3: HPBL-IV to KPW-3 | C3: W LINER (FG) | D3: 0 | J3: Month | K3: QTY | L3: Rate | M3: Amount | N3: QTY | O3: Rate | P3: Amount | Q3: Conversion | S3: May.24 | T3: 434014.46 | U3: =+V3/T3 -> 117.83357 | V3: 51141473 | W3: 469980.3 | X3: =+Y3/W3 -> 160.54472 | Y3: 75452854 | Z3: =+X3-U3 -> 42.711149 | AA3: 407666 | AB3: 469980.3
C4: W/O LINER (FG) | D4: 0 | E4: =+D3+D4 -> 0 | J4: Mar.26 | K4: 499128.4 | L4: 148.6568 | M4: 74198830 | N4: 578392.7 | O4: 180.78847 | P4: 1.0456673e+08 | Q4: 32.131674 | R4: HPBL-IV | S4: June.24 | T4: 522544.44 | U4: =+V4/T4 -> 119.40562 | V4: 62394742 | W4: 418456.2 | X4: =+Y4/W4 -> 160.25586 | Y4: 67060060 | Z4: =+X4-U4 -> 40.850244 | AA4: 415459 | AB4: 418456.2
B5: PIL TO HPBL-IV | C5: FIBC BAGS | D5: 0 | J5: Apr.26 | K5: 506866.58 | L5: =+M5/K5 -> 165.44926 | M5: 83860700 | N5: 405825 | O5: =+P5/N5 -> 220.19842 | P5: 89362024 | Q5: =+O5-L5 -> 54.749163 | R5: HPBL-IV | S5: July.24 | T5: 526452.8 | U5: =+V5/T5 -> 121.73334 | V5: 64086856 | W5: =498942.6-2212 -> 496730.6 | X5: =+Y5/W5 -> 156.90634 | Y5: =77966725.42-26544 -> 77940181 | Z5: =+X5-U5 -> 35.173004 | AA5: 406477 | AB5: 498942.6
B6: OEL to HPBL-IV | C6: RM DIFF (OEL) | D6: 0 | J6: May.26 | K6: 428496.94 | L6: =+M6/K6 -> 129.78421 | M6: 55612136 | N6: 487917 | O6: =+P6/N6 -> 250.40064 | P6: 1.2217473e+08 | Q6: =+O6-L6 -> 120.61644 | R6: HPBL-IV | S6: Aug.24 | T6: 476002.36 | U6: =+V6/T6 -> 119.99106 | V6: 57116029 | W6: 456757 | X6: =+Y6/W6 -> 157.19353 | Y6: 71799243 | Z6: =+X6-U6 -> 37.202464 | AA6: 374454 | AB6: 456757
B7: KPW to HPBL-IV | C7: FG DIFF (KPW) | D7: 0 | E7: =+D6+D7+D5 -> 0 | J7: June.26 | K7: 473714.14 | L7: =+M7/K7 -> 151.75376 | M7: 71887902 | N7: 332726 | O7: =+P7/N7 -> 248.41289 | P7: 82653428 | Q7: =+O7-L7 -> 96.659134 | R7: HPBL-IV | S7: Sept.24 | T7: 565051.98 | U7: =+V7/T7 -> 117.2838 | V7: 66271444 | W7: 755511.4 | X7: =+Y7/W7 -> 167.73592 | Y7: 1.267264e+08 | Z7: =+X7-U7 -> 50.452124 | AA7: 476185 | AB7: 750187.2
C8: NET DIFF | D8: =+E4+E7 -> 0 | E8: OEL/KPW3/KPW-1 | J8: July.26 | K8: 547753.42 | L8: =+M8/K8 -> 152.92043 | M8: 83762688 | N8: 595287.7 | O8: =+P8/N8 -> 228.04789 | P8: 1.357541e+08 | Q8: =+O8-L8 -> 75.127457 | R8: HPBL-IV | S8: Oct.24 | T8: 604520.36 | U8: =+V8/T8 -> 117.82276 | V8: 71226258 | W8: 594994.1 | X8: =+Y8/W8 -> 173.88636 | Y8: 1.0346136e+08 | Z8: =+X8-U8 -> 56.063599 | AA8: 465076 | AB8: 594994.1
C9: Wastage Rate Diff. | D9: 1127835 | J9: Total/Av. | K9: =SUM(K5:K8) -> 1956831.1 | L9: =+M9/K9 -> 150.81702 | M9: =SUM(M5:M8) -> 2.9512343e+08 | N9: =SUM(N5:N8) -> 1821755.7 | O9: =+P9/N9 -> 236.00546 | P9: =SUM(P5:P8) -> 4.2994428e+08 | Q9: =+O9-L9 -> 85.18844 | R9: HPBL-IV | S9: Nov.24 | T9: 498019.1 | U9: =+V9/T9 -> 117.73229 | V9: 58632930 | W9: 599632.9 | X9: =+Y9/W9 -> 171.99244 | Y9: 1.0313232e+08 | Z9: =+X9-U9 -> 54.260143 | AA9: 463388 | AB9: 599632.9
C10: LC Pack. Wastage | D10: 0 | S10: Dec.24 | T10: 609575.11 | U10: =+V10/T10 -> 115.59297 | V10: 70462597 | W10: 546433.9 | X10: =+Y10/W10 -> 165.24191 | Y10: 90293780 | Z10: =+X10-U10 -> 49.648939 | AA10: 530455 | AB10: 546433.9
C11: Total Rate Diff. | D11: =+D8+D9+D10 -> 1127835 | E11: Rate Difference to be consider | S11: Jan.25 | T11: 564302.03 | U11: =+V11/T11 -> 117.80843 | V11: 66479538 | W11: 743253.8 | X11: =+Y11/W11 -> 165.12415 | Y11: 1.2272915e+08 | Z11: =+X11-U11 -> 47.315718 | AA11: 505763 | AB11: 743253.8
S12: Feb.25 | T12: 591945.54 | U12: =+V12/T12 -> 121.73734 | V12: 72061876 | W12: 715664.9 | X12: =+Y12/W12 -> 174.93486 | Y12: 1.2519474e+08 | Z12: =+X12-U12 -> 53.197523 | AA12: 467210 | AB12: 715664.9
S13: Mar.25 | T13: 517056.39 | U13: =+V13/T13 -> 124.09667 | V13: 64164978 | W13: 560251.9 | X13: =+Y13/W13 -> 189.87025 | Y13: 1.0637517e+08 | Z13: =+X13-U13 -> 65.773572 | AA13: 459730 | AB13: 560251.9
B14: Wastage Rate Difference Sheet-JULY-2026 | S14: TOTAL | T14: =SUM(T2:T13) -> 6365782.7 | U14: =+V14/T14 -> 118.99399 | V14: =SUM(V2:V13) -> 7.5748989e+08 | W14: =SUM(W2:W13) -> 6856458.3 | X14: =+Y14/W14 -> 167.57766 | Y14: =SUM(Y2:Y13) -> 1.1489892e+09 | Z14: =+X14-U14 -> 48.583668 | AA14: =SUM(AA2:AA13) -> 5327935 | AB14: =SUM(AB2:AB13) -> 6853346.1
S15: 2025-26 | T15: HPBL-IV
B16: WASTAGE SALE - JULY'26 | S16: Apr.25 | T16: 756969.15 | U16: =+V16/T16 -> 121.37935 | V16: 91880426 | W16: 292137.2 | X16: =+Y16/W16 -> 176.28738 | Y16: 51500101 | Z16: =+X16-U16 -> 54.908025 | AA16: 464875 | AB16: 292137.2
B17: DATE | C17: NO.1 | D17: NO.2 | E17: NO.3 | F17: NO.4 | G17: TOTAL | H17: Invoice | S17: May.25 | T17: 473583.37 | U17: =+V17/T17 -> 117.22124 | V17: 55514030 | W17: 459832 | X17: =+Y17/W17 -> 178.56896 | Y17: 82111722 | Z17: =+X17-U17 -> 61.34772 | AA17: 407546 | AB17: 459832
B18: 46060 | C18: 1198 | D18: 728 | E18: 152 | F18: 0 | G18: =+C18+D18+E18+F18 -> 2078 | H18: HPBL4/D/140 | S18: June.25 | T18: 430845.64 | U18: =+V18/T18 -> 117.47757 | V18: 50614698 | W18: 444822.5 | X18: =+Y18/W18 -> 191.32588 | Y18: 85106054 | Z18: =+X18-U18 -> 73.848308 | AA18: 410451 | AB18: 444822.5
B19: 46119 | C19: 1736 | D19: 1096 | E19: 315 | F19: 0 | G19: =+C19+D19+E19+F19 -> 3147 | H19: HPBL4/D/145 | S19: July.25 | T19: 572685.4 | U19: =+V19/T19 -> 118.07103 | V19: 67617554 | W19: 510650.3 | X19: =+Y19/W19 -> 186.37147 | Y19: 95170646 | Z19: =+X19-U19 -> 68.300441 | AA19: 533251 | AB19: 510650.3
B20: 46210 | C20: 662 | D20: 1068 | E20: 154 | F20: 0 | G20: =+C20+D20+E20+F20 -> 1884 | H20: HPBL4/D/153 | S20: Aug.25 | T20: 573966.8 | U20: =+V20/T20 -> 117.56081 | V20: 67475999 | W20: 479775.9 | X20: =+Y20/W20 -> 179.13429 | Y20: 85944313 | Z20: =+X20-U20 -> 61.57348 | AA20: 494357 | AB20: 479775.9
B21: 46333 | C21: 1086 | D21: 2078 | E21: 329 | F21: 0 | G21: =+C21+D21+E21+F21 -> 3493 | H21: HPBL4/D/160 | S21: Sept.25 | T21: 565461.8 | U21: =+V21/T21 -> 113.57263 | V21: 64220984 | W21: 690216.1 | X21: =+Y21/W21 -> 186.14542 | Y21: 1.2848057e+08 | Z21: =+X21-U21 -> 72.572792 | AA21: 522545 | AB21: 690216.1
B22: 14/07/2026 | C22: 1770 | D22: 1132 | E22: 0 | F22: 0 | G22: =+C22+D22+E22+F22 -> 2902 | H22: HPBL4/D/162 | S22: Oct.25 | T22: 571721.2 | U22: =+V22/T22 -> 112.24911 | V22: 64175198 | W22: 537984.8 | X22: =+Y22/W22 -> 178.59256 | Y22: 96080085 | Z22: =+X22-U22 -> 66.343451 | AA22: 539698 | AB22: 537984.8
B23: 15/07/2026 | C23: 969 | D23: 1160 | E23: 231 | F23: 0 | G23: =+C23+D23+E23+F23 -> 2360 | H23: HPBL4/D/166 | S23: Nov.25 | T23: 440596.55 | U23: =+V23/T23 -> 110.86507 | V23: 48846765 | W23: 477558.5 | X23: =+Y23/W23 -> 171.66995 | Y23: 81982444 | Z23: =+X23-U23 -> 60.804885 | AA23: 428097 | AB23: 477558.5
B24: 18/07/2026 | C24: 1245 | D24: 985 | E24: 30 | F24: 0 | G24: =+C24+D24+E24+F24 -> 2260 | H24: HPBL4/D/169 | S24: Dec.25 | T24: 515991.28 | U24: =+V24/T24 -> 109.27315 | V24: 56383992 | W24: 626206.1 | X24: =+Y24/W24 -> 178.13698 | Y24: 1.1155047e+08 | Z24: =+X24-U24 -> 68.863836 | AA24: 482833 | AB24: 626206.1
B25: 19/07/2026 | C25: 1081 | D25: 893 | E25: 0 | F25: 0 | G25: =+C25+D25+E25+F25 -> 1974 | H25: HPBL4/D/171 | S25: Jan.26 | T25: 579217.78 | U25: =+V25/T25 -> 110.21485 | V25: 63838403 | W25: 473359.8 | X25: =+Y25/W25 -> 177.36297 | Y25: 83956500 | Z25: =+X25-U25 -> 67.148116 | AA25: 475054 | AB25: 473359.8
B26: 21/07/2026 | C26: 1134 | D26: 1042 | E26: 250 | F26: 0 | G26: =+C26+D26+E26+F26 -> 2426 | H26: HPBL4/D/175 | S26: Feb.26 | T26: 507669.08 | U26: =+V26/T26 -> 116.50724 | V26: 59147123 | W26: 462589.4 | X26: =+Y26/W26 -> 174.85136 | Y26: 80884384 | Z26: =+X26-U26 -> 58.344116 | AA26: 404462 | AB26: 462589
B27: 26/07/2026 | C27: 3203 | D27: 2048 | E27: 0 | F27: 0 | G27: =+C27+D27+E27+F27 -> 5251 | H27: HPBL4/D/183 | S27: Mar.26 | T27: 499128.4 | U27: =+V27/T27 -> 148.6568 | V27: 74198830 | W27: 578392.7 | X27: =+Y27/W27 -> 180.78847 | Y27: 1.0456673e+08 | Z27: =+X27-U27 -> 32.131674 | AA27: 514365 | AB27: 578392.7
B28: TOTAL | C28: =SUM(C18:C27) -> 14084 | D28: =SUM(D18:D27) -> 12230 | E28: =SUM(E18:E27) -> 1461 | F28: =SUM(F18:F27) -> 0 | G28: =SUM(G18:G27) -> 27775 | S28: TOTAL | T28: =SUM(T16:T27) -> 6487836.5 | U28: =+V28/T28 -> 117.74557 | V28: =SUM(V16:V27) -> 7.63914e+08 | W28: =SUM(W16:W27) -> 6033525.3 | X28: =+Y28/W28 -> 180.21537 | Y28: =SUM(Y16:Y27) -> 1.087334e+09 | Z28: =+X28-U28 -> 62.469803 | AA28: =SUM(AA16:AA27) -> 5677534 | AB28: =SUM(AB16:AB27) -> 6033524.9
C29: 60 | D29: 45 | E29: 45 | F29: 18 | S29: 2026-27
C30: =+C28*C29 -> 845040 | D30: =+D28*D29 -> 550350 | E30: =+E28*E29 -> 65745 | F30: =+F28*F29 -> 0 | G30: =+G28*12 -> 333300 | S30: Apr.26 | T30: 506866.58 | U30: =+V30/T30 -> 165.44926 | V30: 83860700 | W30: 405825 | X30: =+Y30/W30 -> 220.19842 | Y30: 89362024 | Z30: =+X30-U30 -> 54.749163 | AA30: 416165 | AB30: 405825
G31: =+F32-G30 -> 1127835 | H31: Rate Difference To be consider | S31: May.26 | T31: 428496.94 | U31: =+V31/T31 -> 129.78421 | V31: 55612136 | W31: 487917 | X31: =+Y31/W31 -> 250.40064 | Y31: 1.2217473e+08 | Z31: =+X31-U31 -> 120.61644 | AA31: 419864 | AB31: 487917
F32: =+C30+D30+E30+F30 -> 1461135 | S32: June.26 | T32: 473714.14 | U32: =+V32/T32 -> 151.75376 | V32: 71887902 | W32: 332726 | X32: =+Y32/W32 -> 248.41289 | Y32: 82653428 | Z32: =+X32-U32 -> 96.659134 | AA32: 413289 | AB32: 332726
S33: July.26 | T33: 547753.42 | U33: =+V33/T33 -> 152.92043 | V33: 83762688 | W33: 595287.7 | X33: =+Y33/W33 -> 228.04789 | Y33: 1.357541e+08 | Z33: =+X33-U33 -> 75.127457 | AA33: 481055 | AB33: 595287.7
S34: TOTAL | T34: =SUM(T30:T33) -> 1956831.1 | U34: =+V34/T34 -> 150.81702 | V34: =SUM(V30:V33) -> 2.9512343e+08 | W34: =SUM(W30:W33) -> 1821755.7 | X34: =+Y34/W34 -> 236.00546 | Y34: =SUM(Y30:Y33) -> 4.2994428e+08 | Z34: =+X34-U34 -> 85.18844 | AA34: =SUM(AA30:AA33) -> 1730373 | AB34: =SUM(AB30:AB33) -> 1821755.7

Sheet Purchase Register
A1: Particular | B1: (All)
A3: Row Labels | B3: Sum of Quantity | C3: Sum of Amount
A4: JUMBO BAG | B4: 43346.7 | C4: 8447671.8 | D4: =+GETPIVOTDATA("Sum of Amount",$A$3,"purchase Group Name","JUMBO BAG")/GETPIVOTDATA("Sum of Quantity",$A$3,"purchase Group Name","JUMBO BAG") -> 194.88616 | H4: Raw Material | I4: Qty. | J4: Amount | K4: Rate/Kgs.
A5: LLDPE Bags | B5: 92085.96 | C5: 16914527 | D5: =+GETPIVOTDATA("Sum of Amount",$A$3,"purchase Group Name","LLDPE Bags")/GETPIVOTDATA("Sum of Quantity",$A$3,"purchase Group Name","LLDPE Bags") -> 183.68193 | E5: =+GETPIVOTDATA("Sum of Quantity",$A$3,"purchase Group Name","LLDPE Bags")+GETPIVOTDATA("Sum of Quantity",$A$3,"purchase Group Name","LLDPE Doc") -> 94528.46 | H5: LLDPE Bags | I5: =+GETPIVOTDATA("Sum of Quantity",$A$3,"purchase Group Name","LLDPE Bags") -> 92085.96 | J5: =+GETPIVOTDATA("Sum of Amount",$A$3,"purchase Group Name","LLDPE Bags") -> 16914527 | K5: =+J5/I5 -> 183.68193
A6: LLDPE Doc | B6: 2442.5 | C6: 441380 | D6: =+GETPIVOTDATA("Sum of Amount",$A$3,"purchase Group Name","LLDPE Doc")/GETPIVOTDATA("Sum of Quantity",$A$3,"purchase Group Name","LLDPE Doc") -> 180.70829 | E6: =+GETPIVOTDATA("Sum of Amount",$A$3,"purchase Group Name","LLDPE Bags")+GETPIVOTDATA("Sum of Amount",$A$3,"purchase Group Name","LLDPE Doc") -> 17355907 | F6: =+E6/E5 -> 183.60509 | H6: LLDPE Doc | I6: =+GETPIVOTDATA("Sum of Quantity",$A$3,"purchase Group Name","LLDPE Doc") -> 2442.5 | J6: =+GETPIVOTDATA("Sum of Amount",$A$3,"purchase Group Name","LLDPE Doc") -> 441380 | K6: =+J6/I6 -> 180.70829
A7: PP Filament Yarn | B7: 11028.86 | C7: 1715238.3 | D7: =+GETPIVOTDATA("Sum of Amount",$A$3,"purchase Group Name","PP Filament Yarn")/GETPIVOTDATA("Sum of Quantity",$A$3,"purchase Group Name","PP Filament Yarn") -> 155.52272 | H7: PP Filament Yarn | I7: =+GETPIVOTDATA("Sum of Quantity",$A$3,"purchase Group Name","PP Filament Yarn") -> 11028.86 | J7: =+GETPIVOTDATA("Sum of Amount",$A$3,"purchase Group Name","PP Filament Yarn") -> 1715238.3 | K7: =+J7/I7 -> 155.52272
A8: PP Laminated Woven Fabric | B8: 51178.8 | C8: 7699730.1 | D8: =+GETPIVOTDATA("Sum of Amount",$A$3,"purchase Group Name","PP Laminated Woven Fabric")/GETPIVOTDATA("Sum of Quantity",$A$3,"purchase Group Name","PP Laminated Woven Fabric") -> 150.44765 | H8: PP Laminated Woven Fabric | I8: =+GETPIVOTDATA("Sum of Quantity",$A$3,"purchase Group Name","PP Laminated Woven Fabric") -> 51178.8 | J8: =+GETPIVOTDATA("Sum of Amount",$A$3,"purchase Group Name","PP Laminated Woven Fabric") -> 7699730.1 | K8: =+J8/I8 -> 150.44765
A9: PP Webbing | B9: 50926.8 | C9: 7599377.8 | D9: =+GETPIVOTDATA("Sum of Amount",$A$3,"purchase Group Name","PP Webbing")/GETPIVOTDATA("Sum of Quantity",$A$3,"purchase Group Name","PP Webbing") -> 149.22159 | E9: =+GETPIVOTDATA("Sum of Amount",$A$3,"purchase Group Name","PP Laminated Woven Fabric")+GETPIVOTDATA("Sum of Amount",$A$3,"purchase Group Name","PP Woven Fabric") -> 55757303 | H9: PP Webbing | I9: =+GETPIVOTDATA("Sum of Quantity",$A$3,"purchase Group Name","PP Webbing") -> 50926.8 | J9: =+GETPIVOTDATA("Sum of Amount",$A$3,"purchase Group Name","PP Webbing") -> 7599377.8 | K9: =+J9/I9 -> 149.22159
A10: PP Woven Fabric | B10: 331556.3 | C10: 48057573 | D10: =+GETPIVOTDATA("Sum of Amount",$A$3,"purchase Group Name","PP Woven Fabric")/GETPIVOTDATA("Sum of Quantity",$A$3,"purchase Group Name","PP Woven Fabric") -> 144.94544 | E10: =+GETPIVOTDATA("Sum of Quantity",$A$3,"purchase Group Name","PP Laminated Woven Fabric")+GETPIVOTDATA("Sum of Quantity",$A$3,"purchase Group Name","PP Woven Fabric") -> 382735.1 | F10: =+E9/E10 -> 145.68118 | H10: PP Woven Fabric | I10: =+GETPIVOTDATA("Sum of Quantity",$A$3,"purchase Group Name","PP Woven Fabric")+GETPIVOTDATA("Sum of Quantity",$A$3,"purchase Group Name","FIBC WIP") -> 340008 | J10: =+GETPIVOTDATA("Sum of Amount",$A$3,"purchase Group Name","PP Woven Fabric")+GETPIVOTDATA("Sum of Amount",$A$3,"purchase Group Name","FIBC WIP") -> 49371709 | K10: =+J10/I10 -> 145.20749
A11: LLDPE FILM | B11: 82.5 | C11: 20726 | D11: =+GETPIVOTDATA("Sum of Amount",$A$3,"purchase Group Name","LLDPE FILM")/GETPIVOTDATA("Sum of Quantity",$A$3,"purchase Group Name","LLDPE FILM") -> 251.22424 | H11: LLDPE FILM | I11: =+GETPIVOTDATA("Sum of Quantity",$A$3,"purchase Group Name","LLDPE FILM") -> 82.5 | J11: =+GETPIVOTDATA("Sum of Amount",$A$3,"purchase Group Name","LLDPE FILM") -> 20726 | K11: =+J11/I11 -> 251.22424
A12: Thinner | B12: 5489 | C12: 622392 | D12: =+GETPIVOTDATA("Sum of Amount",$A$3,"purchase Group Name","Thinner")/GETPIVOTDATA("Sum of Quantity",$A$3,"purchase Group Name","Thinner") -> 113.38896 | H12: Total : | I12: =SUM(I5:I11) -> 547753.42 | J12: =SUM(J5:J11) -> 83762688 | K12: =+J12/I12 -> 152.92043
A13: Printing Inks | B13: 1150 | C13: 305250 | D13: =+GETPIVOTDATA("Sum of Amount",$A$3,"purchase Group Name","Printing Inks")/GETPIVOTDATA("Sum of Quantity",$A$3,"purchase Group Name","Printing Inks") -> 265.43478
A14: FIBC WIP | B14: 8451.7 | C14: 1314136.1 | D14: =+GETPIVOTDATA("Sum of Amount",$A$3,"purchase Group Name","FIBC WIP")/GETPIVOTDATA("Sum of Quantity",$A$3,"purchase Group Name","FIBC WIP") -> 155.48778 | I14: 0 | J14: FABRIC CUT PCS.
A15: Grand Total | B15: 597739.12 | C15: 93138002 | I15: =+I13+I14 -> 0
A18: RAW MATERIAL COST | B18: =+GETPIVOTDATA("Sum of Quantity",$A$3,"purchase Group Name","LLDPE Bags")+GETPIVOTDATA("Sum of Quantity",$A$3,"purchase Group Name","LLDPE Doc")+GETPIVOTDATA("Sum of Quantity",$A$3,"purchase Group Name","PP Filament Yarn")+GETPIVOTDATA("Sum of Quantity",$A$3,"purchase Group Name","PP Laminated Woven Fabric")+GETPIVOTDATA("Sum of Quantity",$A$3,"purchase Group Name","PP Webbing")+GETPIVOTDATA("Sum of Quantity",$A$3,"purchase Group Name","PP Woven Fabric")+GETPIVOTDATA("Sum of Quantity",$A$3,"purchase Group Name","LLDPE FILM") -> 539301.72 | C18: =+GETPIVOTDATA("Sum of Amount",$A$3,"purchase Group Name","LLDPE Bags")+GETPIVOTDATA("Sum of Amount",$A$3,"purchase Group Name","LLDPE Doc")+GETPIVOTDATA("Sum of Amount",$A$3,"purchase Group Name","PP Filament Yarn")+GETPIVOTDATA("Sum of Amount",$A$3,"purchase Group Name","PP Laminated Woven Fabric")+GETPIVOTDATA("Sum of Amount",$A$3,"purchase Group Name","PP Webbing")+GETPIVOTDATA("Sum of Amount",$A$3,"purchase Group Name","PP Woven Fabric")+GETPIVOTDATA("Sum of Amount",$A$3,"purchase Group Name","LLDPE FILM") -> 82448552 | D18: =+C18/B18 -> 152.88019
A19: FABRIC COST | B19: =+GETPIVOTDATA("Sum of Quantity",$A$3,"purchase Group Name","PP Woven Fabric")+GETPIVOTDATA("Sum of Quantity",$A$3,"purchase Group Name","PP Laminated Woven Fabric") -> 382735.1 | C19: =+GETPIVOTDATA("Sum of Amount",$A$3,"purchase Group Name","PP Woven Fabric")+GETPIVOTDATA("Sum of Amount",$A$3,"purchase Group Name","PP Laminated Woven Fabric") -> 55757303 | D19: =+C19/B19 -> 145.68118
A22: Purchase value reco with Trail Balance Value
A23: Row Labels | B23: Sum of Amount | C23: AS PER T/B | D23: DIFFERENCE | H23: Date | I23: Particular | J23: Voucher Type | K23: Voucher No | L23: Type | M23: Invoice No | N23: Invoice Date | O23: Main Grp | P23: Group Name | Q23: Sub Grup | R23: purchase Group Name | S23: Item Name | T23: Quantity | U23: Amount | V23: Item Desc | W23: Bill Amount | X23: CGST Rate | Y23: CGST Amt | Z23: SGST Rate | AA23: SGST Amt | AB23: IGST Rate | AC23: IGST Amt | AD23: Freight GST | AE23: Total GST | AF23: TCS | AG23: GST-IN | AH23: Unit | AI23: HSN Code | AJ23: Currencty | AK23: Exc.Rate | AL23: Net Wt | AM23: Country
A24: Branch Transfer In - Raw Material | B24: 737284.43 | C24: =+'Trail Balance-JULY26'!C68 -> 737284.43 | D24: =+GETPIVOTDATA("Amount",$A$23,"Type","Branch Transfer In - Raw Material")-C24 -> 0 | H24: 46029 | I24: Plastene India ltd - Unit 1-Purchase | J24: General Purchase | K24: GNCN 234 | L24: Purchase Withinstate- Stores, Spares & Consumable | M24: PIL1/D/875 | N24: 46029 | O24: Stores/Spares | P24: MS Structure Items | Q24: Spares & Stores | R24: Stores & Consumables | S24: MS Pipe 4 C Class | T24: 354 | U24: 16992 | V24: MS Pipe 4 C Class | W24: 20033.57 | X24: 9 | Y24: 1529.28 | Z24: 9 | AA24: 1529.28 | AB24: 0 | AC24: 0 | AD24: 0 | AE24: 3058.56 | AF24: 0 | AG24: 24AAACO3087C1ZT | AH24: Kgs | AI24: 73063090 | AJ24: Rs. | AK24: 1 | AL24: 0 | AM24: India
A25: Purchase Withinstate - Raw Material | B25: 89309381 | C25: =+'Trail Balance-JULY26'!C72 -> 89309381 | D25: =+GETPIVOTDATA("Amount",$A$23,"Type","Purchase Withinstate - Raw Material")-C25 -> 0 | H25: 46029 | I25: Plastene India ltd - Unit 1-Purchase | J25: R.M.P. | K25: RM 324 | L25: Purchase Withinstate - Raw Material | M25: PIL1/D/874 | N25: 46029 | O25: SF | P25: PP/PE Fabric | Q25: PP Lam Fabric | R25: PP Laminated Woven Fabric | S25: PP Lam Fabric With UV | T25: 289 | U25: 44719.86 | V25: PP Lam Fabric With UV | W25: 1727090.3 | X25: 9 | Y25: 4024.79 | Z25: 9 | AA25: 4024.79 | AB25: 0 | AC25: 0 | AD25: 0 | AE25: 8049.58 | AF25: 0 | AG25: 24AAACO3087C1ZT | AH25: Kgs | AI25: 63053300 | AJ25: Rs. | AK25: 1 | AL25: 289 | AM25: India
A26: Purchase Withinstate - Traded Goods | B26: 2224616.5 | C26: =+'Trail Balance-JULY26'!C76 -> 2224616.5 | D26: =+GETPIVOTDATA("Amount",$A$23,"Type","Purchase Withinstate - Traded Goods")-C26 -> 0 | H26: 46029 | I26: Plastene India ltd - Unit 1-Purchase | J26: R.M.P. | K26: RM 324 | L26: Purchase Withinstate - Raw Material | M26: PIL1/D/874 | N26: 46029 | O26: SF | P26: PP/PE Fabric | Q26: PP UL Fabric | R26: PP Woven Fabric | S26: PP UL Fabric With UV | T26: 2836 | U26: 424662.64 | V26: PP UL Fabric With UV | W26: 0 | X26: 9 | Y26: 38219.64 | Z26: 9 | AA26: 38219.64 | AB26: 0 | AC26: 0 | AD26: 0 | AE26: 76439.28 | AF26: 0 | AG26: 24AAACO3087C1ZT | AH26: Kgs | AI26: 39269080 | AJ26: Rs. | AK26: 1 | AL26: 2836 | AM26: India
A27: Purchase Interstate - Raw Material | B27: 849175 | C27: =+'Trail Balance-JULY26'!C71 -> 849175 | D27: =+GETPIVOTDATA("Amount",$A$23,"Type","Purchase Interstate - Raw Material")-C27 -> 0 | H27: 46029 | I27: Plastene India ltd - Unit 1-Purchase | J27: R.M.P. | K27: RM 324 | L27: Purchase Withinstate - Raw Material | M27: PIL1/D/874 | N27: 46029 | O27: SF | P27: PP/PE Fabric | Q27: PP UL Fabric | R27: PP Woven Fabric | S27: PP UL Fabric With UV | T27: 6027 | U27: 890428.98 | V27: PP UL Fabric With UV | W27: 0 | X27: 9 | Y27: 80138.61 | Z27: 9 | AA27: 80138.61 | AB27: 0 | AC27: 0 | AD27: 0 | AE27: 160277.22 | AF27: 0 | AG27: 24AAACO3087C1ZT | AH27: Kgs | AI27: 39269080 | AJ27: Rs. | AK27: 1 | AL27: 6027 | AM27: India
A28: Branch Transfer In - Trading | B28: 394723.71 | C28: =+'Trail Balance-JULY26'!C69 -> 394723.71 | D28: =+GETPIVOTDATA("Amount",$A$23,"Type","Branch Transfer In - Trading")-C28 -> 0 | H28: 46029 | I28: Plastene India ltd - Unit 1-Purchase | J28: R.M.P. | K28: RM 324 | L28: Purchase Withinstate - Raw Material | M28: PIL1/D/874 | N28: 46029 | O28: SF | P28: PP/PE Fabric | Q28: PP UL Fabric | R28: PP Woven Fabric | S28: PP UL Fabric With UV | T28: 697 | U28: 105065.78 | V28: PP UL Fabric With UV | W28: 0 | X28: 9 | Y28: 9455.92 | Z28: 9 | AA28: 9455.92 | AB28: 0 | AC28: 0 | AD28: 0 | AE28: 18911.84 | AF28: 0 | AG28: 24AAACO3087C1ZT | AH28: Kgs | AI28: 39269080 | AJ28: Rs. | AK28: 1 | AL28: 697 | AM28: India
A29: Grand Total | B29: 93515181 | H29: 46029 | I29: Plastene India ltd - Unit 1-Purchase | J29: R.M.P. | K29: RM 325 | L29: Purchase Withinstate - Raw Material | M29: PIL1/D/876 | N29: 46029 | O29: SF | P29: Liners | Q29: LDPE/LLDPE Bags | R29: LLDPE Bags | S29: LDPE/LLDPE Bags/Liner | T29: 3917 | U29: 709564.55 | V29: LDPE/LLDPE Bags/Liner | W29: 1322447.8 | X29: 9 | Y29: 63860.81 | Z29: 9 | AA29: 63860.81 | AB29: 0 | AC29: 0 | AD29: 0 | AE29: 127721.62 | AF29: 0 | AG29: 24AAACO3087C1ZT | AH29: Kgs | AI29: 39200000 | AJ29: Rs. | AK29: 1 | AL29: 3917 | AM29: India
H30: 46029 | I30: Plastene India ltd - Unit 1-Purchase | J30: R.M.P. | K30: RM 325 | L30: Purchase Withinstate - Raw Material | M30: PIL1/D/876 | N30: 46029 | O30: SF | P30: PP/PE Fabric | Q30: PP Lam Fabric | R30: PP Laminated Woven Fabric | S30: PP Lam Fabric With UV | T30: 571 | U30: 88356.54 | V30: PP Lam Fabric With UV | W30: 0 | X30: 9 | Y30: 7952.09 | Z30: 9 | AA30: 7952.09 | AB30: 0 | AC30: 0 | AD30: 0 | AE30: 15904.18 | AF30: 0 | AG30: 24AAACO3087C1ZT | AH30: Kgs | AI30: 63053300 | AJ30: Rs. | AK30: 1 | AL30: 571 | AM30: India
H31: 46029 | I31: Plastene India ltd - Unit 1-Purchase | J31: R.M.P. | K31: RM 325 | L31: Purchase Withinstate - Raw Material | M31: PIL1/D/876 | N31: 46029 | O31: SF | P31: PP/PE Fabric | Q31: PP Lam Fabric | R31: PP Laminated Woven Fabric | S31: PP Lam Fabric With UV | T31: 400 | U31: 61896 | V31: PP Lam Fabric With UV | W31: 0 | X31: 9 | Y31: 5570.64 | Z31: 9 | AA31: 5570.64 | AB31: 0 | AC31: 0 | AD31: 0 | AE31: 11141.28 | AF31: 0 | AG31: 24AAACO3087C1ZT | AH31: Kgs | AI31: 63053300 | AJ31: Rs. | AK31: 1 | AL31: 400 | AM31: India
H32: 46029 | I32: Plastene India ltd - Unit 1-Purchase | J32: R.M.P. | K32: RM 325 | L32: Purchase Withinstate - Raw Material | M32: PIL1/D/876 | N32: 46029 | O32: SF | P32: Webbing | Q32: PP Webbing | R32: PP Webbing | S32: Webbing | T32: 236.8 | U32: 35458.43 | V32: Webbing | W32: 0 | X32: 9 | Y32: 3191.26 | Z32: 9 | AA32: 3191.26 | AB32: 0 | AC32: 0 | AD32: 0 | AE32: 6382.52 | AF32: 0 | AG32: 24AAACO3087C1ZT | AH32: Kgs | AI32: 3926908 | AJ32: Rs. | AK32: 1 | AL32: 236.8 | AM32: India
H33: 46029 | I33: Plastene India ltd - Unit 1-Purchase | J33: R.M.P. | K33: RM 325 | L33: Purchase Withinstate - Raw Material | M33: PIL1/D/876 | N33: 46029 | O33: SF | P33: Webbing | Q33: PP Webbing | R33: PP Webbing | S33: Webbing | T33: 1091.9 | U33: 166776.81 | V33: Webbing | W33: 0 | X33: 9 | Y33: 15009.91 | Z33: 9 | AA33: 15009.91 | AB33: 0 | AC33: 0 | AD33: 0 | AE33: 30019.82 | AF33: 0 | AG33: 24AAACO3087C1ZT | AH33: Kgs | AI33: 3926908 | AJ33: Rs. | AK33: 1 | AL33: 1091.9 | AM33: India
H34: 46029 | I34: Plastene India ltd - Unit 1-Purchase | J34: R.M.P. | K34: RM 325 | L34: Purchase Withinstate - Raw Material | M34: PIL1/D/876 | N34: 46029 | O34: SF | P34: Webbing | Q34: PP Webbing | R34: PP Webbing | S34: Webbing | T34: 9.8 | U34: 1702.65 | V34: Webbing | W34: 0 | X34: 9 | Y34: 153.24 | Z34: 9 | AA34: 153.24 | AB34: 0 | AC34: 0 | AD34: 0 | AE34: 306.48 | AF34: 0 | AG34: 24AAACO3087C1ZT | AH34: Kgs | AI34: 3926908 | AJ34: Rs. | AK34: 1 | AL34: 9.8 | AM34: India
H35: 46029 | I35: Plastene India ltd - Unit 1-Purchase | J35: R.M.P. | K35: RM 325 | L35: Purchase Withinstate - Raw Material | M35: PIL1/D/876 | N35: 46029 | O35: SF | P35: PP/PE Fabric | Q35: PP UL Fabric | R35: PP Woven Fabric | S35: PP UL Fabric With UV | T35: 392 | U35: 57914.08 | V35: PP UL Fabric With UV | W35: 0 | X35: 9 | Y35: 5212.27 | Z35: 9 | AA35: 5212.27 | AB35: 0 | AC35: 0 | AD35: 0 | AE35: 10424.54 | AF35: 0 | AG35: 24AAACO3087C1ZT | AH35: Kgs | AI35: 39269080 | AJ35: Rs. | AK35: 1 | AL35: 392 | AM35: India
H36: 46060 | I36: Plastene India ltd - Unit 1-Purchase | J36: General Purchase | K36: GNCN 235 | L36: Purchase Withinstate- Stores, Spares & Consumable | M36: PIL1/D/887 | N36: 46060 | O36: Stores/Spares | P36: MS Structure Items | Q36: Spares & Stores | R36: Stores & Consumables | S36: MS Pipe 4 C Class | T36: 194 | U36: 9312 | V36: MS Pipe 4 C Class | W36: 10978.85 | X36: 9 | Y36: 838.08 | Z36: 9 | AA36: 838.08 | AB36: 0 | AC36: 0 | AD36: 0 | AE36: 1676.16 | AF36: 0 | AG36: 24AAACO3087C1ZT | AH36: Kgs | AI36: 73063090 | AJ36: Rs. | AK36: 1 | AL36: 0 | AM36: India
H37: 46060 | I37: Plastene India ltd - Unit 1-Purchase | J37: R.M.P. | K37: RM 326 | L37: Purchase Withinstate - Raw Material | M37: PIL1/D/877 | N37: 46029 | O37: SF | P37: PP/PE Fabric | Q37: PP UL Fabric | R37: PP Woven Fabric | S37: PP UL Fabric With UV | T37: 491 | U37: 73522.34 | V37: PP UL Fabric With UV | W37: 355449.38 | X37: 9 | Y37: 6617.01 | Z37: 9 | AA37: 6617.01 | AB37: 0 | AC37: 0 | AD37: 0 | AE37: 13234.02 | AF37: 0 | AG37: 24AAACO3087C1ZT | AH37: Kgs | AI37: 39269080 | AJ37: Rs. | AK37: 1 | AL37: 491 | AM37: India
H38: 46060 | I38: Plastene India ltd - Unit 1-Purchase | J38: R.M.P. | K38: RM 326 | L38: Purchase Withinstate - Raw Material | M38: PIL1/D/877 | N38: 46029 | O38: FG | P38: FIBC WIP | Q38: FIBC WIP | R38: FIBC WIP | S38: PP Woven Fabric | T38: 500 | U38: 78870 | V38: FIBC WIP | W38: 0 | X38: 9 | Y38: 7098.3 | Z38: 9 | AA38: 7098.3 | AB38: 0 | AC38: 0 | AD38: 0 | AE38: 14196.6 | AF38: 0 | AG38: 24AAACO3087C1ZT | AH38: Kgs | AI38: 39269080 | AJ38: Rs. | AK38: 1 | AL38: 500 | AM38: India
H39: 46060 | I39: Plastene India ltd - Unit 1-Purchase | J39: R.M.P. | K39: RM 326 | L39: Purchase Withinstate - Raw Material | M39: PIL1/D/877 | N39: 46029 | O39: FG | P39: FIBC WIP | Q39: FIBC WIP | R39: FIBC WIP | S39: PP Woven Fabric | T39: 594 | U39: 94885.56 | V39: FIBC WIP | W39: 0 | X39: 9 | Y39: 8539.7 | Z39: 9 | AA39: 8539.7 | AB39: 0 | AC39: 0 | AD39: 0 | AE39: 17079.4 | AF39: 0 | AG39: 24AAACO3087C1ZT | AH39: Kgs | AI39: 39269080 | AJ39: Rs. | AK39: 1 | AL39: 594 | AM39: India
H40: 46060 | I40: Plastene India ltd - Unit 1-Purchase | J40: R.M.P. | K40: RM 326 | L40: Purchase Withinstate - Raw Material | M40: PIL1/D/877 | N40: 46029 | O40: SF | P40: PP/PE Fabric | Q40: PP Lam Fabric | R40: PP Laminated Woven Fabric | S40: PP Lam Fabric With UV | T40: 362 | U40: 54205.88 | V40: PP Lam Fabric With UV | W40: 0 | X40: 9 | Y40: 4878.53 | Z40: 9 | AA40: 4878.53 | AB40: 0 | AC40: 0 | AD40: 0 | AE40: 9757.06 | AF40: 0 | AG40: 24AAACO3087C1ZT | AH40: Kgs | AI40: 63053300 | AJ40: Rs. | AK40: 1 | AL40: 362 | AM40: India
H41: 46060 | I41: Plastene India ltd - Unit 1-Purchase | J41: R.M.P. | K41: RM 327 | L41: Purchase Withinstate - Raw Material | M41: PIL1/D/884 | N41: 46060 | O41: SF | P41: Liners | Q41: LDPE/LLDPE Bags | R41: LLDPE Bags | S41: LDPE/LLDPE Bags/Liner | T41: 435 | U41: 78800.25 | V41: LDPE/LLDPE Bags/Liner | W41: 1680961 | X41: 9 | Y41: 7092.02 | Z41: 9 | AA41: 7092.02 | AB41: 0 | AC41: 0 | AD41: 0 | AE41: 14184.04 | AF41: 0 | AG41: 24AAACO3087C1ZT | AH41: Kgs | AI41: 39200000 | AJ41: Rs. | AK41: 1 | AL41: 435 | AM41: India
... H54: 46060 | I54: Plastene Polyfilms Ltd-Purchase | J54: R.M.P. | K54: RM 329 | L54: Purchase Withinstate - Raw Material | M54: PPL/D/303 | N54: 46060 | O54: SF | P54: Liners | Q54: LDPE/LLDPE Bags | R54: LLDPE Bags | S54: LDPE/LLDPE Bags/Liner | T54: 60 | U54: 11580 | V54: LDPE/LLDPE Bags/Liner | W54: 13652.82 | X54: 9 | Y54: 1042.2 | Z54: 9 | AA54: 1042.2 | AB54: 0 | AC54: 0 | AD54: 0 | AE54: 2084.4 | AF54: 0 | AG54: 24AAFCP2956A1ZR | AH54: Kgs | AI54: 39200000 | AJ54: Rs. | AK54: 1 | AL54: 60 | AM54: India
H55: 46088 | I55: Accurate Rub Tech | J55: General Purchase | K55: GNSP 110 | L55: Purchase Withinstate- Stores, Spares & Consumable | M55: 240 | N55: 26-06-2026 | O55: Stores/Spares | P55: Lamination Plant Spares | Q55: Spares & Stores | R55: Stores & Consumables | S55: Coating Steel Roller | T55: 2 | U55: 26200 | V55: Coating Steel Roller | W55: 30916 | X55: 9 | Y55: 2358 | Z55: 9 | AA55: 2358 | AB55: 0 | AC55: 0 | AD55: 0 | AE55: 4716 | AF55: 0 | AG55: 24ABNFA9143N1ZY | AH55: Pcs | AI55: 84779000 | AJ55: Rs. | AK55: 1 | AL55: 0 | AM55: India
H56: 46088 | I56: Chandan Electric Store | J56: General Purchase | K56: GNSP 108 | L56: Purchase Withinstate- Stores, Spares & Consumable | M56: CES/26-27/776 | N56: 30-06-2026 | O56: Stores/Spares | P56: PVC Fittings | Q56: Spares & Stores | R56: Stores & Consumables | S56: Pvc Flexible Pipe 25 mm | T56: 200 | U56: 2400 | V56: Pvc Flexible Pipe 25 mm | W56: 2832 | X56: 9 | Y56: 216 | Z56: 9 | AA56: 216 | AB56: 0 | AC56: 0 | AD56: 0 | AE56: 432 | AF56: 0 | AG56: 24AAIPH7590J1ZE | AH56: MTR | AI56: 391731 | AJ56: Rs. | AK56: 1 | AL56: 0 | AM56: India
H57: 46088 | I57: Chandan Electric Store | J57: General Purchase | K57: GNSP 109 | L57: Purchase Withinstate- Stores, Spares & Consumable | M57: CES/26-27/777 | N57: 30-06-2026 | O57: Stores/Spares | P57: Capacitors | Q57: Spares & Stores | R57: Stores & Consumables | S57: Capacitor 2.5 Mfd | T57: 70 | U57: 1680 | V57: Capacitor 2.5 Mfd | W57: 1982 | X57: 9 | Y57: 151.2 | Z57: 9 | AA57: 151.2 | AB57: 0 | AC57: 0 | AD57: 0 | AE57: 302.4 | AF57: 0 | AG57: 24AAIPH7590J1ZE | AH57: PCS | AI57: 85322500 | AJ57: Rs. | AK57: 1 | AL57: 0 | AM57: India
...

Sheet Sales Register
A1: Row Labels | B1: Sum of Quantity | C1: Sum of Amount
A2: HDPE/PP Plastik Waste | B2: 27775 | C2: 333300 | D2: =+GETPIVOTDATA("Sum of Amount",$A$1,"sales Group Name","HDPE/PP Plastik Waste")/GETPIVOTDATA("Sum of Quantity",$A$1,"sales Group Name","HDPE/PP Plastik Waste") -> 12
A3: JUMBO BAG | B3: 595287.7 | C3: 1.357541e+08 | D3: =+GETPIVOTDATA("Sum of Amount",$A$1,"sales Group Name","JUMBO BAG")/GETPIVOTDATA("Sum of Quantity",$A$1,"sales Group Name","JUMBO BAG") -> 228.04789
A4: PP Woven Fabric | B4: 1850 | C4: 286960.25 | D4: =+GETPIVOTDATA("Sum of Amount",$A$1,"sales Group Name","PP Woven Fabric")/GETPIVOTDATA("Sum of Quantity",$A$1,"sales Group Name","PP Woven Fabric") -> 155.11365
A5: LLDPE Bags | B5: 26 | C5: 4709.9 | D5: =+GETPIVOTDATA("Sum of Amount",$A$1,"sales Group Name","LLDPE Bags")/GETPIVOTDATA("Sum of Quantity",$A$1,"sales Group Name","LLDPE Bags") -> 181.15 | F5: =+D3*0.95 -> 216.64549
A6: PP Filament Yarn | B6: 132 | C6: 21338.68 | D6: =+GETPIVOTDATA("Sum of Amount",$A$1,"sales Group Name","PP Filament Yarn")/GETPIVOTDATA("Sum of Quantity",$A$1,"sales Group Name","PP Filament Yarn") -> 161.65667
A7: Thinner | B7: 510 | C7: 84660 | D7: =+GETPIVOTDATA("Sum of Amount",$A$1,"sales Group Name","Thinner")/GETPIVOTDATA("Sum of Quantity",$A$1,"sales Group Name","Thinner") -> 166
A8: PP Webbing | B8: 191.9 | C8: 28687.13 | D8: =+GETPIVOTDATA("Sum of Amount",$A$1,"sales Group Name","PP Webbing")/GETPIVOTDATA("Sum of Quantity",$A$1,"sales Group Name","PP Webbing") -> 149.48999
A9: FIBC WIP | B9: 9077 | C9: 261688.38 | D9: =+GETPIVOTDATA("Sum of Amount",$A$1,"sales Group Name","FIBC WIP")/GETPIVOTDATA("Sum of Quantity",$A$1,"sales Group Name","FIBC WIP") -> 28.829831
A10: Grand Total | B10: 634849.6 | C10: 1.3677545e+08
A15: Sales value reco with Trail Balance Value
A16: Row Labels | B16: Sum of Amount | C16: AS PER T/B | D16: DIFFERENCE | H16: Date | I16: Particular | J16: Voucher Type | K16: Voucher No | L16: Type | M16: Invoice No | N16: Invoice Date | O16: Main Grp | P16: Group Name | Q16: Sub Grup | R16: sales Group Name | S16: Item Name | T16: Quantity | U16: Amount | V16: Item Desc | W16: Bill Amount | X16: CGST Rate | Y16: CGST Amt | Z16: SGST Rate | AA16: SGST Amt | AB16: IGST Rate | AC16: IGST Amt | AD16: Freight GST | AE16: Total GST | AF16: TCS | AG16: GST-IN | AH16: Unit | AI16: HSN Code | AJ16: Currencty | AK16: Exc.Rate | AL16: Net Wt | AM16: Country
A17: Sales - Kasez - Mfg - U/B | B17: 2058957 | C17: =+'Trail Balance-JULY26'!D128 -> 2058957 | D17: =+GETPIVOTDATA("Amount",$A$16,"Type","Sales - Kasez - Mfg - U/B")-C17 -> 0.01 | H17: 46029 | I17: Plastene India ltd - Unit 1-Sales | J17: Sales | K17: 137 | L17: Sales - Within State Manufactured Goods | M17: HPBL4/D/137 | N17: 46029 | O17: FG | P17: FIBC Bags | Q17: FIBC Bags | R17: JUMBO BAG | S17: FIBC Bags With UV With Liner | T17: 855 | U17: 179746.65 | V17: 87x87x87 | W17: 1449554.6 | X17: 9 | Y17: 16177.2 | Z17: 9 | AA17: 16177.2 | AB17: 0 | AC17: 0 | AD17: 0 | AE17: 32354.4 | AF17: 0 | AG17: 24AAACO3087C1ZT | AH17: KGS | AI17: 63053200 | AJ17: Rs. | AK17: 1 | AL17: 855 | AM17: India
A18: Sales - Within State - Traded Goods | B18: 3117803.8 | C18: =+'Trail Balance-JULY26'!D137 -> 3117803.8 | D18: =+GETPIVOTDATA("Amount",$A$16,"Type","Sales - Within State - Traded Goods")-C18 -> 0 | H18: 46029 | I18: Plastene India ltd - Unit 1-Sales | J18: Sales | K18: 137 | L18: Sales - Within State Manufactured Goods | M18: HPBL4/D/137 | N18: 46029 | O18: FG | P18: FIBC Bags | Q18: FIBC Bags | R18: JUMBO BAG | S18: FIBC Bags With UV Without Liner | T18: 415 | U18: 110618.25 | V18: 85x85x85 | W18: 0 | X18: 9 | Y18: 9955.64 | Z18: 9 | AA18: 9955.64 | AB18: 0 | AC18: 0 | AD18: 0 | AE18: 19911.28 | AF18: 0 | AG18: 24AAACO3087C1ZT | AH18: KGS | AI18: 63053200 | AJ18: Rs. | AK18: 1 | AL18: 415 | AM18: India
A19: Sales - Within State Manufactured Goods | B19: 19349307 | C19: =+'Trail Balance-JULY26'!D130 -> 19349307 | D19: =+GETPIVOTDATA("Amount",$A$16,"Type","Sales - Within State Manufactured Goods")-C19 -> 0 | H19: 46029 | I19: Plastene India ltd - Unit 1-Sales | J19: Sales | K19: 137 | L19: Sales - Within State Manufactured Goods | M19: HPBL4/D/137 | N19: 46029 | O19: FG | P19: FIBC Bags | Q19: FIBC Bags | R19: JUMBO BAG | S19: FIBC Bags With UV Without Liner | T19: 431 | U19: 109780.01 | V19: 90x90x90 | W19: 0 | X19: 9 | Y19: 9880.2 | Z19: 9 | AA19: 9880.2 | AB19: 0 | AC19: 0 | AD19: 0 | AE19: 19760.4 | AF19: 0 | AG19: 24AAACO3087C1ZT | AH19: KGS | AI19: 63053200 | AJ19: Rs. | AK19: 1 | AL19: 431 | AM19: India
A20: Sales - Direct Export - Mfg - U/R | B20: 49412158 | C20: =+'Trail Balance-JULY26'!D132 -> 49412158 | D20: =+GETPIVOTDATA("Amount",$A$16,"Type","Sales - Direct Export - Mfg - U/R")-C20 -> 0 | H20: 46029 | I20: Plastene India ltd - Unit 1-Sales | J20: Sales | K20: 137 | L20: Sales - Within State Manufactured Goods | M20: HPBL4/D/137 | N20: 46029 | O20: FG | P20: FIBC Bags | Q20: FIBC Bags | R20: JUMBO BAG | S20: FIBC Bags With UV Without Liner | T20: 462 | U20: 115786.44 | V20: 85x85x85 | W20: 0 | X20: 9 | Y20: 10420.78 | Z20: 9 | AA20: 10420.78 | AB20: 0 | AC20: 0 | AD20: 0 | AE20: 20841.56 | AF20: 0 | AG20: 24AAACO3087C1ZT | AH20: KGS | AI20: 63053200 | AJ20: Rs. | AK20: 1 | AL20: 462 | AM20: India
A21: Sales - Waste & Scrape | B21: 383952 | C21: =+'Trail Balance-JULY26'!D138 -> 383952 | D21: =+GETPIVOTDATA("Amount",$A$16,"Type","Sales - Waste & Scrape")-C21 -> 0 | H21: 46029 | I21: Plastene India ltd - Unit 1-Sales | J21: Sales | K21: 137 | L21: Sales - Within State Manufactured Goods | M21: HPBL4/D/137 | N21: 46029 | O21: FG | P21: FIBC Bags | Q21: FIBC Bags | R21: JUMBO BAG | S21: FIBC Bags With UV Without Liner | T21: 838 | U21: 203809.98 | V21: 90x90x90 | W21: 0 | X21: 9 | Y21: 18342.9 | Z21: 9 | AA21: 18342.9 | AB21: 0 | AC21: 0 | AD21: 0 | AE21: 36685.8 | AF21: 0 | AG21: 24AAACO3087C1ZT | AH21: KGS | AI21: 63053200 | AJ21: Rs. | AK21: 1 | AL21: 838 | AM21: India
A22: Sales - Merchant Export | B22: 12043513 | C22: =+'Trail Balance-JULY26'!D129 -> 12043513 | D22: =+GETPIVOTDATA("Amount",$A$16,"Type","Sales - Merchant Export")-C22 -> 0 | H22: 46029 | I22: Plastene India ltd - Unit 1-Sales | J22: Sales | K22: 137 | L22: Sales - Within State Manufactured Goods | M22: HPBL4/D/137 | N22: 46029 | O22: FG | P22: FIBC Bags | Q22: FIBC Bags | R22: JUMBO BAG | S22: FIBC Bags With UV Without Liner | T22: 1329 | U22: 311025.87 | V22: 85x85x85 | W22: 0 | X22: 9 | Y22: 27992.33 | Z22: 9 | AA22: 27992.33 | AB22: 0 | AC22: 0 | AD22: 0 | AE22: 55984.66 | AF22: 0 | AG22: 24AAACO3087C1ZT | AH22: KGS | AI22: 63053200 | AJ22: Rs. | AK22: 1 | AL22: 1329 | AM22: India
A23: Sales - Direct Export - Mfg - U/B | B23: 50894795 | C23: =+'Trail Balance-JULY26'!D131 -> 50894795 | D23: =+GETPIVOTDATA("Amount",$A$16,"Type","Sales - Direct Export - Mfg - U/B")-C23 -> 0 | H23: 46029 | I23: Plastene India ltd - Unit 1-Sales | J23: Sales | K23: 137 | L23: Sales - Within State Manufactured Goods | M23: HPBL4/D/137 | N23: 46029 | O23: FG | P23: FIBC Bags | Q23: FIBC Bags | R23: JUMBO BAG | S23: FIBC Bags With UV Without Liner | T23: 826 | U23: 198710.82 | V23: 90x90x90 | W23: 0 | X23: 9 | Y23: 17883.97 | Z23: 9 | AA23: 17883.97 | AB23: 0 | AC23: 0 | AD23: 0 | AE23: 35767.94 | AF23: 0 | AG23: 24AAACO3087C1ZT | AH23: KGS | AI23: 63053200 | AJ23: Rs. | AK23: 1 | AL23: 826 | AM23: India
A24: Sales - Kasez - Trading - U/B | B24: 48000 | C24: =+'Trail Balance-JULY26'!D136 -> 48000 | D24: =+GETPIVOTDATA("Amount",$A$16,"Type","Sales - Kasez - Trading - U/B")-C24 -> 0 | H24: 46029 | I24: Plastene India ltd - Unit 1-Sales | J24: Sales | K24: 138 | L24: Sales - Within State - Traded Goods | M24: HPBL4/D/138 | N24: 46029 | O24: SF | P24: Yarn All | Q24: PP Yarn | R24: PP Filament Yarn | S24: PP MF Yarn Twisted 3000 Denier UV Deep Blue | T24: 88 | U24: 14321.12 | V24: PP MF Yarn Twisted 3000 Denier UV Deep Blue | W24: 15022.86 | X24: 2.5 | Y24: 358.03 | Z24: 2.5 | AA24: 358.03 | AB24: 0 | AC24: 0 | AD24: 0 | AE24: 716.06 | AF24: 0 | AG24: 24AAACO3087C1ZT | AH24: KGS | AI24: 54026300 | AJ24: Rs. | AK24: 1 | AL24: 88 | AM24: India
A25: Grand Total | B25: 1.3730849e+08 | H25: 46029 | I25: Qpac Ltd | J25: Export Sales | K25: HPBL4/E/52/26-27 | L25: Sales - Direct Export - Mfg - U/R | M25: HPBL4/E/52/26-27 | N25: 46029 | O25: FG | P25: FIBC Bags | Q25: FIBC Bags | R25: JUMBO BAG | S25: FIBC Bags With UV Without Liner | T25: 19351 | U25: 4855238.6 | V25: PP WOVEN BIG BAGS/SACKS | W25: 5166701.6 | X25: 0 | Y25: 0 | Z25: 0 | AA25: 0 | AB25: 18 | AC25: 873942.97 | AD25: 0 | AE25: 873942.97 | AF25: 0 | AG25: N.A. | AH25: KGS | AI25: 63053200 | AJ25: GBP | AK25: 123.7 | AL25: 19351 | AM25: United Kingdom
H26: 46029 | I26: Qpac Ltd | J26: Export Sales | K26: HPBL4/E/53/26-27 | L26: Sales - Direct Export - Mfg - U/R | M26: HPBL4/E/53/26-27 | N26: 46029 | O26: FG | P26: FIBC Bags | Q26: FIBC Bags | R26: JUMBO BAG | S26: FIBC Bags With UV Without Liner | T26: 19049 | U26: 4503569.4 | V26: PP WOVEN BIG BAGS/SACKS | W26: 4814856.7 | X26: 0 | Y26: 0 | Z26: 0 | AA26: 0 | AB26: 18 | AC26: 810642.47 | AD26: 0 | AE26: 810642.47 | AF26: 0 | AG26: N.A. | AH26: KGS | AI26: 63053200 | AJ26: GBP | AK26: 123.7 | AL26: 19049 | AM26: United Kingdom
